File: data/A344/raw/A344_cool_zero_field_500_160908.rso.raw
[Header]
TITLE,MPMS RSO Measurement
BYAPP,MPMS Measurement,2.1,Raw with ABS
FILEOPENTIME, 1473347048.209000 9/9/2016, 3:04:08 AM

INFO, APPNAME, MPMS MultiVu Application, Revision 1.61,  Build 082

INFO, NAME, A344
INFO, WEIGHT, 10.500
INFO, AREA, 1.000
INFO, LENGTH, 1.000
INFO, SHAPE, 0
INFO, COMMENT, m = 0.0105g
INFO, SEQUENCE FILE: cool_zero_field_magnet_reset_120K-5K.seq


INFO, BACKGROUND DATA FILE:, None


STARTUPAXIS,X,8,LINEAR,AUTO,0.000000,0.000000
STARTUPAXIS,Y1,9,LINEAR,AUTO,0.000000,0.000000


STARTUPGROUP,Longitudinal
FIELDGROUP,Longitudinal,1,2,3,4,5,6,7,8,9,10,11,12,13,14,15,16,17,18,19,20,21,22
FIELDGROUP,Transverse,1,2,3,4,5,6,7,8,23,24,25,26,27,28,29,30,31,32,33,34,35,36

PLOT_APPEARANCE,ALL,HORZ_GRID_ON,VERT_GRID_ON,MARKERS_ONLY

[Data]
Time,Comment,Field (Oe),Start Temperature (K),End Temperature (K),Scan,Rejected,Position (cm),Long Voltage,Long Average Voltage,Long Detrended Voltage,Long Demeaned Voltage,Long Reg Fit,Long Detrended Fit,Long Demeaned Fit,Long Scaled Response,Long Avg. Scaled Response,Long Background Response,Long Response [w/ABS],Long Detrended Resp. [w/ABS],Long Fit [w/ABS],Long Detrended Fit [w/ABS],Trans Voltage,Trans Average Voltage,Trans Detrended Voltage,Trans Demeaned Voltage,Trans Reg Fit,Trans Detrended Fit,Trans Demeaned Fit,Trans Scaled Response,Trans Avg. Scaled Response,Trans Background Response,Trans Response [w/ABS],Trans Detrended Resp. [w/ABS],Trans Adjusted Fit,Trans Detrended Fit [w/ABS],
1473347048.188,,0.000000e+000,1.200073e+002,1.200007e+002,1,0,2.590943e+000,2.594073e-003,2.594073e-003,-1.274056e-001,-1.274056e-001,4.649009e-002,-8.350956e-002,-8.350956e-002,6.497933e-008,6.497933e-008,,,,,,,,,,,,,,,,,,,,
1473347048.188,,0.000000e+000,1.200073e+002,1.200007e+002,1,0,4.910390e+000,5.706961e-002,5.706961e-002,1.094299e-002,-7.293004e-002,6.495140e-002,1.882478e-002,-6.504826e-002,1.429545e-006,1.429545e-006,,,,,,,,,,,,,,,,,,,,
1473347061.197,,0.000000e+000,1.200007e+002,1.199974e+002,1,0,3.308583e+000,5.111850e-002,5.111850e-002,-3.697247e-002,-9.647037e-002,5.892771e-002,-2.916327e-002,-8.866117e-002,1.280475e-006,1.280475e-006,,,,,,,,,,,,,,,,,,,,
1473347072.965,,0.000000e+000,1.200106e+002,1.200007e+002,1,0,5.499856e-001,1.692251e-001,1.692251e-001,6.619025e-002,3.050576e-002,1.290698e-001,2.603496e-002,-9.649530e-003,4.238946e-006,4.238946e-006,,,,,,,,,,,,,,,,,,,,
1473347086.335,,0.000000e+000,1.200073e+002,1.200040e+002,1,0,8.663819e-001,2.230903e-001,2.230903e-001,9.468053e-002,8.187141e-002,1.634971e-001,3.508735e-002,2.227823e-002,5.588222e-006,5.588222e-006,,,,,,,,,,,,,,,,,,,,
1473347086.335,,0.000000e+000,1.200073e+002,1.200040e+002,1,0,3.802398e+000,5.783258e-002,5.783258e-002,9.479810e-003,-8.338632e-002,6.601450e-002,1.766173e-002,-7.520440e-002,1.448657e-006,1.448657e-006,,,,,,,,,,,,,,,,,,,,
1473347337.578,,0.000000e+000,1.147312e+002,1.140683e+002,1,0,4.767254e+000,1.058992e-001,1.058992e-001,-4.406981e-003,-6.772920e-002,1.325287e-001,2.222248e-002,-4.109974e-002,2.652685e-006,2.652685e-006,,,,,,,,,,,,,,,,,,,,
1473347351.542,,0.000000e+000,1.139253e+002,1.131862e+002,1,0,1.973575e+000,9.491257e-002,9.491257e-002,-1.405530e-002,-6.631923e-002,7.542999e-002,-3.353788e-002,-8.580181e-002,2.377479e-006,2.377479e-006,,,,,,,,,,,,,,,,,,,,
1473347365.687,,0.000000e+000,1.130601e+002,1.124449e+002,1,0,7.258091e-003,7.873775e-002,7.873776e-002,-4.811562e-002,-7.316253e-002,1.375459e-001,1.069251e-002,-1.435441e-002,1.972314e-006,1.972314e-006,,,,,,,,,,,,,,,,,,,,
1473347379.010,,0.000000e+000,1.123015e+002,1.114971e+002,1,0,2.139451e+000,9.216589e-002,9.216590e-002,-7.951728e-002,-8.265424e-002,1.211241e-001,-5.055911e-002,-5.369607e-002,2.308677e-006,2.308677e-006,,,,,,,,,,,,,,,,,,,,
1473347379.010,,0.000000e+000,1.123015e+002,1.114971e+002,1,0,4.717506e+000,1.031526e-001,1.031526e-001,9.893412e-003,-7.166757e-002,1.191307e-001,2.587152e-002,-5.568947e-002,2.583884e-006,2.583884e-006,,,,,,,,,,,,,,,,,,,,
1473347416.726,,0.000000e+000,1.096904e+002,1.089645e+002,1,0,3.736797e+000,8.117923e-002,8.117924e-002,-2.360292e-002,-8.649648e-002,1.187391e-001,1.395695e-002,-4.893661e-002,2.033471e-006,2.033471e-006,,,,,,,,,,,,,,,,,,,,
1473347429.986,,0.000000e+000,1.087954e+002,1.080752e+002,1,0,8.595889e-001,2.523881e-001,2.523881e-001,1.232408e-001,8.319445e-002,1.660420e-001,3.689470e-002,-3.151655e-003,6.322106e-006,6.322106e-006,,,,,,,,,,,,,,,,,,,,
1473347441.235,,0.000000e+000,1.078818e+002,1.071121e+002,1,0,5.143573e-001,1.821955e-001,1.821955e-001,3.548149e-002,1.946509e-002,1.705217e-001,2.380770e-002,7.791296e-003,4.563842e-006,4.563842e-006,,,,,,,,,,,,,,,,,,,,
1473347441.235,,0.000000e+000,1.078818e+002,1.071121e+002,1,0,3.432496e+000,7.232887e-002,7.232887e-002,5.696849e-003,-9.040155e-002,5.074527e-002,-1.588675e-002,-1.119851e-001,1.811777e-006,1.811777e-006,,,,,,,,,,,,,,,,,,,,
1473347454.211,,0.000000e+000,1.069483e+002,1.061780e+002,1,0,4.944747e+000,8.667257e-002,8.667257e-002,2.680525e-003,-7.478500e-002,1.012580e-001,1.726593e-002,-6.019960e-002,2.171074e-006,2.171074e-006,,,,,,,,,,,,,,,,,,,,
1473347485.927,,0.000000e+000,1.046330e+002,1.038238e+002,1,0,2.409907e+000,2.349925e-002,2.349925e-002,-6.982549e-002,-1.212298e-001,1.565025e-002,-7.767449e-002,-1.290788e-001,5.886363e-007,5.886363e-007,,,,,,,,,,,,,,,,,,,,
1473347497.895,,0.000000e+000,1.038238e+002,1.030263e+002,1,0,9.039408e-002,1.026948e-001,1.026948e-001,-3.344250e-002,-6.152121e-002,1.485732e-001,1.243593e-002,-1.564278e-002,2.572417e-006,2.572417e-006,,,,,,,,,,,,,,,,,,,,
1473347512.359,,0.000000e+000,1.024223e+002,1.018298e+002,1,0,1.691968e+000,1.614429e-001,1.614429e-001,-5.790185e-003,-1.213388e-002,1.639874e-001,-3.245693e-003,-9.589389e-003,4.044008e-006,4.044008e-006,,,,,,,,,,,,,,,,,,,,
1473347512.359,,0.000000e+000,1.024223e+002,1.018298e+002,1,0,4.450659e+000,9.872738e-002,9.872738e-002,1.079047e-002,-7.484943e-002,1.213595e-001,3.342264e-002,-5.221726e-002,2.473037e-006,2.473037e-006,,,,,,,,,,,,,,,,,,,,
1473347525.112,,0.000000e+000,1.015945e+002,1.007958e+002,1,0,4.134386e+000,8.621480e-002,8.621479e-002,-1.220603e-002,-7.659844e-002,1.345757e-001,3.615489e-002,-2.823752e-002,2.159607e-006,2.159607e-006,,,,,,,,,,,,,,,,,,,,
1473347545.608,,0.000000e+000,9.994131e+001,9.912921e+001,1,0,1.198423e+000,2.348399e-001,2.348399e-001,1.242648e-001,8.058614e-002,1.430475e-001,3.247237e-002,-1.120627e-002,5.882540e-006,5.882540e-006,,,,,,,,,,,,,,,,,,,,
1473347559.573,,0.000000e+000,9.868285e+001,9.760344e+001,1,0,2.333769e-001,1.469466e-001,1.469466e-001,-1.239932e-002,-3.107128e-002,1.750554e-001,1.570944e-002,-2.962515e-003,3.680888e-006,3.680888e-006,,,,,,,,,,,,,,,,,,,,
1473347559.573,,0.000000e+000,9.868285e+001,9.760344e+001,1,0,3.027073e+000,7.629627e-002,7.629628e-002,-5.249833e-003,-1.017216e-001,2.261451e-002,-5.893160e-002,-1.554034e-001,1.911157e-006,1.911157e-006,,,,,,,,,,,,,,,,,,,,
1473347574.037,,0.000000e+000,9.739953e+001,9.656572e+001,1,0,4.993517e+000,9.063997e-002,9.063997e-002,1.552057e-002,-6.059282e-002,9.220024e-002,1.708085e-002,-5.903255e-002,2.270454e-006,2.270454e-006,,,,,,,,,,,,,,,,,,,,
1473347587.502,,0.000000e+000,9.611286e+001,9.525300e+001,1,0,2.861384e+000,3.295999e-002,3.295999e-002,-6.229689e-002,-1.166609e-001,2.141859e-002,-7.383829e-002,-1.282023e-001,8.256197e-007,8.256197e-007,,,,,,,,,,,,,,,,,,,,
1473347634.520,,0.000000e+000,9.222878e+001,9.164558e+001,1,0,2.835025e-001,1.815851e-001,1.815851e-001,9.134958e-003,-1.832446e-002,1.897563e-001,1.730617e-002,-1.015325e-002,4.548553e-006,4.548553e-006,,,,,,,,,,,,,,,,,,,,
1473347647.272,,0.000000e+000,9.119807e+001,9.032102e+001,1,0,1.263808e+000,2.832118e-001,2.832118e-001,7.916815e-002,7.113096e-002,2.337707e-001,2.972708e-002,2.168989e-002,7.094214e-006,7.094214e-006,,,,,,,,,,,,,,,,,,,,
1473347647.272,,0.000000e+000,9.119807e+001,9.032102e+001,1,0,4.140894e+000,1.521348e-001,1.521348e-001,1.506772e-002,-5.994603e-002,1.726402e-001,3.557319e-002,-3.944056e-002,3.810846e-006,3.810846e-006,,,,,,,,,,,,,,,,,,,,
1473347658.784,,0.000000e+000,9.012955e+001,8.947481e+001,1,0,4.486442e+000,1.203955e-001,1.203955e-001,-8.092049e-003,-6.464312e-002,1.609812e-001,3.249361e-002,-2.405746e-002,3.015805e-006,3.015805e-006,,,,,,,,,,,,,,,,,,,,
1473347672.748,,0.000000e+000,8.906942e+001,8.821386e+001,1,0,1.568429e+000,2.163762e-001,2.163762e-001,5.474904e-002,1.549508e-002,1.692161e-001,7.588860e-003,-3.166510e-002,5.420040e-006,5.420040e-006,,,,,,,,,,,,,,,,,,,,
1473347684.962,,0.000000e+000,8.801791e+001,8.737904e+001,1,0,5.589960e-002,1.164281e-001,1.164281e-001,-4.369163e-002,-6.371992e-002,1.717822e-001,1.166240e-002,-8.365884e-003,2.916425e-006,2.916425e-006,,,,,,,,,,,,,,,,,,,,
1473347698.927,,0.000000e+000,8.696096e+001,8.614306e+001,1,0,2.590611e+000,7.354961e-002,7.354961e-002,-1.304373e-001,-1.304373e-001,1.214035e-001,-8.258342e-002,-8.258342e-002,1.842355e-006,1.842355e-006,,,,,,,,,,,,,,,,,,,,
1473347698.927,,0.000000e+000,8.696096e+001,8.614306e+001,1,0,4.910243e+000,1.409955e-001,1.409955e-001,1.078581e-002,-6.299137e-002,1.485850e-001,1.837525e-002,-5.540192e-002,3.531818e-006,3.531818e-006,,,,,,,,,,,,,,,,,,,,
1473347712.332,,0.000000e+000,8.571172e+001,8.505946e+001,1,0,3.308893e+000,8.728293e-002,8.728294e-002,-3.769106e-002,-9.112369e-002,9.720524e-002,-2.776875e-002,-8.120138e-002,2.186363e-006,2.186363e-006,,,,,,,,,,,,,,,,,,,,
1473347727.405,,0.000000e+000,8.467735e+001,8.383431e+001,1,0,5.502087e-001,2.049318e-001,2.049318e-001,6.482427e-002,3.089492e-002,1.661903e-001,2.608275e-002,-7.846594e-003,5.133367e-006,5.133367e-006,,,,,,,,,,,,,,,,,,,,
1473347739.869,,0.000000e+000,8.345424e+001,8.284534e+001,1,0,8.662650e-001,2.790917e-001,2.790918e-001,9.780496e-002,8.541156e-002,2.162993e-001,3.501250e-002,2.261910e-002,6.991012e-006,6.991012e-006,,,,,,,,,,,,,,,,,,,,
1473347739.869,,0.000000e+000,8.345424e+001,8.284534e+001,1,0,3.802136e+000,1.159703e-001,1.159703e-001,1.214226e-002,-7.770988e-002,1.222970e-001,1.846890e-002,-7.138324e-002,2.904958e-006,2.904958e-006,,,,,,,,,,,,,,,,,,,,
1473347753.583,,0.000000e+000,8.265342e+001,8.164599e+001,1,0,4.767371e+000,1.115452e-001,1.115452e-001,-5.890238e-004,-6.870418e-002,1.346901e-001,2.255596e-002,-4.555920e-002,2.794111e-006,2.794111e-006,,,,,,,,,,,,,,,,,,,,
1473347767.548,,0.000000e+000,8.148611e+001,8.051755e+001,1,0,1.973751e+000,1.181066e-001,1.181066e-001,-1.019593e-002,-5.678491e-002,9.460455e-002,-3.369801e-002,-8.028699e-002,2.958471e-006,2.958471e-006,,,,,,,,,,,,,,,,,,,,
1473347781.262,,0.000000e+000,8.032487e+001,8.002454e+001,1,0,7.246000e-003,1.113926e-001,1.113926e-001,-4.714477e-002,-7.223563e-002,1.694198e-001,1.088248e-002,-1.420838e-002,2.790289e-006,2.790289e-006,,,,,,,,,,,,,,,,,,,,
1473347913.523,,0.000000e+000,8.012698e+001,8.013615e+001,1,0,2.139264e+000,1.968444e-002,1.968444e-002,-8.388221e-002,-8.765326e-002,5.351783e-002,-5.004882e-002,-5.381988e-002,4.930785e-007,4.930785e-007,,,,,,,,,,,,,,,,,,,,
1473347913.523,,0.000000e+000,8.012698e+001,8.013615e+001,1,0,4.717338e+000,2.319407e-002,2.319407e-002,1.390380e-002,-8.414364e-002,3.321996e-002,2.392969e-002,-7.411775e-002,5.809916e-007,5.809916e-007,,,,,,,,,,,,,,,,,,,,
1473347927.282,,0.000000e+000,8.011779e+001,8.009943e+001,1,0,3.736856e+000,5.035554e-003,5.035554e-003,-2.801756e-002,-9.484550e-002,4.623134e-002,1.317823e-002,-5.364972e-002,1.261363e-007,1.261363e-007,,,,,,,,,,,,,,,,,,,,
1473347939.746,,0.000000e+000,8.009943e+001,8.009178e+001,1,0,8.597471e-001,2.204962e-001,2.204962e-001,1.179976e-001,7.726404e-002,1.367112e-001,3.421251e-002,-6.521031e-003,5.523243e-006,5.523243e-006,,,,,,,,,,,,,,,,,,,,
1473347950.960,,0.000000e+000,8.009178e+001,8.010249e+001,1,0,5.142624e-001,1.603748e-001,1.603748e-001,3.647484e-002,1.962627e-002,1.479908e-001,2.409086e-002,7.242292e-003,4.017251e-006,4.017251e-006,,,,,,,,,,,,,,,,,,,,
1473347950.960,,0.000000e+000,8.009178e+001,8.010249e+001,1,0,3.432328e+000,4.913480e-002,4.913480e-002,9.477712e-003,-9.161368e-002,2.468545e-002,-1.497164e-002,-1.160630e-001,1.230785e-006,1.230785e-006,,,,,,,,,,,,,,,,,,,,
1473348141.136,,0.000000e+000,8.000927e+001,8.001385e+001,1,0,4.944766e+000,2.548295e-002,2.548296e-002,6.209021e-003,-8.839072e-002,3.656437e-002,1.729043e-002,-7.730932e-002,6.383264e-007,6.383264e-007,,,,,,,,,,,,,,,,,,,,
1473348153.708,,0.000000e+000,8.001385e+001,8.001233e+001,1,0,2.410051e+000,-4.577776e-004,-4.577776e-004,-6.581561e-002,-1.266925e-001,-8.316737e-003,-7.367456e-002,-1.345515e-001,-1.146694e-008,-1.146694e-008,,,,,,,,,,,,,,,,,,,,
1473348165.958,,0.000000e+000,8.000927e+001,8.000927e+001,1,0,9.044553e-002,5.645924e-002,5.645924e-002,-3.122862e-002,-6.385572e-002,1.002157e-001,1.252784e-002,-2.009927e-002,1.414256e-006,1.414256e-006,,,,,,,,,,,,,,,,,,,,
1473348178.673,,0.000000e+000,8.000775e+001,8.001080e+001,1,0,1.691934e+000,1.237526e-001,1.237526e-001,-8.224175e-003,-1.535759e-002,1.276585e-001,-4.318261e-003,-1.145168e-002,3.099896e-006,3.099896e-006,,,,,,,,,,,,,,,,,,,,
1473348178.673,,0.000000e+000,8.000775e+001,8.001080e+001,1,0,4.450586e+000,5.539110e-002,5.539110e-002,1.258206e-002,-8.371905e-002,7.482039e-002,3.201136e-002,-6.428976e-002,1.387500e-006,1.387500e-006,,,,,,,,,,,,,,,,,,,,
1473348339.152,,0.000000e+000,7.672219e+001,7.608883e+001,1,0,4.134390e+000,7.309183e-002,7.309183e-002,-1.739861e-002,-8.372521e-002,1.250484e-001,3.455795e-002,-3.176865e-002,1.830888e-006,1.830888e-006,,,,,,,,,,,,,,,,,,,,
1473348351.677,,0.000000e+000,7.595176e+001,7.539321e+001,1,0,1.198541e+000,2.157659e-001,2.157659e-001,1.202628e-001,7.764266e-002,1.257067e-001,3.020360e-002,-1.241650e-002,5.404751e-006,5.404751e-006,,,,,,,,,,,,,,,,,,,,
1473348363.391,,0.000000e+000,7.525992e+001,7.496367e+001,1,0,2.333732e-001,1.190222e-001,1.190222e-001,-1.363618e-002,-3.371981e-002,1.478128e-001,1.515440e-002,-4.929230e-003,2.981405e-006,2.981405e-006,,,,,,,,,,,,,,,,,,,,
1473348363.391,,0.000000e+000,7.525992e+001,7.496367e+001,1,0,3.026979e+000,4.501480e-002,4.501480e-002,-3.961784e-003,-1.077272e-001,-5.668491e-003,-5.464508e-002,-1.584105e-001,1.127582e-006,1.127582e-006,,,,,,,,,,,,,,,,,,,,
1473348375.855,,0.000000e+000,7.468439e+001,7.425465e+001,1,0,4.993484e+000,6.698813e-002,6.698813e-002,1.054352e-002,-6.754956e-002,7.137641e-002,1.493181e-002,-6.316127e-002,1.677996e-006,1.677996e-006,,,,,,,,,,,,,,,,,,,,
1473348397.070,,0.000000e+000,7.350523e+001,7.306410e+001,1,0,2.861530e+000,4.516739e-002,4.516739e-002,-5.699832e-002,-1.129952e-001,3.421171e-002,-6.795401e-002,-1.239509e-001,1.131405e-006,1.131405e-006,,,,,,,,,,,,,,,,,,,,
1473348409.723,,0.000000e+000,7.291181e+001,7.230997e+001,1,0,2.834623e-001,1.144444e-001,1.144444e-001,6.190701e-003,-2.674118e-002,1.232411e-001,1.498741e-002,-1.794447e-002,2.866735e-006,2.866735e-006,,,,,,,,,,,,,,,,,,,,
1473348421.545,,0.000000e+000,7.213441e+001,7.171712e+001,1,0,1.263879e+000,2.165288e-001,2.165288e-001,7.398415e-002,6.379896e-002,1.670467e-001,2.450201e-002,1.431683e-002,5.423863e-006,5.423863e-006,,,,,,,,,,,,,,,,,,,,
1473348421.545,,0.000000e+000,7.213441e+001,7.171712e+001,1,0,4.141014e+000,6.134220e-002,6.134221e-002,3.674034e-003,-9.138764e-002,8.793462e-002,3.026645e-002,-6.479523e-002,1.536570e-006,1.536570e-006,,,,,,,,,,,,,,,,,,,,
1473348434.759,,0.000000e+000,7.156648e+001,7.099423e+001,1,0,4.486448e+000,4.272591e-002,4.272591e-002,-1.571000e-002,-8.560026e-002,8.506377e-002,2.662786e-002,-4.326241e-002,1.070248e-006,1.070248e-006,,,,,,,,,,,,,,,,,,,,
1473348454.474,,0.000000e+000,7.028767e+001,6.977480e+001,1,0,1.568373e+000,1.470992e-001,1.470992e-001,5.256241e-002,5.394444e-003,1.001562e-001,5.619427e-003,-4.154854e-002,3.684710e-006,3.684710e-006,,,,,,,,,,,,,,,,,,,,
1473348467.205,,0.000000e+000,6.977480e+001,6.921642e+001,1,0,5.596482e-002,4.974517e-002,4.974517e-002,-4.524033e-002,-6.890087e-002,1.029017e-001,7.916195e-003,-1.574434e-002,1.246074e-006,1.246074e-006,,,,,,,,,,,,,,,,,,,,
1473348479.170,,0.000000e+000,6.909416e+001,6.856836e+001,1,0,2.590701e+000,3.448591e-002,3.448592e-002,-9.233093e-002,-9.233093e-002,8.239724e-002,-4.441962e-002,-4.441962e-002,8.638428e-007,8.638428e-007,,,,,,,,,,,,,,,,,,,,
1473348479.170,,0.000000e+000,6.909416e+001,6.856836e+001,1,0,4.910277e+000,4.791406e-002,4.791406e-002,6.449109e-003,-7.890280e-002,5.216379e-002,1.069884e-002,-7.465306e-002,1.200206e-006,1.200206e-006,,,,,,,,,,,,,,,,,,,,
1473348491.134,,0.000000e+000,6.841887e+001,6.788719e+001,1,0,3.308794e+000,2.212592e-002,2.212592e-002,-2.190234e-002,-7.841258e-002,4.994587e-002,5.917612e-003,-5.059264e-002,5.542354e-007,5.542354e-007,,,,,,,,,,,,,,,,,,,,
1473348511.349,,0.000000e+000,6.724285e+001,6.685360e+001,1,0,5.501283e-001,-6.454664e-002,-6.454664e-002,-1.435845e-002,-4.952276e-002,-1.073786e-001,-5.719037e-002,-9.235468e-002,-1.616839e-006,-1.616839e-006,,,,,,,,,,,,,,,,,,,,
1473348523.851,,0.000000e+000,6.660363e+001,6.621711e+001,1,0,8.662936e-001,-4.072695e-001,-4.072695e-001,-1.345215e-001,-1.473521e-001,-4.965614e-001,-2.238134e-001,-2.366440e-001,-1.020175e-005,-1.020175e-005,,,,,,,,,,,,,,,,,,,,
1473348523.851,,0.000000e+000,6.660363e+001,6.621711e+001,1,0,3.802220e+000,-5.220191e-001,-5.220191e-001,-1.690800e-001,-2.621017e-001,-5.125545e-001,-1.596154e-001,-2.526370e-001,-1.307613e-005,-1.307613e-005,,,,,,,,,,,,,,,,,,,,
1473348536.815,,0.000000e+000,6.610051e+001,6.560457e+001,1,0,4.767402e+000,-1.259651e+000,-1.259651e+000,-3.406919e-001,-4.095292e-001,-1.208462e+000,-2.895027e-001,-3.583400e-001,-3.155320e-005,-3.155320e-005,,,,,,,,,,,,,,,,,,,,
1473348550.530,,0.000000e+000,6.547338e+001,6.500272e+001,1,0,1.973677e+000,-5.116428e-001,-5.116428e-001,1.316668e+000,1.273268e+000,-6.356691e-001,1.192641e+000,1.149242e+000,-1.281622e-005,-1.281622e-005,,,,,,,,,,,,,,,,,,,,
1473348591.101,,0.000000e+000,6.357549e+001,6.298713e+001,1,0,7.230805e-003,-5.433820e-001,-5.433820e-001,-8.197411e-002,-8.332524e-002,-5.371065e-001,-7.569858e-002,-7.704970e-002,-1.361126e-004,-1.361126e-004,,,,,,,,,,,,,,,,,,,,
1473348604.334,,0.000000e+000,6.298713e+001,6.239006e+001,1,0,2.139126e+000,-1.246681e-001,-1.246681e-001,3.941057e-001,3.939641e-001,-1.126542e-001,4.061196e-001,4.059781e-001,-3.122830e-005,-3.122830e-005,,,,,,,,,,,,,,,,,,,,
1473348604.334,,0.000000e+000,6.298713e+001,6.239006e+001,1,0,4.717267e+000,-6.724753e-001,-6.724753e-001,-1.501628e-001,-1.538431e-001,-6.628073e-001,-1.404947e-001,-1.441751e-001,-1.684493e-004,-1.684493e-004,,,,,,,,,,,,,,,,,,,,
1473348617.481,,0.000000e+000,6.227836e+001,6.179433e+001,1,0,3.736898e+000,-7.309183e-001,-7.309183e-001,-1.547882e-001,-1.571066e-001,-7.284478e-001,-1.523177e-001,-1.546361e-001,-1.830888e-004,-1.830888e-004,,,,,,,,,,,,,,,,,,,,
1473348631.053,,0.000000e+000,6.159012e+001,6.123328e+001,1,0,8.597719e-001,-9.031953e-001,-9.031953e-001,-2.733420e-001,-2.745366e-001,-9.149774e-001,-2.851241e-001,-2.863187e-001,-2.262427e-004,-2.262427e-004,,,,,,,,,,,,,,,,,,,,
1473348643.517,,0.000000e+000,6.110178e+001,6.049340e+001,1,0,5.142642e-001,-9.051790e-001,-9.051790e-001,-2.332529e-001,-2.336811e-001,-9.072360e-001,-2.353100e-001,-2.357382e-001,-2.267396e-004,-2.267396e-004,,,,,,,,,,,,,,,,,,,,
1473348643.517,,0.000000e+000,6.110178e+001,6.049340e+001,1,0,3.432354e+000,-6.204413e-001,-6.204413e-001,5.362546e-002,5.105656e-002,-6.304312e-001,4.363554e-002,4.106665e-002,-1.554153e-004,-1.554153e-004,,,,,,,,,,,,,,,,,,,,
1473348655.731,,0.000000e+000,6.039699e+001,6.000554e+001,1,0,4.944784e+000,-8.534501e-001,-8.534501e-001,-1.395834e-001,-1.412789e-001,-8.448858e-001,-1.310191e-001,-1.327145e-001,-2.137820e-004,-2.137820e-004,,,,,,,,,,,,,,,,,,,,
1473348666.386,,0.000000e+000,6.000554e+001,5.937823e+001,1,0,2.410079e+000,-2.288888e-003,-2.288888e-003,7.480482e-001,7.471165e-001,3.933498e-003,7.542706e-001,7.533389e-001,-5.733470e-007,-5.733470e-007,,,,,,,,,,,,,,,,,,,,
1473348680.209,,0.000000e+000,5.937823e+001,5.875328e+001,1,0,9.053275e-002,-9.430220e-001,-9.430220e-001,-1.504333e-001,-1.508664e-001,-9.381607e-001,-1.455721e-001,-1.460052e-001,-2.362190e-004,-2.362190e-004,,,,,,,,,,,,,,,,,,,,
1473348700.428,,0.000000e+000,5.813756e+001,5.763007e+001,1,0,1.691879e+000,-6.955168e-001,-6.955168e-001,1.564080e-001,1.563460e-001,-6.997811e-001,1.521438e-001,1.520818e-001,-1.742210e-004,-1.742210e-004,,,,,,,,,,,,,,,,,,,,
1473348700.428,,0.000000e+000,5.813756e+001,5.763007e+001,1,0,4.450571e+000,-1.184271e+000,-1.184271e+000,-3.315707e-001,-3.324079e-001,-1.172860e+000,-3.201601e-001,-3.209973e-001,-2.966498e-004,-2.966498e-004,,,,,,,,,,,,,,,,,,,,
1473348712.392,,0.000000e+000,5.751628e+001,5.714064e+001,1,0,4.134439e+000,-1.290475e+000,-1.290475e+000,-4.010364e-001,-4.013465e-001,-1.289288e+000,-3.998497e-001,-4.001598e-001,-3.232530e-004,-3.232530e-004,,,,,,,,,,,,,,,,,,,,
1473348726.606,,0.000000e+000,5.677286e+001,5.623664e+001,1,0,1.198547e+000,-1.231422e+000,-1.231422e+000,-2.993554e-001,-2.993624e-001,-1.246342e+000,-3.142759e-001,-3.142829e-001,-3.084607e-004,-3.084607e-004,,,,,,,,,,,,,,,,,,,,
1473348740.258,,0.000000e+000,5.598602e+001,5.558673e+001,1,0,2.333465e-001,-1.205481e+000,-1.205481e+000,-2.304099e-001,-2.303613e-001,-1.200192e+000,-2.251209e-001,-2.250724e-001,-3.019627e-004,-3.019627e-004,,,,,,,,,,,,,,,,,,,,
1473348740.258,,0.000000e+000,5.598602e+001,5.558673e+001,1,0,3.027054e+000,-3.741569e-001,-3.741569e-001,6.007121e-001,6.009629e-001,-4.024816e-001,5.723873e-001,5.726382e-001,-9.372312e-005,-9.372312e-005,,,,,,,,,,,,,,,,,,,,
1473348760.581,,0.000000e+000,5.507771e+001,5.441716e+001,1,0,4.993437e+000,-1.214179e+000,-1.214179e+000,-1.827499e-001,-1.820151e-001,-1.203925e+000,-1.724958e-001,-1.717610e-001,-3.041415e-004,-3.041415e-004,,,,,,,,,,,,,,,,,,,,
1473348774.327,,0.000000e+000,5.413995e+001,5.359631e+001,1,0,2.861483e+000,-2.276681e-001,-2.276681e-001,8.470465e-001,8.479413e-001,-2.213528e-001,8.533617e-001,8.542565e-001,-5.702892e-005,-5.702892e-005,,,,,,,,,,,,,,,,,,,,
1473348788.589,,0.000000e+000,5.345779e+001,5.277251e+001,1,0,2.833584e-001,-1.402478e+000,-1.402478e+000,-2.876226e-001,-2.870359e-001,-1.393711e+000,-2.788554e-001,-2.782687e-001,-3.513088e-004,-3.513088e-004,,,,,,,,,,,,,,,,,,,,
1473348801.068,,0.000000e+000,5.277251e+001,5.207685e+001,1,0,1.263875e+000,-1.464583e+000,-1.464583e+000,-3.119840e-001,-3.117592e-001,-1.480378e+000,-3.277789e-001,-3.275541e-001,-3.668657e-004,-3.668657e-004,,,,,,,,,,,,,,,,,,,,
1473348801.068,,0.000000e+000,5.277251e+001,5.207685e+001,1,0,4.141111e+000,-1.667989e+000,-1.667989e+000,-5.172633e-001,-5.151651e-001,-1.665671e+000,-5.149451e-001,-5.128469e-001,-4.178171e-004,-4.178171e-004,,,,,,,,,,,,,,,,,,,,
1473348815.784,,0.000000e+000,5.178989e+001,5.121186e+001,1,0,4.486452e+000,-1.633808e+000,-1.633808e+000,-4.397933e-001,-4.379920e-001,-1.620777e+000,-4.267619e-001,-4.249606e-001,-4.092551e-004,-4.092551e-004,,,,,,,,,,,,,,,,,,,,
1473348829.249,,0.000000e+000,5.093642e+001,5.037244e+001,1,0,1.568345e+000,-1.170995e+000,-1.170995e+000,6.058174e-002,6.204104e-002,-1.195477e+000,3.609997e-002,3.755927e-002,-2.933243e-004,-2.933243e-004,,,,,,,,,,,,,,,,,,,,
1473348841.963,,0.000000e+000,5.022296e+001,4.962474e+001,1,0,5.598862e-002,-1.497238e+000,-1.497238e+000,-2.278855e-001,-2.270668e-001,-1.488865e+000,-2.195128e-001,-2.186941e-001,-3.750454e-004,-3.750454e-004,,,,,,,,,,,,,,,,,,,,
1473348855.677,,0.000000e+000,4.933854e+001,4.876235e+001,1,0,2.590760e+000,-9.002960e-003,-9.002960e-003,1.301576e+000,1.301576e+000,9.813282e-003,1.320392e+000,1.320392e+000,-2.255165e-006,-2.255165e-006,,,,,,,,,,,,,,,,,,,,
1473348855.677,,0.000000e+000,4.933854e+001,4.876235e+001,1,0,4.910299e+000,-1.568651e+000,-1.568651e+000,-2.612495e-001,-2.580730e-001,-1.557433e+000,-2.500305e-001,-2.468541e-001,-3.929338e-004,-3.929338e-004,,,,,,,,,,,,,,,,,,,,
1473348869.937,,0.000000e+000,4.847023e+001,4.786928e+001,1,0,3.308759e+000,-1.059755e+000,-1.059755e+000,2.915840e-001,2.941593e-001,-1.064940e+000,2.863996e-001,2.889749e-001,-2.654597e-004,-2.654597e-004,,,,,,,,,,,,,,,,,,,,
1473348884.651,,0.000000e+000,4.757026e+001,4.696299e+001,1,0,5.500137e-001,-1.896878e+000,-1.896878e+000,-5.048249e-001,-5.031493e-001,-1.895521e+000,-5.034681e-001,-5.017924e-001,-4.751518e-004,-4.751518e-004,,,,,,,,,,,,,,,,,,,,
1473348898.901,,0.000000e+000,4.667580e+001,4.605926e+001,1,0,8.662978e-001,-2.054201e+000,-2.054201e+000,-6.176777e-001,-6.169995e-001,-2.076747e+000,-6.402242e-001,-6.395460e-001,-5.145599e-004,-5.145599e-004,,,,,,,,,,,,,,,,,,,,
1473348898.901,,0.000000e+000,4.667580e+001,4.605926e+001,1,0,3.802289e+000,-1.885434e+000,-1.885434e+000,-4.531492e-001,-4.482322e-001,-1.885596e+000,-4.533112e-001,-4.483942e-001,-4.722851e-004,-4.722851e-004,,,,,,,,,,,,,,,,,,,,
1473348911.365,,0.000000e+000,4.591204e+001,4.514835e+001,1,0,4.767381e+000,-1.838435e+000,-1.838435e+000,-3.707066e-001,-3.668240e-001,-1.820727e+000,-3.529991e-001,-3.491164e-001,-4.605123e-004,-4.605123e-004,,,,,,,,,,,,,,,,,,,,
1473348926.845,,0.000000e+000,4.500766e+001,4.424471e+001,1,0,1.973746e+000,-6.373791e-001,-6.373791e-001,8.776252e-001,8.805827e-001,-6.800583e-001,8.349459e-001,8.379034e-001,-1.596580e-004,-1.596580e-004,,,,,,,,,,,,,,,,,,,,
1473348940.060,,0.000000e+000,4.408785e+001,4.330507e+001,1,0,7.265829e-003,-1.809595e+000,-1.809595e+000,-2.554890e-001,-2.537880e-001,-1.801499e+000,-2.473931e-001,-2.456921e-001,-4.532881e-004,-4.532881e-004,,,,,,,,,,,,,,,,,,,,
1473348954.833,,0.000000e+000,4.316199e+001,4.238259e+001,1,0,2.139270e+000,-4.013184e-001,-4.013184e-001,1.197450e+000,1.197673e+000,-3.827956e-001,1.215973e+000,1.216196e+000,-1.005268e-004,-1.005268e-004,,,,,,,,,,,,,,,,,,,,
1473348954.833,,0.000000e+000,4.316199e+001,4.238259e+001,1,0,4.717387e+000,-2.029786e+000,-2.029786e+000,-4.365844e-001,-4.307948e-001,-2.005700e+000,-4.124982e-001,-4.067086e-001,-5.084442e-004,-5.084442e-004,,,,,,,,,,,,,,,,,,,,
1473348967.832,,0.000000e+000,4.222641e+001,4.143751e+001,1,0,3.736869e+000,-2.059084e+000,-2.059084e+000,-4.272292e-001,-4.227544e-001,-2.061126e+000,-4.292708e-001,-4.247960e-001,-5.157830e-004,-5.157830e-004,,,,,,,,,,,,,,,,,,,,
1473348981.046,,0.000000e+000,4.143751e+001,4.065305e+001,1,0,8.596132e-001,-2.394788e+000,-2.394788e+000,-7.240335e-001,-7.210661e-001,-2.412503e+000,-7.417487e-001,-7.387813e-001,-5.998739e-004,-5.998739e-004,,,,,,,,,,,,,,,,,,,,
1473348994.510,,0.000000e+000,4.049643e+001,3.970158e+001,1,0,5.142677e-001,-2.295297e+000,-2.295297e+000,-5.885580e-001,-5.872856e-001,-2.296470e+000,-5.897310e-001,-5.884587e-001,-5.749524e-004,-5.749524e-004,,,,,,,,,,,,,,,,,,,,
1473348994.510,,0.000000e+000,4.049643e+001,3.970158e+001,1,0,3.432443e+000,-1.583453e+000,-1.583453e+000,1.169246e-001,1.245587e-001,-1.604477e+000,9.590074e-002,1.035348e-001,-3.966415e-004,-3.966415e-004,,,,,,,,,,,,,,,,,,,,
1473349021.989,,0.000000e+000,3.857762e+001,3.807730e+001,1,0,4.944795e+000,-1.125523e+000,-1.125523e+000,-1.679507e-001,-1.650179e-001,-1.116256e+000,-1.586845e-001,-1.557518e-001,-5.638677e-004,-5.638677e-004,,,,,,,,,,,,,,,,,,,,
1473349033.634,,0.000000e+000,3.790768e+001,3.725597e+001,1,0,2.410120e+000,-6.942961e-002,-6.942961e-002,8.889045e-001,8.909732e-001,-5.887089e-002,8.994632e-001,9.015319e-001,-3.478305e-005,-3.478305e-005,,,,,,,,,,,,,,,,,,,,
1473349045.456,,0.000000e+000,3.709107e+001,3.643885e+001,1,0,9.050423e-002,-1.130558e+000,-1.130558e+000,-1.712079e-001,-1.700094e-001,-1.127625e+000,-1.682748e-001,-1.670763e-001,-5.663904e-004,-5.663904e-004,,,,,,,,,,,,,,,,,,,,
1473349058.678,,0.000000e+000,3.628202e+001,3.580329e+001,1,0,1.691855e+000,-7.835627e-001,-7.835627e-001,1.767255e-001,1.770072e-001,-7.884012e-001,1.718871e-001,1.721687e-001,-3.925516e-004,-3.925516e-004,,,,,,,,,,,,,,,,,,,,
1473349058.678,,0.000000e+000,3.628202e+001,3.580329e+001,1,0,4.450544e+000,-1.311380e+000,-1.311380e+000,-3.546130e-001,-3.508105e-001,-1.300684e+000,-3.439163e-001,-3.401137e-001,-6.569792e-004,-6.569792e-004,,,,,,,,,,,,,,,,,,,,
1473349071.142,,0.000000e+000,3.564960e+001,3.485872e+001,1,0,4.134441e+000,-1.376690e+000,-1.376690e+000,-4.189217e-001,-4.160327e-001,-1.379013e+000,-4.212447e-001,-4.183558e-001,-6.896982e-004,-6.896982e-004,,,,,,,,,,,,,,,,,,,,
1473349083.356,,0.000000e+000,3.470634e+001,3.423608e+001,1,0,1.198561e+000,-1.264687e+000,-1.264687e+000,-3.059236e-001,-3.039863e-001,-1.275272e+000,-3.165081e-001,-3.145708e-001,-6.335867e-004,-6.335867e-004,,,,,,,,,,,,,,,,,,,,
1473349095.820,,0.000000e+000,3.408696e+001,3.343823e+001,1,0,2.333195e-001,-1.190222e+000,-1.190222e+000,-2.302155e-001,-2.292701e-001,-1.185569e+000,-2.255623e-001,-2.246169e-001,-5.962809e-004,-5.962809e-004,,,,,,,,,,,,,,,,,,,,
1473349095.820,,0.000000e+000,3.408696e+001,3.343823e+001,1,0,3.026931e+000,-3.706473e-001,-3.706473e-001,5.854200e-001,5.903045e-001,-3.958201e-001,5.602472e-001,5.651317e-001,-1.856880e-004,-1.856880e-004,,,,,,,,,,,,,,,,,,,,
1473349109.718,,0.000000e+000,3.315327e+001,3.259161e+001,1,0,4.993459e+000,-1.128117e+000,-1.128117e+000,-1.710494e-001,-1.672091e-001,-1.119189e+000,-1.621215e-001,-1.582811e-001,-5.651673e-004,-5.651673e-004,,,,,,,,,,,,,,,,,,,,
1473349122.290,,0.000000e+000,3.245880e+001,3.191399e+001,1,0,2.861492e+000,-1.825007e-001,-1.825007e-001,7.756386e-001,7.783467e-001,-1.754640e-001,7.826753e-001,7.853833e-001,-9.142973e-005,-9.142973e-005,,,,,,,,,,,,,,,,,,,,
1473349136.254,,0.000000e+000,3.163900e+001,3.109738e+001,1,0,2.833843e-001,-1.220740e+000,-1.220740e+000,-2.614883e-001,-2.598066e-001,-1.213181e+000,-2.539289e-001,-2.522472e-001,-6.115701e-004,-6.115701e-004,,,,,,,,,,,,,,,,,,,,
1473349151.648,,0.000000e+000,3.083440e+001,3.043273e+001,1,0,1.263836e+000,-1.234321e+000,-1.234321e+000,-2.739803e-001,-2.734703e-001,-1.245877e+000,-2.855361e-001,-2.850261e-001,-6.183739e-004,-6.183739e-004,,,,,,,,,,,,,,,,,,,,
1473349151.648,,0.000000e+000,3.083440e+001,3.043273e+001,1,0,4.141027e+000,-1.413007e+000,-1.413007e+000,-4.569159e-001,-4.521562e-001,-1.412320e+000,-4.562292e-001,-4.514695e-001,-7.078925e-004,-7.078925e-004,,,,,,,,,,,,,,,,,,,,
1473349163.720,,0.000000e+000,3.030066e+001,2.962959e+001,1,0,4.486451e+000,-1.332438e+000,-1.332438e+000,-3.752823e-001,-3.714952e-001,-1.323166e+000,-3.660105e-001,-3.622233e-001,-6.675288e-004,-6.675288e-004,,,,,,,,,,,,,,,,,,,,
1473349174.730,,0.000000e+000,2.949500e+001,2.895389e+001,1,0,1.568286e+000,-9.027375e-001,-9.027375e-001,5.565806e-002,5.820280e-002,-9.212048e-001,3.719076e-002,3.973550e-002,-4.522561e-004,-4.522561e-004,,,,,,,,,,,,,,,,,,,,
1473349188.376,,0.000000e+000,2.882184e+001,2.828714e+001,1,0,5.595883e-002,-1.148259e+000,-1.148259e+000,-1.886579e-001,-1.873773e-001,-1.143014e+000,-1.834128e-001,-1.821322e-001,-5.752582e-004,-5.752582e-004,,,,,,,,,,,,,,,,,,,,
1473349201.627,,0.000000e+000,2.815460e+001,2.748948e+001,1,0,2.590763e+000,9.735405e-002,9.735405e-002,1.058182e+000,1.058182e+000,1.084462e-001,1.069274e+000,1.069274e+000,4.877272e-005,4.877272e-005,,,,,,,,,,,,,,,,,,,,
1473349201.627,,0.000000e+000,2.815460e+001,2.748948e+001,1,0,4.910295e+000,-1.165807e+000,-1.165807e+000,-2.096505e-001,-2.049795e-001,-1.157222e+000,-2.010656e-001,-1.963946e-001,-5.840495e-004,-5.840495e-004,,,,,,,,,,,,,,,,,,,,
1473349214.199,,0.000000e+000,2.735807e+001,2.696235e+001,1,0,3.308827e+000,-7.327494e-001,-7.327494e-001,2.246136e-001,2.281004e-001,-7.371861e-001,2.201770e-001,2.236637e-001,-3.670950e-004,-3.670950e-004,,,,,,,,,,,,,,,,,,,,
1473349227.101,,0.000000e+000,2.683381e+001,2.630717e+001,1,0,5.500631e-001,-1.354106e+000,-1.354106e+000,-3.954426e-001,-3.933156e-001,-1.351867e+000,-3.932030e-001,-3.910760e-001,-6.783842e-004,-6.783842e-004,,,,,,,,,,,,,,,,,,,,
1473349238.729,,0.000000e+000,2.617272e+001,2.550920e+001,1,0,8.662803e-001,-1.432539e+000,-1.432539e+000,-4.724752e-001,-4.716867e-001,-1.447013e+000,-4.869491e-001,-4.861606e-001,-7.176776e-004,-7.176776e-004,,,,,,,,,,,,,,,,,,,,
1473349238.729,,0.000000e+000,2.617272e+001,2.550920e+001,1,0,3.802274e+000,-1.303140e+000,-1.303140e+000,-3.480045e-001,-3.422883e-001,-1.303783e+000,-3.486471e-001,-3.429309e-001,-6.528511e-004,-6.528511e-004,,,,,,,,,,,,,,,,,,,,
1473349252.943,,0.000000e+000,2.537296e+001,2.483163e+001,1,0,4.767366e+000,-1.231117e+000,-1.231117e+000,-2.746035e-001,-2.701655e-001,-1.218905e+000,-2.623921e-001,-2.579542e-001,-6.167685e-004,-6.167685e-004,,,,,,,,,,,,,,,,,,,,
1473349266.657,,0.000000e+000,2.454902e+001,2.408865e+001,1,0,1.973662e+000,-3.080843e-001,-3.080843e-001,6.496674e-001,6.526254e-001,-3.381462e-001,6.196055e-001,6.225635e-001,-1.543450e-004,-1.543450e-004,,,,,,,,,,,,,,,,,,,,
1473349279.054,,0.000000e+000,2.377859e+001,2.334347e+001,1,0,7.214821e-003,-1.144292e+000,-1.144292e+000,-1.849583e-001,-1.833287e-001,-1.139467e+000,-1.801339e-001,-1.785043e-001,-5.732705e-004,-5.732705e-004,,,,,,,,,,,,,,,,,,,,
1473349290.876,,0.000000e+000,2.334347e+001,2.296785e+001,1,0,2.139373e+000,-1.065096e-001,-1.065096e-001,8.544558e-001,8.546669e-001,-9.506111e-002,8.659043e-001,8.661154e-001,-5.335949e-005,-5.335949e-005,,,,,,,,,,,,,,,,,,,,
1473349290.876,,0.000000e+000,2.334347e+001,2.296785e+001,1,0,4.717428e+000,-1.261940e+000,-1.261940e+000,-3.062527e-001,-3.007638e-001,-1.245511e+000,-2.898231e-001,-2.843343e-001,-6.322106e-004,-6.322106e-004,,,,,,,,,,,,,,,,,,,,
1473349305.144,,0.000000e+000,2.281570e+001,2.235933e+001,1,0,3.736860e+000,-1.256905e+000,-1.256905e+000,-2.999679e-001,-2.960680e-001,-1.259576e+000,-3.026388e-001,-2.987388e-001,-6.296879e-004,-6.296879e-004,,,,,,,,,,,,,,,,,,,,
1473349318.359,,0.000000e+000,2.221617e+001,2.140664e+001,1,0,8.597063e-001,-1.457106e+000,-1.457106e+000,-4.987574e-001,-4.962415e-001,-1.467740e+000,-5.093914e-001,-5.068756e-001,-7.299854e-004,-7.299854e-004,,,,,,,,,,,,,,,,,,,,
1473349329.122,,0.000000e+000,2.140664e+001,2.090687e+001,1,0,5.142444e-001,-1.360668e+000,-1.360668e+000,-4.009201e-001,-3.998914e-001,-1.360747e+000,-4.009991e-001,-3.999705e-001,-6.816714e-004,-6.816714e-004,,,,,,,,,,,,,,,,,,,,
1473349329.122,,0.000000e+000,2.140664e+001,2.090687e+001,1,0,3.432373e+000,-8.818323e-001,-8.818323e-001,7.277223e-002,7.894397e-002,-8.948103e-001,5.979428e-002,6.596601e-002,-4.417830e-004,-4.417830e-004,,,,,,,,,,,,,,,,,,,,
1473349342.336,,0.000000e+000,2.068327e+001,2.051632e+001,1,0,4.944813e+000,-1.173437e+000,-1.173437e+000,-2.173250e-001,-2.124878e-001,-1.161864e+000,-2.057521e-001,-2.009148e-001,-5.878718e-004,-5.878718e-004,,,,,,,,,,,,,,,,,,,,
1473349360.051,,0.000000e+000,2.047895e+001,1.980756e+001,1,0,2.409976e+000,8.676412e-001,8.676412e-001,1.145961e+000,1.149420e+000,8.822437e-001,1.160563e+000,1.164023e+000,4.346735e-004,4.346735e-004,,,,,,,,,,,,,,,,,,,,
1473349403.751,,0.000000e+000,1.742650e+001,1.690369e+001,1,0,9.039893e-002,-2.849818e+000,-2.849818e+000,-4.465452e-001,-4.421723e-001,-2.843657e+000,-4.403833e-001,-4.360104e-001,-7.138553e-004,-7.138553e-004,,,,,,,,,,,,,,,,,,,,
1473349417.215,,0.000000e+000,1.678469e+001,1.621929e+001,1,0,1.691969e+000,-1.952879e+000,-1.952879e+000,4.656686e-001,4.666469e-001,-1.966188e+000,4.523604e-001,4.533387e-001,-4.891797e-004,-4.891797e-004,,,,,,,,,,,,,,,,,,,,
1473349417.215,,0.000000e+000,1.678469e+001,1.621929e+001,1,0,4.450726e+000,-3.314310e+000,-3.314310e+000,-9.079913e-001,-8.947837e-001,-3.287420e+000,-8.811008e-001,-8.678932e-001,-8.302065e-004,-8.302065e-004,,,,,,,,,,,,,,,,,,,,
1473349429.180,,0.000000e+000,1.621929e+001,1.618046e+001,1,0,4.134454e+000,-3.476669e+000,-3.476669e+000,-1.060948e+000,-1.051138e+000,-3.484602e+000,-1.068881e+000,-1.059072e+000,-8.708759e-004,-8.708759e-004,,,,,,,,,,,,,,,,,,,,
1473349445.144,,0.000000e+000,1.619540e+001,1.599532e+001,1,0,1.198426e+000,-3.183844e+000,-3.183844e+000,-7.631339e-001,-7.566717e-001,-3.208339e+000,-7.876290e-001,-7.811668e-001,-7.975257e-004,-7.975257e-004,,,,,,,,,,,,,,,,,,,,
1473349458.609,,0.000000e+000,1.584158e+001,1.500763e+001,1,0,2.333550e-001,-3.010498e+000,-3.010498e+000,-5.743904e-001,-5.714073e-001,-2.999897e+000,-5.637891e-001,-5.608060e-001,-7.541042e-004,-7.541042e-004,,,,,,,,,,,,,,,,,,,,
1473349458.609,,0.000000e+000,1.584158e+001,1.500763e+001,1,0,3.027033e+000,-9.775078e-001,-9.775078e-001,1.446170e+000,1.461583e+000,-1.039143e+000,1.384536e+000,1.399948e+000,-2.448574e-004,-2.448574e-004,,,,,,,,,,,,,,,,,,,,
1473349474.101,,0.000000e+000,1.445278e+001,1.350558e+001,1,0,4.993498e+000,-2.868587e+000,-2.868587e+000,-4.211854e-001,-4.092038e-001,-2.846306e+000,-3.989042e-001,-3.869226e-001,-7.185567e-004,-7.185567e-004,,,,,,,,,,,,,,,,,,,,
1473349487.583,,0.000000e+000,1.312486e+001,1.235795e+001,1,0,2.861353e+000,-5.685598e-001,-5.685598e-001,1.897817e+000,1.906447e+000,-5.509241e-001,1.915453e+000,1.924083e+000,-1.424194e-004,-1.424194e-004,,,,,,,,,,,,,,,,,,,,
1473349715.571,,0.000000e+000,1.499725e+001,1.499603e+001,1,0,2.833020e-001,-3.072603e+000,-3.072603e+000,-6.286901e-001,-6.243496e-001,-3.054098e+000,-6.101850e-001,-6.058445e-001,-7.696610e-004,-7.696610e-004,,,,,,,,,,,,,,,,,,,,
1473349747.002,,0.000000e+000,1.499908e+001,1.500091e+001,1,0,1.263871e+000,-1.651967e+000,-1.651967e+000,-3.224270e-001,-3.217864e-001,-1.664697e+000,-3.351569e-001,-3.345163e-001,-8.276073e-004,-8.276073e-004,,,,,,,,,,,,,,,,,,,,
1473349747.002,,0.000000e+000,1.499908e+001,1.500091e+001,1,0,4.141126e+000,-1.863613e+000,-1.863613e+000,-5.394108e-001,-5.334322e-001,-1.863151e+000,-5.389495e-001,-5.329709e-001,-9.336382e-004,-9.336382e-004,,,,,,,,,,,,,,,,,,,,
1473349759.218,,0.000000e+000,1.500091e+001,1.500335e+001,1,0,4.486466e+000,-1.765496e+000,-1.765496e+000,-4.374819e-001,-4.327846e-001,-1.755081e+000,-4.270667e-001,-4.223694e-001,-8.844833e-004,-8.844833e-004,,,,,,,,,,,,,,,,,,,,
1473349771.431,,0.000000e+000,1.500335e+001,1.500457e+001,1,0,1.568395e+000,-1.264534e+000,-1.264534e+000,6.689613e-002,7.003355e-002,-1.285595e+000,4.583543e-002,4.897285e-002,-6.335102e-004,-6.335102e-004,,,,,,,,,,,,,,,,,,,,
1473349862.082,,0.000000e+000,1.500274e+001,1.500335e+001,1,0,5.596440e-002,-5.102695e-001,-5.102695e-001,-2.167515e-001,-2.153101e-001,-5.044682e-001,-2.109502e-001,-2.095088e-001,-2.556363e-004,-2.556363e-004,,,,,,,,,,,,,,,,,,,,
1473349874.681,,0.000000e+000,1.500274e+001,1.500274e+001,1,0,2.590747e+000,9.031953e-001,9.031953e-001,1.202170e+000,1.202170e+000,9.143793e-001,1.213354e+000,1.213354e+000,4.524855e-004,4.524855e-004,,,,,,,,,,,,,,,,,,,,
1473349874.681,,0.000000e+000,1.500274e+001,1.500274e+001,1,0,4.910281e+000,-5.307169e-001,-5.307169e-001,-2.371838e-001,-2.317418e-001,-5.212315e-001,-2.276984e-001,-2.222565e-001,-2.658801e-004,-2.658801e-004,,,,,,,,,,,,,,,,,,,,
1473349886.645,,0.000000e+000,1.500457e+001,1.500579e+001,1,0,3.308850e+000,-4.760887e-002,-4.760887e-002,2.500561e-001,2.540461e-001,-5.219260e-002,2.454723e-001,2.494624e-001,-2.385124e-005,-2.385124e-005,,,,,,,,,,,,,,,,,,,,
1473349899.613,,0.000000e+000,1.500579e+001,1.500396e+001,1,0,5.501075e-001,-1.422163e+000,-1.422163e+000,-4.419461e-001,-4.394896e-001,-1.419481e+000,-4.392647e-001,-4.368081e-001,-7.124792e-004,-7.124792e-004,,,,,,,,,,,,,,,,,,,,
1473349980.560,,0.000000e+000,1.355199e+001,1.336113e+001,1,0,8.663012e-001,-6.074709e-001,-6.074709e-001,-2.113036e-001,-2.109206e-001,-6.138293e-001,-2.176620e-001,-2.172789e-001,-7.608315e-004,-7.608315e-004,,,,,,,,,,,,,,,,,,,,
1473349980.560,,0.000000e+000,1.355199e+001,1.336113e+001,1,0,3.802275e+000,-5.497910e-001,-5.497909e-001,-1.560177e-001,-1.532406e-001,-5.500749e-001,-1.563017e-001,-1.535245e-001,-6.885898e-004,-6.885898e-004,,,,,,,,,,,,,,,,,,,,
1473350005.488,,0.000000e+000,1.307994e+001,1.284679e+001,1,0,4.767412e+000,-3.073061e+000,-3.073061e+000,-6.080685e-001,-5.970387e-001,-3.046377e+000,-5.813845e-001,-5.703547e-001,-7.697757e-004,-7.697757e-004,,,,,,,,,,,,,,,,,,,,
1473350018.703,,0.000000e+000,1.280115e+001,1.261366e+001,1,0,1.973745e+000,-1.037629e+000,-1.037629e+000,1.433854e+000,1.441491e+000,-1.102672e+000,1.368811e+000,1.376448e+000,-2.599173e-004,-2.599173e-004,,,,,,,,,,,,,,,,,,,,
1473350031.961,,0.000000e+000,1.256856e+001,1.233470e+001,1,0,7.252706e-003,-2.881405e+000,-2.881405e+000,-4.046160e-001,-4.004774e-001,-2.871592e+000,-3.948029e-001,-3.906643e-001,-7.217674e-004,-7.217674e-004,,,,,,,,,,,,,,,,,,,,
1473350048.926,,0.000000e+000,1.224198e+001,1.201408e+001,1,0,2.139342e+000,-6.196783e-001,-6.196783e-001,1.866636e+000,1.867154e+000,-5.951299e-001,1.891184e+000,1.891702e+000,-1.552241e-004,-1.552241e-004,,,,,,,,,,,,,,,,,,,,
1473350048.926,,0.000000e+000,1.224198e+001,1.201408e+001,1,0,4.717421e+000,-3.140660e+000,-3.140660e+000,-6.672900e-001,-6.538277e-001,-3.104589e+000,-6.312196e-001,-6.177573e-001,-7.867086e-004,-7.867086e-004,,,,,,,,,,,,,,,,,,,,
1473350063.076,,0.000000e+000,1.196883e+001,1.178674e+001,1,0,3.736866e+000,-3.134709e+000,-3.134709e+000,-6.536438e-001,-6.437986e-001,-3.140269e+000,-6.592039e-001,-6.493587e-001,-7.852179e-004,-7.852179e-004,,,,,,,,,,,,,,,,,,,,
1473350075.148,,0.000000e+000,1.174302e+001,1.156610e+001,1,0,8.597174e-001,-3.562731e+000,-3.562731e+000,-1.075274e+000,-1.069197e+000,-3.585558e+000,-1.098101e+000,-1.092024e+000,-8.924337e-004,-8.924337e-004,,,,,,,,,,,,,,,,,,,,
1473350088.621,,0.000000e+000,1.147960e+001,1.130352e+001,1,0,5.142298e-001,-3.353069e+000,-3.353069e+000,-8.594192e-001,-8.568528e-001,-3.353714e+000,-8.600641e-001,-8.574977e-001,-8.399151e-004,-8.399151e-004,,,,,,,,,,,,,,,,,,,,
1473350088.621,,0.000000e+000,1.147960e+001,1.130352e+001,1,0,3.432425e+000,-2.325816e+000,-2.325816e+000,1.550015e-001,1.704001e-001,-2.355073e+000,1.257438e-001,1.411424e-001,-5.825970e-004,-5.825970e-004,,,,,,,,,,,,,,,,,,,,
1473350102.100,,0.000000e+000,1.121566e+001,1.108375e+001,1,0,4.944760e+000,-2.950530e+000,-2.950530e+000,-4.641989e-001,-4.525542e-001,-2.925439e+000,-4.391087e-001,-4.274640e-001,-7.390825e-004,-7.390825e-004,,,,,,,,,,,,,,,,,,,,
1473350114.814,,0.000000e+000,1.099836e+001,1.082468e+001,1,0,2.410013e+000,-5.355999e-002,-5.355999e-002,2.439906e+000,2.447969e+000,-2.225846e-002,2.471208e+000,2.479270e+000,-1.341632e-005,-1.341632e-005,,,,,,,,,,,,,,,,,,,,
1473350127.028,,0.000000e+000,1.078142e+001,1.060966e+001,1,0,9.040619e-002,-2.963347e+000,-2.963347e+000,-4.635532e-001,-4.589138e-001,-2.957397e+000,-4.576032e-001,-4.529638e-001,-7.422933e-004,-7.422933e-004,,,,,,,,,,,,,,,,,,,,
1473350140.493,,0.000000e+000,1.056648e+001,1.039291e+001,1,0,1.691925e+000,-2.025056e+000,-2.025056e+000,4.813036e-001,4.823272e-001,-2.037867e+000,4.684926e-001,4.695163e-001,-5.072592e-004,-5.072592e-004,,,,,,,,,,,,,,,,,,,,
1473350140.493,,0.000000e+000,1.056648e+001,1.039291e+001,1,0,4.450586e+000,-3.432417e+000,-3.432417e+000,-9.388532e-001,-9.250338e-001,-3.404934e+000,-9.113707e-001,-8.975513e-001,-8.597912e-004,-8.597912e-004,,,,,,,,,,,,,,,,,,,,
1473350153.707,,0.000000e+000,1.030925e+001,1.013874e+001,1,0,4.134441e+000,-3.594623e+000,-3.594623e+000,-1.097065e+000,-1.086852e+000,-3.603089e+000,-1.105531e+000,-1.095318e+000,-9.004224e-004,-9.004224e-004,,,,,,,,,,,,,,,,,,,,
1473350167.171,,0.000000e+000,1.009656e+001,9.926807e+000,1,0,1.198508e+000,-3.294931e+000,-3.294931e+000,-7.897658e-001,-7.831864e-001,-3.319569e+000,-8.144040e-001,-8.078246e-001,-8.253522e-004,-8.253522e-004,,,,,,,,,,,,,,,,,,,,
1473350180.148,,0.000000e+000,9.886683e+000,9.682932e+000,1,0,2.333468e-001,-3.100986e+000,-3.100986e+000,-5.910280e-001,-5.880201e-001,-3.089850e+000,-5.798919e-001,-5.768840e-001,-7.767705e-004,-7.767705e-004,,,,,,,,,,,,,,,,,,,,
1473350180.148,,0.000000e+000,9.886683e+000,9.682932e+000,1,0,3.026958e+000,-1.011536e+000,-1.011536e+000,1.485889e+000,1.501430e+000,-1.074088e+000,1.423337e+000,1.438878e+000,-2.533811e-004,-2.533811e-004,,,,,,,,,,,,,,,,,,,,
1473350195.362,,0.000000e+000,9.600144e+000,9.436392e+000,1,0,4.993489e+000,-2.934965e+000,-2.934965e+000,-4.299696e-001,-4.176633e-001,-2.912294e+000,-4.072989e-001,-3.949926e-001,-7.351838e-004,-7.351838e-004,,,,,,,,,,,,,,,,,,,,
1473350209.831,,0.000000e+000,9.396664e+000,9.195789e+000,1,0,2.861517e+000,-5.815302e-001,-5.815302e-001,1.927373e+000,1.936040e+000,-5.632745e-001,1.945629e+000,1.954296e+000,-1.456684e-004,-1.456684e-004,,,,,,,,,,,,,,,,,,,,
1473350224.795,,0.000000e+000,9.156719e+000,8.957270e+000,1,0,2.833664e-001,-3.163701e+000,-3.163701e+000,-6.475855e-001,-6.424520e-001,-3.145042e+000,-6.289266e-001,-6.237931e-001,-7.924802e-004,-7.924802e-004,,,,,,,,,,,,,,,,,,,,
1473350236.449,,0.000000e+000,8.919601e+000,8.767263e+000,1,0,1.263830e+000,-3.182928e+000,-3.182928e+000,-6.653015e-001,-6.637523e-001,-3.208113e+000,-6.904866e-001,-6.889374e-001,-7.972964e-004,-7.972964e-004,,,,,,,,,,,,,,,,,,,,
1473350236.449,,0.000000e+000,8.919601e+000,8.767263e+000,1,0,4.140996e+000,-3.617054e+000,-3.617054e+000,-1.112337e+000,-1.097878e+000,-3.615817e+000,-1.111100e+000,-1.096641e+000,-9.060412e-004,-9.060412e-004,,,,,,,,,,,,,,,,,,,,
1473350250.522,,0.000000e+000,8.691952e+000,8.543892e+000,1,0,4.486490e+000,-3.414106e+000,-3.414106e+000,-9.021417e-001,-8.914106e-001,-3.392699e+000,-8.807346e-001,-8.700035e-001,-8.552044e-004,-8.552044e-004,,,,,,,,,,,,,,,,,,,,
1473350265.034,,0.000000e+000,8.507406e+000,8.326178e+000,1,0,1.568353e+000,-2.380139e+000,-2.380139e+000,1.392517e-001,1.465235e-001,-2.424116e+000,9.527421e-002,1.025460e-001,-5.962044e-004,-5.962044e-004,,,,,,,,,,,,,,,,,,,,
1473350277.558,,0.000000e+000,8.290206e+000,8.150589e+000,1,0,5.593900e-002,-2.971282e+000,-2.971282e+000,-4.475303e-001,-4.439383e-001,-2.959661e+000,-4.359088e-001,-4.323168e-001,-7.442809e-004,-7.442809e-004,,,,,,,,,,,,,,,,,,,,
1473350290.715,,0.000000e+000,8.116535e+000,7.979212e+000,1,0,2.590715e+000,-4.303110e-002,-4.303110e-002,2.485133e+000,2.485133e+000,-2.071665e-002,2.507448e+000,2.507448e+000,-1.077892e-005,-1.077892e-005,,,,,,,,,,,,,,,,,,,,
1473350290.715,,0.000000e+000,8.116535e+000,7.979212e+000,1,0,4.910287e+000,-3.005463e+000,-3.005463e+000,-4.901267e-001,-4.772983e-001,-2.985702e+000,-4.703656e-001,-4.575372e-001,-7.528429e-004,-7.528429e-004,,,,,,,,,,,,,,,,,,,,
1473350303.037,,0.000000e+000,7.946805e+000,7.814858e+000,1,0,3.308808e+000,-2.003845e+000,-2.003845e+000,5.158065e-001,5.251958e-001,-2.012704e+000,5.069478e-001,5.163372e-001,-5.019462e-004,-5.019462e-004,,,,,,,,,,,,,,,,,,,,
1473350317.001,,0.000000e+000,7.752235e+000,7.625953e+000,1,0,5.501244e-001,-3.438826e+000,-3.438826e+000,-9.149102e-001,-9.091740e-001,-3.432998e+000,-9.090825e-001,-9.033463e-001,-8.613965e-004,-8.613965e-004,,,,,,,,,,,,,,,,,,,,
1473350329.665,,0.000000e+000,7.596639e+000,7.471851e+000,1,0,8.662522e-001,-3.614460e+000,-3.614460e+000,-1.082934e+000,-1.080856e+000,-3.646877e+000,-1.115351e+000,-1.113273e+000,-9.053914e-004,-9.053914e-004,,,,,,,,,,,,,,,,,,,,
1473350329.665,,0.000000e+000,7.596639e+000,7.471851e+000,1,0,3.802211e+000,-3.317515e+000,-3.317515e+000,-7.989796e-001,-7.839108e-001,-3.319703e+000,-8.011683e-001,-7.860994e-001,-8.310092e-004,-8.310092e-004,,,,,,,,,,,,,,,,,,,,
1473350343.237,,0.000000e+000,7.444399e+000,7.299897e+000,1,0,4.767371e+000,-3.144322e+000,-3.144322e+000,-6.218530e-001,-6.102149e-001,-3.116921e+000,-5.944525e-001,-5.828145e-001,-7.876259e-004,-7.876259e-004,,,,,,,,,,,,,,,,,,,,
1473350356.451,,0.000000e+000,7.271921e+000,7.159393e+000,1,0,1.973727e+000,-1.059908e+000,-1.059908e+000,1.465649e+000,1.473363e+000,-1.126854e+000,1.398703e+000,1.406416e+000,-2.654979e-004,-2.654979e-004,,,,,,,,,,,,,,,,,,,,
1473350383.687,,0.000000e+000,6.964211e+000,6.886808e+000,1,0,7.225836e-003,-2.945494e+000,-2.945494e+000,-4.125944e-001,-4.085386e-001,-2.935955e+000,-4.030555e-001,-3.989997e-001,-7.378212e-004,-7.378212e-004,,,,,,,,,,,,,,,,,,,,
1473350397.652,,0.000000e+000,6.839593e+000,6.768417e+000,1,0,2.139291e+000,-6.335642e-001,-6.335642e-001,1.903274e+000,1.903783e+000,-6.086614e-001,1.928177e+000,1.928686e+000,-1.587025e-004,-1.587025e-004,,,,,,,,,,,,,,,,,,,,
1473350397.652,,0.000000e+000,6.839593e+000,6.768417e+000,1,0,4.717376e+000,-3.203986e+000,-3.203986e+000,-6.798636e-001,-6.666384e-001,-3.167535e+000,-6.434129e-001,-6.301877e-001,-8.025711e-004,-8.025711e-004,,,,,,,,,,,,,,,,,,,,
1473350410.116,,0.000000e+000,6.723066e+000,6.656627e+000,1,0,3.736928e+000,-3.192694e+000,-3.192694e+000,-6.647770e-001,-6.551189e-001,-3.199685e+000,-6.717682e-001,-6.621101e-001,-7.997426e-004,-7.997426e-004,,,,,,,,,,,,,,,,,,,,
1473350423.330,,0.000000e+000,6.614408e+000,6.546512e+000,1,0,8.596937e-001,-3.625904e+000,-3.625904e+000,-1.094099e+000,-1.088022e+000,-3.649215e+000,-1.117410e+000,-1.111334e+000,-9.082581e-004,-9.082581e-004,,,,,,,,,,,,,,,,,,,,
1473350491.979,,0.000000e+000,5.911064e+000,5.793892e+000,1,0,5.142870e-001,-3.415174e+000,-3.415174e+000,-8.751397e-001,-8.726187e-001,-3.415599e+000,-8.755646e-001,-8.730435e-001,-8.554720e-004,-8.554720e-004,,,,,,,,,,,,,,,,,,,,
1473350491.979,,0.000000e+000,5.911064e+000,5.793892e+000,1,0,3.432394e+000,-2.370525e+000,-2.370525e+000,1.569038e-001,1.720300e-001,-2.399681e+000,1.277483e-001,1.428745e-001,-5.937964e-004,-5.937964e-004,,,,,,,,,,,,,,,,,,,,
1473350505.067,,0.000000e+000,5.763254e+000,5.637052e+000,1,0,4.944764e+000,-3.003174e+000,-3.003174e+000,-4.719179e-001,-4.602699e-001,-2.977762e+000,-4.465066e-001,-4.348586e-001,-7.522695e-004,-7.522695e-004,,,,,,,,,,,,,,,,,,,,
1473350518.532,,0.000000e+000,5.575736e+000,5.450549e+000,1,0,2.410042e+000,-5.569628e-002,-5.569628e-002,2.479269e+000,2.487404e+000,-2.348613e-002,2.511479e+000,2.519614e+000,-1.395144e-005,-1.395144e-005,,,,,,,,,,,,,,,,,,,,
1473350531.021,,0.000000e+000,5.418658e+000,5.297459e+000,1,0,9.038760e-002,-3.009735e+000,-3.009735e+000,-4.710022e-001,-4.664521e-001,-3.003609e+000,-4.648762e-001,-4.603262e-001,-7.539131e-004,-7.539131e-004,,,,,,,,,,,,,,,,,,,,
1473350655.496,,0.000000e+000,5.038725e+000,5.044523e+000,1,0,1.691949e+000,-2.055422e+000,-2.055422e+000,4.896895e-001,4.907176e-001,-2.069154e+000,4.759569e-001,4.769850e-001,-5.148656e-004,-5.148656e-004,,,,,,,,,,,,,,,,,,,,
1473350655.496,,0.000000e+000,5.038725e+000,5.044523e+000,1,0,4.450621e+000,-3.484756e+000,-3.484756e+000,-9.524964e-001,-9.386168e-001,-3.457202e+000,-9.249421e-001,-9.110625e-001,-8.729017e-004,-8.729017e-004,,,,,,,,,,,,,,,,,,,,
1473350668.211,,0.000000e+000,5.047428e+000,5.049957e+000,1,0,4.134468e+000,-3.647420e+000,-3.647420e+000,-1.112509e+000,-1.101833e+000,-3.656047e+000,-1.121137e+000,-1.110461e+000,-9.136476e-004,-9.136476e-004,,,,,,,,,,,,,,,,,,,,
1473350680.980,,0.000000e+000,5.049957e+000,5.057817e+000,1,0,1.198526e+000,-3.339793e+000,-3.339793e+000,-8.003511e-001,-7.933271e-001,-3.364184e+000,-8.247425e-001,-8.177185e-001,-8.365897e-004,-8.365897e-004,,,,,,,,,,,,,,,,,,,,
1473350693.693,,0.000000e+000,5.058706e+000,5.058578e+000,1,0,2.333308e-001,-3.142186e+000,-3.142186e+000,-5.984831e-001,-5.952888e-001,-3.130872e+000,-5.871694e-001,-5.839751e-001,-7.870908e-004,-7.870908e-004,,,,,,,,,,,,,,,,,,,,
1473350693.693,,0.000000e+000,5.058706e+000,5.058578e+000,1,0,3.026963e+000,-1.027406e+000,-1.027406e+000,1.502987e+000,1.519491e+000,-1.090057e+000,1.440336e+000,1.456840e+000,-2.573564e-004,-2.573564e-004,,,,,,,,,,,,,,,,,,,,
1473350693.693,,0.000000e+000,5.058706e+000,5.058578e+000,1,0,2.811894e+000,-3.996399e-001,-3.996399e-001,2.130487e+000,2.147257e+000,-4.245421e-001,2.105585e+000,2.122355e+000,-1.001064e-004,-1.001064e-004,,,,,,,,,,,,,,,,,,,,