File: data/A344/raw/A344_GdN_ZFC_500_Oe_160908.rso.raw
[Header]
TITLE,MPMS RSO Measurement
BYAPP,MPMS Measurement,2.1,Raw with ABS
FILEOPENTIME, 1473351021.304000 9/9/2016, 4:10:21 AM

INFO, APPNAME, MPMS MultiVu Application, Revision 1.61,  Build 082

INFO, NAME, A344
INFO, WEIGHT, 10.500
INFO, AREA, 1.000
INFO, LENGTH, 1.000
INFO, SHAPE, 0
INFO, COMMENT, m = 0.0105g
INFO, SEQUENCE FILE: ZFC_5K-120K.seq


INFO, BACKGROUND DATA FILE:, None


STARTUPAXIS,X,8,LINEAR,AUTO,0.000000,0.000000
STARTUPAXIS,Y1,9,LINEAR,AUTO,0.000000,0.000000


STARTUPGROUP,Longitudinal
FIELDGROUP,Longitudinal,1,2,3,4,5,6,7,8,9,10,11,12,13,14,15,16,17,18,19,20,21,22
FIELDGROUP,Transverse,1,2,3,4,5,6,7,8,23,24,25,26,27,28,29,30,31,32,33,34,35,36

PLOT_APPEARANCE,ALL,HORZ_GRID_ON,VERT_GRID_ON,MARKERS_ONLY

[Data]
Time,Comment,Field (Oe),Start Temperature (K),End Temperature (K),Scan,Rejected,Position (cm),Long Voltage,Long Average Voltage,Long Detrended Voltage,Long Demeaned Voltage,Long Reg Fit,Long Detrended Fit,Long Demeaned Fit,Long Scaled Response,Long Avg. Scaled Response,Long Background Response,Long Response [w/ABS],Long Detrended Resp. [w/ABS],Long Fit [w/ABS],Long Detrended Fit [w/ABS],Trans Voltage,Trans Average Voltage,Trans Detrended Voltage,Trans Demeaned Voltage,Trans Reg Fit,Trans Detrended Fit,Trans Demeaned Fit,Trans Scaled Response,Trans Avg. Scaled Response,Trans Background Response,Trans Response [w/ABS],Trans Detrended Resp. [w/ABS],Trans Adjusted Fit,Trans Detrended Fit [w/ABS],
1473351021.297,,5.000000e+002,4.969472e+000,4.971789e+000,1,0,2.590686e+000,-2.746666e-002,-2.746666e-002,7.134586e-001,7.134586e-001,-1.238364e-002,7.285416e-001,7.285416e-001,-6.879959e-005,-6.879959e-005,,,,,,,,,,,,,,,,,,,,
1473351021.297,,5.000000e+002,4.969472e+000,4.971789e+000,1,0,4.825353e+000,-9.186071e-001,-9.186071e-001,-1.659281e-001,-1.776819e-001,-9.094856e-001,-1.568067e-001,-1.685604e-001,-2.300964e-003,-2.300964e-003,,,,,,,,,,,,,,,,,,,,
1473351034.011,,5.000000e+002,4.972034e+000,4.971179e+000,1,0,3.736923e+000,-9.384441e-001,-9.384441e-001,-2.014639e-001,-2.103365e-001,-9.325308e-001,-1.955506e-001,-2.044232e-001,-2.350653e-003,-2.350653e-003,,,,,,,,,,,,,,,,,,,,
1473351047.475,,5.000000e+002,4.970692e+000,4.968009e+000,1,0,1.025627e+000,-1.001007e+000,-1.001007e+000,-2.798881e-001,-2.858188e-001,-1.026524e+000,-3.054051e-001,-3.113358e-001,-2.507363e-003,-2.507363e-003,,,,,,,,,,,,,,,,,,,,
1473351059.120,,5.000000e+002,4.968009e+000,4.968374e+000,1,0,2.333588e-001,-8.870205e-001,-8.870205e-001,-1.779809e-001,-1.808745e-001,-8.790875e-001,-1.700479e-001,-1.729416e-001,-2.221844e-003,-2.221844e-003,,,,,,,,,,,,,,,,,,,,
1473351059.120,,5.000000e+002,4.968009e+000,4.968374e+000,1,0,2.811931e+000,-9.414960e-002,-9.414960e-002,6.271878e-001,6.119964e-001,-1.140526e-001,6.072848e-001,5.920933e-001,-2.358297e-004,-2.358297e-004,,,,,,,,,,,,,,,,,,,,
1473351161.705,,5.000000e+002,6.160689e+000,6.284136e+000,1,0,4.910305e+000,-8.099612e-001,-8.099613e-001,-1.444300e-001,-1.569983e-001,-8.025744e-001,-1.370432e-001,-1.496114e-001,-2.028823e-003,-2.028823e-003,,,,,,,,,,,,,,,,,,,,
1473351174.436,,5.000000e+002,6.364762e+000,6.521952e+000,1,0,3.525996e+000,-7.043672e-001,-7.043672e-001,-4.660686e-002,-5.589187e-002,-7.007169e-001,-4.295656e-002,-5.224156e-002,-1.764327e-003,-1.764327e-003,,,,,,,,,,,,,,,,,,,,
1473351186.650,,5.000000e+002,6.598800e+000,6.704967e+000,1,0,8.597021e-001,-9.523301e-001,-9.523301e-001,-3.019207e-001,-3.079685e-001,-9.763529e-001,-3.259435e-001,-3.319913e-001,-2.385435e-003,-2.385435e-003,,,,,,,,,,,,,,,,,,,,
1473351201.615,,5.000000e+002,6.779736e+000,6.934163e+000,1,0,3.629334e-001,-9.903256e-001,-9.903256e-001,-2.121777e-001,-2.149466e-001,-9.870353e-001,-2.088874e-001,-2.116563e-001,-2.480607e-003,-2.480607e-003,,,,,,,,,,,,,,,,,,,,
1473351201.615,,5.000000e+002,6.779736e+000,6.934163e+000,1,0,3.026967e+000,-3.434858e-001,-3.434858e-001,4.474997e-001,4.318932e-001,-3.729242e-001,4.180613e-001,4.024548e-001,-8.603770e-004,-8.603770e-004,,,,,,,,,,,,,,,,,,,,
1473351217.770,,5.000000e+002,7.048569e+000,7.192878e+000,1,0,4.967484e+000,-9.154027e-001,-9.154027e-001,-1.324873e-001,-1.449369e-001,-9.080578e-001,-1.251424e-001,-1.375920e-001,-2.292937e-003,-2.292937e-003,,,,,,,,,,,,,,,,,,,,
1473351229.092,,5.000000e+002,7.232095e+000,7.387763e+000,1,0,3.308850e+000,-6.273080e-001,-6.273080e-001,1.485515e-001,1.393768e-001,-6.285556e-001,1.473039e-001,1.381292e-001,-1.571306e-003,-1.571306e-003,,,,,,,,,,,,,,,,,,,,
1473351242.806,,5.000000e+002,7.464398e+000,7.623567e+000,1,0,7.008812e-001,-1.059450e+000,-1.059450e+000,-2.901754e-001,-2.960246e-001,-1.076553e+000,-3.072784e-001,-3.131276e-001,-2.653753e-003,-2.653753e-003,,,,,,,,,,,,,,,,,,,,
1473351255.020,,5.000000e+002,7.661934e+000,7.819383e+000,1,0,5.142521e-001,-1.015351e+000,-1.015351e+000,-2.526937e-001,-2.552741e-001,-1.019385e+000,-2.567274e-001,-2.593078e-001,-2.543291e-003,-2.543291e-003,,,,,,,,,,,,,,,,,,,,
1473351255.020,,5.000000e+002,7.661934e+000,7.819383e+000,1,0,3.234164e+000,-5.327006e-001,-5.327006e-001,2.431167e-001,2.273761e-001,-5.578023e-001,2.180150e-001,2.022744e-001,-1.334330e-003,-1.334330e-003,,,,,,,,,,,,,,,,,,,,
1473351281.179,,5.000000e+002,8.071470e+000,8.230592e+000,1,0,4.993468e+000,-9.063997e-001,-9.063997e-001,-1.286956e-001,-1.422874e-001,-8.980195e-001,-1.203154e-001,-1.339071e-001,-2.270386e-003,-2.270386e-003,,,,,,,,,,,,,,,,,,,,
1473351294.751,,5.000000e+002,8.309769e+000,8.440977e+000,1,0,3.086783e+000,-4.234443e-001,-4.234443e-001,3.656793e-001,3.548875e-001,-4.270364e-001,3.620872e-001,3.512954e-001,-1.060660e-003,-1.060660e-003,,,,,,,,,,,,,,,,,,,,
1473351308.716,,5.000000e+002,8.509207e+000,8.661747e+000,1,0,5.500765e-001,-5.803095e-001,-5.803095e-001,-3.125124e-001,-1.447945e-001,-5.348448e-001,-2.670477e-001,-9.932980e-002,-1.453582e-003,-1.453582e-003,,,,,,,,,,,,,,,,,,,,
1473351320.680,,5.000000e+002,8.700533e+000,8.855011e+000,1,0,6.832525e-001,-1.056398e+000,-1.056398e+000,-2.916726e-001,-2.935843e-001,-1.069492e+000,-3.047662e-001,-3.066779e-001,-2.646109e-003,-2.646109e-003,,,,,,,,,,,,,,,,,,,,
1473351320.680,,5.000000e+002,8.700533e+000,8.855011e+000,1,0,3.432441e+000,-7.258828e-001,-7.258828e-001,4.967605e-002,3.693104e-002,-7.393679e-001,3.619091e-002,2.344590e-002,-1.818220e-003,-1.818220e-003,,,,,,,,,,,,,,,,,,,,
1473351342.905,,5.000000e+002,9.034286e+000,9.182182e+000,1,0,4.986051e+000,-8.926665e-001,-8.926664e-001,-1.316160e-001,-1.433402e-001,-8.832604e-001,-1.222099e-001,-1.339341e-001,-2.235987e-003,-2.235987e-003,,,,,,,,,,,,,,,,,,,,
1473351354.869,,5.000000e+002,9.296551e+000,9.413897e+000,1,0,2.861555e+000,-1.786859e-001,-1.786859e-001,5.736674e-001,5.653498e-001,-1.759169e-001,5.764364e-001,5.681188e-001,-4.475795e-004,-4.475795e-004,,,,,,,,,,,,,,,,,,,,
1473351367.834,,5.000000e+002,9.449049e+000,9.632576e+000,1,0,4.097742e-001,-9.678946e-001,-9.678946e-001,-2.258422e-001,-2.308995e-001,-9.674546e-001,-2.254022e-001,-2.304596e-001,-2.424421e-003,-2.424421e-003,,,,,,,,,,,,,,,,,,,,
1473351379.589,,5.000000e+002,9.632576e+000,9.780964e+000,1,0,8.662706e-001,-1.040071e+000,-1.040071e+000,-3.084664e-001,-3.103959e-001,-1.061337e+000,-3.297331e-001,-3.316626e-001,-2.605211e-003,-2.605211e-003,,,,,,,,,,,,,,,,,,,,
1473351379.589,,5.000000e+002,9.632576e+000,9.780964e+000,1,0,3.621556e+000,-8.586383e-001,-8.586383e-001,-1.147332e-001,-1.289634e-001,-8.627771e-001,-1.188720e-001,-1.331022e-001,-2.150752e-003,-2.150752e-003,,,,,,,,,,,,,,,,,,,,
1473351406.808,,5.000000e+002,1.007940e+001,1.023561e+001,1,0,4.944792e+000,-8.651997e-001,-8.651997e-001,-1.416956e-001,-1.528621e-001,-8.547657e-001,-1.312615e-001,-1.424280e-001,-2.167187e-003,-2.167187e-003,,,,,,,,,,,,,,,,,,,,
1473351421.308,,5.000000e+002,1.030531e+001,1.044900e+001,1,0,2.635062e+000,2.899258e-003,2.899258e-003,7.154275e-001,7.072609e-001,1.535621e-002,7.278845e-001,7.197179e-001,7.262179e-006,7.262179e-006,,,,,,,,,,,,,,,,,,,,
1473351432.272,,5.000000e+002,1.044900e+001,1.063793e+001,1,0,2.833635e-001,-8.989227e-001,-8.989227e-001,-1.931361e-001,-1.981831e-001,-8.932087e-001,-1.874221e-001,-1.924691e-001,-2.251658e-003,-2.251658e-003,,,,,,,,,,,,,,,,,,,,
1473351442.986,,5.000000e+002,1.067633e+001,1.080174e+001,1,0,1.060504e+000,-9.797968e-001,-9.797968e-001,-2.792741e-001,-2.810670e-001,-1.002021e+000,-3.014988e-001,-3.032916e-001,-2.454234e-003,-2.454234e-003,,,,,,,,,,,,,,,,,,,,
1473351442.986,,5.000000e+002,1.067633e+001,1.080174e+001,1,0,3.802224e+000,-9.527879e-001,-9.527879e-001,-2.392033e-001,-2.540581e-001,-9.515440e-001,-2.379595e-001,-2.528142e-001,-2.386581e-003,-2.386581e-003,,,,,,,,,,,,,,,,,,,,
1473351471.141,,5.000000e+002,1.106252e+001,1.120290e+001,1,0,4.870998e+000,-7.281716e-001,-7.281716e-001,-1.597368e-001,-1.709414e-001,-7.169865e-001,-1.485516e-001,-1.597562e-001,-1.823953e-003,-1.823953e-003,,,,,,,,,,,,,,,,,,,,
1473351483.463,,5.000000e+002,1.124175e+001,1.139683e+001,1,0,2.410000e+000,1.722770e-001,1.722770e-001,7.331849e-001,7.250710e-001,1.802871e-001,7.411950e-001,7.330811e-001,4.315263e-004,4.315263e-004,,,,,,,,,,,,,,,,,,,,
1473351496.427,,5.000000e+002,1.146871e+001,1.161490e+001,1,0,1.753612e-001,-7.199317e-001,-7.199317e-001,-1.649616e-001,-1.697794e-001,-7.129731e-001,-1.580030e-001,-1.628208e-001,-1.803314e-003,-1.803314e-003,,,,,,,,,,,,,,,,,,,,
1473351508.392,,5.000000e+002,1.165281e+001,1.180659e+001,1,0,1.263852e+000,-7.388531e-001,-7.388531e-001,-1.896973e-001,-1.912113e-001,-7.536398e-001,-2.044840e-001,-2.059981e-001,-1.850709e-003,-1.850709e-003,,,,,,,,,,,,,,,,,,,,
1473351508.392,,5.000000e+002,1.165281e+001,1.180659e+001,1,0,3.975179e+000,-8.748131e-001,-8.748131e-001,-3.127875e-001,-3.271713e-001,-8.716233e-001,-3.095977e-001,-3.239816e-001,-2.191267e-003,-2.191267e-003,,,,,,,,,,,,,,,,,,,,
1473351543.608,,5.000000e+002,1.218455e+001,1.234358e+001,1,0,4.767355e+000,-8.754234e-001,-8.754234e-001,-1.886084e-001,-1.996807e-001,-8.624650e-001,-1.756500e-001,-1.867222e-001,-2.192796e-003,-2.192796e-003,,,,,,,,,,,,,,,,,,,,
1473351556.322,,5.000000e+002,1.234358e+001,1.251888e+001,1,0,2.188770e+000,-5.813776e-002,-5.813776e-002,6.230342e-001,6.151931e-001,-6.818154e-002,6.129904e-001,6.051494e-001,-1.456258e-004,-1.456258e-004,,,,,,,,,,,,,,,,,,,,
1473351570.537,,5.000000e+002,1.263335e+001,1.275122e+001,1,0,9.044407e-002,-8.217109e-001,-8.217109e-001,-1.464698e-001,-1.510451e-001,-8.125763e-001,-1.373352e-001,-1.419105e-001,-2.058254e-003,-2.058254e-003,,,,,,,,,,,,,,,,,,,,
1473351582.251,,5.000000e+002,1.283006e+001,1.298728e+001,1,0,1.474753e+000,-7.135228e-001,-7.135227e-001,-4.356754e-002,-4.484183e-002,-7.199854e-001,-5.003018e-002,-5.130446e-002,-1.787260e-003,-1.787260e-003,,,,,,,,,,,,,,,,,,,,
1473351582.251,,5.000000e+002,1.283006e+001,1.298728e+001,1,0,4.141033e+000,-1.018098e+000,-1.018098e+000,-3.351446e-001,-3.494166e-001,-1.013244e+000,-3.302914e-001,-3.445634e-001,-2.550171e-003,-2.550171e-003,,,,,,,,,,,,,,,,,,,,
1473351600.216,,5.000000e+002,1.311329e+001,1.330025e+001,1,0,4.637824e+000,-9.044160e-001,-9.044160e-001,-2.280380e-001,-2.389778e-001,-8.900480e-001,-2.136699e-001,-2.246098e-001,-2.265417e-003,-2.265417e-003,,,,,,,,,,,,,,,,,,,,
1473351614.180,,5.000000e+002,1.334528e+001,1.353246e+001,1,0,1.973677e+000,-2.328562e-001,-2.328562e-001,4.378091e-001,4.301910e-001,-2.559035e-001,4.147619e-001,4.071437e-001,-5.832676e-004,-5.832676e-004,,,,,,,,,,,,,,,,,,,,
1473351628.645,,5.000000e+002,1.364760e+001,1.376579e+001,1,0,3.321411e-002,-8.009583e-001,-8.009583e-001,-1.361460e-001,-1.404654e-001,-7.894507e-001,-1.246384e-001,-1.289578e-001,-2.006272e-003,-2.006272e-003,,,,,,,,,,,,,,,,,,,,
1473351643.609,,5.000000e+002,1.380199e+001,1.403480e+001,1,0,1.691954e+000,-5.160680e-001,-5.160680e-001,1.428112e-001,1.417954e-001,-5.177312e-001,1.411480e-001,1.401322e-001,-1.292668e-003,-1.292668e-003,,,,,,,,,,,,,,,,,,,,
1473351643.609,,5.000000e+002,1.380199e+001,1.403480e+001,1,0,4.299874e+000,-9.912412e-001,-9.912412e-001,-3.194106e-001,-3.333778e-001,-9.829814e-001,-3.111508e-001,-3.251181e-001,-2.482901e-003,-2.482901e-003,,,,,,,,,,,,,,,,,,,,
1473351656.073,,5.000000e+002,1.410763e+001,1.422216e+001,1,0,4.486489e+000,-9.414960e-001,-9.414960e-001,-2.751390e-001,-2.858796e-001,-9.270746e-001,-2.607176e-001,-2.714581e-001,-2.358297e-003,-2.358297e-003,,,,,,,,,,,,,,,,,,,,
1473351669.538,,5.000000e+002,1.433474e+001,1.444577e+001,1,0,1.766575e+000,-4.258858e-001,-4.258858e-001,2.348741e-001,2.275042e-001,-4.492524e-001,2.115075e-001,2.041376e-001,-1.066776e-003,-1.066776e-003,,,,,,,,,,,,,,,,,,,,
1473351683.767,,5.000000e+002,1.455687e+001,1.470600e+001,1,0,7.265595e-003,-7.873775e-001,-7.873775e-001,-1.324387e-001,-1.365001e-001,-7.740164e-001,-1.190776e-001,-1.231390e-001,-1.972255e-003,-1.972255e-003,,,,,,,,,,,,,,,,,,,,
1473351696.675,,5.000000e+002,1.471832e+001,1.487450e+001,1,0,1.913943e+000,-2.986236e-001,-2.986236e-001,3.509727e-001,3.502098e-001,-2.946354e-001,3.549610e-001,3.541980e-001,-7.480044e-004,-7.480044e-004,,,,,,,,,,,,,,,,,,,,
1473351696.675,,5.000000e+002,1.471832e+001,1.487450e+001,1,0,4.450553e+000,-9.462264e-001,-9.462264e-001,-2.836594e-001,-2.973930e-001,-9.338296e-001,-2.712626e-001,-2.849962e-001,-2.370146e-003,-2.370146e-003,,,,,,,,,,,,,,,,,,,,
1473351779.260,,5.000000e+002,1.500030e+001,1.500152e+001,1,0,4.317490e+000,-8.684042e-001,-8.684042e-001,-3.188223e-001,-3.296002e-001,-8.567287e-001,-3.071467e-001,-3.179246e-001,-2.175214e-003,-2.175214e-003,,,,,,,,,,,,,,,,,,,,
1473351792.224,,5.000000e+002,1.500152e+001,1.500152e+001,1,0,1.568378e+000,-4.971465e-001,-4.971465e-001,4.972908e-002,4.237095e-002,-5.175930e-001,2.928257e-002,2.192444e-002,-1.245273e-003,-1.245273e-003,,,,,,,,,,,,,,,,,,,,
1473351804.439,,5.000000e+002,1.500335e+001,1.500213e+001,1,0,1.471242e-002,-6.787316e-001,-6.787317e-001,-1.347946e-001,-1.387061e-001,-6.646352e-001,-1.206981e-001,-1.246096e-001,-1.700114e-003,-1.700114e-003,,,,,,,,,,,,,,,,,,,,
1473351817.402,,5.000000e+002,1.500213e+001,1.500091e+001,1,0,2.139227e+000,1.464888e-002,1.464888e-002,5.554599e-001,5.549377e-001,2.907993e-002,5.698909e-001,5.693688e-001,3.669311e-005,3.669311e-005,,,,,,,,,,,,,,,,,,,,
1473351817.402,,5.000000e+002,1.500213e+001,1.500091e+001,1,0,4.590914e+000,-7.966857e-001,-7.966857e-001,-2.425617e-001,-2.563968e-001,-7.821356e-001,-2.280116e-001,-2.418467e-001,-1.995570e-003,-1.995570e-003,,,,,,,,,,,,,,,,,,,,
1473351909.375,,5.000000e+002,1.500030e+001,1.500274e+001,1,0,4.134456e+000,-8.989227e-001,-8.989227e-001,-3.375322e-001,-3.480384e-001,-8.913097e-001,-3.299192e-001,-3.404254e-001,-2.251658e-003,-2.251658e-003,,,,,,,,,,,,,,,,,,,,
1473351920.839,,5.000000e+002,1.500152e+001,1.500274e+001,1,0,1.379060e+000,-6.636250e-001,-6.636250e-001,-1.052953e-001,-1.123678e-001,-6.833835e-001,-1.250538e-001,-1.321263e-001,-1.662274e-003,-1.662274e-003,,,,,,,,,,,,,,,,,,,,
1473351933.053,,5.000000e+002,1.500213e+001,1.500213e+001,1,0,5.595833e-002,-6.978058e-001,-6.978057e-001,-1.424299e-001,-1.461086e-001,-6.848165e-001,-1.294407e-001,-1.331194e-001,-1.747892e-003,-1.747892e-003,,,,,,,,,,,,,,,,,,,,
1473351945.517,,5.000000e+002,1.500213e+001,1.500213e+001,1,0,2.365653e+000,1.474044e-001,1.474044e-001,7.002677e-001,7.000016e-001,1.711542e-001,7.240175e-001,7.237514e-001,3.692245e-004,3.692245e-004,,,,,,,,,,,,,,,,,,,,
1473351945.517,,5.000000e+002,1.500213e+001,1.500213e+001,1,0,4.717360e+000,-7.695242e-001,-7.695242e-001,-2.030892e-001,-2.169270e-001,-7.560585e-001,-1.896235e-001,-2.034613e-001,-1.927535e-003,-1.927535e-003,,,,,,,,,,,,,,,,,,,,
1473352028.742,,5.000000e+002,1.817859e+001,1.863668e+001,1,0,3.940179e+000,-9.935301e-001,-9.935301e-001,-2.992137e-001,-3.091604e-001,-9.878750e-001,-2.935587e-001,-3.035054e-001,-2.488634e-003,-2.488634e-003,,,,,,,,,,,,,,,,,,,,
1473352042.706,,5.000000e+002,1.875123e+001,1.936654e+001,1,0,1.198529e+000,-9.022797e-001,-9.022797e-001,-2.148884e-001,-2.214742e-001,-9.248883e-001,-2.374970e-001,-2.440827e-001,-2.260066e-003,-2.260066e-003,,,,,,,,,,,,,,,,,,,,
1473352054.920,,5.000000e+002,1.947461e+001,2.001032e+001,1,0,1.297647e-001,-8.337657e-001,-8.337657e-001,-1.536785e-001,-1.569637e-001,-8.230621e-001,-1.429749e-001,-1.462601e-001,-2.088450e-003,-2.088450e-003,,,,,,,,,,,,,,,,,,,,
1473352066.634,,5.000000e+002,2.012661e+001,2.047952e+001,1,0,2.590728e+000,1.702933e-001,1.702933e-001,7.084605e-001,7.084605e-001,1.852627e-001,7.234299e-001,7.234299e-001,4.265574e-004,4.265574e-004,,,,,,,,,,,,,,,,,,,,
1473352066.634,,5.000000e+002,2.012661e+001,2.047952e+001,1,0,4.825431e+000,-7.161168e-001,-7.161168e-001,-1.647881e-001,-1.779497e-001,-7.071694e-001,-1.558406e-001,-1.690022e-001,-1.793758e-003,-1.793758e-003,,,,,,,,,,,,,,,,,,,,
1473352085.849,,5.000000e+002,2.094814e+001,2.141589e+001,1,0,3.736914e+000,-7.467879e-001,-7.467879e-001,-1.984131e-001,-2.084312e-001,-7.409493e-001,-1.925744e-001,-2.025926e-001,-1.870584e-003,-1.870584e-003,,,,,,,,,,,,,,,,,,,,
1473352097.317,,5.000000e+002,2.153488e+001,2.211537e+001,1,0,1.025458e+000,-9.546189e-001,-9.546190e-001,-2.751627e-001,-2.816827e-001,-9.800747e-001,-3.006184e-001,-3.071384e-001,-2.391168e-003,-2.391168e-003,,,,,,,,,,,,,,,,,,,,
1473352109.782,,5.000000e+002,2.223140e+001,2.269372e+001,1,0,2.333539e-001,-8.497879e-001,-8.497879e-001,-1.741644e-001,-1.772925e-001,-8.419372e-001,-1.663138e-001,-1.694419e-001,-2.128583e-003,-2.128583e-003,,,,,,,,,,,,,,,,,,,,
1473352109.782,,5.000000e+002,2.223140e+001,2.269372e+001,1,0,2.812058e+000,-7.431257e-002,-7.431257e-002,6.146055e-001,5.981828e-001,-9.358983e-002,5.953282e-001,5.789055e-001,-1.861411e-004,-1.861411e-004,,,,,,,,,,,,,,,,,,,,
1473352121.746,,5.000000e+002,2.281013e+001,2.323113e+001,1,0,4.910316e+000,-8.244575e-001,-8.244575e-001,-1.405668e-001,-1.535878e-001,-8.172013e-001,-1.333105e-001,-1.463316e-001,-2.065134e-003,-2.065134e-003,,,,,,,,,,,,,,,,,,,,
1473352155.008,,5.000000e+002,2.430774e+001,2.485457e+001,1,0,3.525955e+000,-7.200842e-001,-7.200842e-001,-4.399347e-002,-5.368841e-002,-7.163253e-001,-4.023456e-002,-4.992950e-002,-1.803696e-003,-1.803696e-003,,,,,,,,,,,,,,,,,,,,
1473352168.223,,5.000000e+002,2.493435e+001,2.537722e+001,1,0,8.596880e-001,-9.585864e-001,-9.585864e-001,-2.873016e-001,-2.935976e-001,-9.822239e-001,-3.109391e-001,-3.172352e-001,-2.401106e-003,-2.401106e-003,,,,,,,,,,,,,,,,,,,,
1473352182.491,,5.000000e+002,2.548941e+001,2.616640e+001,1,0,3.629195e-001,-8.670308e-001,-8.670309e-001,-2.007002e-001,-2.035959e-001,-8.638284e-001,-1.974977e-001,-2.003934e-001,-2.171774e-003,-2.171774e-003,,,,,,,,,,,,,,,,,,,,
1473352182.491,,5.000000e+002,2.548941e+001,2.616640e+001,1,0,3.026982e+000,-2.543718e-001,-2.543718e-001,4.253844e-001,4.090632e-001,-2.823429e-001,3.974133e-001,3.810921e-001,-6.371606e-004,-6.371606e-004,,,,,,,,,,,,,,,,,,,,
1473352194.705,,5.000000e+002,2.616640e+001,2.680163e+001,1,0,4.967504e+000,-7.998902e-001,-7.998902e-001,-1.251513e-001,-1.380221e-001,-7.928531e-001,-1.181142e-001,-1.309850e-001,-2.003597e-003,-2.003597e-003,,,,,,,,,,,,,,,,,,,,
1473352210.447,,5.000000e+002,2.704197e+001,2.751729e+001,1,0,3.308836e+000,-5.293435e-001,-5.293435e-001,1.400796e-001,1.305717e-001,-5.303974e-001,1.390257e-001,1.295179e-001,-1.325921e-003,-1.325921e-003,,,,,,,,,,,,,,,,,,,,
1473352222.192,,5.000000e+002,2.763512e+001,2.810896e+001,1,0,7.008399e-001,-9.329509e-001,-9.329509e-001,-2.682788e-001,-2.743871e-001,-9.497436e-001,-2.850716e-001,-2.911799e-001,-2.336893e-003,-2.336893e-003,,,,,,,,,,,,,,,,,,,,
1473352235.906,,5.000000e+002,2.835018e+001,2.881966e+001,1,0,5.142176e-001,-8.920560e-001,-8.920560e-001,-2.323377e-001,-2.349965e-001,-8.960270e-001,-2.363086e-001,-2.389675e-001,-2.234458e-003,-2.234458e-003,,,,,,,,,,,,,,,,,,,,
1473352235.906,,5.000000e+002,2.835018e+001,2.881966e+001,1,0,3.234090e+000,-4.466384e-001,-4.466384e-001,2.266400e-001,2.104212e-001,-4.706359e-001,2.026425e-001,1.864237e-001,-1.118758e-003,-1.118758e-003,,,,,,,,,,,,,,,,,,,,
1473352248.121,,5.000000e+002,2.893855e+001,2.940893e+001,1,0,4.993488e+000,-7.870724e-001,-7.870724e-001,-1.183572e-001,-1.311592e-001,-7.792147e-001,-1.104995e-001,-1.233016e-001,-1.971490e-003,-1.971490e-003,,,,,,,,,,,,,,,,,,,,
1473352270.836,,5.000000e+002,2.987555e+001,3.040502e+001,1,0,3.086744e+000,-3.305154e-001,-3.305154e-001,3.327575e-001,3.233727e-001,-3.336815e-001,3.295915e-001,3.202067e-001,-8.278884e-004,-8.278884e-004,,,,,,,,,,,,,,,,,,,,
1473352286.068,,5.000000e+002,3.075425e+001,3.110115e+001,1,0,5.501345e-001,-8.909879e-001,-8.909879e-001,-2.326249e-001,-2.385288e-001,-8.988770e-001,-2.405141e-001,-2.464180e-001,-2.231782e-003,-2.231782e-003,,,,,,,,,,,,,,,,,,,,
1473352299.033,,5.000000e+002,3.144919e+001,3.179558e+001,1,0,6.832309e-001,-9.120457e-001,-9.120457e-001,-2.584892e-001,-2.609073e-001,-9.247301e-001,-2.711736e-001,-2.735917e-001,-2.284528e-003,-2.284528e-003,,,,,,,,,,,,,,,,,,,,
1473352299.033,,5.000000e+002,3.144919e+001,3.179558e+001,1,0,3.432366e+000,-6.208991e-001,-6.208991e-001,4.635975e-002,3.023928e-002,-6.332040e-001,3.405485e-002,1.793438e-002,-1.555253e-003,-1.555253e-003,,,,,,,,,,,,,,,,,,,,
1473352313.451,,5.000000e+002,3.214265e+001,3.260261e+001,1,0,4.986062e+000,-7.792901e-001,-7.792901e-001,-1.169668e-001,-1.296417e-001,-7.707189e-001,-1.083956e-001,-1.210705e-001,-1.951997e-003,-1.951997e-003,,,,,,,,,,,,,,,,,,,,
1473352332.051,,5.000000e+002,3.294997e+001,3.352216e+001,1,0,2.861452e+000,-1.533555e-001,-1.533555e-001,5.035470e-001,4.943074e-001,-1.511339e-001,5.057685e-001,4.965289e-001,-3.841310e-004,-3.841310e-004,,,,,,,,,,,,,,,,,,,,
1473352344.265,,5.000000e+002,3.364006e+001,3.409983e+001,1,0,4.098301e-001,-8.468887e-001,-8.468887e-001,-1.947260e-001,-2.004449e-001,-8.470348e-001,-1.948722e-001,-2.005911e-001,-2.121321e-003,-2.121321e-003,,,,,,,,,,,,,,,,,,,,
1473352355.729,,5.000000e+002,3.420953e+001,3.457487e+001,1,0,8.662467e-001,-9.114353e-001,-9.114353e-001,-2.640242e-001,-2.661932e-001,-9.315964e-001,-2.841853e-001,-2.863543e-001,-2.283000e-003,-2.283000e-003,,,,,,,,,,,,,,,,,,,,
1473352355.729,,5.000000e+002,3.420953e+001,3.457487e+001,1,0,3.621576e+000,-7.577746e-001,-7.577746e-001,-9.653620e-002,-1.125325e-001,-7.619850e-001,-1.007466e-001,-1.167429e-001,-1.898104e-003,-1.898104e-003,,,,,,,,,,,,,,,,,,,,
1473352369.694,,5.000000e+002,3.479139e+001,3.520350e+001,1,0,4.944847e+000,-7.783746e-001,-7.783746e-001,-1.220582e-001,-1.346196e-001,-7.690170e-001,-1.127006e-001,-1.252620e-001,-1.949704e-003,-1.949704e-003,,,,,,,,,,,,,,,,,,,,
1473352406.861,,5.000000e+002,3.641850e+001,3.705951e+001,1,0,2.635132e+000,1.557970e-001,1.557970e-001,5.988972e-001,5.896289e-001,1.657939e-001,6.088940e-001,5.996258e-001,3.902465e-004,3.902465e-004,,,,,,,,,,,,,,,,,,,,
1473352420.685,,5.000000e+002,3.705951e+001,3.771304e+001,1,0,2.834254e-001,-5.993835e-001,-5.993835e-001,-1.591012e-001,-1.647276e-001,-5.946548e-001,-1.543725e-001,-1.599989e-001,-1.501360e-003,-1.501360e-003,,,,,,,,,,,,,,,,,,,,
1473352432.648,,5.000000e+002,3.793695e+001,3.826513e+001,1,0,1.060474e+000,-6.646931e-001,-6.646931e-001,-2.277976e-001,-2.297655e-001,-6.852786e-001,-2.483831e-001,-2.503510e-001,-1.664950e-003,-1.664950e-003,,,,,,,,,,,,,,,,,,,,
1473352432.648,,5.000000e+002,3.793695e+001,3.826513e+001,1,0,3.802219e+000,-6.462294e-001,-6.462294e-001,-1.949963e-001,-2.113019e-001,-6.451005e-001,-1.938674e-001,-2.101729e-001,-1.618701e-003,-1.618701e-003,,,,,,,,,,,,,,,,,,,,
1473352449.363,,5.000000e+002,3.848407e+001,3.904306e+001,1,0,4.870964e+000,-7.138280e-001,-7.138279e-001,-1.310610e-001,-1.436620e-001,-7.039181e-001,-1.211512e-001,-1.337522e-001,-1.788025e-003,-1.788025e-003,,,,,,,,,,,,,,,,,,,,
1473352465.263,,5.000000e+002,3.937262e+001,3.981375e+001,1,0,2.410034e+000,8.850368e-003,8.850368e-003,5.874641e-001,5.784560e-001,1.460385e-002,5.932176e-001,5.842094e-001,2.216876e-005,2.216876e-005,,,,,,,,,,,,,,,,,,,,
1473352480.836,,5.000000e+002,4.003585e+001,4.058501e+001,1,0,1.753453e-001,-7.051302e-001,-7.051302e-001,-1.310782e-001,-1.364394e-001,-6.984493e-001,-1.243973e-001,-1.297585e-001,-1.766238e-003,-1.766238e-003,,,,,,,,,,,,,,,,,,,,
1473352495.800,,5.000000e+002,4.080495e+001,4.139850e+001,1,0,1.263855e+000,-7.174901e-001,-7.174901e-001,-1.483651e-001,-1.500534e-001,-7.310593e-001,-1.619342e-001,-1.636225e-001,-1.797198e-003,-1.797198e-003,,,,,,,,,,,,,,,,,,,,
1473352495.800,,5.000000e+002,4.080495e+001,4.139850e+001,1,0,3.975164e+000,-8.282723e-001,-8.282723e-001,-2.447966e-001,-2.608356e-001,-8.250126e-001,-2.415369e-001,-2.575759e-001,-2.074690e-003,-2.074690e-003,,,,,,,,,,,,,,,,,,,,
1473352509.451,,5.000000e+002,4.163709e+001,4.210709e+001,1,0,4.767402e+000,-7.271035e-001,-7.271035e-001,-1.483185e-001,-1.607509e-001,-7.156438e-001,-1.368588e-001,-1.492912e-001,-1.821278e-003,-1.821278e-003,,,,,,,,,,,,,,,,,,,,
1473352521.773,,5.000000e+002,4.234005e+001,4.268914e+001,1,0,2.188739e+000,-9.842219e-002,-9.842219e-002,4.756115e-001,4.668207e-001,-1.066474e-001,4.673862e-001,4.585955e-001,-2.465319e-004,-2.465319e-004,,,,,,,,,,,,,,,,,,,,
1473352535.532,,5.000000e+002,4.292216e+001,4.338641e+001,1,0,9.042676e-002,-6.814783e-001,-6.814783e-001,-1.124889e-001,-1.176108e-001,-6.723312e-001,-1.033418e-001,-1.084636e-001,-1.706994e-003,-1.706994e-003,,,,,,,,,,,,,,,,,,,,
1473352549.446,,5.000000e+002,4.362455e+001,4.419460e+001,1,0,1.474781e+000,-5.983154e-001,-5.983154e-001,-3.441072e-002,-3.583437e-002,-6.040115e-001,-4.010683e-002,-4.153049e-002,-1.498684e-003,-1.498684e-003,,,,,,,,,,,,,,,,,,,,
1473352549.446,,5.000000e+002,4.362455e+001,4.419460e+001,1,0,4.141109e+000,-8.307139e-001,-8.307138e-001,-2.522879e-001,-2.682328e-001,-8.257892e-001,-2.473633e-001,-2.633082e-001,-2.080805e-003,-2.080805e-003,,,,,,,,,,,,,,,,,,,,
1473352564.268,,5.000000e+002,4.430381e+001,4.488095e+001,1,0,4.637832e+000,-7.446517e-001,-7.446516e-001,-1.715175e-001,-1.838611e-001,-7.320859e-001,-1.589518e-001,-1.712955e-001,-1.865233e-003,-1.865233e-003,,,,,,,,,,,,,,,,,,,,
1473352578.776,,5.000000e+002,4.499445e+001,4.557029e+001,1,0,1.973677e+000,-2.513199e-001,-2.513199e-001,3.167537e-001,3.080845e-001,-2.688594e-001,2.992142e-001,2.905450e-001,-6.295162e-004,-6.295162e-004,,,,,,,,,,,,,,,,,,,,
1473352591.785,,5.000000e+002,4.579723e+001,4.625340e+001,1,0,3.324231e-002,-6.637776e-001,-6.637776e-001,-1.006036e-001,-1.055269e-001,-6.522729e-001,-8.909893e-002,-9.402221e-002,-1.662657e-003,-1.662657e-003,,,,,,,,,,,,,,,,,,,,
1473352604.502,,5.000000e+002,4.636611e+001,4.679158e+001,1,0,1.691955e+000,-4.605243e-001,-4.605243e-001,9.790179e-002,9.674025e-002,-4.611540e-001,9.727213e-002,9.611058e-002,-1.153540e-003,-1.153540e-003,,,,,,,,,,,,,,,,,,,,
1473352604.502,,5.000000e+002,4.636611e+001,4.679158e+001,1,0,4.300030e+000,-8.027894e-001,-8.027894e-001,-2.295536e-001,-2.455248e-001,-7.954351e-001,-2.221992e-001,-2.381705e-001,-2.010859e-003,-2.010859e-003,,,,,,,,,,,,,,,,,,,,
1473352617.513,,5.000000e+002,4.700824e+001,4.745300e+001,1,0,4.486485e+000,-7.654042e-001,-7.654042e-001,-1.970584e-001,-2.093444e-001,-7.527075e-001,-1.843617e-001,-1.966477e-001,-1.917215e-003,-1.917215e-003,,,,,,,,,,,,,,,,,,,,
1473352631.747,,5.000000e+002,4.756461e+001,4.821015e+001,1,0,1.766570e+000,-2.667318e-001,-2.667318e-001,1.608576e-001,1.523479e-001,-2.844533e-001,1.431360e-001,1.346263e-001,-6.681205e-004,-6.681205e-004,,,,,,,,,,,,,,,,,,,,
1473352644.961,,5.000000e+002,4.831821e+001,4.875169e+001,1,0,7.280503e-003,-5.163732e-001,-5.163732e-001,-9.372496e-002,-9.843293e-002,-5.033382e-001,-8.068996e-002,-8.539793e-002,-1.293432e-003,-1.293432e-003,,,,,,,,,,,,,,,,,,,,
1473352659.676,,5.000000e+002,4.908301e+001,4.952330e+001,1,0,1.914011e+000,-1.870785e-001,-1.870785e-001,2.306356e-001,2.297505e-001,-1.823822e-001,2.353319e-001,2.344468e-001,-4.686016e-004,-4.686016e-004,,,,,,,,,,,,,,,,,,,,
1473352659.676,,5.000000e+002,4.908301e+001,4.952330e+001,1,0,4.450687e+000,-6.260872e-001,-6.260872e-001,-1.933263e-001,-2.092583e-001,-6.163359e-001,-1.835750e-001,-1.995069e-001,-1.568248e-003,-1.568248e-003,,,,,,,,,,,,,,,,,,,,
1473352673.640,,5.000000e+002,4.974626e+001,5.018916e+001,1,0,4.317506e+000,-6.428724e-001,-6.428724e-001,-2.151324e-001,-2.273298e-001,-6.315821e-001,-2.038421e-001,-2.160395e-001,-1.610293e-003,-1.610293e-003,,,,,,,,,,,,,,,,,,,,
1473352690.400,,5.000000e+002,5.051771e+001,5.107056e+001,1,0,1.568281e+000,-2.548296e-001,-2.548296e-001,3.209608e-002,2.372646e-002,-2.711548e-001,1.577081e-002,7.401198e-003,-6.383073e-004,-6.383073e-004,,,,,,,,,,,,,,,,,,,,
1473352703.614,,5.000000e+002,5.118329e+001,5.174346e+001,1,0,1.469851e-002,-3.715629e-001,-3.715628e-001,-8.945994e-002,-9.399059e-002,-3.581461e-001,-7.604317e-002,-8.057383e-002,-9.307055e-004,-9.307055e-004,,,,,,,,,,,,,,,,,,,,
1473352716.328,,5.000000e+002,5.196972e+001,5.231807e+001,1,0,2.139223e+000,-7.263406e-002,-7.263406e-002,3.411655e-001,3.405595e-001,-6.079977e-002,3.529998e-001,3.523937e-001,-1.819367e-004,-1.819367e-004,,,,,,,,,,,,,,,,,,,,
1473352716.328,,5.000000e+002,5.196972e+001,5.231807e+001,1,0,4.590918e+000,-5.835139e-001,-5.835139e-001,-1.542596e-001,-1.703204e-001,-5.729293e-001,-1.436750e-001,-1.597357e-001,-1.461609e-003,-1.461609e-003,,,,,,,,,,,,,,,,,,,,
1473352728.293,,5.000000e+002,5.243608e+001,5.290215e+001,1,0,4.134479e+000,-5.008088e-001,-5.008087e-001,-2.115407e-001,-2.236817e-001,-4.918139e-001,-2.025459e-001,-2.146869e-001,-1.254446e-003,-1.254446e-003,,,,,,,,,,,,,,,,,,,,
1473352749.258,,5.000000e+002,5.350154e+001,5.396428e+001,1,0,1.379073e+000,-4.805140e-001,-4.805139e-001,-6.006323e-002,-6.831500e-002,-4.975250e-001,-7.707427e-002,-8.532605e-002,-1.203611e-003,-1.203611e-003,,,,,,,,,,,,,,,,,,,,
1473352761.222,,5.000000e+002,5.407647e+001,5.453360e+001,1,0,5.597057e-002,-5.032502e-001,-5.032502e-001,-8.713303e-002,-9.142983e-002,-4.909251e-001,-7.480789e-002,-7.910469e-002,-1.260561e-003,-1.260561e-003,,,,,,,,,,,,,,,,,,,,
1473352771.686,,5.000000e+002,5.464659e+001,5.511803e+001,1,0,2.365792e+000,-1.480148e-002,-1.480148e-002,3.968422e-001,3.965344e-001,2.424653e-003,4.140683e-001,4.137605e-001,-3.707533e-005,-3.707533e-005,,,,,,,,,,,,,,,,,,,,
1473352771.686,,5.000000e+002,5.464659e+001,5.511803e+001,1,0,4.717457e+000,-5.462813e-001,-5.462813e-001,-1.189419e-001,-1.349455e-001,-5.372314e-001,-1.098919e-001,-1.258955e-001,-1.368347e-003,-1.368347e-003,,,,,,,,,,,,,,,,,,,,
1473352786.651,,5.000000e+002,5.522588e+001,5.581247e+001,1,0,3.940247e+000,-5.963317e-001,-5.963317e-001,-1.734690e-001,-1.855714e-001,-5.886384e-001,-1.657757e-001,-1.778781e-001,-1.493715e-003,-1.493715e-003,,,,,,,,,,,,,,,,,,,,
1473352820.678,,5.000000e+002,5.705746e+001,5.740617e+001,1,0,1.198487e+000,-4.470962e-001,-4.470962e-001,-1.083342e-001,-1.167528e-001,-4.676942e-001,-1.289322e-001,-1.373508e-001,-1.119904e-003,-1.119904e-003,,,,,,,,,,,,,,,,,,,,
1473352844.375,,5.000000e+002,5.809452e+001,5.856960e+001,1,0,1.297820e-001,-2.106693e+000,-2.106693e+000,-4.103871e-001,-4.315774e-001,-2.057179e+000,-3.608730e-001,-3.820634e-001,-1.055386e-003,-1.055386e-003,,,,,,,,,,,,,,,,,,,,
1473352856.625,,5.000000e+002,5.868575e+001,5.915650e+001,1,0,2.590708e+000,5.523850e-002,5.523850e-002,1.741176e+000,1.741176e+000,1.148174e-001,1.800755e+000,1.800755e+000,2.767272e-005,2.767272e-005,,,,,,,,,,,,,,,,,,,,
1473352856.625,,5.000000e+002,5.868575e+001,5.915650e+001,1,0,4.825347e+000,-2.187567e+000,-2.187567e+000,-4.187930e-001,-5.016288e-001,-2.159903e+000,-3.911291e-001,-4.739648e-001,-1.095901e-003,-1.095901e-003,,,,,,,,,,,,,,,,,,,,
1473352871.590,,5.000000e+002,5.938857e+001,5.986328e+001,1,0,3.736898e+000,-2.243721e+000,-2.243721e+000,-4.877170e-001,-5.495282e-001,-2.208963e+000,-4.529592e-001,-5.147704e-001,-1.124032e-003,-1.124032e-003,,,,,,,,,,,,,,,,,,,,
1473352884.105,,5.000000e+002,5.998618e+001,6.058292e+001,1,0,1.025606e+000,-2.327494e+000,-2.327494e+000,-5.877035e-001,-6.285665e-001,-2.441614e+000,-7.018233e-001,-7.426863e-001,-1.166000e-003,-1.166000e-003,,,,,,,,,,,,,,,,,,,,
1473352896.069,,5.000000e+002,6.070509e+001,6.117842e+001,1,0,2.333428e-001,-2.126072e+000,-2.126072e+000,-4.033715e-001,-4.230803e-001,-2.092649e+000,-3.699480e-001,-3.896569e-001,-1.065094e-003,-1.065094e-003,,,,,,,,,,,,,,,,,,,,
1473352896.069,,5.000000e+002,6.070509e+001,6.117842e+001,1,0,2.811938e+000,-3.810236e-001,-3.810236e-001,1.425440e+000,1.321968e+000,-4.582685e-001,1.348195e+000,1.244723e+000,-1.908806e-004,-1.908806e-004,,,,,,,,,,,,,,,,,,,,
1473352911.968,,5.000000e+002,6.141500e+001,6.201669e+001,1,0,4.910277e+000,-2.098453e+000,-2.098453e+000,-3.078249e-001,-3.907369e-001,-2.077925e+000,-2.872975e-001,-3.702096e-001,-1.051258e-003,-1.051258e-003,,,,,,,,,,,,,,,,,,,,
1473352924.337,,5.000000e+002,6.201669e+001,6.260506e+001,1,0,3.526010e+000,-1.189306e+000,-1.189306e+000,-9.539390e-002,-1.570762e-001,-1.167579e+000,-7.366645e-002,-1.353488e-001,-5.958044e-004,-5.958044e-004,,,,,,,,,,,,,,,,,,,,
1473352937.551,,5.000000e+002,6.272554e+001,6.320412e+001,1,0,8.597029e-001,-8.961760e-001,-8.961760e-001,-4.992417e-001,-5.395950e-001,-1.001862e+000,-6.049274e-001,-6.452807e-001,-4.489555e-004,-4.489555e-004,,,,,,,,,,,,,,,,,,,,
1473352951.766,,5.000000e+002,6.344014e+001,6.392121e+001,1,0,3.629127e-001,-7.452620e-001,-7.452620e-001,-3.664006e-001,-3.850358e-001,-7.359064e-001,-3.570450e-001,-3.756802e-001,-3.733524e-004,-3.733524e-004,,,,,,,,,,,,,,,,,,,,
1473352951.766,,5.000000e+002,6.344014e+001,6.392121e+001,1,0,3.027003e+000,3.543199e-001,3.543199e-001,8.195812e-001,7.145461e-001,2.664454e-001,7.317066e-001,6.266716e-001,1.775029e-004,1.775029e-004,,,,,,,,,,,,,,,,,,,,
1473352964.980,,5.000000e+002,6.403660e+001,6.462757e+001,1,0,4.967509e+000,-1.345256e+000,-1.345256e+000,-2.185095e-001,-3.023645e-001,-1.328059e+000,-2.013130e-001,-2.851681e-001,-6.739302e-004,-6.739302e-004,,,,,,,,,,,,,,,,,,,,
1473352978.445,,5.000000e+002,6.486768e+001,6.534268e+001,1,0,3.308873e+000,-8.917509e-001,-8.917509e-001,2.175852e-001,1.553158e-001,-8.888740e-001,2.204621e-001,1.581927e-001,-4.467386e-004,-4.467386e-004,,,,,,,,,,,,,,,,,,,,
1473352992.909,,5.000000e+002,6.558581e+001,6.605608e+001,1,0,7.008783e-001,-1.405377e+000,-1.405377e+000,-3.125511e-001,-3.527457e-001,-1.485417e+000,-3.925904e-001,-4.327850e-001,-7.040491e-004,-7.040491e-004,,,,,,,,,,,,,,,,,,,,
1473353004.623,,5.000000e+002,6.618526e+001,6.664659e+001,1,0,5.142221e-001,-6.649983e-001,-6.649983e-001,-2.694297e-001,-2.870826e-001,-6.858392e-001,-2.902706e-001,-3.079235e-001,-3.331429e-004,-3.331429e-004,,,,,,,,,,,,,,,,,,,,
1473353004.623,,5.000000e+002,6.618526e+001,6.664659e+001,1,0,3.234091e+000,-1.716666e-001,-1.716666e-001,3.139318e-001,2.062491e-001,-2.351867e-001,2.504117e-001,1.427290e-001,-8.599948e-005,-8.599948e-005,,,,,,,,,,,,,,,,,,,,
1473353017.838,,5.000000e+002,6.677152e+001,6.724504e+001,1,0,4.993492e+000,7.919553e-002,7.919553e-002,-1.317368e-001,-2.175109e-001,9.476610e-002,-1.161662e-001,-2.019403e-001,3.967443e-005,3.967443e-005,,,,,,,,,,,,,,,,,,,,
1473353030.052,,5.000000e+002,6.736552e+001,6.783601e+001,1,0,3.086821e+000,-1.498459e-001,-1.498459e-001,2.994646e-001,2.363427e-001,-1.599653e-001,2.893452e-001,2.262233e-001,-7.506800e-005,-7.506800e-005,,,,,,,,,,,,,,,,,,,,
1473353048.017,,5.000000e+002,6.829929e+001,6.875266e+001,1,0,5.501492e-001,-5.406354e-001,-5.406354e-001,-1.085792e-001,-1.486838e-001,-5.917416e-001,-1.596854e-001,-1.997900e-001,-2.708410e-004,-2.708410e-004,,,,,,,,,,,,,,,,,,,,
1473353062.171,,5.000000e+002,6.898838e+001,6.945239e+001,1,0,6.832032e-001,-5.001984e-001,-5.001984e-001,-8.714747e-002,-1.036881e-001,-5.509713e-001,-1.379204e-001,-1.544611e-001,-2.505834e-004,-2.505834e-004,,,,,,,,,,,,,,,,,,,,
1473353062.171,,5.000000e+002,6.898838e+001,6.945239e+001,1,0,3.432375e+000,-4.647969e-001,-4.647969e-001,4.198414e-002,-6.828663e-002,-4.967500e-001,1.003104e-002,-1.002397e-001,-2.328484e-004,-2.328484e-004,,,,,,,,,,,,,,,,,,,,
1473353074.994,,5.000000e+002,6.956187e+001,7.003860e+001,1,0,4.986101e+000,-5.424665e-001,-5.424665e-001,-5.451740e-002,-1.412113e-001,-5.278386e-001,-3.988953e-002,-1.265834e-001,-2.717584e-004,-2.717584e-004,,,,,,,,,,,,,,,,,,,,
1473353099.129,,5.000000e+002,7.074514e+001,7.133553e+001,1,0,2.861555e+000,-2.233955e-001,-2.233955e-001,4.892026e-001,2.402357e-001,-2.996494e-001,4.129487e-001,1.639818e-001,-2.797850e-005,-2.797850e-005,,,,,,,,,,,,,,,,,,,,
1473353113.951,,5.000000e+002,7.156648e+001,7.202523e+001,1,0,4.097639e-001,-4.722739e-001,-4.722739e-001,-3.932720e-002,-1.906467e-001,-5.879231e-001,-1.549764e-001,-3.062959e-001,-5.914853e-005,-5.914853e-005,,,,,,,,,,,,,,,,,,,,
1473353127.347,,5.000000e+002,7.228563e+001,7.271268e+001,1,0,8.662138e-001,-6.744590e-002,-6.744590e-002,1.542045e-001,9.873845e-002,-3.310895e-001,-1.094390e-001,-1.649051e-001,-8.447060e-006,-8.447060e-006,,,,,,,,,,,,,,,,,,,,
1473353127.347,,5.000000e+002,7.228563e+001,7.271268e+001,1,0,3.621557e+000,-6.360058e-001,-6.360058e-001,-6.075886e-002,-4.698214e-001,-7.008134e-001,-1.255665e-001,-5.346290e-001,-7.965463e-005,-7.965463e-005,,,,,,,,,,,,,,,,,,,,
1473353140.420,,5.000000e+002,7.282977e+001,7.330175e+001,1,0,4.944769e+000,-4.991302e-001,-4.991302e-001,-8.856711e-002,-3.703849e-001,-4.170412e-001,-6.478098e-003,-2.882959e-001,-6.251207e-005,-6.251207e-005,,,,,,,,,,,,,,,,,,,,
1473353152.884,,5.000000e+002,7.341549e+001,7.387915e+001,1,0,2.635106e+000,-6.042665e-002,-6.042665e-002,2.078868e-001,1.704221e-002,-3.741381e-001,-1.058246e-001,-2.966692e-001,-7.567955e-006,-7.567955e-006,,,,,,,,,,,,,,,,,,,,
1473353182.808,,5.000000e+002,7.494468e+001,7.541631e+001,1,0,2.833599e-001,-2.456740e-002,-2.456740e-002,-7.084470e-002,-4.726529e-001,3.376909e-002,-1.250821e-002,-4.143164e-001,-1.230748e-006,-1.230748e-006,,,,,,,,,,,,,,,,,,,,
1473353196.880,,5.000000e+002,7.565430e+001,7.612077e+001,1,0,1.060484e+000,1.235542e+000,1.235542e+000,7.076228e-001,5.696087e-001,5.528032e-001,2.488415e-002,-1.131299e-001,6.189670e-005,6.189670e-005,,,,,,,,,,,,,,,,,,,,
1473353196.880,,5.000000e+002,7.565430e+001,7.612077e+001,1,0,3.802253e+000,-5.845820e-001,-5.845820e-001,-1.069700e-001,-1.250515e+000,-4.576837e-001,1.992835e-002,-1.123617e+000,-2.928569e-005,-2.928569e-005,,,,,,,,,,,,,,,,,,,,
1473353211.598,,5.000000e+002,7.635468e+001,7.682673e+001,1,0,4.870973e+000,-3.891110e-001,-3.891110e-001,-1.308027e-001,-1.035626e+000,-2.136603e-001,4.464803e-002,-8.601750e-001,-1.949322e-005,-1.949322e-005,,,,,,,,,,,,,,,,,,,,
1473353226.010,,5.000000e+002,7.703645e+001,7.763480e+001,1,0,2.410125e+000,1.922666e-002,1.922666e-002,-9.310181e-002,-7.305185e-001,-1.225584e-001,-2.348869e-001,-8.723035e-001,9.631942e-007,9.631942e-007,,,,,,,,,,,,,,,,,,,,
1473353241.583,,5.000000e+002,7.786041e+001,7.834690e+001,1,0,1.753425e-001,2.276681e-001,2.276681e-001,-2.292331e-001,-6.052749e-001,5.202513e-001,6.335014e-002,-3.126916e-001,1.140544e-005,1.140544e-005,,,,,,,,,,,,,,,,,,,,
1473353258.298,,5.000000e+002,7.868877e+001,7.915295e+001,1,0,1.263868e+000,1.366771e+000,1.366771e+000,5.993171e-001,4.822651e-001,8.968124e-001,1.293581e-001,1.230597e-002,6.847088e-005,6.847088e-005,,,,,,,,,,,,,,,,,,,,
1473353258.298,,5.000000e+002,7.868877e+001,7.915295e+001,1,0,3.975292e+000,-3.022859e-001,-3.022859e-001,-7.479737e-002,-1.186792e+000,-7.908478e-002,1.484037e-001,-9.635912e-001,-1.514355e-005,-1.514355e-005,,,,,,,,,,,,,,,,,,,,
1473353271.793,,5.000000e+002,7.936292e+001,7.984679e+001,1,0,4.767421e+000,1.617481e-002,1.617481e-002,-1.240139e-001,-9.920717e-001,2.540417e-001,1.138531e-001,-7.542048e-001,8.103063e-007,8.103063e-007,,,,,,,,,,,,,,,,,,,,
1473353294.515,,5.000000e+002,8.038243e+001,8.051200e+001,1,0,2.188853e+000,5.829035e-002,5.829035e-002,-2.060318e-001,-8.543701e-001,-1.061744e-001,-3.704965e-001,-1.018835e+000,2.920160e-006,2.920160e-006,,,,,,,,,,,,,,,,,,,,
1473353447.287,,5.000000e+002,8.004802e+001,8.003580e+001,1,0,9.052379e-002,2.514725e-001,2.514725e-001,-3.881828e-001,-7.426197e-001,7.181918e-001,7.853647e-002,-2.759004e-001,1.259797e-005,1.259797e-005,,,,,,,,,,,,,,,,,,,,
1473353462.002,,5.000000e+002,8.003885e+001,8.003580e+001,1,0,1.474779e+000,1.140782e+000,1.140782e+000,2.536575e-001,1.553283e-001,9.530086e-001,6.588416e-002,-3.244495e-002,5.714953e-005,5.714953e-005,,,,,,,,,,,,,,,,,,,,
1473353462.002,,5.000000e+002,8.003885e+001,8.003580e+001,1,0,4.141203e+000,-1.715140e-001,-1.715140e-001,-5.568151e-002,-1.156968e+000,9.338358e-002,2.092161e-001,-8.920699e-001,-8.592304e-006,-8.592304e-006,,,,,,,,,,,,,,,,,,,,
1473353475.216,,5.000000e+002,8.002053e+001,8.002357e+001,1,0,4.637852e+000,-4.455702e-002,-4.455702e-002,-1.790899e-001,-1.024676e+000,2.842028e-001,1.496699e-001,-6.959163e-001,-2.232164e-006,-2.232164e-006,,,,,,,,,,,,,,,,,,,,
1473353489.129,,5.000000e+002,8.002357e+001,8.002357e+001,1,0,1.973768e+000,4.184088e-001,4.184088e-001,1.246593e-002,-5.767344e-001,1.830292e-001,-2.229137e-001,-8.121139e-001,2.096094e-005,2.096094e-005,,,,,,,,,,,,,,,,,,,,
1473353679.500,,5.000000e+002,8.000526e+001,8.000220e+001,1,0,3.325998e-002,1.272622e-001,1.272622e-001,-5.153849e-001,-8.507716e-001,7.135690e-001,7.092196e-002,-2.644648e-001,6.375429e-006,6.375429e-006,,,,,,,,,,,,,,,,,,,,
1473353692.964,,5.000000e+002,8.000220e+001,8.000220e+001,1,0,1.691874e+000,7.889035e-001,7.889035e-001,-1.101614e-001,-1.889926e-001,8.482561e-001,-5.080881e-002,-1.296399e-001,3.952154e-005,3.952154e-005,,,,,,,,,,,,,,,,,,,,
1473353692.964,,5.000000e+002,8.000220e+001,8.000220e+001,1,0,4.299844e+000,-1.515244e-001,-1.515244e-001,-4.549261e-002,-1.129420e+000,9.955420e-002,2.055860e-001,-8.783419e-001,-7.590888e-006,-7.590888e-006,,,,,,,,,,,,,,,,,,,,
1473353705.678,,5.000000e+002,7.999609e+001,7.998998e+001,1,0,4.486488e+000,-8.743554e-002,-8.743553e-002,-2.480567e-001,-1.073487e+000,3.394148e-001,1.787937e-001,-6.466367e-001,-4.380241e-006,-4.380241e-006,,,,,,,,,,,,,,,,,,,,
1473353719.159,,5.000000e+002,7.999609e+001,7.999609e+001,1,0,1.766659e+000,6.672872e-001,6.672872e-001,2.543246e-001,-3.146640e-001,3.184285e-001,-9.453409e-002,-6.635227e-001,3.342895e-005,3.342895e-005,,,,,,,,,,,,,,,,,,,,
1473353821.415,,5.000000e+002,8.519122e+001,8.613229e+001,1,0,7.238500e-003,3.450118e-001,3.450117e-001,-5.421088e-001,-8.538203e-001,9.866639e-001,9.954330e-002,-2.121682e-001,1.728398e-005,1.728398e-005,,,,,,,,,,,,,,,,,,,,
1473353834.879,,5.000000e+002,8.633627e+001,8.730153e+001,1,0,1.913985e+000,6.512650e-001,6.512650e-001,-5.310485e-001,-5.894579e-001,8.995098e-001,-2.828037e-001,-3.412131e-001,3.262629e-005,3.262629e-005,,,,,,,,,,,,,,,,,,,,
1473353834.879,,5.000000e+002,8.633627e+001,8.730153e+001,1,0,4.450671e+000,2.601703e-001,2.601703e-001,7.081595e-002,-9.805526e-001,4.737509e-001,2.843966e-001,-7.669719e-001,1.303370e-005,1.303370e-005,,,,,,,,,,,,,,,,,,,,
1473353848.344,,5.000000e+002,8.730153e+001,8.859167e+001,1,0,4.317508e+000,2.723777e-001,2.723777e-001,-2.015019e-001,-1.000051e+000,7.989009e-001,3.250213e-001,-4.735275e-001,1.364525e-005,1.364525e-005,,,,,,,,,,,,,,,,,,,,
1473353860.562,,5.000000e+002,8.879191e+001,8.941286e+001,1,0,1.568251e+000,1.259651e+000,1.259651e+000,5.279181e-001,-1.879537e-002,7.611948e-001,2.946145e-002,-5.172520e-001,6.310451e-005,6.310451e-005,,,,,,,,,,,,,,,,,,,,
1473353878.041,,5.000000e+002,9.002296e+001,9.104440e+001,1,0,1.467983e-002,5.067598e-001,5.067598e-001,-5.218042e-001,-8.140517e-001,1.145168e+000,1.166035e-001,-1.756439e-001,2.538705e-005,2.538705e-005,,,,,,,,,,,,,,,,,,,,
1473353890.755,,5.000000e+002,9.125131e+001,9.246748e+001,1,0,2.139236e+000,3.518784e-001,3.518784e-001,-9.351152e-001,-9.739860e-001,7.249417e-001,-5.620519e-001,-6.009227e-001,1.762798e-005,1.762798e-005,,,,,,,,,,,,,,,,,,,,
1473353890.755,,5.000000e+002,9.125131e+001,9.246748e+001,1,0,4.590906e+000,4.072695e-001,4.072695e-001,1.114813e-001,-9.185950e-001,5.710940e-001,2.753057e-001,-7.547705e-001,2.040290e-005,2.040290e-005,,,,,,,,,,,,,,,,,,,,
1473353906.219,,5.000000e+002,9.268054e+001,9.364471e+001,1,0,4.134496e+000,3.645436e-001,3.645436e-001,-2.118452e-001,-9.890270e-001,9.444389e-001,3.680501e-001,-4.091317e-001,1.826247e-005,1.826247e-005,,,,,,,,,,,,,,,,,,,,
1473353921.684,,5.000000e+002,9.425230e+001,9.502760e+001,1,0,1.379153e+000,1.763054e+000,1.763054e+000,9.185768e-001,3.942533e-001,1.043865e+000,1.993872e-001,-3.249364e-001,8.832338e-005,8.832338e-005,,,,,,,,,,,,,,,,,,,,
1473353938.913,,5.000000e+002,9.580219e+001,9.654958e+001,1,0,5.594943e-002,6.520280e-001,6.520280e-001,-4.517203e-001,-7.237347e-001,1.238823e+000,1.350746e-001,-1.369399e-001,3.266452e-005,3.266452e-005,,,,,,,,,,,,,,,,,,,,
1473353952.417,,5.000000e+002,9.708331e+001,9.788998e+001,1,0,2.365740e+000,9.949034e-002,9.949034e-002,-1.265537e+000,-1.284949e+000,5.494229e-001,-8.156048e-001,-8.350166e-001,4.984148e-006,4.984148e-006,,,,,,,,,,,,,,,,,,,,
1473353952.417,,5.000000e+002,9.708331e+001,9.788998e+001,1,0,4.717440e+000,5.067598e-001,5.067598e-001,1.317330e-001,-8.776796e-001,6.236533e-001,2.486265e-001,-7.607862e-001,2.538705e-005,2.538705e-005,,,,,,,,,,,,,,,,,,,,
1473353967.826,,5.000000e+002,9.826657e+001,9.901437e+001,1,0,3.940218e+000,3.929258e-001,3.929258e-001,-2.320913e-001,-9.924050e-001,9.506694e-001,3.256523e-001,-4.346614e-001,1.968433e-005,1.968433e-005,,,,,,,,,,,,,,,,,,,,
1473353980.149,,5.000000e+002,9.939919e+001,1.001852e+002,1,0,1.198555e+000,2.159948e+000,2.159947e+000,1.267027e+000,7.607186e-001,1.225882e+000,3.329616e-001,-1.733468e-001,1.082065e-004,1.082065e-004,,,,,,,,,,,,,,,,,,,,
1473353993.863,,5.000000e+002,1.005693e+002,1.013696e+002,1,0,1.297762e-001,8.494827e-001,8.494827e-001,-3.174635e-001,-5.699869e-001,1.325946e+000,1.589999e-001,-9.352350e-002,4.255637e-005,4.255637e-005,,,,,,,,,,,,,,,,,,,,
1473354008.139,,5.000000e+002,1.015799e+002,1.025707e+002,1,0,2.590720e+000,-1.068148e-002,-1.068148e-002,-1.424732e+000,-1.424732e+000,4.882935e-001,-9.257567e-001,-9.257567e-001,-5.351079e-007,-5.351079e-007,,,,,,,,,,,,,,,,,,,,
1473354008.139,,5.000000e+002,1.015799e+002,1.025707e+002,1,0,4.825398e+000,5.610828e-001,5.610828e-001,1.377109e-001,-8.529674e-001,6.428032e-001,2.194313e-001,-7.712470e-001,2.810845e-005,2.810845e-005,,,,,,,,,,,,,,,,,,,,
1473354022.353,,5.000000e+002,1.029819e+002,1.037589e+002,1,0,3.736905e+000,4.245125e-001,4.245125e-001,-2.594773e-001,-9.987448e-001,8.726147e-001,1.886250e-001,-5.506426e-001,2.126672e-005,2.126672e-005,,,,,,,,,,,,,,,,,,,,
1473354035.567,,5.000000e+002,1.039587e+002,1.049377e+002,1,0,1.025472e+000,2.384564e+000,2.384564e+000,1.445472e+000,9.588096e-001,1.343728e+000,4.046367e-001,-8.202600e-002,1.194590e-004,1.194590e-004,,,,,,,,,,,,,,,,,,,,
1473354071.072,,5.000000e+002,1.066698e+002,1.078797e+002,1,0,2.333142e-001,1.057619e+000,1.057619e+000,-1.116757e-001,-3.499962e-001,1.364533e+000,1.952386e-001,-4.308188e-002,5.298333e-005,5.298333e-005,,,,,,,,,,,,,,,,,,,,
1473354071.072,,5.000000e+002,1.066698e+002,1.078797e+002,1,0,2.811885e+000,-5.951109e-003,-5.951109e-003,-1.623838e-001,-1.413566e+000,-6.912783e-001,-8.477109e-001,-2.098893e+000,-2.981315e-007,-2.981315e-007,,,,,,,,,,,,,,,,,,,,
1473354085.786,,5.000000e+002,1.082564e+002,1.090555e+002,1,0,4.910352e+000,5.456709e-001,5.456709e-001,1.318463e-001,-8.586102e-001,6.124465e-001,1.986219e-001,-7.918347e-001,2.733637e-005,2.733637e-005,,,,,,,,,,,,,,,,,,,,
1473354100.501,,5.000000e+002,1.094565e+002,1.102334e+002,1,0,3.525963e+000,3.950621e-001,3.950621e-001,-3.123434e-001,-1.039738e+000,6.851452e-001,-2.226036e-002,-7.496547e-001,1.979135e-005,1.979135e-005,,,,,,,,,,,,,,,,,,,,
1473354113.218,,5.000000e+002,1.104348e+002,1.112249e+002,1,0,8.596632e-001,2.363353e+000,2.363353e+000,1.384375e+000,9.134693e-001,1.394734e+000,4.157555e-001,-5.514979e-002,1.183964e-004,1.183964e-004,,,,,,,,,,,,,,,,,,,,
1473354130.683,,5.000000e+002,1.119497e+002,1.127765e+002,1,0,3.629356e-001,1.404920e+000,1.404920e+000,1.592036e-001,-5.561244e-002,1.489379e+000,2.436633e-001,2.884722e-002,7.038198e-005,7.038198e-005,,,,,,,,,,,,,,,,,,,,
1473354130.683,,5.000000e+002,1.119497e+002,1.127765e+002,1,0,3.027105e+000,1.895200e-001,1.895199e-001,-6.023065e-002,-1.271012e+000,-3.843858e-001,-6.341364e-001,-1.844918e+000,9.494343e-006,9.494343e-006,,,,,,,,,,,,,,,,,,,,
1473354143.670,,5.000000e+002,1.129810e+002,1.138094e+002,1,0,4.967535e+000,6.193731e-001,6.193731e-001,1.222378e-001,-8.339450e-001,6.813939e-001,1.842586e-001,-7.719242e-001,3.102862e-005,3.102862e-005,,,,,,,,,,,,,,,,,,,,
1473354157.884,,5.000000e+002,1.142206e+002,1.150457e+002,1,0,3.308810e+000,3.578295e-001,3.578295e-001,-4.046642e-001,-1.106733e+000,4.792350e-001,-2.832587e-001,-9.853274e-001,1.792612e-005,1.792612e-005,,,,,,,,,,,,,,,,,,,,
1473354170.849,,5.000000e+002,1.152523e+002,1.162775e+002,1,0,7.008156e-001,2.161779e+000,2.161779e+000,1.142814e+000,6.941431e-001,1.398389e+000,3.794243e-001,-6.924629e-002,1.082982e-004,1.082982e-004,,,,,,,,,,,,,,,,,,,,
1473354184.813,,5.000000e+002,1.164854e+002,1.173019e+002,1,0,5.142205e-001,1.761376e+000,1.761376e+000,4.881272e-001,2.933251e-001,1.579921e+000,3.066724e-001,1.118703e-001,8.823929e-005,8.823929e-005,,,,,,,,,,,,,,,,,,,,
1473354184.813,,5.000000e+002,1.164854e+002,1.173019e+002,1,0,3.234151e+000,3.158666e-001,3.158666e-001,3.610887e-002,-1.152184e+000,-1.008431e-001,-3.806008e-001,-1.568894e+000,1.582391e-005,1.582391e-005,,,,,,,,,,,,,,,,,,,,
1473354198.778,,5.000000e+002,1.177159e+002,1.185333e+002,1,0,4.993504e+000,6.443983e-001,6.443983e-001,1.069615e-001,-8.277051e-001,7.164661e-001,1.790293e-001,-7.556373e-001,3.228230e-005,3.228230e-005,,,,,,,,,,,,,,,,,,,,
1473354214.761,,5.000000e+002,1.189430e+002,1.197608e+002,1,0,3.086839e+000,2.473525e-001,2.473525e-001,-5.461029e-001,-1.226443e+000,2.194133e-001,-5.740421e-001,-1.254382e+000,1.239157e-005,1.239157e-005,,,,,,,,,,,,,,,,,,,,
1473354233.226,,5.000000e+002,1.199612e+002,1.207828e+002,1,0,5.501878e-001,1.851711e+000,1.851711e+000,8.127361e-001,3.838825e-001,1.362743e+000,3.237689e-001,-1.050847e-001,9.276478e-005,9.276478e-005,,,,,,,,,,,,,,,,,,,,
1473354354.201,,5.000000e+002,1.202416e+002,1.201953e+002,1,0,6.832246e-001,2.124241e+000,2.124241e+000,8.391930e-001,6.625972e-001,1.661631e+000,3.765835e-001,1.999876e-001,1.064177e-004,1.064177e-004,,,,,,,,,,,,,,,,,,,,
1473354354.201,,5.000000e+002,1.202416e+002,1.201953e+002,1,0,3.432401e+000,3.833125e-001,3.833125e-001,9.897427e-002,-1.078331e+000,1.471099e-001,-1.372283e-001,-1.314534e+000,1.920273e-005,1.920273e-005,,,,,,,,,,,,,,,,,,,,
1473354367.195,,5.000000e+002,1.201953e+002,1.201293e+002,1,0,4.986058e+000,6.091495e-001,6.091495e-001,8.901145e-002,-8.330061e-001,7.029727e-001,1.828346e-001,-7.391829e-001,3.051644e-005,3.051644e-005,,,,,,,,,,,,,,,,,,,,
1473354380.410,,5.000000e+002,1.201293e+002,1.200963e+002,1,0,2.861474e+000,5.554369e-002,5.554369e-002,-7.150357e-001,-1.387164e+000,-7.021666e-002,-8.407961e-001,-1.512925e+000,2.782561e-006,2.782561e-006,,,,,,,,,,,,,,,,,,,,
1473354393.374,,5.000000e+002,1.200897e+002,1.200699e+002,1,0,4.097556e-001,1.495865e+000,1.495865e+000,4.788427e-001,6.494939e-002,1.282933e+000,2.659115e-001,-1.479819e-001,7.493804e-005,7.493804e-005,,,,,,,,,,,,,,,,,,,,
1473354393.374,,5.000000e+002,1.200897e+002,1.200699e+002,1,0,2.812022e+000,-1.419111e-002,-1.419111e-002,-2.034264e-001,-1.445107e+000,-6.973427e-001,-8.865780e-001,-2.128258e+000,-7.109291e-007,-7.109291e-007,,,,,,,,,,,,,,,,,,,,