File: data/A344/raw/A344_GdN_FC_500_Oe_160908.rso.raw
[Header]
TITLE,MPMS RSO Measurement
BYAPP,MPMS Measurement,2.1,Raw with ABS
FILEOPENTIME, 1473354629.153000 9/9/2016, 5:10:29 AM

INFO, APPNAME, MPMS MultiVu Application, Revision 1.61,  Build 082

INFO, NAME, A344
INFO, WEIGHT, 10.500
INFO, AREA, 1.000
INFO, LENGTH, 1.000
INFO, SHAPE, 0
INFO, COMMENT, m = 0.0105g
INFO, SEQUENCE FILE: FC_120K-5K.seq


INFO, BACKGROUND DATA FILE:, None


STARTUPAXIS,X,8,LINEAR,AUTO,0.000000,0.000000
STARTUPAXIS,Y1,9,LINEAR,AUTO,0.000000,0.000000


STARTUPGROUP,Longitudinal
FIELDGROUP,Longitudinal,1,2,3,4,5,6,7,8,9,10,11,12,13,14,15,16,17,18,19,20,21,22
FIELDGROUP,Transverse,1,2,3,4,5,6,7,8,23,24,25,26,27,28,29,30,31,32,33,34,35,36

PLOT_APPEARANCE,ALL,HORZ_GRID_ON,VERT_GRID_ON,MARKERS_ONLY

[Data]
Time,Comment,Field (Oe),Start Temperature (K),End Temperature (K),Scan,Rejected,Position (cm),Long Voltage,Long Average Voltage,Long Detrended Voltage,Long Demeaned Voltage,Long Reg Fit,Long Detrended Fit,Long Demeaned Fit,Long Scaled Response,Long Avg. Scaled Response,Long Background Response,Long Response [w/ABS],Long Detrended Resp. [w/ABS],Long Fit [w/ABS],Long Detrended Fit [w/ABS],Trans Voltage,Trans Average Voltage,Trans Detrended Voltage,Trans Demeaned Voltage,Trans Reg Fit,Trans Detrended Fit,Trans Demeaned Fit,Trans Scaled Response,Trans Avg. Scaled Response,Trans Background Response,Trans Response [w/ABS],Trans Detrended Resp. [w/ABS],Trans Adjusted Fit,Trans Detrended Fit [w/ABS],
1473354629.146,,5.000000e+002,1.200139e+002,1.200106e+002,1,0,2.590896e+000,1.266518e-002,1.266518e-002,-1.487410e+000,-1.487410e+000,5.102077e-001,-9.898672e-001,-9.898672e-001,6.344851e-007,6.344851e-007,,,,,,,,,,,,,,,,,,,,
1473354629.146,,5.000000e+002,1.200139e+002,1.200106e+002,1,0,4.825487e+000,6.721702e-001,6.721702e-001,1.483939e-001,-8.279047e-001,7.604926e-001,2.367163e-001,-7.395823e-001,3.367358e-005,3.367358e-005,,,,,,,,,,,,,,,,,,,,
1473354641.360,,5.000000e+002,1.200106e+002,1.200139e+002,1,0,3.736877e+000,5.146947e-001,5.146947e-001,-2.470633e-001,-9.767960e-001,9.559059e-001,1.941479e-001,-5.355848e-001,2.578456e-005,2.578456e-005,,,,,,,,,,,,,,,,,,,,
1473354653.378,,5.000000e+002,1.200073e+002,1.200073e+002,1,0,1.025577e+000,2.489700e+000,2.489700e+000,1.473985e+000,9.928181e-001,1.443798e+000,4.280833e-001,-5.308402e-002,1.247260e-004,1.247260e-004,,,,,,,,,,,,,,,,,,,,
1473354665.342,,5.000000e+002,1.200040e+002,1.200040e+002,1,0,2.333249e-001,1.158788e+000,1.158788e+000,-1.073403e-001,-3.381065e-001,1.467488e+000,2.013602e-001,-2.940595e-002,5.805156e-005,5.805156e-005,,,,,,,,,,,,,,,,,,,,
1473354665.342,,5.000000e+002,1.200040e+002,1.200040e+002,1,0,2.811891e+000,8.331553e-002,8.331553e-002,-2.020564e-001,-1.413579e+000,-6.002175e-001,-8.855894e-001,-2.097112e+000,4.173842e-006,4.173842e-006,,,,,,,,,,,,,,,,,,,,
1473354899.083,,5.000000e+002,1.147342e+002,1.139938e+002,1,0,4.910310e+000,6.732383e-001,6.732383e-001,1.381008e-001,-8.235226e-001,7.389103e-001,2.037728e-001,-7.578506e-001,3.372709e-005,3.372709e-005,,,,,,,,,,,,,,,,,,,,
1473354912.547,,5.000000e+002,1.136819e+002,1.130337e+002,1,0,3.525997e+000,4.663228e-001,4.663228e-001,-3.126074e-001,-1.024444e+000,7.535067e-001,-2.542360e-002,-7.372597e-001,2.336128e-005,2.336128e-005,,,,,,,,,,,,,,,,,,,,
1473354925.511,,5.000000e+002,1.128611e+002,1.121629e+002,1,0,8.597292e-001,2.413251e+000,2.413251e+000,1.390306e+000,9.284054e-001,1.440906e+000,4.179602e-001,-4.394019e-002,1.208962e-004,1.208962e-004,,,,,,,,,,,,,,,,,,,,
1473354939.976,,5.000000e+002,1.118176e+002,1.108755e+002,1,0,3.628739e-001,1.418195e+000,1.418195e+000,1.585199e-001,-5.349088e-002,1.502542e+000,2.428666e-001,3.085577e-002,7.104704e-005,7.104704e-005,,,,,,,,,,,,,,,,,,,,
1473354939.976,,5.000000e+002,1.118176e+002,1.108755e+002,1,0,3.026903e+000,2.140874e-001,2.140873e-001,-6.262868e-002,-1.257599e+000,-3.585471e-001,-6.352631e-001,-1.830233e+000,1.072509e-005,1.072509e-005,,,,,,,,,,,,,,,,,,,,
1473354992.064,,5.000000e+002,1.073826e+002,1.064729e+002,1,0,4.967502e+000,2.482681e-001,2.482681e-001,4.723566e-002,-3.335078e-001,2.731353e-001,7.210290e-002,-3.086405e-001,3.109359e-005,3.109359e-005,,,,,,,,,,,,,,,,,,,,
1473355006.140,,5.000000e+002,1.059988e+002,1.050395e+002,1,0,3.308864e+000,1.422163e-001,1.422163e-001,-1.581860e-001,-4.379130e-001,1.911067e-001,-1.092955e-001,-3.890226e-001,1.781145e-005,1.781145e-005,,,,,,,,,,,,,,,,,,,,
1473355019.355,,5.000000e+002,1.050395e+002,1.035873e+002,1,0,7.009222e-001,8.471938e-001,8.471938e-001,4.519627e-001,2.733101e-001,5.406249e-001,1.453938e-001,-3.325886e-002,1.061042e-004,1.061042e-004,,,,,,,,,,,,,,,,,,,,
1473355033.569,,5.000000e+002,1.033394e+002,1.023300e+002,1,0,5.142362e-001,6.848354e-001,6.848354e-001,1.901141e-001,1.123509e-001,6.112042e-001,1.164830e-001,3.871977e-002,8.577015e-005,8.577015e-005,,,,,,,,,,,,,,,,,,,,
1473355033.569,,5.000000e+002,1.033394e+002,1.023300e+002,1,0,3.234040e+000,1.205481e-001,1.205481e-001,2.241909e-002,-4.519363e-001,-4.524967e-002,-1.433787e-001,-6.177341e-001,1.509769e-005,1.509769e-005,,,,,,,,,,,,,,,,,,,,
1473355047.533,,5.000000e+002,1.020950e+002,1.010678e+002,1,0,4.993504e+000,2.323985e-001,2.323985e-001,3.840268e-002,-3.356591e-001,2.608815e-001,6.688568e-002,-3.071761e-001,2.910605e-005,2.910605e-005,,,,,,,,,,,,,,,,,,,,
1473355061.748,,5.000000e+002,1.005744e+002,9.982532e+001,1,0,3.086800e+000,9.125035e-002,9.125035e-002,-2.005390e-001,-4.733846e-001,8.094890e-002,-2.108405e-001,-4.836861e-001,1.142838e-005,1.142838e-005,,,,,,,,,,,,,,,,,,,,
1473355073.910,,5.000000e+002,9.956094e+001,9.852889e+001,1,0,5.501254e-001,7.026887e-001,7.026887e-001,3.156227e-001,1.438755e-001,5.058977e-001,1.188316e-001,-5.291545e-002,8.800614e-005,8.800614e-005,,,,,,,,,,,,,,,,,,,,
1473355087.771,,5.000000e+002,9.799355e+001,9.694365e+001,1,0,6.832492e-001,8.102664e-001,8.102664e-001,3.223882e-001,2.521641e-001,6.243836e-001,1.365054e-001,6.628126e-002,1.014794e-004,1.014794e-004,,,,,,,,,,,,,,,,,,,,
1473355087.771,,5.000000e+002,9.799355e+001,9.694365e+001,1,0,3.432367e+000,1.364177e-001,1.364177e-001,4.647604e-002,-4.216846e-001,4.226242e-002,-4.767928e-002,-5.158399e-001,1.708523e-005,1.708523e-005,,,,,,,,,,,,,,,,,,,,
1473355100.236,,5.000000e+002,9.668994e+001,9.567256e+001,1,0,4.986071e+000,2.105777e-001,2.105777e-001,2.798930e-002,-3.394644e-001,2.472581e-001,6.466967e-002,-3.027840e-001,2.637317e-005,2.637317e-005,,,,,,,,,,,,,,,,,,,,
1473355115.450,,5.000000e+002,9.513437e+001,9.412057e+001,1,0,2.861504e+000,3.372295e-002,3.372295e-002,-2.439681e-001,-5.099827e-001,-1.469607e-002,-2.923872e-001,-5.584017e-001,4.223530e-006,4.223530e-006,,,,,,,,,,,,,,,,,,,,
1473355127.664,,5.000000e+002,9.412057e+001,9.279884e+001,1,0,4.097695e-001,5.555894e-001,5.555894e-001,1.786219e-001,1.416409e-002,4.693015e-001,9.233397e-002,-7.212386e-002,6.958314e-005,6.958314e-005,,,,,,,,,,,,,,,,,,,,
1473355141.129,,5.000000e+002,9.253909e+001,9.175414e+001,1,0,8.662546e-001,8.830531e-001,8.830531e-001,4.113747e-001,3.486714e-001,6.161179e-001,1.444396e-001,8.173621e-002,1.105953e-004,1.105953e-004,,,,,,,,,,,,,,,,,,,,
1473355141.129,,5.000000e+002,9.253909e+001,9.175414e+001,1,0,3.621581e+000,1.202429e-001,1.202429e-001,4.829866e-002,-4.141388e-001,1.003818e-001,2.843748e-002,-4.339999e-001,1.505947e-005,1.505947e-005,,,,,,,,,,,,,,,,,,,,
1473355154.593,,5.000000e+002,9.126258e+001,9.020988e+001,1,0,4.944797e+000,1.773125e-001,1.773125e-001,1.269651e-002,-3.481127e-001,2.285580e-001,6.394199e-002,-2.968673e-001,2.220698e-005,2.220698e-005,,,,,,,,,,,,,,,,,,,,
1473355167.057,,5.000000e+002,8.996930e+001,8.898727e+001,1,0,2.635127e+000,1.831111e-003,1.831111e-003,-2.590738e-001,-5.178391e-001,-5.556857e-002,-3.164735e-001,-5.752388e-001,2.293320e-007,2.293320e-007,,,,,,,,,,,,,,,,,,,,
1473355179.037,,5.000000e+002,8.872310e+001,8.800510e+001,1,0,2.834143e-001,4.020814e-001,4.020814e-001,4.965827e-002,-1.076435e-001,4.213097e-001,6.888658e-002,-8.841524e-002,5.035748e-005,5.035748e-005,,,,,,,,,,,,,,,,,,,,
1473355192.001,,5.000000e+002,8.748190e+001,8.649887e+001,1,0,1.060480e+000,8.430738e-001,8.430738e-001,3.956360e-001,3.408132e-001,5.740705e-001,1.266327e-001,7.180989e-002,1.055883e-004,1.055883e-004,,,,,,,,,,,,,,,,,,,,
1473355192.001,,5.000000e+002,8.748190e+001,8.649887e+001,1,0,3.802197e+000,8.194220e-002,8.194220e-002,3.392775e-002,-4.203184e-001,1.258147e-001,7.780028e-002,-3.764459e-001,1.026261e-005,1.026261e-005,,,,,,,,,,,,,,,,,,,,
1473355205.970,,5.000000e+002,8.628188e+001,8.534991e+001,1,0,4.870967e+000,1.239052e-001,1.239052e-001,-7.514800e-003,-3.619510e-001,1.944211e-001,6.300113e-002,-2.914351e-001,1.551813e-005,1.551813e-005,,,,,,,,,,,,,,,,,,,,
1473355219.364,,5.000000e+002,8.511088e+001,8.418911e+001,1,0,2.410080e+000,1.632740e-002,1.632740e-002,-2.028105e-001,-4.552374e-001,-3.759571e-002,-2.567336e-001,-5.091605e-001,2.044877e-006,2.044877e-006,,,,,,,,,,,,,,,,,,,,
1473355230.197,,5.000000e+002,8.418911e+001,8.329423e+001,1,0,1.753341e-001,2.471999e-001,2.471999e-001,-6.747639e-002,-2.174478e-001,3.629297e-001,4.825339e-002,-1.017180e-001,3.095981e-005,3.095981e-005,,,,,,,,,,,,,,,,,,,,
1473355244.411,,5.000000e+002,8.290079e+001,8.231072e+001,1,0,1.263892e+000,6.694235e-001,6.694235e-001,2.688914e-001,2.214146e-001,4.784352e-001,7.790314e-002,3.042635e-002,8.383994e-005,8.383994e-005,,,,,,,,,,,,,,,,,,,,
1473355244.411,,5.000000e+002,8.290079e+001,8.231072e+001,1,0,3.975178e+000,-6.103702e-004,-6.103702e-004,2.410213e-003,-4.486193e-001,8.819199e-002,9.121257e-002,-3.598169e-001,-7.644399e-008,-7.644399e-008,,,,,,,,,,,,,,,,,,,,
1473355259.876,,5.000000e+002,8.168088e+001,8.113366e+001,1,0,4.767404e+000,3.097629e-002,3.097629e-002,-4.182491e-002,-3.906134e-001,1.292962e-001,5.649503e-002,-2.922934e-001,3.879532e-006,3.879532e-006,,,,,,,,,,,,,,,,,,,,
1473355272.370,,5.000000e+002,8.074367e+001,8.019590e+001,1,0,2.188781e+000,8.392590e-002,8.392590e-002,-7.652932e-002,-3.221131e-001,1.554465e-002,-1.449106e-001,-3.904943e-001,1.051105e-005,1.051105e-005,,,,,,,,,,,,,,,,,,,,
1473355290.585,,5.000000e+002,7.973236e+001,7.948138e+001,1,0,9.044842e-002,6.820887e-002,6.820887e-002,-1.615530e-001,-3.045641e-001,2.571123e-001,2.735045e-002,-1.156607e-001,8.542615e-006,8.542615e-006,,,,,,,,,,,,,,,,,,,,
1473355303.553,,5.000000e+002,7.947987e+001,7.957040e+001,1,0,1.474729e+000,4.271065e-001,4.271065e-001,1.021828e-001,6.245485e-002,3.483945e-001,2.347068e-002,-1.625723e-002,5.349168e-005,5.349168e-005,,,,,,,,,,,,,,,,,,,,
1473355303.553,,5.000000e+002,7.947987e+001,7.957040e+001,1,0,4.141022e+000,-1.139866e-001,-1.139866e-001,-3.368581e-002,-4.786383e-001,-8.798001e-003,7.150282e-002,-3.734497e-001,-1.427591e-005,-1.427591e-005,,,,,,,,,,,,,,,,,,,,
1473355416.027,,5.000000e+002,8.011932e+001,8.013462e+001,1,0,4.637789e+000,-3.845332e-002,-3.845332e-002,-7.275596e-002,-4.159355e-001,9.324474e-002,5.894210e-002,-2.842374e-001,-4.815971e-006,-4.815971e-006,,,,,,,,,,,,,,,,,,,,
1473355427.741,,5.000000e+002,8.009789e+001,8.010555e+001,1,0,1.973730e+000,1.576281e-001,1.576281e-001,1.010333e-002,-2.271698e-001,6.097672e-002,-8.654806e-002,-3.238212e-001,1.974166e-005,1.974166e-005,,,,,,,,,,,,,,,,,,,,
1473355458.671,,5.000000e+002,8.010095e+001,8.007190e+001,1,0,3.321912e-002,1.545763e-001,1.545763e-001,-5.202820e-001,-8.505388e-001,7.446295e-001,6.977127e-002,-2.604855e-001,7.743776e-006,7.743776e-006,,,,,,,,,,,,,,,,,,,,
1473355470.635,,5.000000e+002,8.007190e+001,8.005204e+001,1,0,1.691761e+000,8.185064e-001,8.185064e-001,-1.083605e-001,-1.868370e-001,8.778905e-001,-4.897641e-002,-1.274530e-001,4.100455e-005,4.100455e-005,,,,,,,,,,,,,,,,,,,,
1473355470.635,,5.000000e+002,8.007190e+001,8.005204e+001,1,0,4.299695e+000,-1.240577e-001,-1.240577e-001,-5.034843e-002,-1.129401e+000,1.299498e-001,2.036591e-001,-8.753936e-001,-6.214896e-006,-6.214896e-006,,,,,,,,,,,,,,,,,,,,
1473355663.121,,5.000000e+002,8.000621e+001,8.000164e+001,1,0,4.486435e+000,-8.621480e-002,-8.621479e-002,-2.492035e-001,-1.076212e+000,3.418475e-001,1.788588e-001,-6.481500e-001,-4.319085e-006,-4.319085e-006,,,,,,,,,,,,,,,,,,,,
1473355676.334,,5.000000e+002,7.999706e+001,8.001080e+001,1,0,1.766673e+000,6.709495e-001,6.709495e-001,2.553085e-001,-3.141009e-001,3.221642e-001,-9.347672e-002,-6.628861e-001,3.361242e-005,3.361242e-005,,,,,,,,,,,,,,,,,,,,
1473355688.318,,5.000000e+002,8.000317e+001,8.001233e+001,1,0,7.223286e-003,9.048738e-002,9.048738e-002,-5.786066e-001,-8.928485e-001,7.363716e-001,6.727761e-002,-2.469643e-001,4.533129e-006,4.533129e-006,,,,,,,,,,,,,,,,,,,,
1473355700.727,,5.000000e+002,7.999706e+001,8.000927e+001,1,0,1.913818e+000,5.038606e-001,5.038606e-001,-4.215414e-001,-4.805169e-001,7.421865e-001,-1.832155e-001,-2.421910e-001,2.524180e-005,2.524180e-005,,,,,,,,,,,,,,,,,,,,
1473355700.727,,5.000000e+002,7.999706e+001,8.000927e+001,1,0,4.450418e+000,-1.022370e-001,-1.022370e-001,-2.505570e-002,-1.086614e+000,1.078231e-001,1.850044e-001,-8.765544e-001,-5.121747e-006,-5.121747e-006,,,,,,,,,,,,,,,,,,,,
1473355866.564,,5.000000e+002,7.673910e+001,7.623890e+001,1,0,4.317432e+000,-5.185094e-001,-5.185094e-001,-4.413573e-001,-1.258384e+000,-6.164944e-003,7.098722e-002,-7.460392e-001,-2.597567e-005,-2.597567e-005,,,,,,,,,,,,,,,,,,,,
1473355879.529,,5.000000e+002,7.609992e+001,7.555297e+001,1,0,1.568406e+000,6.329539e-001,6.329539e-001,6.732107e-001,3.944672e-001,6.013717e-001,6.416286e-001,3.628851e-001,3.170897e-005,3.170897e-005,,,,,,,,,,,,,,,,,,,,
1473355891.743,,5.000000e+002,7.555297e+001,7.482780e+001,1,0,1.466778e-002,-3.962829e-001,-3.962829e-001,-6.552896e-001,-9.523983e-001,2.553580e-001,-3.648726e-003,-3.007574e-001,-1.985250e-005,-1.985250e-005,,,,,,,,,,,,,,,,,,,,
1473355906.212,,5.000000e+002,7.452016e+001,7.406723e+001,1,0,2.139147e+000,1.350444e-001,1.350444e-001,-2.331714e-001,-2.727795e-001,5.079482e-001,1.397323e-001,1.001242e-001,6.765293e-006,6.765293e-006,,,,,,,,,,,,,,,,,,,,
1473355906.212,,5.000000e+002,7.452016e+001,7.406723e+001,1,0,4.590837e+000,-8.502457e-001,-8.502457e-001,-2.084540e-001,-1.258070e+000,-6.969770e-001,-5.518537e-002,-1.104801e+000,-4.259459e-005,-4.259459e-005,,,,,,,,,,,,,,,,,,,,
1473355919.236,,5.000000e+002,7.388989e+001,7.310772e+001,1,0,4.134427e+000,-1.299936e+000,-1.299936e+000,-7.223196e-001,-1.275829e+000,-6.340839e-001,-5.646760e-002,-6.099773e-001,-6.512263e-005,-6.512263e-005,,,,,,,,,,,,,,,,,,,,
1473355931.700,,5.000000e+002,7.293736e+001,7.227229e+001,1,0,1.379215e+000,1.304666e-001,1.304666e-001,7.330086e-001,3.159214e-001,-1.799302e-002,5.845490e-001,1.674618e-001,6.535961e-006,6.535961e-006,,,,,,,,,,,,,,,,,,,,
1473355945.664,,5.000000e+002,7.210816e+001,7.145820e+001,1,0,5.595087e-002,-1.361278e+000,-1.361278e+000,-7.316729e-001,-9.806572e-001,-8.525177e-001,-2.229125e-001,-4.718968e-001,-6.819568e-005,-6.819568e-005,,,,,,,,,,,,,,,,,,,,
1473355958.879,,5.000000e+002,7.128904e+001,7.046185e+001,1,0,2.365551e+000,1.185644e-001,1.185644e-001,9.376342e-001,9.193660e-001,6.899369e-001,1.509007e+000,1.490739e+000,5.939698e-006,5.939698e-006,,,,,,,,,,,,,,,,,,,,
1473355958.879,,5.000000e+002,7.128904e+001,7.046185e+001,1,0,4.717262e+000,-2.301095e+000,-2.301096e+000,-5.503479e-001,-1.500294e+000,-2.101725e+000,-3.509770e-001,-1.300923e+000,-1.152775e-004,-1.152775e-004,,,,,,,,,,,,,,,,,,,,
1473355986.057,,5.000000e+002,6.948498e+001,6.883944e+001,1,0,3.940201e+000,-2.075259e+000,-2.075259e+000,-7.763934e-001,-1.066541e+000,-1.851283e+000,-5.524180e-001,-8.425654e-001,-2.599095e-004,-2.599095e-004,,,,,,,,,,,,,,,,,,,,
1473356000.022,,5.000000e+002,6.832182e+001,6.778269e+001,1,0,1.198543e+000,-2.055269e+000,-2.055269e+000,-2.745349e-001,-4.669170e-001,-2.432568e+000,-6.518342e-001,-8.442163e-001,-2.574060e-004,-2.574060e-004,,,,,,,,,,,,,,,,,,,,
1473356025.200,,5.000000e+002,6.677583e+001,6.607301e+001,1,0,1.298086e-001,-1.904355e+000,-1.904355e+000,-4.108669e-001,-4.576694e-001,-1.813780e+000,-3.202923e-001,-3.670948e-001,-4.770105e-004,-4.770105e-004,,,,,,,,,,,,,,,,,,,,
1473356038.931,,5.000000e+002,6.577189e+001,6.525996e+001,1,0,2.590730e+000,4.242073e-002,4.242073e-002,1.831238e+000,1.831238e+000,1.924317e-001,1.981249e+000,1.981249e+000,1.062571e-005,1.062571e-005,,,,,,,,,,,,,,,,,,,,
1473356038.931,,5.000000e+002,6.577189e+001,6.525996e+001,1,0,4.825398e+000,-2.443312e+000,-2.443312e+000,-4.738644e-001,-6.544944e-001,-2.400843e+000,-4.313954e-001,-6.120254e-001,-6.120105e-004,-6.120105e-004,,,,,,,,,,,,,,,,,,,,
1473356051.645,,5.000000e+002,6.510539e+001,6.429061e+001,1,0,3.736858e+000,-2.877132e+000,-2.877132e+000,-6.689319e-001,-8.016942e-001,-2.792425e+000,-5.842244e-001,-7.169867e-001,-7.206757e-004,-7.206757e-004,,,,,,,,,,,,,,,,,,,,
1473356064.359,,5.000000e+002,6.429061e+001,6.364436e+001,1,0,1.025585e+000,-3.245796e+000,-3.245796e+000,-8.264678e-001,-9.125962e-001,-3.469911e+000,-1.050583e+000,-1.136711e+000,-8.130200e-004,-8.130200e-004,,,,,,,,,,,,,,,,,,,,
1473356088.037,,5.000000e+002,6.256119e+001,6.209178e+001,1,0,2.333482e-001,-7.556383e-001,-7.556383e-001,-3.607851e-001,-3.811570e-001,-7.244671e-001,-3.296139e-001,-3.499858e-001,-3.785506e-004,-3.785506e-004,,,,,,,,,,,,,,,,,,,,
1473356088.037,,5.000000e+002,6.256119e+001,6.209178e+001,1,0,2.811942e+000,8.095034e-001,8.095034e-001,1.290937e+000,1.183985e+000,7.281171e-001,1.209551e+000,1.102598e+000,4.055353e-004,4.055353e-004,,,,,,,,,,,,,,,,,,,,
1473356099.937,,5.000000e+002,6.195114e+001,6.131942e+001,1,0,4.910288e+000,-1.451002e+000,-1.451002e+000,-3.094831e-001,-3.932940e-001,-1.429923e+000,-2.884038e-001,-3.722147e-001,-7.269059e-004,-7.269059e-004,,,,,,,,,,,,,,,,,,,,
1473356114.759,,5.000000e+002,6.104713e+001,6.066012e+001,1,0,3.525950e+000,-1.902676e+000,-1.902676e+000,-1.007230e-001,-1.620789e-001,-1.879185e+000,-7.723186e-002,-1.385877e-001,-9.531801e-004,-9.531801e-004,,,,,,,,,,,,,,,,,,,,
1473356127.973,,5.000000e+002,6.038809e+001,5.983525e+001,1,0,8.596739e-001,-2.424390e+000,-2.424390e+000,-6.394179e-001,-6.789479e-001,-2.532291e+000,-7.473183e-001,-7.868483e-001,-1.214542e-003,-1.214542e-003,,,,,,,,,,,,,,,,,,,,
1473356139.989,,5.000000e+002,5.958071e+001,5.919249e+001,1,0,3.629297e-001,-2.266762e+000,-2.266762e+000,-4.994936e-001,-5.174712e-001,-2.257483e+000,-4.902139e-001,-5.081915e-001,-1.135575e-003,-1.135575e-003,,,,,,,,,,,,,,,,,,,,
1473356139.989,,5.000000e+002,5.958071e+001,5.919249e+001,1,0,3.027023e+000,-7.330546e-001,-7.330546e-001,1.117565e+000,1.016237e+000,-8.352990e-001,1.015320e+000,9.139920e-001,-3.672369e-004,-3.672369e-004,,,,,,,,,,,,,,,,,,,,
1473356152.953,,5.000000e+002,5.896018e+001,5.844385e+001,1,0,4.967490e+000,-2.169256e+000,-2.169256e+000,-3.350017e-001,-4.147487e-001,-2.146846e+000,-3.125915e-001,-3.923385e-001,-1.086728e-003,-1.086728e-003,,,,,,,,,,,,,,,,,,,,
1473356165.417,,5.000000e+002,5.832530e+001,5.783597e+001,1,0,3.308801e+000,-1.423231e+000,-1.423231e+000,3.949752e-001,3.367549e-001,-1.423329e+000,3.948764e-001,3.366561e-001,-7.129930e-004,-7.129930e-004,,,,,,,,,,,,,,,,,,,,
1473356176.678,,5.000000e+002,5.770018e+001,5.719357e+001,1,0,7.008370e-001,-2.514267e+000,-2.514267e+000,-7.127005e-001,-7.497262e-001,-2.596075e+000,-7.945076e-001,-8.315333e-001,-1.259568e-003,-1.259568e-003,,,,,,,,,,,,,,,,,,,,
1473356189.325,,5.000000e+002,5.707823e+001,5.659932e+001,1,0,5.142882e-001,-2.441023e+000,-2.441023e+000,-6.563080e-001,-6.722821e-001,-2.463198e+000,-6.784833e-001,-6.944574e-001,-1.222874e-003,-1.222874e-003,,,,,,,,,,,,,,,,,,,,
1473356189.325,,5.000000e+002,5.707823e+001,5.659932e+001,1,0,3.234168e+000,-1.171606e+000,-1.171606e+000,6.945773e-001,5.971352e-001,-1.262183e+000,6.039997e-001,5.065576e-001,-5.869369e-004,-5.869369e-004,,,,,,,,,,,,,,,,,,,,
1473356204.187,,5.000000e+002,5.635339e+001,5.588299e+001,1,0,4.993498e+000,-2.212897e+000,-2.212897e+000,-3.629352e-001,-4.392855e-001,-2.184982e+000,-3.350200e-001,-4.113703e-001,-1.108591e-003,-1.108591e-003,,,,,,,,,,,,,,,,,,,,
1473356216.151,,5.000000e+002,5.575587e+001,5.528144e+001,1,0,3.086710e+000,-1.011689e-001,-1.011689e-001,1.052852e+000,9.975427e-001,-1.154687e-001,1.038552e+000,9.832429e-001,-5.068236e-005,-5.068236e-005,,,,,,,,,,,,,,,,,,,,
1473356228.866,,5.000000e+002,5.515843e+001,5.468338e+001,1,0,5.500590e-001,-1.856441e+000,-1.856441e+000,-7.187102e-001,-7.532587e-001,-1.900204e+000,-7.624729e-001,-7.970214e-001,-9.300176e-004,-9.300176e-004,,,,,,,,,,,,,,,,,,,,
1473356240.830,,5.000000e+002,5.456144e+001,5.410097e+001,1,0,6.832406e-001,-1.946318e+000,-1.946318e+000,-8.248127e-001,-8.389113e-001,-2.006335e+000,-8.848296e-001,-8.989282e-001,-9.750430e-004,-9.750430e-004,,,,,,,,,,,,,,,,,,,,
1473356240.830,,5.000000e+002,5.456144e+001,5.410097e+001,1,0,3.432387e+000,-1.025117e+000,-1.025117e+000,1.762804e-001,8.228993e-002,-1.075146e+000,1.262510e-001,3.226054e-002,-5.135507e-004,-5.135507e-004,,,,,,,,,,,,,,,,,,,,
1473356252.855,,5.000000e+002,5.397720e+001,5.351143e+001,1,0,4.986083e+000,-2.265236e+000,-2.265236e+000,-4.013956e-001,-4.746493e-001,-2.232060e+000,-3.682194e-001,-4.414731e-001,-1.134811e-003,-1.134811e-003,,,,,,,,,,,,,,,,,,,,
1473356265.819,,5.000000e+002,5.325689e+001,5.291044e+001,1,0,2.861463e+000,-8.362072e-002,-8.362072e-002,1.765064e+000,1.712143e+000,-8.210113e-002,1.766584e+000,1.713663e+000,-4.189130e-005,-4.189130e-005,,,,,,,,,,,,,,,,,,,,
1473356276.783,,5.000000e+002,5.279728e+001,5.232483e+001,1,0,4.097312e-001,-2.512589e+000,-2.512589e+000,-6.789674e-001,-7.114953e-001,-2.520011e+000,-6.863893e-001,-7.189173e-001,-1.258727e-003,-1.258727e-003,,,,,,,,,,,,,,,,,,,,
1473356288.748,,5.000000e+002,5.221404e+001,5.173948e+001,1,0,8.663025e-001,-3.434095e+000,-3.434095e+000,-9.362123e-001,-9.485600e-001,-3.528277e+000,-1.030394e+000,-1.042742e+000,-1.720372e-003,-1.720372e-003,,,,,,,,,,,,,,,,,,,,
1473356288.748,,5.000000e+002,5.221404e+001,5.173948e+001,1,0,3.621671e+000,-2.914670e+000,-2.914670e+000,-3.380705e-001,-4.291348e-001,-2.931305e+000,-3.547057e-001,-4.457700e-001,-1.460157e-003,-1.460157e-003,,,,,,,,,,,,,,,,,,,,
1473356301.774,,5.000000e+002,5.163235e+001,5.117680e+001,1,0,4.944757e+000,-3.023774e+000,-3.023774e+000,-4.611570e-001,-5.316846e-001,-2.984663e+000,-4.220459e-001,-4.925735e-001,-1.514814e-003,-1.514814e-003,,,,,,,,,,,,,,,,,,,,
1473356313.988,,5.000000e+002,5.105376e+001,5.059509e+001,1,0,2.634978e+000,-2.247688e-001,-2.247688e-001,2.322944e+000,2.272778e+000,-1.912399e-001,2.356473e+000,2.306307e+000,-1.126020e-004,-1.126020e-004,,,,,,,,,,,,,,,,,,,,
1473356326.952,,5.000000e+002,5.047594e+001,5.001583e+001,1,0,2.832951e-001,-3.158055e+000,-3.158055e+000,-6.269500e-001,-6.571820e-001,-3.138448e+000,-6.073422e-001,-6.375742e-001,-1.582085e-003,-1.582085e-003,,,,,,,,,,,,,,,,,,,,
1473356338.917,,5.000000e+002,4.989801e+001,4.944413e+001,1,0,1.060573e+000,-3.422040e+000,-3.422040e+000,-9.088296e-001,-9.193377e-001,-3.520952e+000,-1.007741e+000,-1.018250e+000,-1.714333e-003,-1.714333e-003,,,,,,,,,,,,,,,,,,,,
1473356338.917,,5.000000e+002,4.989801e+001,4.944413e+001,1,0,3.802301e+000,-3.375652e+000,-3.375652e+000,-7.858822e-001,-8.729496e-001,-3.367974e+000,-7.782035e-001,-8.652709e-001,-1.691094e-003,-1.691094e-003,,,,,,,,,,,,,,,,,,,,
1473356354.185,,5.000000e+002,4.920323e+001,4.873867e+001,1,0,4.870951e+000,-3.124790e+000,-3.124790e+000,-5.520182e-001,-6.197975e-001,-3.079675e+000,-5.069032e-001,-5.746825e-001,-1.565420e-003,-1.565420e-003,,,,,,,,,,,,,,,,,,,,
1473356369.150,,5.000000e+002,4.851007e+001,4.804374e+001,1,0,2.409930e+000,-4.669332e-002,-4.669332e-002,2.516392e+000,2.468044e+000,-2.703317e-002,2.536052e+000,2.487704e+000,-2.339186e-005,-2.339186e-005,,,,,,,,,,,,,,,,,,,,
1473356381.864,,5.000000e+002,4.804374e+001,4.743838e+001,1,0,1.752891e-001,-3.125706e+000,-3.125706e+000,-5.762596e-001,-6.046646e-001,-3.093357e+000,-5.439104e-001,-5.723155e-001,-1.565879e-003,-1.565879e-003,,,,,,,,,,,,,,,,,,,,
1473356394.861,,5.000000e+002,4.721124e+001,4.686286e+001,1,0,1.263904e+000,-3.200324e+000,-3.200324e+000,-6.656705e-001,-6.748333e-001,-3.267825e+000,-7.331718e-001,-7.423346e-001,-1.603260e-003,-1.603260e-003,,,,,,,,,,,,,,,,,,,,
1473356394.861,,5.000000e+002,4.721124e+001,4.686286e+001,1,0,3.975240e+000,-3.716239e+000,-3.716239e+000,-1.103702e+000,-1.190749e+000,-3.697706e+000,-1.085170e+000,-1.172216e+000,-1.861717e-003,-1.861717e-003,,,,,,,,,,,,,,,,,,,,
1473356408.075,,5.000000e+002,4.674345e+001,4.631022e+001,1,0,4.767349e+000,-3.232978e+000,-3.232978e+000,-6.892994e-001,-7.902553e-001,-3.175910e+000,-6.322306e-001,-7.331865e-001,-1.619619e-003,-1.619619e-003,,,,,,,,,,,,,,,,,,,,
1473356420.540,,5.000000e+002,4.619991e+001,4.576258e+001,1,0,2.188732e+000,-3.494369e-001,-3.494369e-001,2.237114e+000,2.192417e+000,-3.905802e-001,2.195971e+000,2.151274e+000,-1.750567e-004,-1.750567e-004,,,,,,,,,,,,,,,,,,,,
1473356432.801,,5.000000e+002,4.564535e+001,4.509422e+001,1,0,9.041176e-002,-3.096560e+000,-3.096560e+000,-5.421100e-001,-5.691183e-001,-3.050980e+000,-4.965291e-001,-5.235374e-001,-1.551278e-003,-1.551278e-003,,,,,,,,,,,,,,,,,,,,
1473356446.015,,5.000000e+002,4.498633e+001,4.454770e+001,1,0,1.474774e+000,-2.716910e+000,-2.716910e+000,-1.715561e-001,-1.789446e-001,-2.745497e+000,-2.001429e-001,-2.075315e-001,-1.361085e-003,-1.361085e-003,,,,,,,,,,,,,,,,,,,,
1473356446.015,,5.000000e+002,4.498633e+001,4.454770e+001,1,0,4.141114e+000,-3.865780e+000,-3.865780e+000,-1.245062e+000,-1.327814e+000,-3.839583e+000,-1.218866e+000,-1.301617e+000,-1.936632e-003,-1.936632e-003,,,,,,,,,,,,,,,,,,,,
1473356459.411,,5.000000e+002,4.431861e+001,4.387099e+001,1,0,4.637796e+000,-3.458968e+000,-3.458968e+000,-8.669009e-001,-9.276035e-001,-3.395569e+000,-8.035015e-001,-8.642042e-001,-1.732832e-003,-1.732832e-003,,,,,,,,,,,,,,,,,,,,
1473356472.233,,5.000000e+002,4.376381e+001,4.330696e+001,1,0,1.973636e+000,-2.378918e-001,-2.378918e-001,1.638385e+000,1.595800e+000,-3.295873e-001,1.546690e+000,1.504104e+000,-1.191762e-004,-1.191762e-004,,,,,,,,,,,,,,,,,,,,
1473356484.197,,5.000000e+002,4.320426e+001,4.274064e+001,1,0,3.318962e-002,-2.378765e+000,-2.378765e+000,-5.288745e-001,-5.531067e-001,-2.321185e+000,-4.712947e-001,-4.955269e-001,-1.191685e-003,-1.191685e-003,,,,,,,,,,,,,,,,,,,,
1473356497.161,,5.000000e+002,4.261759e+001,4.213843e+001,1,0,1.691941e+000,-1.292611e+000,-1.292611e+000,5.307193e-001,5.248682e-001,-1.296361e+000,5.269695e-001,5.211184e-001,-6.475570e-004,-6.475570e-004,,,,,,,,,,,,,,,,,,,,
1473356497.161,,5.000000e+002,4.261759e+001,4.213843e+001,1,0,4.299876e+000,-3.139744e+000,-3.139744e+000,-1.241812e+000,-1.322265e+000,-3.100617e+000,-1.202685e+000,-1.283137e+000,-1.572912e-003,-1.572912e-003,,,,,,,,,,,,,,,,,,,,
1473356510.380,,5.000000e+002,4.202136e+001,4.153664e+001,1,0,4.486447e+000,-2.959380e+000,-2.959380e+000,-1.087584e+000,-1.146532e+000,-2.893427e+000,-1.021631e+000,-1.080579e+000,-1.482555e-003,-1.482555e-003,,,,,,,,,,,,,,,,,,,,
1473356524.594,,5.000000e+002,4.127245e+001,4.075028e+001,1,0,1.766552e+000,-1.593219e+000,-1.593219e+000,9.170667e-001,8.800414e-001,-1.691925e+000,8.183607e-001,7.813354e-001,-7.981517e-004,-7.981517e-004,,,,,,,,,,,,,,,,,,,,
1473356545.474,,5.000000e+002,4.023247e+001,3.982098e+001,1,0,7.251745e-003,-1.466262e+000,-1.466262e+000,-2.164860e-001,-2.259083e-001,-1.439869e+000,-1.900930e-001,-1.995153e-001,-1.836376e-003,-1.836376e-003,,,,,,,,,,,,,,,,,,,,
1473356558.568,,5.000000e+002,3.968641e+001,3.897239e+001,1,0,1.913980e+000,-6.900235e-001,-6.900235e-001,5.611011e-001,5.593397e-001,-6.801734e-001,5.709512e-001,5.691898e-001,-8.641992e-004,-8.641992e-004,,,,,,,,,,,,,,,,,,,,
1473356558.568,,5.000000e+002,3.968641e+001,3.897239e+001,1,0,4.450646e+000,-1.745964e+000,-1.745964e+000,-4.648956e-001,-4.966007e-001,-1.723974e+000,-4.429059e-001,-4.746110e-001,-2.186680e-003,-2.186680e-003,,,,,,,,,,,,,,,,,,,,
1473356570.845,,5.000000e+002,3.883024e+001,3.809796e+001,1,0,4.317468e+000,-1.811121e+000,-1.811121e+000,-5.285859e-001,-5.525454e-001,-1.787935e+000,-5.053995e-001,-5.293591e-001,-2.268284e-003,-2.268284e-003,,,,,,,,,,,,,,,,,,,,
1473356583.059,,5.000000e+002,3.809796e+001,3.765555e+001,1,0,1.568302e+000,-1.197851e+000,-1.197852e+000,8.091462e-002,6.508636e-002,-1.235414e+000,4.335249e-002,2.752423e-002,-1.500213e-003,-1.500213e-003,,,,,,,,,,,,,,,,,,,,
1473356595.523,,5.000000e+002,3.718885e+001,3.672467e+001,1,0,1.470508e-002,-1.499527e+000,-1.499527e+000,-2.287440e-001,-2.371123e-001,-1.471829e+000,-2.010459e-001,-2.094141e-001,-1.878038e-003,-1.878038e-003,,,,,,,,,,,,,,,,,,,,
1473356608.238,,5.000000e+002,3.656688e+001,3.592846e+001,1,0,2.139297e+000,-3.263955e-001,-3.263955e-001,9.326769e-001,9.315807e-001,-2.987760e-001,9.602964e-001,9.592002e-001,-4.087842e-004,-4.087842e-004,,,,,,,,,,,,,,,,,,,,
1473356608.238,,5.000000e+002,3.656688e+001,3.592846e+001,1,0,4.591009e+000,-1.700949e+000,-1.700949e+000,-4.139240e-001,-4.429729e-001,-1.674663e+000,-3.876380e-001,-4.166869e-001,-2.130303e-003,-2.130303e-003,,,,,,,,,,,,,,,,,,,,
1473356620.202,,5.000000e+002,3.592846e+001,3.526913e+001,1,0,4.134453e+000,-1.856899e+000,-1.856899e+000,-5.804949e-001,-6.024398e-001,-1.840302e+000,-5.638978e-001,-5.858426e-001,-2.325617e-003,-2.325617e-003,,,,,,,,,,,,,,,,,,,,
1473356634.866,,5.000000e+002,3.476528e+001,3.425057e+001,1,0,1.379108e+000,-1.448561e+000,-1.448561e+000,-1.819437e-001,-1.967807e-001,-1.486537e+000,-2.199193e-001,-2.347562e-001,-1.814207e-003,-1.814207e-003,,,,,,,,,,,,,,,,,,,,
1473356646.138,,5.000000e+002,3.425057e+001,3.348594e+001,1,0,5.598209e-002,-1.508682e+000,-1.508682e+000,-2.505408e-001,-2.581744e-001,-1.483187e+000,-2.250454e-001,-2.326790e-001,-1.889504e-003,-1.889504e-003,,,,,,,,,,,,,,,,,,,,
1473356658.961,,5.000000e+002,3.333172e+001,3.252302e+001,1,0,2.365686e+000,-1.861629e-002,-1.861629e-002,1.230712e+000,1.230166e+000,2.640238e-002,1.275731e+000,1.275185e+000,-2.331542e-005,-2.331542e-005,,,,,,,,,,,,,,,,,,,,
1473356658.961,,5.000000e+002,3.333172e+001,3.252302e+001,1,0,4.717371e+000,-1.637776e+000,-1.637776e+000,-3.605971e-001,-3.889931e-001,-1.613060e+000,-3.358814e-001,-3.642775e-001,-2.051183e-003,-2.051183e-003,,,,,,,,,,,,,,,,,,,,
1473356672.720,,5.000000e+002,3.218285e+001,3.169233e+001,1,0,3.940219e+000,-1.812799e+000,-1.812799e+000,-5.440104e-001,-5.651921e-001,-1.800104e+000,-5.313153e-001,-5.524970e-001,-2.270386e-003,-2.270386e-003,,,,,,,,,,,,,,,,,,,,
1473356688.185,,5.000000e+002,3.118810e+001,3.034855e+001,1,0,1.198407e+000,-1.383251e+000,-1.383251e+000,-3.942724e-001,-4.083446e-001,-1.428142e+000,-4.391628e-001,-4.532350e-001,-1.732412e-003,-1.732412e-003,,,,,,,,,,,,,,,,,,,,
1473356703.399,,5.000000e+002,3.000762e+001,2.933345e+001,1,0,1.297778e-001,-1.267739e+000,-1.267739e+000,-2.875956e-001,-2.945999e-001,-1.246524e+000,-2.663803e-001,-2.733846e-001,-1.587742e-003,-1.587742e-003,,,,,,,,,,,,,,,,,,,,
1473356715.863,,5.000000e+002,2.916915e+001,2.849511e+001,1,0,2.590724e+000,3.657643e-001,3.657643e-001,1.337122e+000,1.337122e+000,3.968045e-001,1.368162e+000,1.368162e+000,4.580906e-004,4.580906e-004,,,,,,,,,,,,,,,,,,,,
1473356715.863,,5.000000e+002,2.916915e+001,2.849511e+001,1,0,4.825395e+000,-1.311228e+000,-1.311228e+000,-3.126111e-001,-3.398699e-001,-1.293856e+000,-2.952392e-001,-3.224980e-001,-1.642208e-003,-1.642208e-003,,,,,,,,,,,,,,,,,,,,
1473356728.328,,5.000000e+002,2.832388e+001,2.764615e+001,1,0,3.736864e+000,-1.369365e+000,-1.369366e+000,-3.799097e-001,-4.001991e-001,-1.357341e+000,-3.678855e-001,-3.881749e-001,-1.715021e-003,-1.715021e-003,,,,,,,,,,,,,,,,,,,,
1473356741.083,,5.000000e+002,2.730310e+001,2.661822e+001,1,0,1.025575e+000,-1.513413e+000,-1.513413e+000,-5.328726e-001,-5.461664e-001,-1.564440e+000,-5.839002e-001,-5.971939e-001,-1.895429e-003,-1.895429e-003,,,,,,,,,,,,,,,,,,,,
1473356753.797,,5.000000e+002,2.645122e+001,2.576216e+001,1,0,2.333289e-001,-1.585131e+000,-1.585131e+000,-3.419469e-001,-3.483206e-001,-1.569579e+000,-3.263944e-001,-3.327681e-001,-1.985250e-003,-1.985250e-003,,,,,,,,,,,,,,,,,,,,
1473356753.797,,5.000000e+002,2.645122e+001,2.576216e+001,1,0,2.811979e+000,-5.951110e-002,-5.951110e-002,1.210762e+000,1.177300e+000,-9.932720e-002,1.170946e+000,1.137484e+000,-7.453289e-005,-7.453289e-005,,,,,,,,,,,,,,,,,,,,
1473356766.762,,5.000000e+002,2.559386e+001,2.490551e+001,1,0,4.910290e+000,-1.541032e+000,-1.541032e+000,-2.798091e-001,-3.061767e-001,-1.526604e+000,-2.653812e-001,-2.917488e-001,-1.930020e-003,-1.930020e-003,,,,,,,,,,,,,,,,,,,,
1473356780.727,,5.000000e+002,2.455383e+001,2.388999e+001,1,0,3.525979e+000,-1.341594e+000,-1.341594e+000,-8.927257e-002,-1.087490e-001,-1.333718e+000,-8.139737e-002,-1.008738e-001,-1.680239e-003,-1.680239e-003,,,,,,,,,,,,,,,,,,,,
1473356794.704,,5.000000e+002,2.372740e+001,2.326292e+001,1,0,8.596853e-001,-2.104709e+000,-2.104709e+000,-5.894776e-001,-6.021287e-001,-2.152830e+000,-6.375983e-001,-6.502495e-001,-2.635980e-003,-2.635980e-003,,,,,,,,,,,,,,,,,,,,
1473356808.227,,5.000000e+002,2.318864e+001,2.300532e+001,1,0,3.629158e-001,-1.921445e+000,-1.921445e+000,-4.144162e-001,-4.202087e-001,-1.915013e+000,-4.079837e-001,-4.137762e-001,-2.406457e-003,-2.406457e-003,,,,,,,,,,,,,,,,,,,,
1473356808.227,,5.000000e+002,2.318864e+001,2.300532e+001,1,0,3.027020e+000,-6.555376e-001,-6.555376e-001,8.783475e-001,8.456991e-001,-7.137777e-001,8.201074e-001,7.874590e-001,-8.210084e-004,-8.210084e-004,,,,,,,,,,,,,,,,,,,,
1473356821.732,,5.000000e+002,2.287227e+001,2.235397e+001,1,0,4.967543e+000,-1.785791e+000,-1.785791e+000,-2.607625e-001,-2.864801e-001,-1.771384e+000,-2.463558e-001,-2.720734e-001,-2.236560e-003,-2.236560e-003,,,,,,,,,,,,,,,,,,,,
1473356834.695,,5.000000e+002,2.197391e+001,2.142822e+001,1,0,3.308762e+000,-1.221046e+000,-1.221046e+000,2.954613e-001,2.767178e-001,-1.223055e+000,2.934515e-001,2.747080e-001,-1.529262e-003,-1.529262e-003,,,,,,,,,,,,,,,,,,,,
1473356848.660,,5.000000e+002,2.119193e+001,2.025250e+001,1,0,7.007965e-001,-2.084719e+000,-2.084719e+000,-5.769634e-001,-5.889959e-001,-2.118797e+000,-6.110408e-001,-6.230733e-001,-2.610944e-003,-2.610944e-003,,,,,,,,,,,,,,,,,,,,
1473356862.124,,5.000000e+002,2.025250e+001,1.942706e+001,1,0,5.142469e-001,-2.003998e+000,-2.003998e+000,-5.047079e-001,-5.099081e-001,-2.012238e+000,-5.129474e-001,-5.181476e-001,-2.509847e-003,-2.509847e-003,,,,,,,,,,,,,,,,,,,,
1473356862.124,,5.000000e+002,2.025250e+001,1.942706e+001,1,0,3.234118e+000,-1.037324e+000,-1.037324e+000,4.884869e-001,4.567658e-001,-1.088200e+000,4.376111e-001,4.058900e-001,-1.299166e-003,-1.299166e-003,,,,,,,,,,,,,,,,,,,,
1473356876.838,,5.000000e+002,1.922608e+001,1.909893e+001,1,0,4.993488e+000,-1.775567e+000,-1.775567e+000,-2.581151e-001,-2.830744e-001,-1.758768e+000,-2.413164e-001,-2.662756e-001,-2.223755e-003,-2.223755e-003,,,,,,,,,,,,,,,,,,,,
1473356889.604,,5.000000e+002,1.909597e+001,1.909251e+001,1,0,3.086723e+000,-7.762383e-001,-7.762383e-001,7.331784e-001,7.149926e-001,-7.830746e-001,7.263421e-001,7.081563e-001,-9.721764e-004,-9.721764e-004,,,,,,,,,,,,,,,,,,,,
1473356904.318,,5.000000e+002,1.904921e+001,1.853794e+001,1,0,5.501396e-001,-2.022919e+000,-2.022919e+000,-5.226368e-001,-5.340528e-001,-2.038384e+000,-5.381016e-001,-5.495176e-001,-2.533545e-003,-2.533545e-003,,,,,,,,,,,,,,,,,,,,
1473356918.037,,5.000000e+002,1.833486e+001,1.734164e+001,1,0,6.832532e-001,-2.079836e+000,-2.079836e+000,-5.885231e-001,-5.931580e-001,-2.106483e+000,-6.151702e-001,-6.198051e-001,-2.604829e-003,-2.604829e-003,,,,,,,,,,,,,,,,,,,,
1473356918.037,,5.000000e+002,1.833486e+001,1.734164e+001,1,0,3.432363e+000,-1.416211e+000,-1.416211e+000,1.013659e-001,7.046688e-002,-1.443187e+000,7.439003e-002,4.349101e-002,-1.773692e-003,-1.773692e-003,,,,,,,,,,,,,,,,,,,,
1473356931.752,,5.000000e+002,1.713482e+001,1.595306e+001,1,0,4.986067e+000,-1.776025e+000,-1.776025e+000,-2.679248e-001,-2.919942e-001,-1.756788e+000,-2.486877e-001,-2.727572e-001,-2.224329e-003,-2.224329e-003,,,,,,,,,,,,,,,,,,,,
1473356945.216,,5.000000e+002,1.544090e+001,1.427228e+001,1,0,2.861477e+000,-3.227332e-001,-3.227332e-001,1.175793e+000,1.158419e+000,-3.166392e-001,1.181888e+000,1.164513e+000,-4.041976e-004,-4.041976e-004,,,,,,,,,,,,,,,,,,,,
1473356961.720,,5.000000e+002,1.371938e+001,1.272670e+001,1,0,4.097075e-001,-1.954863e+000,-1.954863e+000,-4.663420e-001,-4.770256e-001,-1.953334e+000,-4.648133e-001,-4.754969e-001,-2.448310e-003,-2.448310e-003,,,,,,,,,,,,,,,,,,,,
1473356972.684,,5.000000e+002,1.272670e+001,1.221238e+001,1,0,8.663222e-001,-2.118442e+000,-2.118442e+000,-6.382030e-001,-6.422675e-001,-2.162086e+000,-6.818470e-001,-6.859114e-001,-2.653180e-003,-2.653180e-003,,,,,,,,,,,,,,,,,,,,
1473356972.684,,5.000000e+002,1.272670e+001,1.221238e+001,1,0,3.621598e+000,-1.742912e+000,-1.742912e+000,-2.367622e-001,-2.667372e-001,-1.751629e+000,-2.454794e-001,-2.754545e-001,-2.182858e-003,-2.182858e-003,,,,,,,,,,,,,,,,,,,,
1473356991.149,,5.000000e+002,1.192812e+001,1.243664e+001,1,0,4.944783e+000,-1.790674e+000,-1.790673e+000,-2.923012e-001,-3.160986e-001,-1.769591e+000,-2.712187e-001,-2.950161e-001,-2.242676e-003,-2.242676e-003,,,,,,,,,,,,,,,,,,,,
1473357006.057,,5.000000e+002,1.256706e+001,1.316602e+001,1,0,2.635075e+000,-2.105777e-002,-2.105777e-002,1.472850e+000,1.455668e+000,4.912406e-003,1.498820e+000,1.481638e+000,-2.637317e-005,-2.637317e-005,,,,,,,,,,,,,,,,,,,,
1473357161.648,,5.000000e+002,1.500579e+001,1.500702e+001,1,0,2.832792e-001,-1.528825e+000,-1.528825e+000,-3.937733e-001,-4.043239e-001,-1.517223e+000,-3.821721e-001,-3.927227e-001,-1.914731e-003,-1.914731e-003,,,,,,,,,,,,,,,,,,,,
1473357174.311,,5.000000e+002,1.500702e+001,1.500579e+001,1,0,1.060538e+000,-1.702933e+000,-1.702933e+000,-5.704277e-001,-5.741210e-001,-1.747881e+000,-6.153762e-001,-6.190695e-001,-2.132787e-003,-2.132787e-003,,,,,,,,,,,,,,,,,,,,
1473357174.311,,5.000000e+002,1.500702e+001,1.500579e+001,1,0,3.802285e+000,-1.646779e+000,-1.646779e+000,-4.873654e-001,-5.179670e-001,-1.644560e+000,-4.851463e-001,-5.157479e-001,-2.062459e-003,-2.062459e-003,,,,,,,,,,,,,,,,,,,,
1473357186.883,,5.000000e+002,1.500579e+001,1.500335e+001,1,0,4.870939e+000,-1.482284e+000,-1.482284e+000,-3.258994e-001,-3.495543e-001,-1.459529e+000,-3.031446e-001,-3.267995e-001,-1.856442e-003,-1.856442e-003,,,,,,,,,,,,,,,,,,,,
1473357200.348,,5.000000e+002,1.500335e+001,1.500518e+001,1,0,2.409928e+000,3.422651e-001,3.422651e-001,1.495394e+000,1.478627e+000,3.579927e-001,1.511121e+000,1.494355e+000,4.286596e-004,4.286596e-004,,,,,,,,,,,,,,,,,,,,
1473357293.570,,5.000000e+002,1.500091e+001,1.500213e+001,1,0,1.753004e-001,-1.490066e+000,-1.490066e+000,-3.358914e-001,-3.458865e-001,-1.476077e+000,-3.219021e-001,-3.318971e-001,-1.866189e-003,-1.866189e-003,,,,,,,,,,,,,,,,,,,,
1473357305.034,,5.000000e+002,1.500213e+001,1.500213e+001,1,0,1.263904e+000,-1.537980e+000,-1.537980e+000,-3.873591e-001,-3.905022e-001,-1.568009e+000,-4.173876e-001,-4.205308e-001,-1.926197e-003,-1.926197e-003,,,,,,,,,,,,,,,,,,,,
1473357305.034,,5.000000e+002,1.500213e+001,1.500213e+001,1,0,3.975236e+000,-1.814783e+000,-1.814783e+000,-6.374451e-001,-6.673051e-001,-1.808327e+000,-6.309887e-001,-6.608487e-001,-2.272871e-003,-2.272871e-003,,,,,,,,,,,,,,,,,,,,
1473357317.248,,5.000000e+002,1.500152e+001,1.500091e+001,1,0,4.767378e+000,-1.558580e+000,-1.558580e+000,-3.847326e-001,-4.078845e-001,-1.532185e+000,-3.583373e-001,-3.814892e-001,-1.951997e-003,-1.951997e-003,,,,,,,,,,,,,,,,,,,,
1473357329.713,,5.000000e+002,1.500152e+001,1.500030e+001,1,0,2.188765e+000,9.796442e-002,9.796441e-002,1.269199e+000,1.252763e+000,7.827953e-002,1.249515e+000,1.233078e+000,1.226926e-004,1.226926e-004,,,,,,,,,,,,,,,,,,,,
1473357398.182,,5.000000e+002,1.383620e+001,1.361261e+001,1,0,9.040171e-002,-1.462752e+000,-1.462752e+000,-3.002769e-001,-3.094488e-001,-1.444270e+000,-2.817946e-001,-2.909665e-001,-1.831980e-003,-1.831980e-003,,,,,,,,,,,,,,,,,,,,
1473357410.401,,5.000000e+002,1.355938e+001,1.334510e+001,1,0,1.474768e+000,-1.243477e+000,-1.243477e+000,-9.019517e-002,-9.273553e-002,-1.256680e+000,-1.033984e-001,-1.059388e-001,-1.557355e-003,-1.557355e-003,,,,,,,,,,,,,,,,,,,,
1473357410.401,,5.000000e+002,1.355938e+001,1.334510e+001,1,0,4.141116e+000,-1.868191e+000,-1.868191e+000,-6.889974e-001,-7.174494e-001,-1.858319e+000,-6.791258e-001,-7.075778e-001,-2.339759e-003,-2.339759e-003,,,,,,,,,,,,,,,,,,,,
1473357423.314,,5.000000e+002,1.324274e+001,1.304415e+001,1,0,4.637818e+000,-1.639912e+000,-1.639912e+000,-4.696136e-001,-4.913820e-001,-1.610502e+000,-4.402039e-001,-4.619722e-001,-2.053859e-003,-2.053859e-003,,,,,,,,,,,,,,,,,,,,
1473357435.071,,5.000000e+002,1.299668e+001,1.284034e+001,1,0,1.973698e+000,-2.597125e-001,-2.597125e-001,9.018744e-001,8.866374e-001,-3.066471e-001,8.549399e-001,8.397028e-001,-3.252692e-004,-3.252692e-004,,,,,,,,,,,,,,,,,,,,
1473357448.951,,5.000000e+002,1.279391e+001,1.254067e+001,1,0,3.319350e-002,-1.433149e+000,-1.433149e+000,-2.805207e-001,-2.891585e-001,-1.409948e+000,-2.573198e-001,-2.659576e-001,-1.794905e-003,-1.794905e-003,,,,,,,,,,,,,,,,,,,,
1473357461.665,,5.000000e+002,1.249506e+001,1.231988e+001,1,0,1.691941e+000,-8.487198e-001,-8.487198e-001,2.951271e-001,2.930998e-001,-8.522493e-001,2.915976e-001,2.895703e-001,-1.062954e-003,-1.062954e-003,,,,,,,,,,,,,,,,,,,,
1473357461.665,,5.000000e+002,1.249506e+001,1.231988e+001,1,0,4.299928e+000,-1.830348e+000,-1.830348e+000,-6.606528e-001,-6.885281e-001,-1.813238e+000,-6.435429e-001,-6.714182e-001,-2.292364e-003,-2.292364e-003,,,,,,,,,,,,,,,,,,,,
1473357473.629,,5.000000e+002,1.227469e+001,1.210091e+001,1,0,4.486499e+000,-1.729637e+000,-1.729637e+000,-5.690861e-001,-5.902600e-001,-1.700571e+000,-5.400203e-001,-5.611942e-001,-2.166231e-003,-2.166231e-003,,,,,,,,,,,,,,,,,,,,
1473357486.523,,5.000000e+002,1.205755e+001,1.188163e+001,1,0,1.766512e+000,-9.360027e-001,-9.360027e-001,4.865395e-001,4.718208e-001,-9.843827e-001,4.381595e-001,4.234408e-001,-1.172269e-003,-1.172269e-003,,,,,,,,,,,,,,,,,,,,
1473357498.596,,5.000000e+002,1.183838e+001,1.166364e+001,1,0,7.265814e-003,-1.416211e+000,-1.416211e+000,-2.741214e-001,-2.822537e-001,-1.389303e+000,-2.472126e-001,-2.553449e-001,-1.773692e-003,-1.773692e-003,,,,,,,,,,,,,,,,,,,,
1473357512.310,,5.000000e+002,1.157753e+001,1.140388e+001,1,0,1.914055e+000,-4.034547e-001,-4.034547e-001,7.296056e-001,7.280867e-001,-3.950262e-001,7.380340e-001,7.365152e-001,-5.052948e-004,-5.052948e-004,,,,,,,,,,,,,,,,,,,,
1473357512.310,,5.000000e+002,1.157753e+001,1.140388e+001,1,0,4.450743e+000,-1.748405e+000,-1.748405e+000,-5.895240e-001,-6.168641e-001,-1.722919e+000,-5.640380e-001,-5.913781e-001,-2.189738e-003,-2.189738e-003,,,,,,,,,,,,,,,,,,,,
1473357524.292,,5.000000e+002,1.136116e+001,1.119043e+001,1,0,4.317487e+000,-1.811884e+000,-1.811884e+000,-6.619267e-001,-6.826649e-001,-1.788482e+000,-6.385252e-001,-6.592634e-001,-2.269240e-003,-2.269240e-003,,,,,,,,,,,,,,,,,,,,
1473357535.256,,5.000000e+002,1.119043e+001,1.101993e+001,1,0,1.568269e+000,-1.038697e+000,-1.038697e+000,1.030472e-001,8.886039e-002,-1.081116e+000,6.062900e-002,4.644215e-002,-1.300886e-003,-1.300886e-003,,,,,,,,,,,,,,,,,,,,
1473357548.017,,5.000000e+002,1.093735e+001,1.076881e+001,1,0,1.466633e-002,-1.413160e+000,-1.413160e+000,-2.795407e-001,-2.871418e-001,-1.384784e+000,-2.511649e-001,-2.587661e-001,-1.769869e-003,-1.769869e-003,,,,,,,,,,,,,,,,,,,,
1473357559.482,,5.000000e+002,1.076881e+001,1.060056e+001,1,0,2.139346e+000,-2.397229e-001,-2.397229e-001,1.157488e+000,1.156476e+000,-2.100864e-001,1.187125e+000,1.186112e+000,-3.002337e-004,-3.002337e-004,,,,,,,,,,,,,,,,,,,,
1473357559.482,,5.000000e+002,1.076881e+001,1.060056e+001,1,0,4.591093e+000,-1.928312e+000,-1.928312e+000,-5.052754e-001,-5.321137e-001,-1.897796e+000,-4.747597e-001,-5.015979e-001,-2.415057e-003,-2.415057e-003,,,,,,,,,,,,,,,,,,,,
1473357571.446,,5.000000e+002,1.055974e+001,1.039206e+001,1,0,4.134457e+000,-2.117527e+000,-2.117527e+000,-7.022491e-001,-7.223929e-001,-2.102469e+000,-6.871918e-001,-7.073356e-001,-2.652033e-003,-2.652033e-003,,,,,,,,,,,,,,,,,,,,
1473357584.940,,5.000000e+002,1.031050e+001,1.014424e+001,1,0,1.379057e+000,-1.628315e+000,-1.628315e+000,-2.209116e-001,-2.345260e-001,-1.668260e+000,-2.608569e-001,-2.744714e-001,-2.039335e-003,-2.039335e-003,,,,,,,,,,,,,,,,,,,,
1473357607.467,,5.000000e+002,9.933388e+000,9.767144e+000,1,0,5.603065e-002,-1.694388e+000,-1.694388e+000,-2.962309e-001,-3.032833e-001,-1.668320e+000,-2.701632e-001,-2.772156e-001,-2.122085e-003,-2.122085e-003,,,,,,,,,,,,,,,,,,,,
1473357620.182,,5.000000e+002,9.728018e+000,9.565636e+000,1,0,2.365772e+000,7.370220e-002,7.370220e-002,1.463579e+000,1.463076e+000,1.224243e-001,1.512301e+000,1.511798e+000,9.230612e-005,9.230612e-005,,,,,,,,,,,,,,,,,,,,
1473357620.182,,5.000000e+002,9.728018e+000,9.565636e+000,1,0,4.717412e+000,-1.839503e+000,-1.839503e+000,-4.239526e-001,-4.501294e-001,-1.811567e+000,-3.960164e-001,-4.221932e-001,-2.303831e-003,-2.303831e-003,,,,,,,,,,,,,,,,,,,,
1473357633.396,,5.000000e+002,9.485477e+000,9.326693e+000,1,0,3.940231e+000,-2.042299e+000,-2.042299e+000,-6.344801e-001,-6.541747e-001,-2.031703e+000,-6.238850e-001,-6.435796e-001,-2.557816e-003,-2.557816e-003,,,,,,,,,,,,,,,,,,,,
1473357645.360,,5.000000e+002,9.287188e+000,9.130939e+000,1,0,1.198391e+000,-1.860103e+000,-1.860103e+000,-4.602675e-001,-4.733536e-001,-1.906342e+000,-5.065060e-001,-5.195920e-001,-2.329631e-003,-2.329631e-003,,,,,,,,,,,,,,,,,,,,
1473357669.826,,5.000000e+002,8.933744e+000,8.742220e+000,1,0,1.297911e-001,-1.718650e+000,-1.718650e+000,-3.281106e-001,-3.346725e-001,-1.696849e+000,-3.063099e-001,-3.128717e-001,-2.152472e-003,-2.152472e-003,,,,,,,,,,,,,,,,,,,,
1473357681.790,,5.000000e+002,8.704725e+000,8.558037e+000,1,0,2.590814e+000,1.406903e-001,1.406903e-001,1.523200e+000,1.523200e+000,1.720379e-001,1.554548e+000,1.554548e+000,1.762034e-004,1.762034e-004,,,,,,,,,,,,,,,,,,,,
1473357681.790,,5.000000e+002,8.704725e+000,8.558037e+000,1,0,4.825466e+000,-1.761834e+000,-1.761834e+000,-3.536603e-001,-3.793235e-001,-1.742881e+000,-3.347079e-001,-3.603711e-001,-2.206556e-003,-2.206556e-003,,,,,,,,,,,,,,,,,,,,
1473357694.004,,5.000000e+002,8.522026e+000,8.379293e+000,1,0,3.736848e+000,-1.827753e+000,-1.827754e+000,-4.278656e-001,-4.470048e-001,-1.816707e+000,-4.168195e-001,-4.359587e-001,-2.289115e-003,-2.289115e-003,,,,,,,,,,,,,,,,,,,,
1473357705.972,,5.000000e+002,8.343613e+000,8.238626e+000,1,0,1.025484e+000,-1.992096e+000,-1.992096e+000,-6.002191e-001,-6.128117e-001,-2.044215e+000,-6.523388e-001,-6.649314e-001,-2.494941e-003,-2.494941e-003,,,,,,,,,,,,,,,,,,,,
1473357731.712,,5.000000e+002,7.994640e+000,7.860363e+000,1,0,2.333746e-001,-1.760918e+000,-1.760918e+000,-3.792827e-001,-3.853462e-001,-1.744757e+000,-3.631215e-001,-3.691850e-001,-2.205409e-003,-2.205409e-003,,,,,,,,,,,,,,,,,,,,
1473357731.712,,5.000000e+002,7.994640e+000,7.860363e+000,1,0,2.812024e+000,-6.912442e-002,-6.912442e-002,1.338281e+000,1.306447e+000,-1.094282e-001,1.297977e+000,1.266144e+000,-8.657281e-005,-8.657281e-005,,,,,,,,,,,,,,,,,,,,
1473357744.426,,5.000000e+002,7.829628e+000,7.700713e+000,1,0,4.910333e+000,-1.706442e+000,-1.706442e+000,-3.073869e-001,-3.325537e-001,-1.690851e+000,-2.917952e-001,-3.169620e-001,-2.137183e-003,-2.137183e-003,,,,,,,,,,,,,,,,,,,,
1473357755.907,,5.000000e+002,7.670625e+000,7.578066e+000,1,0,3.525985e+000,-1.488845e+000,-1.488845e+000,-9.769638e-002,-1.163191e-001,-1.481868e+000,-9.071846e-002,-1.093411e-001,-1.864660e-003,-1.864660e-003,,,,,,,,,,,,,,,,,,,,
1473357767.870,,5.000000e+002,7.519843e+000,7.402507e+000,1,0,8.595357e-001,-2.298349e+000,-2.298349e+000,-6.437508e-001,-6.557972e-001,-2.347123e+000,-6.925253e-001,-7.045717e-001,-2.878498e-003,-2.878498e-003,,,,,,,,,,,,,,,,,,,,
1473357817.588,,5.000000e+002,6.970230e+000,6.892108e+000,1,0,3.629606e-001,-2.099063e+000,-2.099063e+000,-4.503396e-001,-4.559617e-001,-2.092337e+000,-4.436139e-001,-4.492359e-001,-2.628909e-003,-2.628909e-003,,,,,,,,,,,,,,,,,,,,
1473357817.588,,5.000000e+002,6.970230e+000,6.892108e+000,1,0,3.027107e+000,-7.254249e-001,-7.254249e-001,9.493645e-001,9.176765e-001,-7.861643e-001,8.886252e-001,8.569372e-001,-9.085368e-004,-9.085368e-004,,,,,,,,,,,,,,,,,,,,
1473357829.587,,5.000000e+002,6.871160e+000,6.756039e+000,1,0,4.967505e+000,-1.679281e+000,-1.679281e+000,-2.810840e-001,-3.061357e-001,-1.663959e+000,-2.657622e-001,-2.908138e-001,-2.103165e-003,-2.103165e-003,,,,,,,,,,,,,,,,,,,,
1473357841.551,,5.000000e+002,6.756039e+000,6.670750e+000,1,0,3.308802e+000,-1.077303e+000,-1.077303e+000,3.156841e-001,2.972354e-001,-1.079769e+000,3.132189e-001,2.947701e-001,-1.349236e-003,-1.349236e-003,,,,,,,,,,,,,,,,,,,,
1473357855.713,,5.000000e+002,6.625992e+000,6.552913e+000,1,0,7.007093e-001,-2.005066e+000,-2.005066e+000,-6.167662e-001,-6.284871e-001,-2.039411e+000,-6.511111e-001,-6.628320e-001,-2.511185e-003,-2.511185e-003,,,,,,,,,,,,,,,,,,,,
1473357916.988,,5.000000e+002,5.936684e+000,5.777057e+000,1,0,5.142550e-001,-1.922361e+000,-1.922361e+000,-5.362300e-001,-5.413425e-001,-1.930414e+000,-5.442834e-001,-5.493959e-001,-2.407603e-003,-2.407603e-003,,,,,,,,,,,,,,,,,,,,
1473357916.988,,5.000000e+002,5.936684e+000,5.777057e+000,1,0,3.234239e+000,-8.964812e-001,-8.964812e-001,5.157232e-001,4.845372e-001,-9.494714e-001,4.627331e-001,4.315470e-001,-1.122771e-003,-1.122771e-003,,,,,,,,,,,,,,,,,,,,
1473357929.331,,5.000000e+002,5.777057e+000,5.654298e+000,1,0,4.993488e+000,-1.678823e+000,-1.678823e+000,-2.725375e-001,-2.969764e-001,-1.661223e+000,-2.549369e-001,-2.793759e-001,-2.102592e-003,-2.102592e-003,,,,,,,,,,,,,,,,,,,,
1473357941.073,,5.000000e+002,5.626760e+000,5.478584e+000,1,0,3.086674e+000,-6.265450e-001,-6.265450e-001,7.738323e-001,7.560599e-001,-6.330910e-001,7.672863e-001,7.495139e-001,-7.846975e-004,-7.846975e-004,,,,,,,,,,,,,,,,,,,,
1473357952.537,,5.000000e+002,5.478584e+000,5.357911e+000,1,0,5.499597e-001,-1.946776e+000,-1.946776e+000,-5.526710e-001,-5.638297e-001,-1.961918e+000,-5.678132e-001,-5.789719e-001,-2.438181e-003,-2.438181e-003,,,,,,,,,,,,,,,,,,,,
1473358076.809,,5.000000e+002,5.055786e+000,5.057944e+000,1,0,6.832489e-001,-2.113559e+000,-2.113559e+000,-6.177553e-001,-6.223611e-001,-2.140430e+000,-6.446255e-001,-6.492313e-001,-2.647064e-003,-2.647064e-003,,,,,,,,,,,,,,,,,,,,
1473358076.809,,5.000000e+002,5.055786e+000,5.057944e+000,1,0,3.432485e+000,-1.417585e+000,-1.417585e+000,1.043188e-001,7.361364e-002,-1.444924e+000,7.697937e-002,4.627419e-002,-1.775412e-003,-1.775412e-003,,,,,,,,,,,,,,,,,,,,
1473358089.801,,5.000000e+002,5.064813e+000,5.070170e+000,1,0,4.986085e+000,-1.794488e+000,-1.794488e+000,-2.783081e-001,-3.022401e-001,-1.774529e+000,-2.583486e-001,-2.822807e-001,-2.247453e-003,-2.247453e-003,,,,,,,,,,,,,,,,,,,,
1473358101.265,,5.000000e+002,5.070170e+000,5.074953e+000,1,0,2.861391e+000,-2.975555e-001,-2.975555e-001,1.212184e+000,1.195045e+000,-2.914974e-001,1.218242e+000,1.201103e+000,-3.726644e-004,-3.726644e-004,,,,,,,,,,,,,,,,,,,,
1473358113.421,,5.000000e+002,5.074953e+000,5.077643e+000,1,0,4.096739e-001,-1.981109e+000,-1.981109e+000,-4.773810e-001,-4.880971e-001,-1.979468e+000,-4.757397e-001,-4.864558e-001,-2.481181e-003,-2.481181e-003,,,,,,,,,,,,,,,,,,,,
1473358113.421,,5.000000e+002,5.074953e+000,5.077643e+000,1,0,2.812034e+000,-1.797540e-001,-1.797540e-001,1.345406e+000,1.313258e+000,-2.203768e-001,1.304783e+000,1.272635e+000,-2.251275e-004,-2.251275e-004,,,,,,,,,,,,,,,,,,,,