File: data/A344/dat/A344_GdN_MH_010K_160905.rso.dat
[Header]
TITLE,MPMS RSO Measurement
BYAPP,MPMS Measurement,1.1,Summary
FILEOPENTIME, 1473083072.696000 9/6/2016, 1:44:32 AM

INFO, APPNAME, MPMS MultiVu Application, Revision 1.61,  Build 082

INFO, NAME, A344
INFO, WEIGHT, 10.500
INFO, AREA, 1.000
INFO, LENGTH, 1.000
INFO, SHAPE, 0
INFO, COMMENT, m = 0.0105g
INFO, SEQUENCE FILE: 7T_hysteresis_sweep_hi_res_zero_n4.seq


INFO, BACKGROUND DATA FILE:, None


STARTUPAXIS,X,4,LINEAR,AUTO,0.000000,0.000000
STARTUPAXIS,Y1,5,LINEAR,AUTO,0.000000,0.000000


STARTUPGROUP,Longitudinal
FIELDGROUP,Longitudinal,1,2,3,4,5,6,7,8,9,10,11,19,20,21,22,23,35
FIELDGROUP,Transverse,1,2,3,4,12,13,14,15,16,17,18,24,25,26,27,28,35

PLOT_APPEARANCE,ALL,HORZ_GRID_ON,VERT_GRID_ON,MARKERS_AND_LINES

[Data]
Time,Comment,Field (Oe),Temperature (K),Long Moment (emu),Long Scan Std Dev,Long Offset (cm),Long Offset Std Dev,Long Algorithm,Long Reg Fit,Long Reg Factor,Trans Moment (emu),Trans Scan Std Dev,Trans Offset (cm),Trans Offset Std Dev,Trans Algorithm,Trans Reg Fit,Trans Reg Factor,Long Moment [w/o ABS] (emu),Long Scan Std Dev [w/o ABS],Long Offset [w/o ABS] (cm),Long Offset Std Dev [w/o ABS],Long Reg Fit [w/o ABS],Trans Moment [w/o ABS] (emu),Trans Scan Std Dev [w/o ABS],Trans Offset [w/o ABS] (cm),Trans Offset Std Dev [w/o ABS],Trans Reg Fit [w/o ABS],RSO Position (deg),Amplitude (cm),Frequency,Cycles to Average,Scans per Measurement,Delta Temp (K),Error,EC Comp. Running,Using ABS,
1473083072.695,,7.000000e+004,9.929004e+000,1.299725e-003,0.000000e+000,5.048699e-003,0.000000e+000,3,9.537420e-001,1.825000e+000,,,,,,,,,,,,,,,,,,0,5.000000e+000,5.000000e-001,2,1,1.206398e-002,0,0,0,
1473083099.123,,7.000000e+004,9.920234e+000,1.298355e-003,0.000000e+000,4.842139e-003,0.000000e+000,3,9.535046e-001,1.825000e+000,,,,,,,,,,,,,,,,,,0,5.000000e+000,5.000000e-001,2,1,0.000000e+000,0,0,0,
1473083296.152,,6.000000e+004,9.927904e+000,1.304049e-003,0.000000e+000,3.813970e-003,0.000000e+000,3,9.535779e-001,1.825000e+000,,,,,,,,,,,,,,,,,,0,5.000000e+000,5.000000e-001,2,1,4.384041e-003,0,1,0,
1473083321.641,,6.000000e+004,9.941078e+000,1.302137e-003,0.000000e+000,4.119604e-003,0.000000e+000,3,9.541844e-001,1.825000e+000,,,,,,,,,,,,,,,,,,0,5.000000e+000,5.000000e-001,2,1,3.298759e-003,0,1,0,
1473083494.899,,5.000000e+004,9.945753e+000,1.304128e-003,0.000000e+000,3.541636e-003,0.000000e+000,3,9.556060e-001,1.825000e+000,,,,,,,,,,,,,,,,,,0,5.000000e+000,5.000000e-001,2,1,4.952431e-003,0,1,0,
1473083519.578,,5.000000e+004,9.961733e+000,1.302196e-003,0.000000e+000,2.789838e-003,0.000000e+000,3,9.561615e-001,1.825000e+000,,,,,,,,,,,,,,,,,,0,5.000000e+000,5.000000e-001,2,1,7.175446e-003,0,0,0,
1473083698.603,,4.000000e+004,9.924067e+000,1.304689e-003,0.000000e+000,1.756440e-003,0.000000e+000,3,9.550794e-001,1.825000e+000,,,,,,,,,,,,,,,,,,0,5.000000e+000,5.000000e-001,2,1,2.191544e-003,0,0,0,
1473083727.342,,4.000000e+004,9.938331e+000,1.305010e-003,0.000000e+000,2.042340e-003,0.000000e+000,3,9.549320e-001,1.825000e+000,,,,,,,,,,,,,,,,,,0,5.000000e+000,5.000000e-001,2,1,0.000000e+000,0,0,0,
1473083904.083,,3.000000e+004,9.957598e+000,1.299542e-003,0.000000e+000,1.003033e-003,0.000000e+000,3,9.555888e-001,1.825000e+000,,,,,,,,,,,,,,,,,,0,5.000000e+000,5.000000e-001,2,1,1.103115e-002,0,1,0,
1473083929.591,,3.000000e+004,1.000677e+001,1.299064e-003,0.000000e+000,2.029776e-003,0.000000e+000,3,9.544800e-001,1.825000e+000,,,,,,,,,,,,,,,,,,0,5.000000e+000,5.000000e-001,2,1,2.640247e-002,0,1,0,
1473084102.802,,2.000000e+004,1.001345e+001,1.291924e-003,0.000000e+000,4.819206e-004,0.000000e+000,3,9.554767e-001,1.825000e+000,,,,,,,,,,,,,,,,,,0,5.000000e+000,5.000000e-001,2,1,2.200127e-003,0,0,0,
1473084131.981,,2.000000e+004,1.003501e+001,1.291675e-003,0.000000e+000,3.130105e-004,0.000000e+000,3,9.555753e-001,1.825000e+000,,,,,,,,,,,,,,,,,,0,5.000000e+000,5.000000e-001,2,1,1.768017e-002,0,0,0,
1473084304.677,,1.000000e+004,1.031665e+001,1.272817e-003,0.000000e+000,-1.412797e-004,0.000000e+000,3,9.558311e-001,1.825000e+000,,,,,,,,,,,,,,,,,,0,5.000000e+000,5.000000e-001,2,1,2.011013e-002,0,1,0,
1473084332.395,,1.000000e+004,1.041052e+001,1.273163e-003,0.000000e+000,-1.862572e-004,0.000000e+000,3,9.558608e-001,1.825000e+000,,,,,,,,,,,,,,,,,,0,5.000000e+000,5.000000e-001,2,1,4.506969e-002,0,1,0,
1473084468.084,,9.000000e+003,1.061535e+001,1.269069e-003,0.000000e+000,1.494300e-004,0.000000e+000,3,9.555063e-001,1.825000e+000,,,,,,,,,,,,,,,,,,0,5.000000e+000,5.000000e-001,2,1,1.919746e-003,0,0,0,
1473084496.263,,9.000000e+003,1.064622e+001,1.269183e-003,0.000000e+000,-1.908798e-004,0.000000e+000,3,9.554031e-001,1.825000e+000,,,,,,,,,,,,,,,,,,0,5.000000e+000,5.000000e-001,2,1,1.837063e-002,0,0,0,
1473084640.746,,7.000000e+003,1.062075e+001,1.262735e-003,0.000000e+000,-3.590549e-004,0.000000e+000,3,9.565325e-001,1.825000e+000,,,,,,,,,,,,,,,,,,0,5.000000e+000,5.000000e-001,2,1,2.949715e-003,0,1,0,
1473084668.615,,7.000000e+003,1.067294e+001,1.262045e-003,0.000000e+000,-1.743057e-004,0.000000e+000,3,9.558054e-001,1.825000e+000,,,,,,,,,,,,,,,,,,0,5.000000e+000,5.000000e-001,2,1,2.739048e-002,0,1,0,
1473084808.163,,5.000000e+003,1.093119e+001,1.252432e-003,0.000000e+000,-2.112617e-004,0.000000e+000,3,9.559358e-001,1.825000e+000,,,,,,,,,,,,,,,,,,0,5.000000e+000,5.000000e-001,2,1,1.776981e-002,0,1,0,
1473084836.346,,5.000000e+003,1.102238e+001,1.251411e-003,0.000000e+000,-2.205397e-004,0.000000e+000,3,9.556796e-001,1.825000e+000,,,,,,,,,,,,,,,,,,0,5.000000e+000,5.000000e-001,2,1,4.117966e-002,0,1,0,
1473084973.824,,3.000000e+003,1.095652e+001,1.238108e-003,0.000000e+000,2.463727e-004,0.000000e+000,3,9.566510e-001,1.825000e+000,,,,,,,,,,,,,,,,,,0,5.000000e+000,5.000000e-001,2,1,1.531029e-002,0,0,0,
1473085000.371,,3.000000e+003,1.093843e+001,1.237078e-003,0.000000e+000,-1.958341e-005,0.000000e+000,3,9.570283e-001,1.825000e+000,,,,,,,,,,,,,,,,,,0,5.000000e+000,5.000000e-001,2,1,1.470566e-003,0,0,0,
1473085140.069,,1.000000e+003,1.073545e+001,1.203404e-003,0.000000e+000,1.368767e-003,0.000000e+000,3,9.633927e-001,1.825000e+000,,,,,,,,,,,,,,,,,,0,5.000000e+000,5.000000e-001,2,1,3.259659e-003,0,1,0,
1473085167.997,,1.000000e+003,1.073802e+001,1.203835e-003,0.000000e+000,1.506108e-003,0.000000e+000,3,9.639559e-001,1.825000e+000,,,,,,,,,,,,,,,,,,0,5.000000e+000,5.000000e-001,2,1,7.179260e-003,0,1,0,
1473085312.689,,7.000000e+002,1.080855e+001,1.191142e-003,0.000000e+000,1.800069e-003,0.000000e+000,3,9.666827e-001,1.825000e+000,,,,,,,,,,,,,,,,,,0,5.000000e+000,5.000000e-001,2,1,6.939888e-003,0,1,0,
1473085336.186,,7.000000e+002,1.083955e+001,1.190558e-003,0.000000e+000,1.839952e-003,0.000000e+000,3,9.670622e-001,1.825000e+000,,,,,,,,,,,,,,,,,,0,5.000000e+000,5.000000e-001,2,1,1.091003e-002,0,0,0,
1473085472.880,,6.000000e+002,1.055274e+001,1.185332e-003,0.000000e+000,2.312361e-003,0.000000e+000,3,9.681296e-001,1.825000e+000,,,,,,,,,,,,,,,,,,0,5.000000e+000,5.000000e-001,2,1,2.062035e-002,0,0,0,
1473085502.309,,6.000000e+002,1.051311e+001,1.186125e-003,0.000000e+000,2.398619e-003,0.000000e+000,3,9.677658e-001,1.825000e+000,,,,,,,,,,,,,,,,,,0,5.000000e+000,5.000000e-001,2,1,1.360989e-002,0,0,0,
1473085637.998,,5.000000e+002,1.031814e+001,1.179674e-003,0.000000e+000,2.133834e-003,0.000000e+000,3,9.692838e-001,1.825000e+000,,,,,,,,,,,,,,,,,,0,5.000000e+000,5.000000e-001,2,1,6.669998e-003,0,1,0,
1473085663.986,,5.000000e+002,1.035509e+001,1.175977e-003,0.000000e+000,-1.150170e-003,0.000000e+000,3,9.728510e-001,1.825000e+000,,,,,,,,,,,,,,,,,,0,5.000000e+000,5.000000e-001,2,1,1.395035e-002,0,1,0,
1473085800.931,,4.000000e+002,1.046393e+001,1.169844e-003,0.000000e+000,2.547976e-003,0.000000e+000,3,9.721800e-001,1.825000e+000,,,,,,,,,,,,,,,,,,0,5.000000e+000,5.000000e-001,2,1,7.280350e-003,0,1,0,
1473085825.135,,4.000000e+002,1.050770e+001,1.169750e-003,0.000000e+000,2.582036e-003,0.000000e+000,3,9.722052e-001,1.825000e+000,,,,,,,,,,,,,,,,,,0,5.000000e+000,5.000000e-001,2,1,1.412964e-002,0,0,0,
1473085958.385,,3.000000e+002,1.013002e+001,1.157589e-003,0.000000e+000,2.887549e-003,0.000000e+000,3,9.750292e-001,1.825000e+000,,,,,,,,,,,,,,,,,,0,5.000000e+000,5.000000e-001,2,1,3.660965e-002,0,0,0,
1473085984.814,,3.000000e+002,1.003924e+001,1.160449e-003,0.000000e+000,3.249753e-003,0.000000e+000,3,9.742535e-001,1.825000e+000,,,,,,,,,,,,,,,,,,0,5.000000e+000,5.000000e-001,2,1,3.312016e-002,0,0,0,
1473086117.009,,2.000000e+002,9.913124e+000,1.139365e-003,0.000000e+000,3.683817e-003,0.000000e+000,3,9.773269e-001,1.825000e+000,,,,,,,,,,,,,,,,,,0,5.000000e+000,5.000000e-001,2,1,6.559372e-003,0,1,0,
1473086142.451,,2.000000e+002,9.942590e+000,1.140235e-003,0.000000e+000,3.284119e-003,0.000000e+000,3,9.773782e-001,1.825000e+000,,,,,,,,,,,,,,,,,,0,5.000000e+000,5.000000e-001,2,1,6.322861e-003,0,1,0,
1473086263.889,,1.800000e+002,9.926807e+000,1.135207e-003,0.000000e+000,3.173086e-003,0.000000e+000,3,9.777080e-001,1.825000e+000,,,,,,,,,,,,,,,,,,0,5.000000e+000,5.000000e-001,2,1,5.464554e-004,0,1,0,
1473086288.781,,1.800000e+002,9.942591e+000,1.134899e-003,0.000000e+000,3.290767e-003,0.000000e+000,3,9.779319e-001,1.825000e+000,,,,,,,,,,,,,,,,,,0,5.000000e+000,5.000000e-001,2,1,8.249283e-004,0,1,0,
1473086407.594,,1.600000e+002,9.894709e+000,1.129101e-003,0.000000e+000,2.992607e-003,0.000000e+000,3,9.790465e-001,1.825000e+000,,,,,,,,,,,,,,,,,,0,5.000000e+000,5.000000e-001,2,1,1.360893e-003,0,0,0,
1473086432.812,,1.600000e+002,9.910801e+000,1.129135e-003,0.000000e+000,2.434784e-003,0.000000e+000,3,9.794499e-001,1.825000e+000,,,,,,,,,,,,,,,,,,0,5.000000e+000,5.000000e-001,2,1,1.365662e-003,0,0,0,
1473086561.751,,1.400000e+002,9.909435e+000,1.122487e-003,0.000000e+000,3.532823e-003,0.000000e+000,3,9.786968e-001,1.825000e+000,,,,,,,,,,,,,,,,,,0,5.000000e+000,5.000000e-001,2,1,6.827354e-003,0,1,0,
1473086588.230,,1.400000e+002,9.925986e+000,1.121794e-003,0.000000e+000,3.735202e-003,0.000000e+000,3,9.788026e-001,1.825000e+000,,,,,,,,,,,,,,,,,,0,5.000000e+000,5.000000e-001,2,1,6.576538e-003,0,1,0,
1473086709.725,,1.200000e+002,9.935173e+000,1.113203e-003,0.000000e+000,3.649501e-003,0.000000e+000,3,9.803391e-001,1.825000e+000,,,,,,,,,,,,,,,,,,0,5.000000e+000,5.000000e-001,2,1,5.214691e-003,0,1,0,
1473086734.659,,1.200000e+002,9.954287e+000,1.114072e-003,0.000000e+000,3.501750e-003,0.000000e+000,3,9.796832e-001,1.825000e+000,,,,,,,,,,,,,,,,,,0,5.000000e+000,5.000000e-001,2,1,3.857613e-003,0,1,0,
1473086863.789,,1.000000e+002,9.903976e+000,1.105451e-003,0.000000e+000,3.767719e-003,0.000000e+000,3,9.810830e-001,1.825000e+000,,,,,,,,,,,,,,,,,,0,5.000000e+000,5.000000e-001,2,1,7.365227e-003,0,0,0,
1473086889.325,,1.000000e+002,9.917635e+000,1.105526e-003,0.000000e+000,3.701234e-003,0.000000e+000,3,9.805564e-001,1.825000e+000,,,,,,,,,,,,,,,,,,0,5.000000e+000,5.000000e-001,2,1,1.914978e-003,0,0,0,
1473087009.267,,8.000000e+001,9.906979e+000,1.096010e-003,0.000000e+000,3.350027e-003,0.000000e+000,3,9.815037e-001,1.825000e+000,,,,,,,,,,,,,,,,,,0,5.000000e+000,5.000000e-001,2,1,6.824493e-003,0,0,0,
1473087034.980,,8.000000e+001,9.919277e+000,1.095918e-003,0.000000e+000,3.804420e-003,0.000000e+000,3,9.812546e-001,1.825000e+000,,,,,,,,,,,,,,,,,,0,5.000000e+000,5.000000e-001,2,1,7.934570e-003,0,1,0,
1473087156.168,,6.000000e+001,9.924205e+000,1.083282e-003,0.000000e+000,3.024642e-003,0.000000e+000,3,9.828771e-001,1.825000e+000,,,,,,,,,,,,,,,,,,0,5.000000e+000,5.000000e-001,2,1,6.299973e-003,0,1,0,
1473087181.598,,6.000000e+001,9.947680e+000,1.084076e-003,0.000000e+000,4.043998e-003,0.000000e+000,3,9.816537e-001,1.825000e+000,,,,,,,,,,,,,,,,,,0,5.000000e+000,5.000000e-001,2,1,6.052971e-003,0,1,0,
1473087311.290,,4.000000e+001,9.902475e+000,1.069513e-003,0.000000e+000,3.928367e-003,0.000000e+000,3,9.822975e-001,1.825000e+000,,,,,,,,,,,,,,,,,,0,5.000000e+000,5.000000e-001,2,1,2.181053e-003,0,0,0,
1473087335.754,,4.000000e+001,9.916677e+000,1.070517e-003,0.000000e+000,3.813083e-003,0.000000e+000,3,9.806422e-001,1.825000e+000,,,,,,,,,,,,,,,,,,0,5.000000e+000,5.000000e-001,2,1,5.464554e-004,0,0,0,
1473087463.193,,2.000000e+001,9.907660e+000,1.052409e-003,0.000000e+000,4.020340e-003,0.000000e+000,3,9.831299e-001,1.825000e+000,,,,,,,,,,,,,,,,,,0,5.000000e+000,5.000000e-001,2,1,3.275871e-003,0,1,0,
1473087487.933,,2.000000e+001,9.926537e+000,1.051444e-003,0.000000e+000,4.482850e-003,0.000000e+000,3,9.827749e-001,1.825000e+000,,,,,,,,,,,,,,,,,,0,5.000000e+000,5.000000e-001,2,1,1.260662e-002,0,1,0,
1473087609.838,,0.000000e+000,9.936411e+000,1.029658e-003,0.000000e+000,4.490992e-003,0.000000e+000,3,9.833651e-001,1.825000e+000,,,,,,,,,,,,,,,,,,0,5.000000e+000,5.000000e-001,2,1,9.884834e-003,0,1,0,
1473087633.919,,0.000000e+000,9.954702e+000,1.029132e-003,0.000000e+000,4.218577e-003,0.000000e+000,3,9.835612e-001,1.825000e+000,,,,,,,,,,,,,,,,,,0,5.000000e+000,5.000000e-001,2,1,7.992744e-003,0,1,0,
1473087755.653,,-2.000000e+001,9.929275e+000,9.990457e-004,0.000000e+000,4.180885e-003,0.000000e+000,3,9.847224e-001,1.825000e+000,,,,,,,,,,,,,,,,,,0,5.000000e+000,5.000000e-001,2,1,4.934311e-003,0,1,0,
1473087780.136,,-2.000000e+001,9.942314e+000,9.999083e-004,0.000000e+000,1.867743e-003,0.000000e+000,3,9.835732e-001,1.825000e+000,,,,,,,,,,,,,,,,,,0,5.000000e+000,5.000000e-001,2,1,1.923561e-003,0,0,0,
1473087900.123,,-4.000000e+001,9.916952e+000,9.571352e-004,0.000000e+000,4.732989e-003,0.000000e+000,3,9.845148e-001,1.825000e+000,,,,,,,,,,,,,,,,,,0,5.000000e+000,5.000000e-001,2,1,7.658005e-003,0,0,0,
1473087925.359,,-4.000000e+001,9.930508e+000,9.574419e-004,0.000000e+000,4.978405e-003,0.000000e+000,3,9.840915e-001,1.825000e+000,,,,,,,,,,,,,,,,,,0,5.000000e+000,5.000000e-001,2,1,2.746582e-004,0,0,0,
1473088053.308,,-6.000000e+001,9.919687e+000,8.789858e-004,0.000000e+000,5.062354e-003,0.000000e+000,3,9.853426e-001,1.825000e+000,,,,,,,,,,,,,,,,,,0,5.000000e+000,5.000000e-001,2,1,6.567955e-003,0,0,0,
1473088077.236,,-6.000000e+001,9.935721e+000,8.785233e-004,0.000000e+000,4.801817e-003,0.000000e+000,3,9.850738e-001,1.825000e+000,,,,,,,,,,,,,,,,,,0,5.000000e+000,5.000000e-001,2,1,4.667282e-003,0,1,0,
1473088215.687,,-8.000000e+001,9.940254e+000,3.659068e-004,0.000000e+000,7.178859e-003,0.000000e+000,3,9.848558e-001,1.825000e+000,,,,,,,,,,,,,,,,,,0,5.000000e+000,5.000000e-001,2,1,3.847122e-003,0,1,0,
1473088239.615,,-8.000000e+001,9.967260e+000,3.371845e-004,0.000000e+000,7.664338e-003,0.000000e+000,3,9.844357e-001,1.825000e+000,,,,,,,,,,,,,,,,,,0,5.000000e+000,5.000000e-001,2,1,1.657581e-002,0,1,0,
1473088374.430,,-1.000000e+002,9.912988e+000,-3.905015e-004,0.000000e+000,-3.492590e-004,0.000000e+000,3,9.732311e-001,1.825000e+000,,,,,,,,,,,,,,,,,,0,5.000000e+000,5.000000e-001,2,1,6.286621e-003,0,0,0,
1473088399.385,,-1.000000e+002,9.924205e+000,-3.960502e-004,0.000000e+000,8.064824e-004,0.000000e+000,3,9.713465e-001,1.825000e+000,,,,,,,,,,,,,,,,,,0,5.000000e+000,5.000000e-001,2,1,4.657745e-003,0,0,0,
1473088518.577,,-1.200000e+002,9.906569e+000,-5.236405e-004,0.000000e+000,2.014349e-003,0.000000e+000,3,9.738711e-001,1.825000e+000,,,,,,,,,,,,,,,,,,0,5.000000e+000,5.000000e-001,2,1,3.275871e-003,0,0,0,
1473088543.756,,-1.200000e+002,9.922287e+000,-5.266606e-004,0.000000e+000,2.010443e-003,0.000000e+000,3,9.743990e-001,1.825000e+000,,,,,,,,,,,,,,,,,,0,5.000000e+000,5.000000e-001,2,1,4.653931e-003,0,1,0,
1473088662.944,,-1.400000e+002,9.946029e+000,-6.073392e-004,0.000000e+000,1.464062e-003,0.000000e+000,3,9.743366e-001,1.825000e+000,,,,,,,,,,,,,,,,,,0,5.000000e+000,5.000000e-001,2,1,8.253098e-003,0,1,0,
1473088686.912,,-1.400000e+002,1.000771e+001,-6.101295e-004,0.000000e+000,8.174148e-004,0.000000e+000,3,9.730766e-001,1.825000e+000,,,,,,,,,,,,,,,,,,0,5.000000e+000,5.000000e-001,2,1,2.938843e-002,0,1,0,
1473088806.854,,-1.600000e+002,9.945911e+000,-6.775831e-004,0.000000e+000,2.551202e-003,0.000000e+000,3,9.730764e-001,1.825000e+000,,,,,,,,,,,,,,,,,,0,5.000000e+000,5.000000e-001,2,1,2.943516e-002,0,0,0,
1473088830.580,,-1.600000e+002,9.934623e+000,-6.796430e-004,0.000000e+000,2.373156e-003,0.000000e+000,3,9.731212e-001,1.825000e+000,,,,,,,,,,,,,,,,,,0,5.000000e+000,5.000000e-001,2,1,2.727509e-004,0,0,0,
1473088965.003,,-1.800000e+002,9.927629e+000,-7.333952e-004,0.000000e+000,1.769890e-003,0.000000e+000,3,9.749188e-001,1.825000e+000,,,,,,,,,,,,,,,,,,0,5.000000e+000,5.000000e-001,2,1,2.192497e-003,0,1,0,
1473088989.373,,-1.800000e+002,9.944515e+000,-7.354938e-004,0.000000e+000,2.348556e-003,0.000000e+000,3,9.744473e-001,1.825000e+000,,,,,,,,,,,,,,,,,,0,5.000000e+000,5.000000e-001,2,1,3.575325e-003,0,1,0,
1473089109.423,,-2.000000e+002,9.976242e+000,-7.808722e-004,0.000000e+000,2.441557e-003,0.000000e+000,3,9.742491e-001,1.825000e+000,,,,,,,,,,,,,,,,,,0,5.000000e+000,5.000000e-001,2,1,1.079273e-002,0,1,0,
1473089132.900,,-2.000000e+002,1.005237e+001,-7.842443e-004,0.000000e+000,2.092721e-003,0.000000e+000,3,9.743873e-001,1.825000e+000,,,,,,,,,,,,,,,,,,0,5.000000e+000,5.000000e-001,2,1,3.767014e-002,0,1,0,
1473089265.339,,-3.000000e+002,1.006649e+001,-9.508688e-004,0.000000e+000,2.043109e-003,0.000000e+000,3,9.724125e-001,1.825000e+000,,,,,,,,,,,,,,,,,,0,5.000000e+000,5.000000e-001,2,1,1.610947e-002,0,0,0,
1473089289.517,,-3.000000e+002,1.006066e+001,-9.530613e-004,0.000000e+000,2.446229e-003,0.000000e+000,3,9.719454e-001,1.825000e+000,,,,,,,,,,,,,,,,,,0,5.000000e+000,5.000000e-001,2,1,3.859520e-003,0,0,0,
1473089422.396,,-4.000000e+002,9.995234e+000,-1.036476e-003,0.000000e+000,2.471894e-003,0.000000e+000,3,9.705774e-001,1.825000e+000,,,,,,,,,,,,,,,,,,0,5.000000e+000,5.000000e-001,2,1,4.444122e-003,0,1,0,
1473089445.932,,-4.000000e+002,1.001390e+001,-1.037586e-003,0.000000e+000,2.508961e-003,0.000000e+000,3,9.702907e-001,1.825000e+000,,,,,,,,,,,,,,,,,,0,5.000000e+000,5.000000e-001,2,1,1.851082e-002,0,1,0,
1473089581.171,,-5.000000e+002,1.020777e+001,-1.086149e-003,0.000000e+000,2.039971e-003,0.000000e+000,3,9.686971e-001,1.825000e+000,,,,,,,,,,,,,,,,,,0,5.000000e+000,5.000000e-001,2,1,2.505970e-002,0,1,0,
1473089605.879,,-5.000000e+002,1.028755e+001,-1.087835e-003,0.000000e+000,2.181898e-003,0.000000e+000,3,9.687634e-001,1.825000e+000,,,,,,,,,,,,,,,,,,0,5.000000e+000,5.000000e-001,2,1,4.136086e-002,0,1,0,
1473089738.865,,-6.000000e+002,1.031557e+001,-1.118852e-003,0.000000e+000,2.468515e-003,0.000000e+000,3,9.668324e-001,1.825000e+000,,,,,,,,,,,,,,,,,,0,5.000000e+000,5.000000e-001,2,1,1.307011e-002,0,0,0,
1473089765.294,,-6.000000e+002,1.031433e+001,-1.119372e-003,0.000000e+000,1.823548e-003,0.000000e+000,3,9.671014e-001,1.825000e+000,,,,,,,,,,,,,,,,,,0,5.000000e+000,5.000000e-001,2,1,2.550125e-003,0,0,0,
1473089891.533,,-7.000000e+002,1.025996e+001,-1.138179e-003,0.000000e+000,1.869716e-003,0.000000e+000,3,9.657461e-001,1.825000e+000,,,,,,,,,,,,,,,,,,0,5.000000e+000,5.000000e-001,2,1,6.149292e-003,0,1,0,
1473089918.009,,-7.000000e+002,1.031713e+001,-1.138923e-003,0.000000e+000,1.826584e-003,0.000000e+000,3,9.657534e-001,1.825000e+000,,,,,,,,,,,,,,,,,,0,5.000000e+000,5.000000e-001,2,1,1.868057e-002,0,1,0,
1473090046.200,,-1.000000e+003,1.049434e+001,-1.170441e-003,0.000000e+000,1.531233e-003,0.000000e+000,3,9.630685e-001,1.825000e+000,,,,,,,,,,,,,,,,,,0,5.000000e+000,5.000000e-001,2,1,2.801037e-002,0,1,0,
1473090073.402,,-1.000000e+003,1.060046e+001,-1.129959e-003,0.000000e+000,2.972976e-002,0.000000e+000,3,9.282387e-001,1.825000e+000,,,,,,,,,,,,,,,,,,0,5.000000e+000,5.000000e-001,2,1,4.096985e-002,0,1,0,
1473090211.393,,-3.000000e+003,1.064082e+001,-1.232583e-003,0.000000e+000,-1.014668e-005,0.000000e+000,3,9.559088e-001,1.825000e+000,,,,,,,,,,,,,,,,,,0,5.000000e+000,5.000000e-001,2,1,8.130074e-003,0,0,0,
1473090236.883,,-3.000000e+003,1.065924e+001,-1.231825e-003,0.000000e+000,4.529308e-004,0.000000e+000,3,9.565498e-001,1.825000e+000,,,,,,,,,,,,,,,,,,0,5.000000e+000,5.000000e-001,2,1,1.158905e-002,0,0,0,
1473090375.594,,-5.000000e+003,1.067535e+001,-1.249906e-003,0.000000e+000,1.403523e-004,0.000000e+000,3,9.558724e-001,1.825000e+000,,,,,,,,,,,,,,,,,,0,5.000000e+000,5.000000e-001,2,1,8.000374e-003,0,1,0,
1473090400.804,,-5.000000e+003,1.071108e+001,-1.249707e-003,0.000000e+000,3.283953e-004,0.000000e+000,3,9.557444e-001,1.825000e+000,,,,,,,,,,,,,,,,,,0,5.000000e+000,5.000000e-001,2,1,3.658009e-002,0,1,0,
1473090539.767,,-7.000000e+003,1.121035e+001,-1.258787e-003,0.000000e+000,9.694508e-004,0.000000e+000,3,9.551315e-001,1.825000e+000,,,,,,,,,,,,,,,,,,0,5.000000e+000,5.000000e-001,2,1,4.294968e-002,0,1,0,
1473090565.196,,-7.000000e+003,1.135184e+001,-1.257720e-003,0.000000e+000,2.487875e-004,0.000000e+000,3,9.552429e-001,1.825000e+000,,,,,,,,,,,,,,,,,,0,5.000000e+000,5.000000e-001,2,1,6.544971e-002,0,1,0,
1473090709.136,,-9.000000e+003,1.190397e+001,-1.261296e-003,0.000000e+000,5.605774e-004,0.000000e+000,3,9.553741e-001,1.825000e+000,,,,,,,,,,,,,,,,,,0,5.000000e+000,5.000000e-001,2,1,3.117085e-002,0,0,0,
1473090734.876,,-9.000000e+003,1.204555e+001,-1.260623e-003,0.000000e+000,5.576328e-004,0.000000e+000,3,9.553463e-001,1.825000e+000,,,,,,,,,,,,,,,,,,0,5.000000e+000,5.000000e-001,2,1,5.526066e-002,0,0,0,
1473090869.070,,-1.000000e+004,1.252287e+001,-1.258328e-003,0.000000e+000,2.060049e-004,0.000000e+000,3,9.546520e-001,1.825000e+000,,,,,,,,,,,,,,,,,,0,5.000000e+000,5.000000e-001,2,1,7.249832e-003,0,0,0,
1473090899.530,,-1.000000e+004,1.259597e+001,-1.260668e-003,0.000000e+000,8.193158e-004,0.000000e+000,3,9.551725e-001,1.825000e+000,,,,,,,,,,,,,,,,,,0,5.000000e+000,5.000000e-001,2,1,2.935028e-002,0,1,0,
1473091067.973,,-2.000000e+004,1.339210e+001,-1.271099e-003,0.000000e+000,1.447669e-003,0.000000e+000,3,9.549717e-001,1.825000e+000,,,,,,,,,,,,,,,,,,0,5.000000e+000,5.000000e-001,2,1,3.525066e-002,0,1,0,
1473091092.652,,-2.000000e+004,1.349959e+001,-1.271608e-003,0.000000e+000,2.105109e-003,0.000000e+000,3,9.549232e-001,1.825000e+000,,,,,,,,,,,,,,,,,,0,5.000000e+000,5.000000e-001,2,1,3.787994e-002,0,1,0,
1473091261.635,,-3.000000e+004,1.369456e+001,-1.276959e-003,0.000000e+000,2.297117e-003,0.000000e+000,3,9.549010e-001,1.825000e+000,,,,,,,,,,,,,,,,,,0,5.000000e+000,5.000000e-001,2,1,2.467918e-002,0,0,0,
1473091288.391,,-3.000000e+004,1.377717e+001,-1.276545e-003,0.000000e+000,2.281330e-003,0.000000e+000,3,9.546856e-001,1.825000e+000,,,,,,,,,,,,,,,,,,0,5.000000e+000,5.000000e-001,2,1,3.085995e-002,0,0,0,
1473091463.339,,-4.000000e+004,1.393743e+001,-1.277837e-003,0.000000e+000,2.853914e-003,0.000000e+000,3,9.542385e-001,1.825000e+000,,,,,,,,,,,,,,,,,,0,5.000000e+000,5.000000e-001,2,1,1.817036e-002,0,1,0,
1473091489.767,,-4.000000e+004,1.403137e+001,-1.279077e-003,0.000000e+000,3.144536e-003,0.000000e+000,3,9.545630e-001,1.825000e+000,,,,,,,,,,,,,,,,,,0,5.000000e+000,5.000000e-001,2,1,4.311943e-002,0,1,0,
1473091669.990,,-5.000000e+004,1.410145e+001,-1.282113e-003,0.000000e+000,2.774593e-003,0.000000e+000,3,9.525492e-001,1.825000e+000,,,,,,,,,,,,,,,,,,0,5.000000e+000,5.000000e-001,2,1,3.388977e-002,0,1,0,
1473091694.919,,-5.000000e+004,1.424443e+001,-1.279148e-003,0.000000e+000,2.279356e-003,0.000000e+000,3,9.548194e-001,1.825000e+000,,,,,,,,,,,,,,,,,,0,5.000000e+000,5.000000e-001,2,1,5.984974e-002,0,1,0,
1473091881.392,,-6.000000e+004,1.491721e+001,-1.271959e-003,0.000000e+000,4.194805e-003,0.000000e+000,3,9.533206e-001,1.825000e+000,,,,,,,,,,,,,,,,,,0,5.000000e+000,5.000000e-001,2,1,3.851986e-002,0,0,0,
1473091906.820,,-6.000000e+004,1.504840e+001,-1.270813e-003,0.000000e+000,4.236596e-003,0.000000e+000,3,9.531168e-001,1.825000e+000,,,,,,,,,,,,,,,,,,0,5.000000e+000,5.000000e-001,2,1,3.626060e-002,0,0,0,
1473092087.518,,-7.000000e+004,1.571962e+001,-1.264716e-003,0.000000e+000,4.897229e-003,0.000000e+000,3,9.516617e-001,1.825000e+000,,,,,,,,,,,,,,,,,,0,5.000000e+000,5.000000e-001,2,1,5.634022e-002,0,1,0,
1473092113.697,,-7.000000e+004,1.587167e+001,-1.263803e-003,0.000000e+000,5.809245e-003,0.000000e+000,3,9.520860e-001,1.825000e+000,,,,,,,,,,,,,,,,,,0,5.000000e+000,5.000000e-001,2,1,5.674934e-002,0,1,0,
1473092301.932,,-6.000000e+004,1.623323e+001,-1.263593e-003,0.000000e+000,3.921830e-003,0.000000e+000,3,9.531518e-001,1.825000e+000,,,,,,,,,,,,,,,,,,0,5.000000e+000,5.000000e-001,2,1,2.075005e-002,0,0,0,
1473092328.110,,-6.000000e+004,1.629789e+001,-1.259909e-003,0.000000e+000,3.391214e-003,0.000000e+000,3,9.518111e-001,1.825000e+000,,,,,,,,,,,,,,,,,,0,5.000000e+000,5.000000e-001,2,1,2.091026e-002,0,0,0,
1473092507.559,,-5.000000e+004,1.644817e+001,-1.262727e-003,0.000000e+000,3.052132e-003,0.000000e+000,3,9.534872e-001,1.825000e+000,,,,,,,,,,,,,,,,,,0,5.000000e+000,5.000000e-001,2,1,7.339478e-003,0,0,0,
1473092538.059,,-5.000000e+004,1.650678e+001,-1.262924e-003,0.000000e+000,3.408203e-003,0.000000e+000,3,9.528821e-001,1.825000e+000,,,,,,,,,,,,,,,,,,0,5.000000e+000,5.000000e-001,2,1,2.293015e-002,0,1,0,
1473092721.267,,-4.000000e+004,1.737934e+001,-1.255434e-003,0.000000e+000,2.687779e-003,0.000000e+000,3,9.537591e-001,1.825000e+000,,,,,,,,,,,,,,,,,,0,5.000000e+000,5.000000e-001,2,1,7.538986e-002,0,1,0,
1473092749.196,,-4.000000e+004,1.757405e+001,-1.253540e-003,0.000000e+000,2.482103e-003,0.000000e+000,3,9.529682e-001,1.825000e+000,,,,,,,,,,,,,,,,,,0,5.000000e+000,5.000000e-001,2,1,8.209038e-002,0,1,0,
1473092928.639,,-3.000000e+004,1.849107e+001,-1.241409e-003,0.000000e+000,3.731411e-003,0.000000e+000,3,9.534543e-001,1.825000e+000,,,,,,,,,,,,,,,,,,0,5.000000e+000,5.000000e-001,2,1,5.558968e-002,0,1,0,
1473092957.290,,-3.000000e+004,1.866169e+001,-1.242702e-003,0.000000e+000,1.594175e-003,0.000000e+000,3,9.518216e-001,1.825000e+000,,,,,,,,,,,,,,,,,,0,5.000000e+000,5.000000e-001,2,1,5.566978e-002,0,1,0,
1473093129.915,,-2.000000e+004,1.938636e+001,-1.229730e-003,0.000000e+000,1.074511e-003,0.000000e+000,3,9.536861e-001,1.825000e+000,,,,,,,,,,,,,,,,,,0,5.000000e+000,5.000000e-001,2,1,5.283165e-002,0,0,0,
1473093155.781,,-2.000000e+004,1.948180e+001,-1.229427e-003,0.000000e+000,1.549091e-003,0.000000e+000,3,9.542901e-001,1.825000e+000,,,,,,,,,,,,,,,,,,0,5.000000e+000,5.000000e-001,2,1,2.873039e-002,0,0,0,
1473093319.350,,-1.000000e+004,2.006181e+001,-1.208834e-003,0.000000e+000,3.546895e-004,0.000000e+000,3,9.543489e-001,1.825000e+000,,,,,,,,,,,,,,,,,,0,5.000000e+000,5.000000e-001,2,1,4.561043e-002,0,0,0,
1473093344.603,,-1.000000e+004,2.016385e+001,-1.208069e-003,0.000000e+000,9.677242e-004,0.000000e+000,3,9.535348e-001,1.825000e+000,,,,,,,,,,,,,,,,,,0,5.000000e+000,5.000000e-001,2,1,3.728867e-002,0,0,0,
1473093481.793,,-9.000000e+003,2.058035e+001,-1.201611e-003,0.000000e+000,9.755294e-004,0.000000e+000,3,9.536836e-001,1.825000e+000,,,,,,,,,,,,,,,,,,0,5.000000e+000,5.000000e-001,2,1,3.252983e-002,0,0,0,
1473093508.271,,-9.000000e+003,2.067004e+001,-1.200965e-003,0.000000e+000,8.671281e-004,0.000000e+000,3,9.540640e-001,1.825000e+000,,,,,,,,,,,,,,,,,,0,5.000000e+000,5.000000e-001,2,1,3.912926e-002,0,0,0,
1473093646.715,,-7.000000e+003,2.104397e+001,-1.191708e-003,0.000000e+000,9.295570e-004,0.000000e+000,3,9.536487e-001,1.825000e+000,,,,,,,,,,,,,,,,,,0,5.000000e+000,5.000000e-001,2,1,2.682114e-002,0,0,0,
1473093673.428,,-7.000000e+003,2.112838e+001,-1.191136e-003,0.000000e+000,9.554997e-004,0.000000e+000,3,9.536711e-001,1.825000e+000,,,,,,,,,,,,,,,,,,0,5.000000e+000,5.000000e-001,2,1,2.223015e-002,0,0,0,
1473093811.420,,-5.000000e+003,2.160743e+001,-1.177852e-003,0.000000e+000,6.074450e-004,0.000000e+000,3,9.543051e-001,1.825000e+000,,,,,,,,,,,,,,,,,,0,5.000000e+000,5.000000e-001,2,1,5.518913e-002,0,1,0,
1473093833.347,,-5.000000e+003,2.172500e+001,-1.176925e-003,0.000000e+000,1.002427e-003,0.000000e+000,3,9.537827e-001,1.825000e+000,,,,,,,,,,,,,,,,,,0,5.000000e+000,5.000000e-001,2,1,5.260086e-002,0,1,0,
1473093966.093,,-3.000000e+003,2.236369e+001,-1.157414e-003,0.000000e+000,1.485449e-003,0.000000e+000,3,9.545633e-001,1.825000e+000,,,,,,,,,,,,,,,,,,0,5.000000e+000,5.000000e-001,2,1,3.417969e-002,0,1,0,
1473093994.286,,-3.000000e+003,2.250159e+001,-1.155811e-003,0.000000e+000,1.258621e-003,0.000000e+000,3,9.546201e-001,1.825000e+000,,,,,,,,,,,,,,,,,,0,5.000000e+000,5.000000e-001,2,1,4.747009e-002,0,1,0,
1473094129.725,,-1.000000e+003,2.298940e+001,-1.114221e-003,0.000000e+000,3.388748e-003,0.000000e+000,3,9.619149e-001,1.825000e+000,,,,,,,,,,,,,,,,,,0,5.000000e+000,5.000000e-001,2,1,2.615929e-002,0,1,0,
1473094157.430,,-1.000000e+003,2.310202e+001,-1.114684e-003,0.000000e+000,2.587098e-003,0.000000e+000,3,9.618313e-001,1.825000e+000,,,,,,,,,,,,,,,,,,0,5.000000e+000,5.000000e-001,2,1,5.994987e-002,0,0,0,
1473094299.434,,-7.000000e+002,2.344843e+001,-1.099870e-003,0.000000e+000,3.108453e-003,0.000000e+000,3,9.648630e-001,1.825000e+000,,,,,,,,,,,,,,,,,,0,5.000000e+000,5.000000e-001,2,1,2.571106e-002,0,0,0,
1473094328.880,,-7.000000e+002,2.352765e+001,-1.097359e-003,0.000000e+000,3.312859e-003,0.000000e+000,3,9.651786e-001,1.825000e+000,,,,,,,,,,,,,,,,,,0,5.000000e+000,5.000000e-001,2,1,3.695869e-002,0,0,0,
1473094461.073,,-6.000000e+002,2.388656e+001,-1.089126e-003,0.000000e+000,3.510252e-003,0.000000e+000,3,9.669130e-001,1.825000e+000,,,,,,,,,,,,,,,,,,0,5.000000e+000,5.000000e-001,2,1,2.359009e-002,0,0,0,
1473094487.041,,-6.000000e+002,2.395906e+001,-1.088008e-003,0.000000e+000,3.642508e-003,0.000000e+000,3,9.667999e-001,1.825000e+000,,,,,,,,,,,,,,,,,,0,5.000000e+000,5.000000e-001,2,1,3.137016e-002,0,0,0,
1473094621.268,,-5.000000e+002,2.425595e+001,-1.076371e-003,0.000000e+000,4.375815e-003,0.000000e+000,3,9.680476e-001,1.825000e+000,,,,,,,,,,,,,,,,,,0,5.000000e+000,5.000000e-001,2,1,2.350044e-002,0,0,0,
1473094650.947,,-5.000000e+002,2.433490e+001,-1.076280e-003,0.000000e+000,4.283433e-003,0.000000e+000,3,9.680279e-001,1.825000e+000,,,,,,,,,,,,,,,,,,0,5.000000e+000,5.000000e-001,2,1,2.915001e-002,0,0,0,
1473094787.391,,-4.000000e+002,2.464793e+001,-1.063300e-003,0.000000e+000,4.180579e-003,0.000000e+000,3,9.711181e-001,1.825000e+000,,,,,,,,,,,,,,,,,,0,5.000000e+000,5.000000e-001,2,1,1.936913e-002,0,1,0,
1473094818.569,,-4.000000e+002,2.475777e+001,-1.062075e-003,0.000000e+000,4.442982e-003,0.000000e+000,3,9.707305e-001,1.825000e+000,,,,,,,,,,,,,,,,,,0,5.000000e+000,5.000000e-001,2,1,3.499985e-002,0,1,0,
1473094946.813,,-3.000000e+002,2.523767e+001,-1.042794e-003,0.000000e+000,4.981385e-003,0.000000e+000,3,9.735500e-001,1.825000e+000,,,,,,,,,,,,,,,,,,0,5.000000e+000,5.000000e-001,2,1,3.628922e-002,0,1,0,
1473094972.741,,-3.000000e+002,2.534317e+001,-1.041622e-003,0.000000e+000,4.963169e-003,0.000000e+000,3,9.732016e-001,1.825000e+000,,,,,,,,,,,,,,,,,,0,5.000000e+000,5.000000e-001,2,1,3.912926e-002,0,1,0,
1473095105.742,,-2.000000e+002,2.579158e+001,-1.012986e-003,0.000000e+000,5.317328e-003,0.000000e+000,3,9.768226e-001,1.825000e+000,,,,,,,,,,,,,,,,,,0,5.000000e+000,5.000000e-001,2,1,2.374840e-002,0,1,0,
1473095132.945,,-2.000000e+002,2.587449e+001,-1.013021e-003,0.000000e+000,5.759899e-003,0.000000e+000,3,9.760757e-001,1.825000e+000,,,,,,,,,,,,,,,,,,0,5.000000e+000,5.000000e-001,2,1,3.981018e-002,0,1,0,
1473095261.384,,-1.800000e+002,2.615601e+001,-1.002447e-003,0.000000e+000,5.840314e-003,0.000000e+000,3,9.769568e-001,1.825000e+000,,,,,,,,,,,,,,,,,,0,5.000000e+000,5.000000e-001,2,1,1.895905e-002,0,0,0,
1473095287.853,,-1.800000e+002,2.622253e+001,-1.002434e-003,0.000000e+000,4.660543e-003,0.000000e+000,3,9.779519e-001,1.825000e+000,,,,,,,,,,,,,,,,,,0,5.000000e+000,5.000000e-001,2,1,2.359009e-002,0,0,0,
1473095412.095,,-1.600000e+002,2.649742e+001,-9.912963e-004,0.000000e+000,6.079618e-003,0.000000e+000,3,9.776093e-001,1.825000e+000,,,,,,,,,,,,,,,,,,0,5.000000e+000,5.000000e-001,2,1,2.590942e-002,0,0,0,
1473095437.531,,-1.600000e+002,2.655629e+001,-9.912377e-004,0.000000e+000,5.769065e-003,0.000000e+000,3,9.777318e-001,1.825000e+000,,,,,,,,,,,,,,,,,,0,5.000000e+000,5.000000e-001,2,1,3.066063e-002,0,0,0,
1473095558.518,,-1.400000e+002,2.680305e+001,-9.812464e-004,0.000000e+000,6.558484e-003,0.000000e+000,3,9.776205e-001,1.825000e+000,,,,,,,,,,,,,,,,,,0,5.000000e+000,5.000000e-001,2,1,1.986122e-002,0,0,0,
1473095583.947,,-1.400000e+002,2.685563e+001,-9.804709e-004,0.000000e+000,5.643968e-003,0.000000e+000,3,9.788350e-001,1.825000e+000,,,,,,,,,,,,,,,,,,0,5.000000e+000,5.000000e-001,2,1,2.278900e-002,0,0,0,
1473095707.934,,-1.200000e+002,2.709787e+001,-9.687669e-004,0.000000e+000,6.532672e-003,0.000000e+000,3,9.788956e-001,1.825000e+000,,,,,,,,,,,,,,,,,,0,5.000000e+000,5.000000e-001,2,1,2.124977e-002,0,0,0,
1473095736.420,,-1.200000e+002,2.715448e+001,-9.679675e-004,0.000000e+000,5.849857e-003,0.000000e+000,3,9.792701e-001,1.825000e+000,,,,,,,,,,,,,,,,,,0,5.000000e+000,5.000000e-001,2,1,2.036858e-002,0,1,0,
1473095865.920,,-1.000000e+002,2.749196e+001,-9.522890e-004,0.000000e+000,6.372129e-003,0.000000e+000,3,9.796773e-001,1.825000e+000,,,,,,,,,,,,,,,,,,0,5.000000e+000,5.000000e-001,2,1,2.680969e-002,0,1,0,
1473095893.123,,-1.000000e+002,2.758308e+001,-9.527180e-004,0.000000e+000,6.334020e-003,0.000000e+000,3,9.791605e-001,1.825000e+000,,,,,,,,,,,,,,,,,,0,5.000000e+000,5.000000e-001,2,1,3.397179e-002,0,1,0,
1473096013.065,,-8.000000e+001,2.796519e+001,-9.344227e-004,0.000000e+000,6.751308e-003,0.000000e+000,3,9.803622e-001,1.825000e+000,,,,,,,,,,,,,,,,,,0,5.000000e+000,5.000000e-001,2,1,2.972984e-002,0,1,0,
1473096036.723,,-8.000000e+001,2.805418e+001,-9.339899e-004,0.000000e+000,6.606979e-003,0.000000e+000,3,9.804029e-001,1.825000e+000,,,,,,,,,,,,,,,,,,0,5.000000e+000,5.000000e-001,2,1,2.477074e-002,0,1,0,
1473096165.020,,-6.000000e+001,2.836966e+001,-9.144598e-004,0.000000e+000,6.851767e-003,0.000000e+000,3,9.812543e-001,1.825000e+000,,,,,,,,,,,,,,,,,,0,5.000000e+000,5.000000e-001,2,1,2.635002e-002,0,1,0,
1473096189.752,,-6.000000e+001,2.844312e+001,-9.135430e-004,0.000000e+000,6.602168e-003,0.000000e+000,3,9.812382e-001,1.825000e+000,,,,,,,,,,,,,,,,,,0,5.000000e+000,5.000000e-001,2,1,2.330971e-002,0,1,0,
1473096318.006,,-4.000000e+001,2.867049e+001,-8.909798e-004,0.000000e+000,6.861873e-003,0.000000e+000,3,9.823510e-001,1.825000e+000,,,,,,,,,,,,,,,,,,0,5.000000e+000,5.000000e-001,2,1,1.506042e-002,0,0,0,
1473096343.488,,-4.000000e+001,2.872491e+001,-8.898792e-004,0.000000e+000,6.834347e-003,0.000000e+000,3,9.819708e-001,1.825000e+000,,,,,,,,,,,,,,,,,,0,5.000000e+000,5.000000e-001,2,1,2.051163e-002,0,0,0,
1473096465.676,,-2.000000e+001,2.896321e+001,-8.626621e-004,0.000000e+000,7.212340e-003,0.000000e+000,3,9.827107e-001,1.825000e+000,,,,,,,,,,,,,,,,,,0,5.000000e+000,5.000000e-001,2,1,1.864052e-002,0,0,0,
1473096490.620,,-2.000000e+001,2.901870e+001,-8.616230e-004,0.000000e+000,6.442834e-003,0.000000e+000,3,9.829428e-001,1.825000e+000,,,,,,,,,,,,,,,,,,0,5.000000e+000,5.000000e-001,2,1,2.421951e-002,0,0,0,
1473096611.813,,0.000000e+000,2.923097e+001,-8.257714e-004,0.000000e+000,6.537925e-003,0.000000e+000,3,9.836406e-001,1.825000e+000,,,,,,,,,,,,,,,,,,0,5.000000e+000,5.000000e-001,2,1,1.673889e-002,0,0,0,
1473096637.240,,0.000000e+000,2.928128e+001,-8.239230e-004,0.000000e+000,6.913158e-003,0.000000e+000,3,9.838721e-001,1.825000e+000,,,,,,,,,,,,,,,,,,0,5.000000e+000,5.000000e-001,2,1,1.679039e-002,0,0,0,
1473096758.694,,2.000000e+001,2.948308e+001,-7.667830e-004,0.000000e+000,7.761451e-003,0.000000e+000,3,9.846656e-001,1.825000e+000,,,,,,,,,,,,,,,,,,0,5.000000e+000,5.000000e-001,2,1,1.475906e-002,0,0,0,
1473096784.123,,2.000000e+001,2.952854e+001,-7.665677e-004,0.000000e+000,6.618081e-003,0.000000e+000,3,9.848188e-001,1.825000e+000,,,,,,,,,,,,,,,,,,0,5.000000e+000,5.000000e-001,2,1,2.161980e-002,0,1,0,
1473096909.329,,4.000000e+001,2.978271e+001,-6.493722e-004,0.000000e+000,6.964635e-003,0.000000e+000,3,9.856421e-001,1.825000e+000,,,,,,,,,,,,,,,,,,0,5.000000e+000,5.000000e-001,2,1,2.083015e-002,0,1,0,
1473096934.461,,4.000000e+001,2.985810e+001,-6.442039e-004,0.000000e+000,8.005283e-003,0.000000e+000,3,9.850575e-001,1.825000e+000,,,,,,,,,,,,,,,,,,0,5.000000e+000,5.000000e-001,2,1,2.092171e-002,0,1,0,
1473097061.780,,6.000000e+001,3.019816e+001,4.552856e-004,0.000000e+000,4.665039e-003,0.000000e+000,3,9.781120e-001,1.825000e+000,,,,,,,,,,,,,,,,,,0,5.000000e+000,5.000000e-001,2,1,3.326035e-002,0,1,0,
1473097215.224,,6.000000e+001,3.058842e+001,4.914587e-004,0.000000e+000,5.219842e-003,0.000000e+000,3,9.791751e-001,1.825000e+000,,,,,,,,,,,,,,,,,,0,5.000000e+000,5.000000e-001,2,1,2.800941e-002,0,1,0,
1473097335.485,,8.000000e+001,3.077578e+001,6.921938e-004,0.000000e+000,5.920539e-003,0.000000e+000,3,9.796685e-001,1.825000e+000,,,,,,,,,,,,,,,,,,0,5.000000e+000,5.000000e-001,2,1,8.630753e-003,0,0,0,
1473097359.235,,8.000000e+001,3.081587e+001,6.959993e-004,0.000000e+000,7.076511e-003,0.000000e+000,3,9.781117e-001,1.825000e+000,,,,,,,,,,,,,,,,,,0,5.000000e+000,5.000000e-001,2,1,1.976013e-002,0,0,0,
1473097481.427,,1.000000e+002,3.102154e+001,7.774203e-004,0.000000e+000,7.139531e-003,0.000000e+000,3,9.778612e-001,1.825000e+000,,,,,,,,,,,,,,,,,,0,5.000000e+000,5.000000e-001,2,1,1.375961e-002,0,0,0,
1473097506.605,,1.000000e+002,3.107290e+001,7.823874e-004,0.000000e+000,6.438826e-003,0.000000e+000,3,9.788557e-001,1.825000e+000,,,,,,,,,,,,,,,,,,0,5.000000e+000,5.000000e-001,2,1,1.379967e-002,0,0,0,
1473097632.296,,1.200000e+002,3.126472e+001,8.311187e-004,0.000000e+000,6.372954e-003,0.000000e+000,3,9.784682e-001,1.825000e+000,,,,,,,,,,,,,,,,,,0,5.000000e+000,5.000000e-001,2,1,1.651001e-002,0,0,0,
1473097658.474,,1.200000e+002,3.130858e+001,8.332970e-004,0.000000e+000,6.440331e-003,0.000000e+000,3,9.783463e-001,1.825000e+000,,,,,,,,,,,,,,,,,,0,5.000000e+000,5.000000e-001,2,1,1.527977e-002,0,0,0,
1473097785.668,,1.400000e+002,3.149033e+001,8.650718e-004,0.000000e+000,6.753797e-003,0.000000e+000,3,9.774889e-001,1.825000e+000,,,,,,,,,,,,,,,,,,0,5.000000e+000,5.000000e-001,2,1,1.029968e-002,0,1,0,
1473097822.370,,1.400000e+002,3.155093e+001,8.660323e-004,0.000000e+000,6.458027e-003,0.000000e+000,3,9.777210e-001,1.825000e+000,,,,,,,,,,,,,,,,,,0,5.000000e+000,5.000000e-001,2,1,1.808167e-002,0,1,0,
1473097945.562,,1.600000e+002,3.181591e+001,8.875547e-004,0.000000e+000,6.482289e-003,0.000000e+000,3,9.768762e-001,1.825000e+000,,,,,,,,,,,,,,,,,,0,5.000000e+000,5.000000e-001,2,1,2.757072e-002,0,1,0,
1473097972.172,,1.600000e+002,3.188892e+001,8.873407e-004,0.000000e+000,6.357214e-003,0.000000e+000,3,9.770684e-001,1.825000e+000,,,,,,,,,,,,,,,,,,0,5.000000e+000,5.000000e-001,2,1,2.636909e-002,0,1,0,
1473098100.701,,1.800000e+002,3.219829e+001,9.021448e-004,0.000000e+000,6.471471e-003,0.000000e+000,3,9.764420e-001,1.825000e+000,,,,,,,,,,,,,,,,,,0,5.000000e+000,5.000000e-001,2,1,2.820206e-002,0,1,0,
1473098125.063,,1.800000e+002,3.226018e+001,9.025943e-004,0.000000e+000,6.468555e-003,0.000000e+000,3,9.763485e-001,1.825000e+000,,,,,,,,,,,,,,,,,,0,5.000000e+000,5.000000e-001,2,1,3.100204e-002,0,1,0,
1473098249.260,,2.000000e+002,3.250318e+001,9.135919e-004,0.000000e+000,6.672154e-003,0.000000e+000,3,9.757087e-001,1.825000e+000,,,,,,,,,,,,,,,,,,0,5.000000e+000,5.000000e-001,2,1,1.230240e-002,0,1,0,
1473098274.439,,2.000000e+002,3.255933e+001,9.133133e-004,0.000000e+000,6.239118e-003,0.000000e+000,3,9.754769e-001,1.825000e+000,,,,,,,,,,,,,,,,,,0,5.000000e+000,5.000000e-001,2,1,1.509094e-002,0,0,0,
1473098406.829,,3.000000e+002,3.274071e+001,9.506560e-004,0.000000e+000,7.331876e-003,0.000000e+000,3,9.717172e-001,1.825000e+000,,,,,,,,,,,,,,,,,,0,5.000000e+000,5.000000e-001,2,1,8.327484e-003,0,0,0,
1473098433.616,,3.000000e+002,3.278791e+001,9.510821e-004,0.000000e+000,6.074131e-003,0.000000e+000,3,9.726586e-001,1.825000e+000,,,,,,,,,,,,,,,,,,0,5.000000e+000,5.000000e-001,2,1,1.947021e-002,0,0,0,
1473098562.305,,4.000000e+002,3.299283e+001,9.694956e-004,0.000000e+000,5.763403e-003,0.000000e+000,3,9.699693e-001,1.825000e+000,,,,,,,,,,,,,,,,,,0,5.000000e+000,5.000000e-001,2,1,1.266098e-002,0,0,0,
1473098589.528,,4.000000e+002,3.303580e+001,9.688466e-004,0.000000e+000,6.088821e-003,0.000000e+000,3,9.694484e-001,1.825000e+000,,,,,,,,,,,,,,,,,,0,5.000000e+000,5.000000e-001,2,1,1.691818e-002,0,0,0,
1473098725.693,,5.000000e+002,3.321802e+001,9.795866e-004,0.000000e+000,5.619437e-003,0.000000e+000,3,9.670420e-001,1.825000e+000,,,,,,,,,,,,,,,,,,0,5.000000e+000,5.000000e-001,2,1,9.990692e-003,0,0,0,
1473098755.667,,5.000000e+002,3.325655e+001,9.795466e-004,0.000000e+000,5.641915e-003,0.000000e+000,3,9.669964e-001,1.825000e+000,,,,,,,,,,,,,,,,,,0,5.000000e+000,5.000000e-001,2,1,2.143097e-002,0,0,0,
1473098883.022,,6.000000e+002,3.342812e+001,9.860463e-004,0.000000e+000,5.526153e-003,0.000000e+000,3,9.645891e-001,1.825000e+000,,,,,,,,,,,,,,,,,,0,5.000000e+000,5.000000e-001,2,1,8.647919e-003,0,1,0,
1473098909.388,,6.000000e+002,3.347219e+001,9.853913e-004,0.000000e+000,5.762395e-003,0.000000e+000,3,9.643736e-001,1.825000e+000,,,,,,,,,,,,,,,,,,0,5.000000e+000,5.000000e-001,2,1,1.590729e-002,0,1,0,
1473099045.189,,7.000000e+002,3.375362e+001,9.896698e-004,0.000000e+000,4.918618e-003,0.000000e+000,3,9.627725e-001,1.825000e+000,,,,,,,,,,,,,,,,,,0,5.000000e+000,5.000000e-001,2,1,1.322174e-002,0,1,0,
1473099071.384,,7.000000e+002,3.381813e+001,9.889242e-004,0.000000e+000,5.317641e-003,0.000000e+000,3,9.624159e-001,1.825000e+000,,,,,,,,,,,,,,,,,,0,5.000000e+000,5.000000e-001,2,1,1.622009e-002,0,1,0,
1473099191.336,,1.000000e+003,3.408636e+001,9.996491e-004,0.000000e+000,4.860419e-003,0.000000e+000,3,9.586373e-001,1.825000e+000,,,,,,,,,,,,,,,,,,0,5.000000e+000,5.000000e-001,2,1,2.395248e-002,0,1,0,
1473099215.514,,1.000000e+003,3.414033e+001,9.981669e-004,0.000000e+000,4.890472e-003,0.000000e+000,3,9.586926e-001,1.825000e+000,,,,,,,,,,,,,,,,,,0,5.000000e+000,5.000000e-001,2,1,2.101898e-002,0,1,0,
1473099351.958,,3.000000e+003,3.434113e+001,1.031748e-003,0.000000e+000,3.546403e-003,0.000000e+000,3,9.508238e-001,1.825000e+000,,,,,,,,,,,,,,,,,,0,5.000000e+000,5.000000e-001,2,1,1.517868e-002,0,0,0,
1473099379.207,,3.000000e+003,3.439206e+001,1.030361e-003,0.000000e+000,4.458279e-003,0.000000e+000,3,9.492499e-001,1.825000e+000,,,,,,,,,,,,,,,,,,0,5.000000e+000,5.000000e-001,2,1,1.510620e-003,0,0,0,
1473099513.947,,5.000000e+003,3.458488e+001,1.043211e-003,0.000000e+000,3.098617e-003,0.000000e+000,3,9.489768e-001,1.825000e+000,,,,,,,,,,,,,,,,,,0,5.000000e+000,5.000000e-001,2,1,1.076889e-002,0,0,0,
1473099540.439,,5.000000e+003,3.462569e+001,1.041754e-003,0.000000e+000,3.056514e-003,0.000000e+000,3,9.488568e-001,1.825000e+000,,,,,,,,,,,,,,,,,,0,5.000000e+000,5.000000e-001,2,1,1.848984e-002,0,0,0,
1473099681.129,,7.000000e+003,3.480384e+001,1.051721e-003,0.000000e+000,3.354796e-003,0.000000e+000,3,9.489589e-001,1.825000e+000,,,,,,,,,,,,,,,,,,0,5.000000e+000,5.000000e-001,2,1,1.245117e-002,0,0,0,
1473099707.375,,7.000000e+003,3.484592e+001,1.051170e-003,0.000000e+000,3.383938e-003,0.000000e+000,3,9.488790e-001,1.825000e+000,,,,,,,,,,,,,,,,,,0,5.000000e+000,5.000000e-001,2,1,6.240845e-003,0,0,0,
1473099844.589,,9.000000e+003,3.503252e+001,1.056794e-003,0.000000e+000,3.535146e-003,0.000000e+000,3,9.490311e-001,1.825000e+000,,,,,,,,,,,,,,,,,,0,5.000000e+000,5.000000e-001,2,1,1.576233e-002,0,1,0,
1473099870.767,,9.000000e+003,3.508539e+001,1.056205e-003,0.000000e+000,3.466696e-003,0.000000e+000,3,9.488215e-001,1.825000e+000,,,,,,,,,,,,,,,,,,0,5.000000e+000,5.000000e-001,2,1,2.054214e-002,0,1,0,
1473099999.386,,1.000000e+004,3.534878e+001,1.055702e-003,0.000000e+000,3.849506e-003,0.000000e+000,3,9.483973e-001,1.825000e+000,,,,,,,,,,,,,,,,,,0,5.000000e+000,5.000000e-001,2,1,2.244186e-002,0,1,0,
1473100025.706,,1.000000e+004,3.541139e+001,1.055620e-003,0.000000e+000,3.562234e-003,0.000000e+000,3,9.487677e-001,1.825000e+000,,,,,,,,,,,,,,,,,,0,5.000000e+000,5.000000e-001,2,1,1.607895e-002,0,1,0,
1473100192.655,,2.000000e+004,3.572269e+001,1.073940e-003,0.000000e+000,5.081938e-003,0.000000e+000,3,9.475393e-001,1.825000e+000,,,,,,,,,,,,,,,,,,0,5.000000e+000,5.000000e-001,2,1,1.635742e-002,0,1,0,
1473100216.100,,2.000000e+004,3.576606e+001,1.074154e-003,0.000000e+000,4.895382e-003,0.000000e+000,3,9.493377e-001,1.825000e+000,,,,,,,,,,,,,,,,,,0,5.000000e+000,5.000000e-001,2,1,1.802063e-002,0,1,0,
1473100391.583,,3.000000e+004,3.602007e+001,1.086739e-003,0.000000e+000,5.296574e-003,0.000000e+000,3,9.487870e-001,1.825000e+000,,,,,,,,,,,,,,,,,,0,5.000000e+000,5.000000e-001,2,1,1.494980e-002,0,0,0,
1473100417.541,,3.000000e+004,3.606744e+001,1.085567e-003,0.000000e+000,5.394807e-003,0.000000e+000,3,9.486699e-001,1.825000e+000,,,,,,,,,,,,,,,,,,0,5.000000e+000,5.000000e-001,2,1,1.332092e-002,0,0,0,
1473100600.029,,4.000000e+004,3.631622e+001,1.089032e-003,0.000000e+000,5.666166e-003,0.000000e+000,3,9.471899e-001,1.825000e+000,,,,,,,,,,,,,,,,,,0,5.000000e+000,5.000000e-001,2,1,1.179886e-002,0,0,0,
1473100628.435,,4.000000e+004,3.635419e+001,1.091844e-003,0.000000e+000,6.392972e-003,0.000000e+000,3,9.485630e-001,1.825000e+000,,,,,,,,,,,,,,,,,,0,5.000000e+000,5.000000e-001,2,1,1.351166e-002,0,0,0,
1473100805.547,,5.000000e+004,3.656141e+001,1.096271e-003,0.000000e+000,6.919143e-003,0.000000e+000,3,9.481047e-001,1.825000e+000,,,,,,,,,,,,,,,,,,0,5.000000e+000,5.000000e-001,2,1,1.366043e-002,0,1,0,
1473100832.476,,5.000000e+004,3.660587e+001,1.096499e-003,0.000000e+000,7.289897e-003,0.000000e+000,3,9.483895e-001,1.825000e+000,,,,,,,,,,,,,,,,,,0,5.000000e+000,5.000000e-001,2,1,1.711273e-002,0,1,0,
1473101006.233,,6.000000e+004,3.692770e+001,1.094184e-003,0.000000e+000,8.551693e-003,0.000000e+000,3,9.473705e-001,1.825000e+000,,,,,,,,,,,,,,,,,,0,5.000000e+000,5.000000e-001,2,1,1.217651e-002,0,1,0,
1473101032.162,,6.000000e+004,3.697648e+001,1.100579e-003,0.000000e+000,8.963980e-003,0.000000e+000,3,9.454765e-001,1.825000e+000,,,,,,,,,,,,,,,,,,0,5.000000e+000,5.000000e-001,2,1,2.267838e-002,0,1,0,
1473101221.361,,7.000000e+004,3.730185e+001,1.096768e-003,0.000000e+000,7.193926e-003,0.000000e+000,3,9.454201e-001,1.825000e+000,,,,,,,,,,,,,,,,,,0,5.000000e+000,5.000000e-001,2,1,1.596069e-002,0,1,0,
1473101245.346,,7.000000e+004,3.734178e+001,1.097832e-003,0.000000e+000,8.193879e-003,0.000000e+000,3,9.454292e-001,1.825000e+000,,,,,,,,,,,,,,,,,,0,5.000000e+000,5.000000e-001,2,1,1.066208e-002,0,1,0,
1473101257.810,,7.000000e+004,3.736401e+001,1.097933e-003,0.000000e+000,9.857155e-003,0.000000e+000,3,9.460023e-001,1.825000e+000,,,,,,,,,,,,,,,,,,0,5.000000e+000,5.000000e-001,2,1,2.311707e-002,0,1,0,