File: data/A344/dat/A344_GdN_MH_020K_160905.rso.dat
[Header]
TITLE,MPMS RSO Measurement
BYAPP,MPMS Measurement,1.1,Summary
FILEOPENTIME, 1473102611.120000 9/6/2016, 7:10:11 AM

INFO, APPNAME, MPMS MultiVu Application, Revision 1.61,  Build 082

INFO, NAME, A344
INFO, WEIGHT, 10.500
INFO, AREA, 1.000
INFO, LENGTH, 1.000
INFO, SHAPE, 0
INFO, COMMENT, m = 0.0105g
INFO, SEQUENCE FILE: 7T_hysteresis_sweep_hi_res_zero_n4.seq


INFO, BACKGROUND DATA FILE:, None


STARTUPAXIS,X,4,LINEAR,AUTO,0.000000,0.000000
STARTUPAXIS,Y1,5,LINEAR,AUTO,0.000000,0.000000


STARTUPGROUP,Longitudinal
FIELDGROUP,Longitudinal,1,2,3,4,5,6,7,8,9,10,11,19,20,21,22,23,35
FIELDGROUP,Transverse,1,2,3,4,12,13,14,15,16,17,18,24,25,26,27,28,35

PLOT_APPEARANCE,ALL,HORZ_GRID_ON,VERT_GRID_ON,MARKERS_AND_LINES

[Data]
Time,Comment,Field (Oe),Temperature (K),Long Moment (emu),Long Scan Std Dev,Long Offset (cm),Long Offset Std Dev,Long Algorithm,Long Reg Fit,Long Reg Factor,Trans Moment (emu),Trans Scan Std Dev,Trans Offset (cm),Trans Offset Std Dev,Trans Algorithm,Trans Reg Fit,Trans Reg Factor,Long Moment [w/o ABS] (emu),Long Scan Std Dev [w/o ABS],Long Offset [w/o ABS] (cm),Long Offset Std Dev [w/o ABS],Long Reg Fit [w/o ABS],Trans Moment [w/o ABS] (emu),Trans Scan Std Dev [w/o ABS],Trans Offset [w/o ABS] (cm),Trans Offset Std Dev [w/o ABS],Trans Reg Fit [w/o ABS],RSO Position (deg),Amplitude (cm),Frequency,Cycles to Average,Scans per Measurement,Delta Temp (K),Error,EC Comp. Running,Using ABS,
1473102611.119,,7.000000e+004,2.016301e+001,1.234112e-003,0.000000e+000,6.133169e-003,0.000000e+000,3,9.512879e-001,1.825000e+000,,,,,,,,,,,,,,,,,,0,5.000000e+000,5.000000e-001,2,1,1.810074e-002,0,0,0,
1473102637.835,,7.000000e+004,2.023980e+001,1.233835e-003,0.000000e+000,6.419840e-003,0.000000e+000,3,9.513797e-001,1.825000e+000,,,,,,,,,,,,,,,,,,0,5.000000e+000,5.000000e-001,2,1,2.540970e-002,0,0,0,
1473102820.887,,6.000000e+004,2.069683e+001,1.232649e-003,0.000000e+000,5.126455e-003,0.000000e+000,3,9.514588e-001,1.825000e+000,,,,,,,,,,,,,,,,,,0,5.000000e+000,5.000000e-001,2,1,3.866005e-002,0,1,0,
1473102847.844,,6.000000e+004,2.082195e+001,1.232337e-003,0.000000e+000,5.186838e-003,0.000000e+000,3,9.516941e-001,1.825000e+000,,,,,,,,,,,,,,,,,,0,5.000000e+000,5.000000e-001,2,1,7.239151e-002,0,1,0,
1473103027.066,,5.000000e+004,2.167189e+001,1.222669e-003,0.000000e+000,5.425691e-003,0.000000e+000,3,9.517329e-001,1.825000e+000,,,,,,,,,,,,,,,,,,0,5.000000e+000,5.000000e-001,2,1,4.604912e-002,0,1,0,
1473103053.995,,5.000000e+004,2.181697e+001,1.225896e-003,0.000000e+000,4.619890e-003,0.000000e+000,3,9.525110e-001,1.825000e+000,,,,,,,,,,,,,,,,,,0,5.000000e+000,5.000000e-001,2,1,6.389999e-002,0,1,0,
1473103233.193,,4.000000e+004,2.248328e+001,1.219493e-003,0.000000e+000,4.087412e-003,0.000000e+000,3,9.492919e-001,1.825000e+000,,,,,,,,,,,,,,,,,,0,5.000000e+000,5.000000e-001,2,1,3.656960e-002,0,0,0,
1473103257.930,,4.000000e+004,2.258223e+001,1.215981e-003,0.000000e+000,2.557341e-003,0.000000e+000,3,9.538165e-001,1.825000e+000,,,,,,,,,,,,,,,,,,0,5.000000e+000,5.000000e-001,2,1,4.438972e-002,0,0,0,
1473103432.566,,3.000000e+004,2.307917e+001,1.207988e-003,0.000000e+000,2.594992e-003,0.000000e+000,3,9.527539e-001,1.825000e+000,,,,,,,,,,,,,,,,,,0,5.000000e+000,5.000000e-001,2,1,3.133965e-002,0,0,0,
1473103458.120,,3.000000e+004,2.316784e+001,1.207290e-003,0.000000e+000,2.750693e-003,0.000000e+000,3,9.527052e-001,1.825000e+000,,,,,,,,,,,,,,,,,,0,5.000000e+000,5.000000e-001,2,1,4.305840e-002,0,0,0,
1473103635.592,,2.000000e+004,2.364988e+001,1.194497e-003,0.000000e+000,1.974432e-003,0.000000e+000,3,9.526055e-001,1.825000e+000,,,,,,,,,,,,,,,,,,0,5.000000e+000,5.000000e-001,2,1,2.314949e-002,0,0,0,
1473103664.270,,2.000000e+004,2.374471e+001,1.194144e-003,0.000000e+000,2.045872e-003,0.000000e+000,3,9.528266e-001,1.825000e+000,,,,,,,,,,,,,,,,,,0,5.000000e+000,5.000000e-001,2,1,3.610039e-002,0,0,0,
1473103836.217,,1.000000e+004,2.422271e+001,1.173706e-003,0.000000e+000,1.463845e-003,0.000000e+000,3,9.525157e-001,1.825000e+000,,,,,,,,,,,,,,,,,,0,5.000000e+000,5.000000e-001,2,1,2.733994e-002,0,1,0,
1473103864.146,,1.000000e+004,2.434752e+001,1.172379e-003,0.000000e+000,1.336305e-003,0.000000e+000,3,9.526484e-001,1.825000e+000,,,,,,,,,,,,,,,,,,0,5.000000e+000,5.000000e-001,2,1,3.391838e-002,0,1,0,
1473104001.380,,9.000000e+003,2.492818e+001,1.164316e-003,0.000000e+000,1.730270e-003,0.000000e+000,3,9.524671e-001,1.825000e+000,,,,,,,,,,,,,,,,,,0,5.000000e+000,5.000000e-001,2,1,3.875923e-002,0,1,0,
1473104027.873,,9.000000e+003,2.506453e+001,1.162611e-003,0.000000e+000,1.424485e-003,0.000000e+000,3,9.525265e-001,1.825000e+000,,,,,,,,,,,,,,,,,,0,5.000000e+000,5.000000e-001,2,1,5.665016e-002,0,1,0,
1473104168.066,,7.000000e+003,2.557483e+001,1.151310e-003,0.000000e+000,1.825123e-003,0.000000e+000,3,9.522641e-001,1.825000e+000,,,,,,,,,,,,,,,,,,0,5.000000e+000,5.000000e-001,2,1,3.981018e-002,0,1,0,
1473104195.040,,7.000000e+003,2.567820e+001,1.150115e-003,0.000000e+000,1.827351e-003,0.000000e+000,3,9.523029e-001,1.825000e+000,,,,,,,,,,,,,,,,,,0,5.000000e+000,5.000000e-001,2,1,3.662109e-002,0,0,0,
1473104333.981,,5.000000e+003,2.601990e+001,1.183585e-003,0.000000e+000,-5.130840e-003,0.000000e+000,3,9.509085e-001,1.825000e+000,,,,,,,,,,,,,,,,,,0,5.000000e+000,5.000000e-001,2,1,2.145004e-002,0,0,0,
1473104357.662,,5.000000e+003,2.609386e+001,1.136738e-003,0.000000e+000,1.383000e-003,0.000000e+000,3,9.525871e-001,1.825000e+000,,,,,,,,,,,,,,,,,,0,5.000000e+000,5.000000e-001,2,1,3.145981e-002,0,0,0,
1473104632.549,,3.000000e+003,2.676668e+001,1.115801e-003,0.000000e+000,1.850690e-003,0.000000e+000,3,9.534255e-001,1.825000e+000,,,,,,,,,,,,,,,,,,0,5.000000e+000,5.000000e-001,2,1,1.319885e-002,0,0,0,
1473104658.838,,3.000000e+003,2.683240e+001,1.114967e-003,0.000000e+000,1.948590e-003,0.000000e+000,3,9.532790e-001,1.825000e+000,,,,,,,,,,,,,,,,,,0,5.000000e+000,5.000000e-001,2,1,2.557945e-002,0,0,0,
1473104789.482,,1.000000e+003,2.714188e+001,1.077141e-003,0.000000e+000,3.228982e-003,0.000000e+000,3,9.610476e-001,1.825000e+000,,,,,,,,,,,,,,,,,,0,5.000000e+000,5.000000e-001,2,1,2.616119e-002,0,1,0,
1473104815.269,,1.000000e+003,2.722105e+001,1.076003e-003,0.000000e+000,3.238109e-003,0.000000e+000,3,9.607861e-001,1.825000e+000,,,,,,,,,,,,,,,,,,0,5.000000e+000,5.000000e-001,2,1,3.507042e-002,0,1,0,
1473104952.463,,7.000000e+002,2.769038e+001,1.058648e-003,0.000000e+000,3.945726e-003,0.000000e+000,3,9.637225e-001,1.825000e+000,,,,,,,,,,,,,,,,,,0,5.000000e+000,5.000000e-001,2,1,2.617073e-002,0,1,0,
1473104979.929,,7.000000e+002,2.778985e+001,1.057497e-003,0.000000e+000,3.744187e-003,0.000000e+000,3,9.640702e-001,1.825000e+000,,,,,,,,,,,,,,,,,,0,5.000000e+000,5.000000e-001,2,1,3.952026e-002,0,1,0,
1473105114.907,,6.000000e+002,2.824006e+001,1.046967e-003,0.000000e+000,4.157385e-003,0.000000e+000,3,9.653798e-001,1.825000e+000,,,,,,,,,,,,,,,,,,0,5.000000e+000,5.000000e-001,2,1,3.134918e-002,0,1,0,
1473105139.085,,6.000000e+002,2.832021e+001,1.045609e-003,0.000000e+000,4.168606e-003,0.000000e+000,3,9.655635e-001,1.825000e+000,,,,,,,,,,,,,,,,,,0,5.000000e+000,5.000000e-001,2,1,3.256035e-002,0,1,0,
1473105274.291,,5.000000e+002,2.861787e+001,1.035304e-003,0.000000e+000,5.122388e-003,0.000000e+000,3,9.674008e-001,1.825000e+000,,,,,,,,,,,,,,,,,,0,5.000000e+000,5.000000e-001,2,1,1.928902e-002,0,0,0,
1473105300.219,,5.000000e+002,2.868555e+001,1.033733e-003,0.000000e+000,4.557728e-003,0.000000e+000,3,9.674757e-001,1.825000e+000,,,,,,,,,,,,,,,,,,0,5.000000e+000,5.000000e-001,2,1,1.722908e-002,0,0,0,
1473105428.408,,4.000000e+002,2.897528e+001,1.019815e-003,0.000000e+000,4.597182e-003,0.000000e+000,3,9.707618e-001,1.825000e+000,,,,,,,,,,,,,,,,,,0,5.000000e+000,5.000000e-001,2,1,2.086067e-002,0,0,0,
1473105453.587,,4.000000e+002,2.904183e+001,1.019692e-003,0.000000e+000,4.799406e-003,0.000000e+000,3,9.705663e-001,1.825000e+000,,,,,,,,,,,,,,,,,,0,5.000000e+000,5.000000e-001,2,1,1.984024e-002,0,0,0,
1473105582.048,,3.000000e+002,2.929698e+001,1.001192e-003,0.000000e+000,5.738533e-003,0.000000e+000,3,9.729528e-001,1.825000e+000,,,,,,,,,,,,,,,,,,0,5.000000e+000,5.000000e-001,2,1,2.130127e-002,0,0,0,
1473105610.476,,3.000000e+002,2.935876e+001,1.001430e-003,0.000000e+000,5.105588e-003,0.000000e+000,3,9.730489e-001,1.825000e+000,,,,,,,,,,,,,,,,,,0,5.000000e+000,5.000000e-001,2,1,2.589035e-002,0,0,0,
1473105750.667,,2.000000e+002,2.963189e+001,9.738912e-004,0.000000e+000,5.677471e-003,0.000000e+000,3,9.760345e-001,1.825000e+000,,,,,,,,,,,,,,,,,,0,5.000000e+000,5.000000e-001,2,1,2.750015e-002,0,1,0,
1473105778.431,,2.000000e+002,2.971173e+001,9.733349e-004,0.000000e+000,5.729569e-003,0.000000e+000,3,9.762557e-001,1.825000e+000,,,,,,,,,,,,,,,,,,0,5.000000e+000,5.000000e-001,2,1,3.109932e-002,0,1,0,
1473105901.634,,1.800000e+002,3.007156e+001,9.636549e-004,0.000000e+000,5.731608e-003,0.000000e+000,3,9.764513e-001,1.825000e+000,,,,,,,,,,,,,,,,,,0,5.000000e+000,5.000000e-001,2,1,4.241943e-002,0,1,0,
1473105927.595,,1.800000e+002,3.015782e+001,9.619435e-004,0.000000e+000,6.210481e-003,0.000000e+000,3,9.764253e-001,1.825000e+000,,,,,,,,,,,,,,,,,,0,5.000000e+000,5.000000e-001,2,1,3.318024e-002,0,1,0,
1473106049.283,,1.600000e+002,3.051493e+001,9.499718e-004,0.000000e+000,6.132744e-003,0.000000e+000,3,9.770315e-001,1.825000e+000,,,,,,,,,,,,,,,,,,0,5.000000e+000,5.000000e-001,2,1,2.423096e-002,0,1,0,
1473106073.504,,1.600000e+002,3.058112e+001,9.498713e-004,0.000000e+000,5.948672e-003,0.000000e+000,3,9.773901e-001,1.825000e+000,,,,,,,,,,,,,,,,,,0,5.000000e+000,5.000000e-001,2,1,2.556038e-002,0,1,0,
1473106203.447,,1.400000e+002,3.088766e+001,9.372073e-004,0.000000e+000,6.269345e-003,0.000000e+000,3,9.778649e-001,1.825000e+000,,,,,,,,,,,,,,,,,,0,5.000000e+000,5.000000e-001,2,1,3.223991e-002,0,1,0,
1473106226.375,,1.400000e+002,3.095166e+001,9.367503e-004,0.000000e+000,6.774161e-003,0.000000e+000,3,9.776569e-001,1.825000e+000,,,,,,,,,,,,,,,,,,0,5.000000e+000,5.000000e-001,2,1,2.864075e-002,0,0,0,
1473106346.614,,1.200000e+002,3.116726e+001,9.251997e-004,0.000000e+000,6.961672e-003,0.000000e+000,3,9.774672e-001,1.825000e+000,,,,,,,,,,,,,,,,,,0,5.000000e+000,5.000000e-001,2,1,1.134872e-002,0,0,0,
1473106372.392,,1.200000e+002,3.122099e+001,9.234670e-004,0.000000e+000,6.704806e-003,0.000000e+000,3,9.786370e-001,1.825000e+000,,,,,,,,,,,,,,,,,,0,5.000000e+000,5.000000e-001,2,1,2.025986e-002,0,0,0,
1473106494.583,,1.000000e+002,3.146846e+001,9.093820e-004,0.000000e+000,6.694207e-003,0.000000e+000,3,9.792062e-001,1.825000e+000,,,,,,,,,,,,,,,,,,0,5.000000e+000,5.000000e-001,2,1,2.056122e-002,0,0,0,
1473106520.261,,1.000000e+002,3.151867e+001,9.091274e-004,0.000000e+000,6.682150e-003,0.000000e+000,3,9.797797e-001,1.825000e+000,,,,,,,,,,,,,,,,,,0,5.000000e+000,5.000000e-001,2,1,2.578163e-002,0,0,0,
1473106639.991,,8.000000e+001,3.173081e+001,8.929743e-004,0.000000e+000,7.075050e-003,0.000000e+000,3,9.807612e-001,1.825000e+000,,,,,,,,,,,,,,,,,,0,5.000000e+000,5.000000e-001,2,1,1.435852e-002,0,0,0,
1473106665.920,,8.000000e+001,3.177986e+001,8.927589e-004,0.000000e+000,6.725579e-003,0.000000e+000,3,9.802633e-001,1.825000e+000,,,,,,,,,,,,,,,,,,0,5.000000e+000,5.000000e-001,2,1,1.832962e-002,0,0,0,
1473106792.613,,6.000000e+001,3.199008e+001,8.731187e-004,0.000000e+000,6.555115e-003,0.000000e+000,3,9.812338e-001,1.825000e+000,,,,,,,,,,,,,,,,,,0,5.000000e+000,5.000000e-001,2,1,1.194000e-002,0,1,0,
1473106818.102,,6.000000e+001,3.203857e+001,8.722969e-004,0.000000e+000,6.878513e-003,0.000000e+000,3,9.812449e-001,1.825000e+000,,,,,,,,,,,,,,,,,,0,5.000000e+000,5.000000e-001,2,1,2.128983e-002,0,1,0,
1473106941.895,,4.000000e+001,3.232838e+001,8.486640e-004,0.000000e+000,6.987675e-003,0.000000e+000,3,9.818975e-001,1.825000e+000,,,,,,,,,,,,,,,,,,0,5.000000e+000,5.000000e-001,2,1,2.165985e-002,0,1,0,
1473106965.823,,4.000000e+001,3.239482e+001,8.471258e-004,0.000000e+000,7.217946e-003,0.000000e+000,3,9.820843e-001,1.825000e+000,,,,,,,,,,,,,,,,,,0,5.000000e+000,5.000000e-001,2,1,2.989197e-002,0,1,0,
1473107090.718,,2.000000e+001,3.271716e+001,8.161578e-004,0.000000e+000,7.490922e-003,0.000000e+000,3,9.825958e-001,1.825000e+000,,,,,,,,,,,,,,,,,,0,5.000000e+000,5.000000e-001,2,1,2.769089e-002,0,1,0,
1473107117.593,,2.000000e+001,3.279417e+001,8.145131e-004,0.000000e+000,7.581936e-003,0.000000e+000,3,9.827052e-001,1.825000e+000,,,,,,,,,,,,,,,,,,0,5.000000e+000,5.000000e-001,2,1,2.365112e-002,0,1,0,
1473121411.488,,0.000000e+000,1.999440e+001,-6.689649e-004,0.000000e+000,4.840930e-003,0.000000e+000,3,9.834965e-001,1.825000e+000,,,,,,,,,,,,,,,,,,0,5.000000e+000,5.000000e-001,2,1,2.691269e-003,0,0,0,
1473121437.417,,0.000000e+000,2.000033e+001,-6.689647e-004,0.000000e+000,4.887495e-003,0.000000e+000,3,9.836571e-001,1.825000e+000,,,,,,,,,,,,,,,,,,0,5.000000e+000,5.000000e-001,2,1,3.780365e-003,0,0,0,
1473121556.298,,-2.000000e+001,1.999683e+001,-7.317713e-004,0.000000e+000,5.007075e-003,0.000000e+000,3,9.828358e-001,1.825000e+000,,,,,,,,,,,,,,,,,,0,5.000000e+000,5.000000e-001,2,1,3.229141e-003,0,0,0,
1473121579.927,,-2.000000e+001,2.000033e+001,-7.322886e-004,0.000000e+000,5.030817e-003,0.000000e+000,3,9.828560e-001,1.825000e+000,,,,,,,,,,,,,,,,,,0,5.000000e+000,5.000000e-001,2,1,5.416870e-004,0,0,0,
1473121701.881,,-4.000000e+001,1.999493e+001,-7.827334e-004,0.000000e+000,5.058484e-003,0.000000e+000,3,9.822544e-001,1.825000e+000,,,,,,,,,,,,,,,,,,0,5.000000e+000,5.000000e-001,2,1,1.611710e-003,0,0,0,
1473121725.576,,-4.000000e+001,2.000195e+001,-7.831373e-004,0.000000e+000,5.085541e-003,0.000000e+000,3,9.820465e-001,1.825000e+000,,,,,,,,,,,,,,,,,,0,5.000000e+000,5.000000e-001,2,1,5.397797e-004,0,0,0,
1473121844.947,,-6.000000e+001,1.999898e+001,-8.302974e-004,0.000000e+000,5.048851e-003,0.000000e+000,3,9.816934e-001,1.825000e+000,,,,,,,,,,,,,,,,,,0,5.000000e+000,5.000000e-001,2,1,2.159119e-003,0,0,0,
1473121871.233,,-6.000000e+001,2.000195e+001,-8.312892e-004,0.000000e+000,4.975989e-003,0.000000e+000,3,9.816638e-001,1.825000e+000,,,,,,,,,,,,,,,,,,0,5.000000e+000,5.000000e-001,2,1,1.619339e-003,0,0,0,
1473121990.691,,-8.000000e+001,1.999871e+001,-8.704753e-004,0.000000e+000,4.903979e-003,0.000000e+000,3,9.805403e-001,1.825000e+000,,,,,,,,,,,,,,,,,,0,5.000000e+000,5.000000e-001,2,1,1.630783e-003,0,0,0,
1473122017.635,,-8.000000e+001,2.000249e+001,-8.708563e-004,0.000000e+000,5.708034e-003,0.000000e+000,3,9.801381e-001,1.825000e+000,,,,,,,,,,,,,,,,,,0,5.000000e+000,5.000000e-001,2,1,1.619339e-003,0,0,0,
1473122138.838,,-1.000000e+002,2.000330e+001,-9.032964e-004,0.000000e+000,5.377681e-003,0.000000e+000,3,9.794143e-001,1.825000e+000,,,,,,,,,,,,,,,,,,0,5.000000e+000,5.000000e-001,2,1,1.079559e-003,0,1,0,
1473122163.053,,-1.000000e+002,2.000681e+001,-9.039819e-004,0.000000e+000,5.303117e-003,0.000000e+000,3,9.794828e-001,1.825000e+000,,,,,,,,,,,,,,,,,,0,5.000000e+000,5.000000e-001,2,1,3.780365e-003,0,1,0,
1473122282.538,,-1.200000e+002,2.000034e+001,-9.303425e-004,0.000000e+000,5.491931e-003,0.000000e+000,3,9.784552e-001,1.825000e+000,,,,,,,,,,,,,,,,,,0,5.000000e+000,5.000000e-001,2,1,1.609802e-003,0,1,0,
1473122309.166,,-1.200000e+002,2.000438e+001,-9.308475e-004,0.000000e+000,5.249265e-003,0.000000e+000,3,9.789619e-001,1.825000e+000,,,,,,,,,,,,,,,,,,0,5.000000e+000,5.000000e-001,2,1,3.240585e-003,0,1,0,
1473122429.966,,-1.400000e+002,1.999871e+001,-9.529875e-004,0.000000e+000,5.153424e-003,0.000000e+000,3,9.784692e-001,1.825000e+000,,,,,,,,,,,,,,,,,,0,5.000000e+000,5.000000e-001,2,1,2.698898e-003,0,1,0,
1473122454.447,,-1.400000e+002,2.002087e+001,-9.535088e-004,0.000000e+000,5.237949e-003,0.000000e+000,3,9.784822e-001,1.825000e+000,,,,,,,,,,,,,,,,,,0,5.000000e+000,5.000000e-001,2,1,2.758980e-002,0,1,0,
1473122576.925,,-1.600000e+002,2.000195e+001,-9.723891e-004,0.000000e+000,5.023377e-003,0.000000e+000,3,9.777690e-001,1.825000e+000,,,,,,,,,,,,,,,,,,0,5.000000e+000,5.000000e-001,2,1,2.698898e-003,0,1,0,
1473122601.853,,-1.600000e+002,2.000654e+001,-9.726730e-004,0.000000e+000,5.053267e-003,0.000000e+000,3,9.777915e-001,1.825000e+000,,,,,,,,,,,,,,,,,,0,5.000000e+000,5.000000e-001,2,1,1.079559e-003,0,1,0,
1473122729.546,,-1.800000e+002,2.000033e+001,-9.879856e-004,0.000000e+000,5.396519e-003,0.000000e+000,3,9.771785e-001,1.825000e+000,,,,,,,,,,,,,,,,,,0,5.000000e+000,5.000000e-001,2,1,5.416870e-004,0,0,0,
1473122752.764,,-1.800000e+002,2.000303e+001,-9.891625e-004,0.000000e+000,5.106939e-003,0.000000e+000,3,9.772078e-001,1.825000e+000,,,,,,,,,,,,,,,,,,0,5.000000e+000,5.000000e-001,2,1,5.397797e-004,0,0,0,
1473122870.951,,-2.000000e+002,2.000034e+001,-1.003383e-003,0.000000e+000,5.124619e-003,0.000000e+000,3,9.760079e-001,1.825000e+000,,,,,,,,,,,,,,,,,,0,5.000000e+000,5.000000e-001,2,1,1.609802e-003,0,0,0,
1473122896.130,,-2.000000e+002,2.000276e+001,-1.002947e-003,0.000000e+000,5.306008e-003,0.000000e+000,3,9.758292e-001,1.825000e+000,,,,,,,,,,,,,,,,,,0,5.000000e+000,5.000000e-001,2,1,1.079559e-003,0,0,0,
1473123029.344,,-3.000000e+002,1.999952e+001,-1.050273e-003,0.000000e+000,4.761340e-003,0.000000e+000,3,9.740732e-001,1.825000e+000,,,,,,,,,,,,,,,,,,0,5.000000e+000,5.000000e-001,2,1,1.070023e-003,0,0,0,
1473123053.273,,-3.000000e+002,2.000519e+001,-1.050248e-003,0.000000e+000,4.778203e-003,0.000000e+000,3,9.737762e-001,1.825000e+000,,,,,,,,,,,,,,,,,,0,5.000000e+000,5.000000e-001,2,1,2.700806e-003,0,0,0,
1473123188.272,,-4.000000e+002,1.999763e+001,-1.077041e-003,0.000000e+000,4.323402e-003,0.000000e+000,3,9.715148e-001,1.825000e+000,,,,,,,,,,,,,,,,,,0,5.000000e+000,5.000000e-001,2,1,7.011414e-003,0,0,0,
1473123214.190,,-4.000000e+002,2.000141e+001,-1.077494e-003,0.000000e+000,4.521377e-003,0.000000e+000,3,9.713478e-001,1.825000e+000,,,,,,,,,,,,,,,,,,0,5.000000e+000,5.000000e-001,2,1,5.397797e-004,0,0,0,
1473123346.206,,-5.000000e+002,1.999871e+001,-1.094910e-003,0.000000e+000,4.102478e-003,0.000000e+000,3,9.688574e-001,1.825000e+000,,,,,,,,,,,,,,,,,,0,5.000000e+000,5.000000e-001,2,1,1.630783e-003,0,0,0,
1473123373.493,,-5.000000e+002,2.000034e+001,-1.094438e-003,0.000000e+000,4.030052e-003,0.000000e+000,3,9.693409e-001,1.825000e+000,,,,,,,,,,,,,,,,,,0,5.000000e+000,5.000000e-001,2,1,2.691269e-003,0,0,0,
1473123500.181,,-6.000000e+002,2.000168e+001,-1.106116e-003,0.000000e+000,4.403151e-003,0.000000e+000,3,9.668081e-001,1.825000e+000,,,,,,,,,,,,,,,,,,0,5.000000e+000,5.000000e-001,2,1,1.079941e-002,0,1,0,
1473123523.838,,-6.000000e+002,2.000465e+001,-1.107549e-003,0.000000e+000,3.607689e-003,0.000000e+000,3,9.668899e-001,1.825000e+000,,,,,,,,,,,,,,,,,,0,5.000000e+000,5.000000e-001,2,1,1.621246e-003,0,1,0,
1473123660.639,,-7.000000e+002,2.000303e+001,-1.115413e-003,0.000000e+000,4.004427e-003,0.000000e+000,3,9.652641e-001,1.825000e+000,,,,,,,,,,,,,,,,,,0,5.000000e+000,5.000000e-001,2,1,1.619339e-003,0,1,0,
1473123683.854,,-7.000000e+002,2.000924e+001,-1.115742e-003,0.000000e+000,3.728968e-003,0.000000e+000,3,9.655480e-001,1.825000e+000,,,,,,,,,,,,,,,,,,0,5.000000e+000,5.000000e-001,2,1,0.000000e+000,0,1,0,
1473123812.085,,-1.000000e+003,2.000384e+001,-1.136197e-003,0.000000e+000,3.606269e-003,0.000000e+000,3,9.613656e-001,1.825000e+000,,,,,,,,,,,,,,,,,,0,5.000000e+000,5.000000e-001,2,1,2.159119e-003,0,1,0,
1473123837.264,,-1.000000e+003,2.000438e+001,-1.132516e-003,0.000000e+000,3.298598e-003,0.000000e+000,3,9.622573e-001,1.825000e+000,,,,,,,,,,,,,,,,,,0,5.000000e+000,5.000000e-001,2,1,1.079559e-003,0,1,0,
1473123965.465,,-3.000000e+003,2.000303e+001,-1.174906e-003,0.000000e+000,2.312863e-003,0.000000e+000,3,9.548330e-001,1.825000e+000,,,,,,,,,,,,,,,,,,0,5.000000e+000,5.000000e-001,2,1,5.397797e-004,0,1,0,
1473123989.522,,-3.000000e+003,2.000492e+001,-1.173775e-003,0.000000e+000,2.276701e-003,0.000000e+000,3,9.549982e-001,1.825000e+000,,,,,,,,,,,,,,,,,,0,5.000000e+000,5.000000e-001,2,1,1.081467e-003,0,1,0,
1473124130.011,,-5.000000e+003,1.999790e+001,-1.190574e-003,0.000000e+000,1.874145e-003,0.000000e+000,3,9.540442e-001,1.825000e+000,,,,,,,,,,,,,,,,,,0,5.000000e+000,5.000000e-001,2,1,0.000000e+000,0,0,0,
1473124154.690,,-5.000000e+003,1.999871e+001,-1.189118e-003,0.000000e+000,1.849412e-003,0.000000e+000,3,9.538549e-001,1.825000e+000,,,,,,,,,,,,,,,,,,0,5.000000e+000,5.000000e-001,2,1,5.493164e-004,0,0,0,
1473124290.900,,-7.000000e+003,2.000087e+001,-1.199317e-003,0.000000e+000,1.997420e-003,0.000000e+000,3,9.536824e-001,1.825000e+000,,,,,,,,,,,,,,,,,,0,5.000000e+000,5.000000e-001,2,1,5.397797e-004,0,0,0,
1473124316.097,,-7.000000e+003,2.000357e+001,-1.199171e-003,0.000000e+000,1.987371e-003,0.000000e+000,3,9.538397e-001,1.825000e+000,,,,,,,,,,,,,,,,,,0,5.000000e+000,5.000000e-001,2,1,1.619339e-003,0,0,0,
1473124449.036,,-9.000000e+003,2.000006e+001,-1.205295e-003,0.000000e+000,2.314932e-003,0.000000e+000,3,9.532431e-001,1.825000e+000,,,,,,,,,,,,,,,,,,0,5.000000e+000,5.000000e-001,2,1,1.070023e-003,0,0,0,
1473124475.219,,-9.000000e+003,2.000195e+001,-1.205157e-003,0.000000e+000,1.946774e-003,0.000000e+000,3,9.535735e-001,1.825000e+000,,,,,,,,,,,,,,,,,,0,5.000000e+000,5.000000e-001,2,1,5.397797e-004,0,0,0,
1473124608.658,,-1.000000e+004,2.000276e+001,-1.208247e-003,0.000000e+000,2.043662e-003,0.000000e+000,3,9.535761e-001,1.825000e+000,,,,,,,,,,,,,,,,,,0,5.000000e+000,5.000000e-001,2,1,2.159119e-003,0,0,0,
1473124633.837,,-1.000000e+004,1.998846e+001,-1.208337e-003,0.000000e+000,2.036654e-003,0.000000e+000,3,9.536408e-001,1.825000e+000,,,,,,,,,,,,,,,,,,0,5.000000e+000,5.000000e-001,2,1,5.397797e-004,0,0,0,
1473124806.328,,-2.000000e+004,1.999926e+001,-1.224102e-003,0.000000e+000,2.788417e-003,0.000000e+000,3,9.535375e-001,1.825000e+000,,,,,,,,,,,,,,,,,,0,5.000000e+000,5.000000e-001,2,1,5.416870e-004,0,0,0,
1473124831.824,,-2.000000e+004,2.000034e+001,-1.223856e-003,0.000000e+000,2.730153e-003,0.000000e+000,3,9.535108e-001,1.825000e+000,,,,,,,,,,,,,,,,,,0,5.000000e+000,5.000000e-001,2,1,2.691269e-003,0,0,0,
1473125003.294,,-3.000000e+004,2.000762e+001,-1.232034e-003,0.000000e+000,3.496940e-003,0.000000e+000,3,9.534645e-001,1.825000e+000,,,,,,,,,,,,,,,,,,0,5.000000e+000,5.000000e-001,2,1,2.159119e-003,0,1,0,
1473125028.275,,-3.000000e+004,2.000357e+001,-1.231098e-003,0.000000e+000,3.422336e-003,0.000000e+000,3,9.529158e-001,1.825000e+000,,,,,,,,,,,,,,,,,,0,5.000000e+000,5.000000e-001,2,1,2.698898e-003,0,1,0,
1473125203.747,,-4.000000e+004,2.000438e+001,-1.235257e-003,0.000000e+000,4.173088e-003,0.000000e+000,3,9.529824e-001,1.825000e+000,,,,,,,,,,,,,,,,,,0,5.000000e+000,5.000000e-001,2,1,1.079559e-003,0,1,0,
1473125228.980,,-4.000000e+004,2.001114e+001,-1.236239e-003,0.000000e+000,3.976485e-003,0.000000e+000,3,9.531809e-001,1.825000e+000,,,,,,,,,,,,,,,,,,0,5.000000e+000,5.000000e-001,2,1,5.493164e-004,0,1,0,
1473125406.625,,-5.000000e+004,1.999926e+001,-1.235739e-003,0.000000e+000,5.003144e-003,0.000000e+000,3,9.516119e-001,1.825000e+000,,,,,,,,,,,,,,,,,,0,5.000000e+000,5.000000e-001,2,1,5.416870e-004,0,1,0,
1473125433.848,,-5.000000e+004,2.000303e+001,-1.233325e-003,0.000000e+000,6.315577e-003,0.000000e+000,3,9.503236e-001,1.825000e+000,,,,,,,,,,,,,,,,,,0,5.000000e+000,5.000000e-001,2,1,5.397797e-004,0,1,0,
1473125617.650,,-6.000000e+004,2.000168e+001,-1.234533e-003,0.000000e+000,3.578774e-003,0.000000e+000,3,9.526179e-001,1.825000e+000,,,,,,,,,,,,,,,,,,0,5.000000e+000,5.000000e-001,2,1,1.079559e-003,0,1,0,
1473125640.578,,-6.000000e+004,2.000357e+001,-1.235280e-003,0.000000e+000,5.224713e-003,0.000000e+000,3,9.517401e-001,1.825000e+000,,,,,,,,,,,,,,,,,,0,5.000000e+000,5.000000e-001,2,1,5.397797e-004,0,0,0,
1473125817.551,,-7.000000e+004,1.999979e+001,-1.234520e-003,0.000000e+000,5.395415e-003,0.000000e+000,3,9.519154e-001,1.825000e+000,,,,,,,,,,,,,,,,,,0,5.000000e+000,5.000000e-001,2,1,3.780365e-003,0,0,0,
1473125844.730,,-7.000000e+004,2.000249e+001,-1.235438e-003,0.000000e+000,5.780356e-003,0.000000e+000,3,9.513273e-001,1.825000e+000,,,,,,,,,,,,,,,,,,0,5.000000e+000,5.000000e-001,2,1,1.619339e-003,0,0,0,
1473126029.427,,-6.000000e+004,2.000006e+001,-1.237887e-003,0.000000e+000,4.533262e-003,0.000000e+000,3,9.521762e-001,1.825000e+000,,,,,,,,,,,,,,,,,,0,5.000000e+000,5.000000e-001,2,1,1.070023e-003,0,0,0,
1473126054.606,,-6.000000e+004,2.000141e+001,-1.236922e-003,0.000000e+000,4.360812e-003,0.000000e+000,3,9.519629e-001,1.825000e+000,,,,,,,,,,,,,,,,,,0,5.000000e+000,5.000000e-001,2,1,5.397797e-004,0,0,0,
1473126234.094,,-5.000000e+004,1.999898e+001,-1.236961e-003,0.000000e+000,3.404659e-003,0.000000e+000,3,9.524626e-001,1.825000e+000,,,,,,,,,,,,,,,,,,0,5.000000e+000,5.000000e-001,2,1,3.240585e-003,0,0,0,
1473126259.526,,-5.000000e+004,2.000061e+001,-1.237103e-003,0.000000e+000,3.438630e-003,0.000000e+000,3,9.525119e-001,1.825000e+000,,,,,,,,,,,,,,,,,,0,5.000000e+000,5.000000e-001,2,1,2.149582e-003,0,0,0,
1473126438.221,,-4.000000e+004,1.999791e+001,-1.235497e-003,0.000000e+000,2.753435e-003,0.000000e+000,3,9.526258e-001,1.825000e+000,,,,,,,,,,,,,,,,,,0,5.000000e+000,5.000000e-001,2,1,7.551193e-003,0,1,0,
1473126463.923,,-4.000000e+004,2.000871e+001,-1.236106e-003,0.000000e+000,2.968065e-003,0.000000e+000,3,9.524217e-001,1.825000e+000,,,,,,,,,,,,,,,,,,0,5.000000e+000,5.000000e-001,2,1,1.189041e-002,0,1,0,
1473126639.378,,-3.000000e+004,2.000924e+001,-1.230743e-003,0.000000e+000,1.870008e-003,0.000000e+000,3,9.533047e-001,1.825000e+000,,,,,,,,,,,,,,,,,,0,5.000000e+000,5.000000e-001,2,1,4.329681e-003,0,1,0,
1473126664.560,,-3.000000e+004,2.001330e+001,-1.231197e-003,0.000000e+000,2.052404e-003,0.000000e+000,3,9.533569e-001,1.825000e+000,,,,,,,,,,,,,,,,,,0,5.000000e+000,5.000000e-001,2,1,5.416870e-004,0,1,0,
1473126838.753,,-2.000000e+004,2.000114e+001,-1.223704e-003,0.000000e+000,1.302926e-003,0.000000e+000,3,9.536380e-001,1.825000e+000,,,,,,,,,,,,,,,,,,0,5.000000e+000,5.000000e-001,2,1,2.161026e-003,0,1,0,
1473126863.435,,-2.000000e+004,2.000411e+001,-1.223999e-003,0.000000e+000,1.975718e-003,0.000000e+000,3,9.539953e-001,1.825000e+000,,,,,,,,,,,,,,,,,,0,5.000000e+000,5.000000e-001,2,1,5.397797e-004,0,1,0,
1473127034.836,,-1.000000e+004,2.000141e+001,-1.207834e-003,0.000000e+000,3.600875e-004,0.000000e+000,3,9.534599e-001,1.825000e+000,,,,,,,,,,,,,,,,,,0,5.000000e+000,5.000000e-001,2,1,5.397797e-004,0,1,0,
1473127060.622,,-1.000000e+004,2.000330e+001,-1.207289e-003,0.000000e+000,7.384576e-004,0.000000e+000,3,9.537621e-001,1.825000e+000,,,,,,,,,,,,,,,,,,0,5.000000e+000,5.000000e-001,2,1,2.159119e-003,0,0,0,
1473127194.328,,-9.000000e+003,2.000141e+001,-1.205786e-003,0.000000e+000,6.456819e-004,0.000000e+000,3,9.540428e-001,1.825000e+000,,,,,,,,,,,,,,,,,,0,5.000000e+000,5.000000e-001,2,1,5.397797e-004,0,0,0,
1473127217.506,,-9.000000e+003,2.000195e+001,-1.205835e-003,0.000000e+000,8.869158e-004,0.000000e+000,3,9.536512e-001,1.825000e+000,,,,,,,,,,,,,,,,,,0,5.000000e+000,5.000000e-001,2,1,1.619339e-003,0,0,0,
1473127354.962,,-7.000000e+003,1.999925e+001,-1.198529e-003,0.000000e+000,1.003975e-003,0.000000e+000,3,9.535418e-001,1.825000e+000,,,,,,,,,,,,,,,,,,0,5.000000e+000,5.000000e-001,2,1,1.619339e-003,0,0,0,
1473127380.423,,-7.000000e+003,2.000114e+001,-1.198885e-003,0.000000e+000,6.521394e-004,0.000000e+000,3,9.537643e-001,1.825000e+000,,,,,,,,,,,,,,,,,,0,5.000000e+000,5.000000e-001,2,1,1.079559e-003,0,0,0,
1473127515.117,,-5.000000e+003,1.999979e+001,-1.190703e-003,0.000000e+000,9.689459e-004,0.000000e+000,3,9.534557e-001,1.825000e+000,,,,,,,,,,,,,,,,,,0,5.000000e+000,5.000000e-001,2,1,5.283356e-004,0,0,0,
1473127538.497,,-5.000000e+003,2.000249e+001,-1.190540e-003,0.000000e+000,8.760661e-004,0.000000e+000,3,9.539828e-001,1.825000e+000,,,,,,,,,,,,,,,,,,0,5.000000e+000,5.000000e-001,2,1,5.397797e-004,0,0,0,
1473127673.795,,-3.000000e+003,1.999736e+001,-1.176681e-003,0.000000e+000,1.297717e-003,0.000000e+000,3,9.549254e-001,1.825000e+000,,,,,,,,,,,,,,,,,,0,5.000000e+000,5.000000e-001,2,1,2.159119e-003,0,0,0,
1473127699.223,,-3.000000e+003,2.000087e+001,-1.176180e-003,0.000000e+000,1.236016e-003,0.000000e+000,3,9.550059e-001,1.825000e+000,,,,,,,,,,,,,,,,,,0,5.000000e+000,5.000000e-001,2,1,5.397797e-004,0,0,0,
1473127836.924,,-1.000000e+003,1.999952e+001,-1.140484e-003,0.000000e+000,2.639336e-003,0.000000e+000,3,9.621222e-001,1.825000e+000,,,,,,,,,,,,,,,,,,0,5.000000e+000,5.000000e-001,2,1,1.070023e-003,0,0,0,
1473127862.351,,-1.000000e+003,2.000060e+001,-1.140591e-003,0.000000e+000,2.507162e-003,0.000000e+000,3,9.623970e-001,1.825000e+000,,,,,,,,,,,,,,,,,,0,5.000000e+000,5.000000e-001,2,1,3.231049e-003,0,0,0,
1473128001.541,,-7.000000e+002,2.000141e+001,-1.127968e-003,0.000000e+000,3.410280e-003,0.000000e+000,3,9.648851e-001,1.825000e+000,,,,,,,,,,,,,,,,,,0,5.000000e+000,5.000000e-001,2,1,2.700806e-003,0,1,0,
1473128026.970,,-7.000000e+002,1.999979e+001,-1.127913e-003,0.000000e+000,3.142879e-003,0.000000e+000,3,9.651969e-001,1.825000e+000,,,,,,,,,,,,,,,,,,0,5.000000e+000,5.000000e-001,2,1,5.283356e-004,0,1,0,
1473128159.859,,-6.000000e+002,2.000843e+001,-1.120367e-003,0.000000e+000,3.764728e-003,0.000000e+000,3,9.667554e-001,1.825000e+000,,,,,,,,,,,,,,,,,,0,5.000000e+000,5.000000e-001,2,1,3.780365e-003,0,1,0,
1473128187.191,,-6.000000e+002,2.001032e+001,-1.120699e-003,0.000000e+000,3.472611e-003,0.000000e+000,3,9.671889e-001,1.825000e+000,,,,,,,,,,,,,,,,,,0,5.000000e+000,5.000000e-001,2,1,4.310608e-003,0,1,0,
1473128314.130,,-5.000000e+002,1.999871e+001,-1.113629e-003,0.000000e+000,3.830676e-003,0.000000e+000,3,9.690500e-001,1.825000e+000,,,,,,,,,,,,,,,,,,0,5.000000e+000,5.000000e-001,2,1,5.493164e-004,0,1,0,
1473128339.558,,-5.000000e+002,2.000168e+001,-1.113553e-003,0.000000e+000,3.560062e-003,0.000000e+000,3,9.690614e-001,1.825000e+000,,,,,,,,,,,,,,,,,,0,5.000000e+000,5.000000e-001,2,1,1.079559e-003,0,1,0,
1473128475.310,,-4.000000e+002,2.000357e+001,-1.101617e-003,0.000000e+000,4.098714e-003,0.000000e+000,3,9.709191e-001,1.825000e+000,,,,,,,,,,,,,,,,,,0,5.000000e+000,5.000000e-001,2,1,2.698898e-003,0,1,0,
1473128498.512,,-4.000000e+002,2.000546e+001,-1.102768e-003,0.000000e+000,3.822138e-003,0.000000e+000,3,9.712657e-001,1.825000e+000,,,,,,,,,,,,,,,,,,0,5.000000e+000,5.000000e-001,2,1,0.000000e+000,0,1,0,
1473128630.739,,-3.000000e+002,1.999548e+001,-1.088766e-003,0.000000e+000,4.638353e-003,0.000000e+000,3,9.736255e-001,1.825000e+000,,,,,,,,,,,,,,,,,,0,5.000000e+000,5.000000e-001,2,1,5.302429e-004,0,0,0,
1473128655.716,,-3.000000e+002,1.999925e+001,-1.087164e-003,0.000000e+000,4.749336e-003,0.000000e+000,3,9.729336e-001,1.825000e+000,,,,,,,,,,,,,,,,,,0,5.000000e+000,5.000000e-001,2,1,1.619339e-003,0,0,0,
1473128788.220,,-2.000000e+002,2.000060e+001,-1.066270e-003,0.000000e+000,4.144787e-003,0.000000e+000,3,9.773593e-001,1.825000e+000,,,,,,,,,,,,,,,,,,0,5.000000e+000,5.000000e-001,2,1,3.231049e-003,0,0,0,
1473128813.692,,-2.000000e+002,2.000222e+001,-1.067177e-003,0.000000e+000,4.527257e-003,0.000000e+000,3,9.766955e-001,1.825000e+000,,,,,,,,,,,,,,,,,,0,5.000000e+000,5.000000e-001,2,1,1.079559e-003,0,0,0,
1473128939.426,,-1.800000e+002,2.000033e+001,-1.059938e-003,0.000000e+000,4.315532e-003,0.000000e+000,3,9.782366e-001,1.825000e+000,,,,,,,,,,,,,,,,,,0,5.000000e+000,5.000000e-001,2,1,5.416870e-004,0,0,0,
1473128965.358,,-1.800000e+002,2.000195e+001,-1.058934e-003,0.000000e+000,4.959594e-003,0.000000e+000,3,9.772408e-001,1.825000e+000,,,,,,,,,,,,,,,,,,0,5.000000e+000,5.000000e-001,2,1,5.397797e-004,0,0,0,
1473129092.336,,-1.600000e+002,2.000060e+001,-1.052124e-003,0.000000e+000,4.845579e-003,0.000000e+000,3,9.774008e-001,1.825000e+000,,,,,,,,,,,,,,,,,,0,5.000000e+000,5.000000e-001,2,1,0.000000e+000,0,0,0,
1473129120.015,,-1.600000e+002,1.999278e+001,-1.052438e-003,0.000000e+000,4.918930e-003,0.000000e+000,3,9.780138e-001,1.825000e+000,,,,,,,,,,,,,,,,,,0,5.000000e+000,5.000000e-001,2,1,1.024055e-002,0,0,0,
1473129239.245,,-1.400000e+002,1.999817e+001,-1.044979e-003,0.000000e+000,4.941782e-003,0.000000e+000,3,9.784200e-001,1.825000e+000,,,,,,,,,,,,,,,,,,0,5.000000e+000,5.000000e-001,2,1,5.397797e-004,0,0,0,
1473129264.926,,-1.400000e+002,2.000141e+001,-1.044988e-003,0.000000e+000,4.948339e-003,0.000000e+000,3,9.783302e-001,1.825000e+000,,,,,,,,,,,,,,,,,,0,5.000000e+000,5.000000e-001,2,1,5.397797e-004,0,0,0,
1473129394.056,,-1.200000e+002,1.999979e+001,-1.035813e-003,0.000000e+000,5.126300e-003,0.000000e+000,3,9.795048e-001,1.825000e+000,,,,,,,,,,,,,,,,,,0,5.000000e+000,5.000000e-001,2,1,1.611710e-003,0,0,0,
1473129418.822,,-1.200000e+002,1.999925e+001,-1.035821e-003,0.000000e+000,5.179145e-003,0.000000e+000,3,9.791399e-001,1.825000e+000,,,,,,,,,,,,,,,,,,0,5.000000e+000,5.000000e-001,2,1,1.619339e-003,0,0,0,
1473129540.369,,-1.000000e+002,2.000357e+001,-1.026101e-003,0.000000e+000,4.887692e-003,0.000000e+000,3,9.806021e-001,1.825000e+000,,,,,,,,,,,,,,,,,,0,5.000000e+000,5.000000e-001,2,1,2.698898e-003,0,1,0,
1473129562.746,,-1.000000e+002,1.999952e+001,-1.025398e-003,0.000000e+000,5.106559e-003,0.000000e+000,3,9.802256e-001,1.825000e+000,,,,,,,,,,,,,,,,,,0,5.000000e+000,5.000000e-001,2,1,4.320145e-003,0,1,0,
1473129688.581,,-8.000000e+001,2.000438e+001,-1.013354e-003,0.000000e+000,5.390483e-003,0.000000e+000,3,9.807230e-001,1.825000e+000,,,,,,,,,,,,,,,,,,0,5.000000e+000,5.000000e-001,2,1,3.240585e-003,0,1,0,
1473129711.562,,-8.000000e+001,2.000627e+001,-1.014070e-003,0.000000e+000,5.500042e-003,0.000000e+000,3,9.805719e-001,1.825000e+000,,,,,,,,,,,,,,,,,,0,5.000000e+000,5.000000e-001,2,1,1.619339e-003,0,1,0,
1473129833.751,,-6.000000e+001,2.000924e+001,-9.993329e-004,0.000000e+000,5.753750e-003,0.000000e+000,3,9.813826e-001,1.825000e+000,,,,,,,,,,,,,,,,,,0,5.000000e+000,5.000000e-001,2,1,3.240585e-003,0,1,0,
1473129857.700,,-6.000000e+001,2.000681e+001,-9.992941e-004,0.000000e+000,5.542522e-003,0.000000e+000,3,9.812992e-001,1.825000e+000,,,,,,,,,,,,,,,,,,0,5.000000e+000,5.000000e-001,2,1,5.397797e-004,0,1,0,
1473129976.393,,-4.000000e+001,2.000141e+001,-9.822320e-004,0.000000e+000,5.722560e-003,0.000000e+000,3,9.823741e-001,1.825000e+000,,,,,,,,,,,,,,,,,,0,5.000000e+000,5.000000e-001,2,1,2.700806e-003,0,1,0,
1473130000.608,,-4.000000e+001,2.000492e+001,-9.823041e-004,0.000000e+000,5.419100e-003,0.000000e+000,3,9.820451e-001,1.825000e+000,,,,,,,,,,,,,,,,,,0,5.000000e+000,5.000000e-001,2,1,0.000000e+000,0,1,0,
1473130127.797,,-2.000000e+001,2.000195e+001,-9.713469e-004,0.000000e+000,3.061109e-002,0.000000e+000,3,7.510974e-001,1.825000e+000,,,,,,,,,,,,,,,,,,0,5.000000e+000,5.000000e-001,2,1,1.619339e-003,0,1,0,
1473130151.475,,-2.000000e+001,2.000196e+001,-9.598976e-004,0.000000e+000,5.240244e-003,0.000000e+000,3,9.833990e-001,1.825000e+000,,,,,,,,,,,,,,,,,,0,5.000000e+000,5.000000e-001,2,1,4.848480e-003,0,0,0,
1473130268.184,,0.000000e+000,2.000114e+001,-9.319203e-004,0.000000e+000,5.834642e-003,0.000000e+000,3,9.836817e-001,1.825000e+000,,,,,,,,,,,,,,,,,,0,5.000000e+000,5.000000e-001,2,1,0.000000e+000,0,0,0,
1473130291.861,,0.000000e+000,2.000114e+001,-9.316918e-004,0.000000e+000,5.401406e-003,0.000000e+000,3,9.837661e-001,1.825000e+000,,,,,,,,,,,,,,,,,,0,5.000000e+000,5.000000e-001,2,1,1.079559e-003,0,0,0,
1473130412.549,,2.000000e+001,1.999952e+001,-8.916165e-004,0.000000e+000,5.536223e-003,0.000000e+000,3,9.831213e-001,1.825000e+000,,,,,,,,,,,,,,,,,,0,5.000000e+000,5.000000e-001,2,1,2.161026e-003,0,0,0,
1473130439.540,,2.000000e+001,2.000060e+001,-8.892657e-004,0.000000e+000,5.496627e-003,0.000000e+000,3,9.846523e-001,1.825000e+000,,,,,,,,,,,,,,,,,,0,5.000000e+000,5.000000e-001,2,1,1.081467e-003,0,0,0,
1473130569.257,,4.000000e+001,2.000060e+001,-8.227803e-004,0.000000e+000,6.362986e-003,0.000000e+000,3,9.839099e-001,1.825000e+000,,,,,,,,,,,,,,,,,,0,5.000000e+000,5.000000e-001,2,1,1.081467e-003,0,0,0,
1473130593.741,,4.000000e+001,2.000141e+001,-8.215377e-004,0.000000e+000,6.551524e-003,0.000000e+000,3,9.841718e-001,1.825000e+000,,,,,,,,,,,,,,,,,,0,5.000000e+000,5.000000e-001,2,1,5.397797e-004,0,0,0,
1473130714.215,,6.000000e+001,1.999763e+001,-5.849157e-004,0.000000e+000,6.841344e-003,0.000000e+000,3,9.858158e-001,1.825000e+000,,,,,,,,,,,,,,,,,,0,5.000000e+000,5.000000e-001,2,1,5.397797e-004,0,0,0,
1473130741.143,,6.000000e+001,1.999979e+001,-5.713308e-004,0.000000e+000,5.974431e-003,0.000000e+000,3,9.861675e-001,1.825000e+000,,,,,,,,,,,,,,,,,,0,5.000000e+000,5.000000e-001,2,1,1.611710e-003,0,0,0,
1473130871.817,,8.000000e+001,1.999952e+001,5.124303e-004,0.000000e+000,3.708107e-003,0.000000e+000,3,9.782752e-001,1.825000e+000,,,,,,,,,,,,,,,,,,0,5.000000e+000,5.000000e-001,2,1,2.161026e-003,0,0,0,
1473130897.886,,8.000000e+001,1.999979e+001,5.185868e-004,0.000000e+000,3.608735e-003,0.000000e+000,3,9.777923e-001,1.825000e+000,,,,,,,,,,,,,,,,,,0,5.000000e+000,5.000000e-001,2,1,2.700806e-003,0,0,0,
1473131021.074,,1.000000e+002,2.000276e+001,6.698663e-004,0.000000e+000,5.358513e-003,0.000000e+000,3,9.771035e-001,1.825000e+000,,,,,,,,,,,,,,,,,,0,5.000000e+000,5.000000e-001,2,1,0.000000e+000,0,1,0,
1473131048.253,,1.000000e+002,2.000573e+001,6.742672e-004,0.000000e+000,4.696893e-003,0.000000e+000,3,9.780948e-001,1.825000e+000,,,,,,,,,,,,,,,,,,0,5.000000e+000,5.000000e-001,2,1,5.397797e-004,0,1,0,
1473131169.484,,1.200000e+002,2.000222e+001,7.630755e-004,0.000000e+000,3.664771e-003,0.000000e+000,3,9.781420e-001,1.825000e+000,,,,,,,,,,,,,,,,,,0,5.000000e+000,5.000000e-001,2,1,1.079559e-003,0,1,0,
1473131193.238,,1.200000e+002,2.000519e+001,7.669224e-004,0.000000e+000,4.640610e-003,0.000000e+000,3,9.774958e-001,1.825000e+000,,,,,,,,,,,,,,,,,,0,5.000000e+000,5.000000e-001,2,1,1.621246e-003,0,1,0,
1473131319.676,,1.400000e+002,2.001167e+001,8.315318e-004,0.000000e+000,4.580813e-003,0.000000e+000,3,9.775120e-001,1.825000e+000,,,,,,,,,,,,,,,,,,0,5.000000e+000,5.000000e-001,2,1,5.302429e-004,0,1,0,
1473131344.039,,1.400000e+002,2.001005e+001,8.345232e-004,0.000000e+000,4.528627e-003,0.000000e+000,3,9.769234e-001,1.825000e+000,,,,,,,,,,,,,,,,,,0,5.000000e+000,5.000000e-001,2,1,1.621246e-003,0,1,0,
1473131463.884,,1.600000e+002,1.999899e+001,8.815994e-004,0.000000e+000,4.462667e-003,0.000000e+000,3,9.773960e-001,1.825000e+000,,,,,,,,,,,,,,,,,,0,5.000000e+000,5.000000e-001,2,1,0.000000e+000,0,1,0,
1473131486.562,,1.600000e+002,2.000330e+001,8.839013e-004,0.000000e+000,4.371041e-003,0.000000e+000,3,9.769905e-001,1.825000e+000,,,,,,,,,,,,,,,,,,0,5.000000e+000,5.000000e-001,2,1,1.079559e-003,0,1,0,
1473131607.802,,1.800000e+002,2.000357e+001,9.203955e-004,0.000000e+000,4.531279e-003,0.000000e+000,3,9.762229e-001,1.825000e+000,,,,,,,,,,,,,,,,,,0,5.000000e+000,5.000000e-001,2,1,5.397797e-004,0,1,0,
1473131652.702,,1.800000e+002,2.000141e+001,9.237591e-004,0.000000e+000,4.383543e-003,0.000000e+000,3,9.767521e-001,1.825000e+000,,,,,,,,,,,,,,,,,,0,5.000000e+000,5.000000e-001,2,1,2.700806e-003,0,1,0,
1473131775.691,,2.000000e+002,1.999979e+001,9.512759e-004,0.000000e+000,4.698099e-003,0.000000e+000,3,9.767753e-001,1.825000e+000,,,,,,,,,,,,,,,,,,0,5.000000e+000,5.000000e-001,2,1,3.780365e-003,0,0,0,
1473131801.119,,2.000000e+002,2.000222e+001,9.529092e-004,0.000000e+000,4.665354e-003,0.000000e+000,3,9.762080e-001,1.825000e+000,,,,,,,,,,,,,,,,,,0,5.000000e+000,5.000000e-001,2,1,1.079559e-003,0,0,0,
1473131927.058,,3.000000e+002,2.000006e+001,1.030168e-003,0.000000e+000,3.562405e-003,0.000000e+000,3,9.742996e-001,1.825000e+000,,,,,,,,,,,,,,,,,,0,5.000000e+000,5.000000e-001,2,1,1.070023e-003,0,0,0,
1473131952.172,,3.000000e+002,2.000034e+001,1.034237e-003,0.000000e+000,4.640635e-003,0.000000e+000,3,9.732516e-001,1.825000e+000,,,,,,,,,,,,,,,,,,0,5.000000e+000,5.000000e-001,2,1,1.609802e-003,0,0,0,
1473132083.762,,4.000000e+002,2.000060e+001,1.070267e-003,0.000000e+000,4.205945e-003,0.000000e+000,3,9.711842e-001,1.825000e+000,,,,,,,,,,,,,,,,,,0,5.000000e+000,5.000000e-001,2,1,1.081467e-003,0,0,0,
1473132108.491,,4.000000e+002,2.000114e+001,1.070555e-003,0.000000e+000,4.175015e-003,0.000000e+000,3,9.708089e-001,1.825000e+000,,,,,,,,,,,,,,,,,,0,5.000000e+000,5.000000e-001,2,1,2.161026e-003,0,0,0,
1473132235.930,,5.000000e+002,1.999008e+001,1.090470e-003,0.000000e+000,4.083766e-003,0.000000e+000,3,9.687464e-001,1.825000e+000,,,,,,,,,,,,,,,,,,0,5.000000e+000,5.000000e-001,2,1,2.700806e-003,0,0,0,
1473132260.858,,5.000000e+002,2.000006e+001,1.090846e-003,0.000000e+000,4.039185e-003,0.000000e+000,3,9.686808e-001,1.825000e+000,,,,,,,,,,,,,,,,,,0,5.000000e+000,5.000000e-001,2,1,0.000000e+000,0,0,0,
1473132392.339,,6.000000e+002,1.999899e+001,1.104928e-003,0.000000e+000,3.703561e-003,0.000000e+000,3,9.667656e-001,1.825000e+000,,,,,,,,,,,,,,,,,,0,5.000000e+000,5.000000e-001,2,1,1.091003e-003,0,0,0,
1473132420.272,,6.000000e+002,2.000141e+001,1.104993e-003,0.000000e+000,3.786546e-003,0.000000e+000,3,9.668487e-001,1.825000e+000,,,,,,,,,,,,,,,,,,0,5.000000e+000,5.000000e-001,2,1,5.397797e-004,0,0,0,
1473132547.770,,7.000000e+002,1.999925e+001,1.156614e-003,0.000000e+000,5.303441e-002,0.000000e+000,3,8.007129e-001,1.825000e+000,,,,,,,,,,,,,,,,,,0,5.000000e+000,5.000000e-001,2,1,1.619339e-003,0,1,0,
1473132573.758,,7.000000e+002,2.000573e+001,1.115596e-003,0.000000e+000,3.377424e-003,0.000000e+000,3,9.654505e-001,1.825000e+000,,,,,,,,,,,,,,,,,,0,5.000000e+000,5.000000e-001,2,1,2.700806e-003,0,1,0,
1473132700.644,,1.000000e+003,2.000411e+001,1.132677e-003,0.000000e+000,3.233427e-003,0.000000e+000,3,9.621217e-001,1.825000e+000,,,,,,,,,,,,,,,,,,0,5.000000e+000,5.000000e-001,2,1,2.700806e-003,0,1,0,
1473132725.681,,1.000000e+003,2.000465e+001,1.132813e-003,0.000000e+000,3.199568e-003,0.000000e+000,3,9.621189e-001,1.825000e+000,,,,,,,,,,,,,,,,,,0,5.000000e+000,5.000000e-001,2,1,2.700806e-003,0,1,0,
1473132860.399,,3.000000e+003,2.001195e+001,1.174794e-003,0.000000e+000,1.825461e-003,0.000000e+000,3,9.554098e-001,1.825000e+000,,,,,,,,,,,,,,,,,,0,5.000000e+000,5.000000e-001,2,1,3.250122e-003,0,1,0,
1473132887.332,,3.000000e+003,2.000627e+001,1.174931e-003,0.000000e+000,1.971850e-003,0.000000e+000,3,9.550595e-001,1.825000e+000,,,,,,,,,,,,,,,,,,0,5.000000e+000,5.000000e-001,2,1,5.397797e-004,0,1,0,
1473133023.274,,5.000000e+003,2.000168e+001,1.189982e-003,0.000000e+000,1.872173e-003,0.000000e+000,3,9.539728e-001,1.825000e+000,,,,,,,,,,,,,,,,,,0,5.000000e+000,5.000000e-001,2,1,1.079559e-003,0,1,0,
1473133047.703,,5.000000e+003,2.000384e+001,1.190014e-003,0.000000e+000,1.604296e-003,0.000000e+000,3,9.541374e-001,1.825000e+000,,,,,,,,,,,,,,,,,,0,5.000000e+000,5.000000e-001,2,1,1.079559e-003,0,1,0,
1473133185.147,,7.000000e+003,2.000195e+001,1.199499e-003,0.000000e+000,1.814223e-003,0.000000e+000,3,9.538249e-001,1.825000e+000,,,,,,,,,,,,,,,,,,0,5.000000e+000,5.000000e-001,2,1,1.619339e-003,0,1,0,
1473133209.325,,7.000000e+003,2.000357e+001,1.199349e-003,0.000000e+000,2.034732e-003,0.000000e+000,3,9.535137e-001,1.825000e+000,,,,,,,,,,,,,,,,,,0,5.000000e+000,5.000000e-001,2,1,1.619339e-003,0,0,0,
1473133347.015,,9.000000e+003,2.000114e+001,1.205776e-003,0.000000e+000,2.030745e-003,0.000000e+000,3,9.538267e-001,1.825000e+000,,,,,,,,,,,,,,,,,,0,5.000000e+000,5.000000e-001,2,1,0.000000e+000,0,0,0,
1473133373.217,,9.000000e+003,2.000168e+001,1.205675e-003,0.000000e+000,1.894549e-003,0.000000e+000,3,9.537821e-001,1.825000e+000,,,,,,,,,,,,,,,,,,0,5.000000e+000,5.000000e-001,2,1,2.159119e-003,0,0,0,
1473133504.661,,1.000000e+004,2.000033e+001,1.208170e-003,0.000000e+000,1.998276e-003,0.000000e+000,3,9.537370e-001,1.825000e+000,,,,,,,,,,,,,,,,,,0,5.000000e+000,5.000000e-001,2,1,5.416870e-004,0,0,0,
1473133530.339,,1.000000e+004,2.000222e+001,1.210826e-003,0.000000e+000,2.321942e-003,0.000000e+000,3,9.534383e-001,1.825000e+000,,,,,,,,,,,,,,,,,,0,5.000000e+000,5.000000e-001,2,1,0.000000e+000,0,0,0,
1473133701.345,,2.000000e+004,1.999979e+001,1.219921e-003,0.000000e+000,2.103536e-003,0.000000e+000,3,9.517984e-001,1.825000e+000,,,,,,,,,,,,,,,,,,0,5.000000e+000,5.000000e-001,2,1,5.283356e-004,0,0,0,
1473133726.524,,2.000000e+004,2.000114e+001,1.224169e-003,0.000000e+000,2.683132e-003,0.000000e+000,3,9.535977e-001,1.825000e+000,,,,,,,,,,,,,,,,,,0,5.000000e+000,5.000000e-001,2,1,0.000000e+000,0,0,0,
1473133902.531,,3.000000e+004,1.999736e+001,1.231862e-003,0.000000e+000,3.357665e-003,0.000000e+000,3,9.534084e-001,1.825000e+000,,,,,,,,,,,,,,,,,,0,5.000000e+000,5.000000e-001,2,1,2.159119e-003,0,0,0,
1473133926.898,,3.000000e+004,2.000006e+001,1.231550e-003,0.000000e+000,3.398150e-003,0.000000e+000,3,9.533943e-001,1.825000e+000,,,,,,,,,,,,,,,,,,0,5.000000e+000,5.000000e-001,2,1,2.151489e-003,0,0,0,
1473134103.954,,4.000000e+004,2.000087e+001,1.235367e-003,0.000000e+000,4.324757e-003,0.000000e+000,3,9.531509e-001,1.825000e+000,,,,,,,,,,,,,,,,,,0,5.000000e+000,5.000000e-001,2,1,5.397797e-004,0,1,0,
1473134127.439,,4.000000e+004,2.000843e+001,1.235850e-003,0.000000e+000,4.195034e-003,0.000000e+000,3,9.527924e-001,1.825000e+000,,,,,,,,,,,,,,,,,,0,5.000000e+000,5.000000e-001,2,1,1.619339e-003,0,1,0,
1473134308.919,,5.000000e+004,2.000681e+001,1.236718e-003,0.000000e+000,4.991422e-003,0.000000e+000,3,9.528763e-001,1.825000e+000,,,,,,,,,,,,,,,,,,0,5.000000e+000,5.000000e-001,2,1,2.708435e-003,0,1,0,
1473134333.356,,5.000000e+004,2.001086e+001,1.236756e-003,0.000000e+000,4.857592e-003,0.000000e+000,3,9.520765e-001,1.825000e+000,,,,,,,,,,,,,,,,,,0,5.000000e+000,5.000000e-001,2,1,1.089096e-003,0,1,0,
1473134512.554,,6.000000e+004,1.999871e+001,1.237032e-003,0.000000e+000,3.967337e-003,0.000000e+000,3,9.512798e-001,1.825000e+000,,,,,,,,,,,,,,,,,,0,5.000000e+000,5.000000e-001,2,1,1.630783e-003,0,1,0,
1473134536.233,,6.000000e+004,2.000222e+001,1.241937e-003,0.000000e+000,7.780451e-003,0.000000e+000,3,9.498699e-001,1.825000e+000,,,,,,,,,,,,,,,,,,0,5.000000e+000,5.000000e-001,2,1,1.079559e-003,0,1,0,
1473134713.993,,7.000000e+004,2.000141e+001,1.239392e-003,0.000000e+000,5.377584e-003,0.000000e+000,3,9.505391e-001,1.825000e+000,,,,,,,,,,,,,,,,,,0,5.000000e+000,5.000000e-001,2,1,2.700806e-003,0,1,0,
1473134737.921,,7.000000e+004,2.000465e+001,1.236934e-003,0.000000e+000,5.195669e-003,0.000000e+000,3,9.517456e-001,1.825000e+000,,,,,,,,,,,,,,,,,,0,5.000000e+000,5.000000e-001,2,1,5.397797e-004,0,1,0,
1473134751.135,,7.000000e+004,2.000303e+001,1.238682e-003,0.000000e+000,5.409742e-003,0.000000e+000,3,9.500771e-001,1.825000e+000,,,,,,,,,,,,,,,,,,0,5.000000e+000,5.000000e-001,2,1,1.619339e-003,0,1,0,