File: data/A344/dat/A344_cool_zero_field_500_160908.rso.dat
[Header]
TITLE,MPMS RSO Measurement
BYAPP,MPMS Measurement,1.1,Summary
FILEOPENTIME, 1473347048.203000 9/9/2016, 3:04:08 AM

INFO, APPNAME, MPMS MultiVu Application, Revision 1.61,  Build 082

INFO, NAME, A344
INFO, WEIGHT, 10.500
INFO, AREA, 1.000
INFO, LENGTH, 1.000
INFO, SHAPE, 0
INFO, COMMENT, m = 0.0105g
INFO, SEQUENCE FILE: cool_zero_field_magnet_reset_120K-5K.seq


INFO, BACKGROUND DATA FILE:, None


STARTUPAXIS,X,4,LINEAR,AUTO,0.000000,0.000000
STARTUPAXIS,Y1,5,LINEAR,AUTO,0.000000,0.000000


STARTUPGROUP,Longitudinal
FIELDGROUP,Longitudinal,1,2,3,4,5,6,7,8,9,10,11,19,20,21,22,23,35
FIELDGROUP,Transverse,1,2,3,4,12,13,14,15,16,17,18,24,25,26,27,28,35

PLOT_APPEARANCE,ALL,HORZ_GRID_ON,VERT_GRID_ON,MARKERS_AND_LINES

[Data]
Time,Comment,Field (Oe),Temperature (K),Long Moment (emu),Long Scan Std Dev,Long Offset (cm),Long Offset Std Dev,Long Algorithm,Long Reg Fit,Long Reg Factor,Trans Moment (emu),Trans Scan Std Dev,Trans Offset (cm),Trans Offset Std Dev,Trans Algorithm,Trans Reg Fit,Trans Reg Factor,Long Moment [w/o ABS] (emu),Long Scan Std Dev [w/o ABS],Long Offset [w/o ABS] (cm),Long Offset Std Dev [w/o ABS],Long Reg Fit [w/o ABS],Trans Moment [w/o ABS] (emu),Trans Scan Std Dev [w/o ABS],Trans Offset [w/o ABS] (cm),Trans Offset Std Dev [w/o ABS],Trans Reg Fit [w/o ABS],RSO Position (deg),Amplitude (cm),Frequency,Cycles to Average,Scans per Measurement,Delta Temp (K),Error,EC Comp. Running,Using ABS,
1473347048.188,,0.000000e+000,1.200040e+002,-1.242562e-006,0.000000e+000,1.261223e-001,0.000000e+000,3,1.980168e-001,1.825000e+000,,,,,,,,,,,,,,,,,,0,5.000000e+000,5.000000e-001,2,1,6.599426e-003,0,1,0,
1473347061.197,,0.000000e+000,1.199991e+002,-1.226331e-006,0.000000e+000,1.268194e-001,0.000000e+000,3,1.795736e-001,1.825000e+000,,,,,,,,,,,,,,,,,,0,5.000000e+000,5.000000e-001,2,1,3.303528e-003,0,1,0,
1473347072.965,,0.000000e+000,1.200056e+002,-1.257427e-006,0.000000e+000,1.251087e-001,0.000000e+000,3,2.098242e-001,1.825000e+000,,,,,,,,,,,,,,,,,,0,5.000000e+000,5.000000e-001,2,1,9.895325e-003,0,1,0,
1473347086.335,,0.000000e+000,1.200056e+002,-1.236284e-006,0.000000e+000,1.287464e-001,0.000000e+000,3,1.813056e-001,1.825000e+000,,,,,,,,,,,,,,,,,,0,5.000000e+000,5.000000e-001,2,1,3.303528e-003,0,1,0,
1473347337.578,,0.000000e+000,1.143997e+002,-1.172295e-006,0.000000e+000,1.293960e-001,0.000000e+000,3,1.260907e-001,1.825000e+000,,,,,,,,,,,,,,,,,,0,5.000000e+000,5.000000e-001,2,1,6.629028e-001,0,1,0,
1473347351.542,,0.000000e+000,1.135558e+002,-1.245780e-006,0.000000e+000,1.194249e-001,0.000000e+000,3,1.767643e-001,1.825000e+000,,,,,,,,,,,,,,,,,,0,5.000000e+000,5.000000e-001,2,1,7.390976e-001,0,1,0,
1473347365.687,,0.000000e+000,1.127525e+002,-1.224333e-006,0.000000e+000,1.225077e-001,0.000000e+000,3,1.758834e-001,1.825000e+000,,,,,,,,,,,,,,,,,,0,5.000000e+000,5.000000e-001,2,1,6.151962e-001,0,1,0,
1473347379.010,,0.000000e+000,1.118993e+002,-1.261377e-006,0.000000e+000,1.354692e-001,0.000000e+000,3,2.120867e-001,1.825000e+000,,,,,,,,,,,,,,,,,,0,5.000000e+000,5.000000e-001,2,1,8.043976e-001,0,1,0,
1473347416.726,,0.000000e+000,1.093275e+002,-1.234633e-006,0.000000e+000,1.093998e-001,0.000000e+000,3,1.567437e-001,1.825000e+000,,,,,,,,,,,,,,,,,,0,5.000000e+000,5.000000e-001,2,1,7.258987e-001,0,1,0,
1473347429.986,,0.000000e+000,1.084353e+002,-1.291462e-006,0.000000e+000,1.095461e-001,0.000000e+000,3,2.421360e-001,1.825000e+000,,,,,,,,,,,,,,,,,,0,5.000000e+000,5.000000e-001,2,1,7.201996e-001,0,1,0,
1473347441.235,,0.000000e+000,1.074969e+002,-1.209819e-006,0.000000e+000,1.261192e-001,0.000000e+000,3,1.661045e-001,1.825000e+000,,,,,,,,,,,,,,,,,,0,5.000000e+000,5.000000e-001,2,1,7.696991e-001,0,1,0,
1473347454.211,,0.000000e+000,1.065632e+002,-1.207636e-006,0.000000e+000,1.244735e-001,0.000000e+000,3,1.410502e-001,1.825000e+000,,,,,,,,,,,,,,,,,,0,5.000000e+000,5.000000e-001,2,1,7.703018e-001,0,1,0,
1473347485.927,,0.000000e+000,1.042284e+002,-1.278632e-006,0.000000e+000,1.322302e-001,0.000000e+000,3,2.300474e-001,1.825000e+000,,,,,,,,,,,,,,,,,,0,5.000000e+000,5.000000e-001,2,1,8.092041e-001,0,1,0,
1473347497.895,,0.000000e+000,1.034250e+002,-1.257389e-006,0.000000e+000,1.320741e-001,0.000000e+000,3,1.958549e-001,1.825000e+000,,,,,,,,,,,,,,,,,,0,5.000000e+000,5.000000e-001,2,1,7.975006e-001,0,1,0,
1473347512.359,,0.000000e+000,1.021261e+002,-1.225436e-006,0.000000e+000,1.277858e-001,0.000000e+000,3,1.917428e-001,1.825000e+000,,,,,,,,,,,,,,,,,,0,5.000000e+000,5.000000e-001,2,1,5.924988e-001,0,1,0,
1473347525.112,,0.000000e+000,1.011951e+002,-1.274965e-006,0.000000e+000,1.287942e-001,0.000000e+000,3,2.156399e-001,1.825000e+000,,,,,,,,,,,,,,,,,,0,5.000000e+000,5.000000e-001,2,1,7.986984e-001,0,1,0,
1473347545.608,,0.000000e+000,9.953526e+001,-1.233147e-006,0.000000e+000,1.226137e-001,0.000000e+000,3,1.668090e-001,1.825000e+000,,,,,,,,,,,,,,,,,,0,5.000000e+000,5.000000e-001,2,1,8.120956e-001,0,1,0,
1473347559.573,,0.000000e+000,9.814314e+001,-1.231160e-006,0.000000e+000,1.230745e-001,0.000000e+000,3,1.748199e-001,1.825000e+000,,,,,,,,,,,,,,,,,,0,5.000000e+000,5.000000e-001,2,1,1.079414e+000,0,1,0,
1473347574.037,,0.000000e+000,9.698262e+001,-1.282263e-006,0.000000e+000,1.299071e-001,0.000000e+000,3,2.401924e-001,1.825000e+000,,,,,,,,,,,,,,,,,,0,5.000000e+000,5.000000e-001,2,1,8.338089e-001,0,1,0,
1473347587.502,,0.000000e+000,9.568293e+001,-1.225935e-006,0.000000e+000,1.300302e-001,0.000000e+000,3,1.610258e-001,1.825000e+000,,,,,,,,,,,,,,,,,,0,5.000000e+000,5.000000e-001,2,1,8.598633e-001,0,1,0,
1473347634.520,,0.000000e+000,9.193718e+001,-1.241654e-006,0.000000e+000,1.194401e-001,0.000000e+000,3,2.016606e-001,1.825000e+000,,,,,,,,,,,,,,,,,,0,5.000000e+000,5.000000e-001,2,1,5.832062e-001,0,1,0,
1473347647.272,,0.000000e+000,9.075954e+001,-1.243429e-006,0.000000e+000,1.208671e-001,0.000000e+000,3,2.079583e-001,1.825000e+000,,,,,,,,,,,,,,,,,,0,5.000000e+000,5.000000e-001,2,1,8.770447e-001,0,0,0,
1473347658.784,,0.000000e+000,8.980218e+001,-1.237510e-006,0.000000e+000,1.177984e-001,0.000000e+000,3,1.989737e-001,1.825000e+000,,,,,,,,,,,,,,,,,,0,5.000000e+000,5.000000e-001,2,1,6.547394e-001,0,0,0,
1473347672.748,,0.000000e+000,8.864164e+001,-1.237121e-006,0.000000e+000,1.211044e-001,0.000000e+000,3,1.893629e-001,1.825000e+000,,,,,,,,,,,,,,,,,,0,5.000000e+000,5.000000e-001,2,1,8.555603e-001,0,0,0,
1473347684.962,,0.000000e+000,8.769847e+001,-1.230872e-006,0.000000e+000,1.229619e-001,0.000000e+000,3,1.951223e-001,1.825000e+000,,,,,,,,,,,,,,,,,,0,5.000000e+000,5.000000e-001,2,1,6.388626e-001,0,0,0,
1473347698.927,,0.000000e+000,8.655201e+001,-1.227585e-006,0.000000e+000,1.184456e-001,0.000000e+000,3,1.906307e-001,1.825000e+000,,,,,,,,,,,,,,,,,,0,5.000000e+000,5.000000e-001,2,1,8.179016e-001,0,0,0,
1473347712.332,,0.000000e+000,8.538559e+001,-1.237098e-006,0.000000e+000,1.117825e-001,0.000000e+000,3,2.019798e-001,1.825000e+000,,,,,,,,,,,,,,,,,,0,5.000000e+000,5.000000e-001,2,1,6.522598e-001,0,0,0,
1473347727.405,,0.000000e+000,8.425583e+001,-1.238260e-006,0.000000e+000,1.125798e-001,0.000000e+000,3,1.963663e-001,1.825000e+000,,,,,,,,,,,,,,,,,,0,5.000000e+000,5.000000e-001,2,1,8.430405e-001,0,0,0,
1473347739.869,,0.000000e+000,8.314979e+001,-1.225290e-006,0.000000e+000,1.157575e-001,0.000000e+000,3,1.960912e-001,1.825000e+000,,,,,,,,,,,,,,,,,,0,5.000000e+000,5.000000e-001,2,1,6.089020e-001,0,0,0,
1473347753.583,,0.000000e+000,8.214970e+001,-1.222383e-006,0.000000e+000,1.110902e-001,0.000000e+000,3,1.873755e-001,1.825000e+000,,,,,,,,,,,,,,,,,,0,5.000000e+000,5.000000e-001,2,1,1.007431e+000,0,0,0,
1473347767.548,,0.000000e+000,8.100183e+001,-1.228646e-006,0.000000e+000,1.138391e-001,0.000000e+000,3,1.916898e-001,1.825000e+000,,,,,,,,,,,,,,,,,,0,5.000000e+000,5.000000e-001,2,1,9.685593e-001,0,0,0,
1473347781.262,,0.000000e+000,8.017471e+001,-1.213486e-006,0.000000e+000,1.068211e-001,0.000000e+000,3,1.753468e-001,1.825000e+000,,,,,,,,,,,,,,,,,,0,5.000000e+000,5.000000e-001,2,1,3.003235e-001,0,0,0,
1473347913.523,,0.000000e+000,8.013156e+001,-1.198508e-006,0.000000e+000,1.158818e-001,0.000000e+000,3,1.689297e-001,1.825000e+000,,,,,,,,,,,,,,,,,,0,5.000000e+000,5.000000e-001,2,1,9.162903e-003,0,0,0,
1473347927.282,,0.000000e+000,8.010861e+001,-1.204364e-006,0.000000e+000,1.148995e-001,0.000000e+000,3,1.833212e-001,1.825000e+000,,,,,,,,,,,,,,,,,,0,5.000000e+000,5.000000e-001,2,1,1.836395e-002,0,0,0,
1473347939.746,,0.000000e+000,8.009560e+001,-1.201055e-006,0.000000e+000,1.153239e-001,0.000000e+000,3,1.800114e-001,1.825000e+000,,,,,,,,,,,,,,,,,,0,5.000000e+000,5.000000e-001,2,1,7.644653e-003,0,0,0,
1473347950.960,,0.000000e+000,8.009714e+001,-1.208761e-006,0.000000e+000,1.170072e-001,0.000000e+000,3,1.868466e-001,1.825000e+000,,,,,,,,,,,,,,,,,,0,5.000000e+000,5.000000e-001,2,1,1.071167e-002,0,0,0,
1473348141.136,,0.000000e+000,8.001156e+001,-1.228137e-006,0.000000e+000,1.149949e-001,0.000000e+000,3,2.062599e-001,1.825000e+000,,,,,,,,,,,,,,,,,,0,5.000000e+000,5.000000e-001,2,1,4.577637e-003,0,1,0,
1473348153.708,,0.000000e+000,8.001309e+001,-1.191662e-006,0.000000e+000,1.125966e-001,0.000000e+000,3,1.716911e-001,1.825000e+000,,,,,,,,,,,,,,,,,,0,5.000000e+000,5.000000e-001,2,1,1.518250e-003,0,1,0,
1473348165.958,,0.000000e+000,8.000927e+001,-1.235646e-006,0.000000e+000,1.174363e-001,0.000000e+000,3,2.031960e-001,1.825000e+000,,,,,,,,,,,,,,,,,,0,5.000000e+000,5.000000e-001,2,1,0.000000e+000,0,1,0,
1473348178.673,,0.000000e+000,8.000928e+001,-1.185300e-006,0.000000e+000,1.150819e-001,0.000000e+000,3,1.669800e-001,1.825000e+000,,,,,,,,,,,,,,,,,,0,5.000000e+000,5.000000e-001,2,1,3.051758e-003,0,1,0,
1473348339.152,,0.000000e+000,7.640551e+001,-1.206543e-006,0.000000e+000,1.123071e-001,0.000000e+000,3,1.905833e-001,1.825000e+000,,,,,,,,,,,,,,,,,,0,5.000000e+000,5.000000e-001,2,1,6.333618e-001,0,1,0,
1473348351.677,,0.000000e+000,7.567249e+001,-1.154565e-006,0.000000e+000,1.172575e-001,0.000000e+000,3,1.419083e-001,1.825000e+000,,,,,,,,,,,,,,,,,,0,5.000000e+000,5.000000e-001,2,1,5.585480e-001,0,1,0,
1473348363.391,,0.000000e+000,7.511179e+001,-1.164868e-006,0.000000e+000,1.113435e-001,0.000000e+000,3,1.670437e-001,1.825000e+000,,,,,,,,,,,,,,,,,,0,5.000000e+000,5.000000e-001,2,1,2.962494e-001,0,1,0,
1473348375.855,,0.000000e+000,7.446951e+001,-1.143095e-006,0.000000e+000,1.179821e-001,0.000000e+000,3,1.399361e-001,1.825000e+000,,,,,,,,,,,,,,,,,,0,5.000000e+000,5.000000e-001,2,1,4.297409e-001,0,1,0,
1473348397.070,,0.000000e+000,7.328467e+001,-1.140458e-006,0.000000e+000,1.192902e-001,0.000000e+000,3,1.338658e-001,1.825000e+000,,,,,,,,,,,,,,,,,,0,5.000000e+000,5.000000e-001,2,1,4.411316e-001,0,1,0,
1473348409.723,,0.000000e+000,7.261089e+001,-1.077047e-006,0.000000e+000,1.204007e-001,0.000000e+000,3,7.754099e-002,1.825000e+000,,,,,,,,,,,,,,,,,,0,5.000000e+000,5.000000e-001,2,1,6.018448e-001,0,1,0,
1473348421.545,,0.000000e+000,7.192577e+001,-1.050222e-006,0.000000e+000,1.071807e-001,0.000000e+000,3,5.108697e-002,1.825000e+000,,,,,,,,,,,,,,,,,,0,5.000000e+000,5.000000e-001,2,1,4.172897e-001,0,1,0,
1473348434.759,,0.000000e+000,7.128036e+001,-1.011754e-006,0.000000e+000,1.204082e-001,0.000000e+000,3,3.637748e-003,1.825000e+000,,,,,,,,,,,,,,,,,,0,5.000000e+000,5.000000e-001,2,1,5.722504e-001,0,1,0,
1473348454.474,,0.000000e+000,7.003123e+001,-9.265186e-007,0.000000e+000,1.200853e-001,0.000000e+000,3,0.000000e+000,1.825000e+000,,,,,,,,,,,,,,,,,,0,5.000000e+000,5.000000e-001,2,1,5.128632e-001,0,1,0,
1473348467.205,,0.000000e+000,6.949561e+001,-8.308080e-007,0.000000e+000,1.197042e-001,0.000000e+000,3,0.000000e+000,1.825000e+000,,,,,,,,,,,,,,,,,,0,5.000000e+000,5.000000e-001,2,1,5.583801e-001,0,1,0,
1473348479.170,,0.000000e+000,6.883126e+001,-6.664297e-007,0.000000e+000,1.626262e-001,0.000000e+000,3,0.000000e+000,1.825000e+000,,,,,,,,,,,,,,,,,,0,5.000000e+000,5.000000e-001,2,1,5.258026e-001,0,1,0,
1473348491.134,,0.000000e+000,6.815303e+001,-2.058619e-007,0.000000e+000,2.337568e+000,0.000000e+000,3,0.000000e+000,1.825000e+000,,,,,,,,,,,,,,,,,,0,5.000000e+000,5.000000e-001,2,1,5.316772e-001,0,1,0,
1473348511.349,,0.000000e+000,6.704823e+001,2.193216e-006,0.000000e+000,-7.361316e-002,0.000000e+000,3,4.919451e-001,1.825000e+000,,,,,,,,,,,,,,,,,,0,5.000000e+000,5.000000e-001,2,1,3.892517e-001,0,1,0,
1473348523.851,,0.000000e+000,6.641037e+001,7.593800e-006,0.000000e+000,8.912530e-003,0.000000e+000,3,8.233921e-001,1.825000e+000,,,,,,,,,,,,,,,,,,0,5.000000e+000,5.000000e-001,2,1,3.865204e-001,0,1,0,
1473348536.815,,0.000000e+000,6.585254e+001,1.806999e-005,0.000000e+000,1.844829e-002,0.000000e+000,3,9.086775e-001,1.825000e+000,,,,,,,,,,,,,,,,,,0,5.000000e+000,5.000000e-001,2,1,4.959412e-001,0,1,0,
1473348550.530,,0.000000e+000,6.523805e+001,3.342714e-005,0.000000e+000,2.006429e-002,0.000000e+000,3,9.427991e-001,1.825000e+000,,,,,,,,,,,,,,,,,,0,5.000000e+000,5.000000e-001,2,1,4.706573e-001,0,1,0,
1473348591.101,,0.000000e+000,6.328131e+001,7.259176e-005,0.000000e+000,1.754695e-002,0.000000e+000,3,9.703025e-001,1.825000e+000,,,,,,,,,,,,,,,,,,0,5.000000e+000,5.000000e-001,2,1,5.883598e-001,0,1,0,
1473348604.334,,0.000000e+000,6.268859e+001,8.130072e-005,0.000000e+000,1.723681e-002,0.000000e+000,3,9.721212e-001,1.825000e+000,,,,,,,,,,,,,,,,,,0,5.000000e+000,5.000000e-001,2,1,5.970688e-001,0,0,0,
1473348617.481,,0.000000e+000,6.203635e+001,8.925093e-005,0.000000e+000,1.707016e-002,0.000000e+000,3,9.736541e-001,1.825000e+000,,,,,,,,,,,,,,,,,,0,5.000000e+000,5.000000e-001,2,1,4.840279e-001,0,0,0,
1473348631.053,,0.000000e+000,6.141170e+001,9.686844e-005,0.000000e+000,1.669536e-002,0.000000e+000,3,9.748979e-001,1.825000e+000,,,,,,,,,,,,,,,,,,0,5.000000e+000,5.000000e-001,2,1,3.568382e-001,0,0,0,
1473348643.517,,0.000000e+000,6.079759e+001,1.034140e-004,0.000000e+000,1.650441e-002,0.000000e+000,3,9.755741e-001,1.825000e+000,,,,,,,,,,,,,,,,,,0,5.000000e+000,5.000000e-001,2,1,6.083794e-001,0,0,0,
1473348655.731,,0.000000e+000,6.020126e+001,1.095119e-004,0.000000e+000,1.633050e-002,0.000000e+000,3,9.762540e-001,1.825000e+000,,,,,,,,,,,,,,,,,,0,5.000000e+000,5.000000e-001,2,1,3.914528e-001,0,0,0,
1473348666.386,,0.000000e+000,5.969189e+001,1.146189e-004,0.000000e+000,1.614739e-002,0.000000e+000,3,9.767258e-001,1.825000e+000,,,,,,,,,,,,,,,,,,0,5.000000e+000,5.000000e-001,2,1,6.273079e-001,0,0,0,
1473348680.209,,0.000000e+000,5.906576e+001,1.210697e-004,0.000000e+000,1.599175e-002,0.000000e+000,3,9.771971e-001,1.825000e+000,,,,,,,,,,,,,,,,,,0,5.000000e+000,5.000000e-001,2,1,6.249504e-001,0,0,0,
1473348700.428,,0.000000e+000,5.788382e+001,1.301981e-004,0.000000e+000,1.563383e-002,0.000000e+000,3,9.776501e-001,1.825000e+000,,,,,,,,,,,,,,,,,,0,5.000000e+000,5.000000e-001,2,1,5.074921e-001,0,0,0,
1473348712.392,,0.000000e+000,5.732846e+001,1.356483e-004,0.000000e+000,1.537495e-002,0.000000e+000,3,9.779425e-001,1.825000e+000,,,,,,,,,,,,,,,,,,0,5.000000e+000,5.000000e-001,2,1,3.756409e-001,0,0,0,
1473348726.606,,0.000000e+000,5.650475e+001,1.419670e-004,0.000000e+000,1.515846e-002,0.000000e+000,3,9.784048e-001,1.825000e+000,,,,,,,,,,,,,,,,,,0,5.000000e+000,5.000000e-001,2,1,5.362206e-001,0,0,0,
1473348740.258,,0.000000e+000,5.578638e+001,1.479668e-004,0.000000e+000,1.495954e-002,0.000000e+000,3,9.785248e-001,1.825000e+000,,,,,,,,,,,,,,,,,,0,5.000000e+000,5.000000e-001,2,1,3.992882e-001,0,0,0,
1473348760.581,,0.000000e+000,5.474744e+001,1.568685e-004,0.000000e+000,1.463267e-002,0.000000e+000,3,9.789165e-001,1.825000e+000,,,,,,,,,,,,,,,,,,0,5.000000e+000,5.000000e-001,2,1,6.605492e-001,0,0,0,
1473348774.327,,0.000000e+000,5.386813e+001,1.629666e-004,0.000000e+000,1.435880e-002,0.000000e+000,3,9.791715e-001,1.825000e+000,,,,,,,,,,,,,,,,,,0,5.000000e+000,5.000000e-001,2,1,5.436401e-001,0,0,0,
1473348788.589,,0.000000e+000,5.311515e+001,1.691781e-004,0.000000e+000,1.411286e-002,0.000000e+000,3,9.793527e-001,1.825000e+000,,,,,,,,,,,,,,,,,,0,5.000000e+000,5.000000e-001,2,1,6.852798e-001,0,0,0,
1473348801.068,,0.000000e+000,5.242468e+001,1.746506e-004,0.000000e+000,1.394316e-002,0.000000e+000,3,9.795024e-001,1.825000e+000,,,,,,,,,,,,,,,,,,0,5.000000e+000,5.000000e-001,2,1,6.956596e-001,0,0,0,
1473348815.784,,0.000000e+000,5.150088e+001,1.810695e-004,0.000000e+000,1.364775e-002,0.000000e+000,3,9.796613e-001,1.825000e+000,,,,,,,,,,,,,,,,,,0,5.000000e+000,5.000000e-001,2,1,5.780296e-001,0,0,0,
1473348829.249,,0.000000e+000,5.065443e+001,1.868970e-004,0.000000e+000,1.335779e-002,0.000000e+000,3,9.797846e-001,1.825000e+000,,,,,,,,,,,,,,,,,,0,5.000000e+000,5.000000e-001,2,1,5.639801e-001,0,0,0,
1473348841.963,,0.000000e+000,4.992385e+001,1.925163e-004,0.000000e+000,1.319008e-002,0.000000e+000,3,9.799459e-001,1.825000e+000,,,,,,,,,,,,,,,,,,0,5.000000e+000,5.000000e-001,2,1,5.982208e-001,0,0,0,
1473348855.677,,0.000000e+000,4.905045e+001,1.984707e-004,0.000000e+000,1.288680e-002,0.000000e+000,3,9.800216e-001,1.825000e+000,,,,,,,,,,,,,,,,,,0,5.000000e+000,5.000000e-001,2,1,5.761909e-001,0,0,0,
1473348869.937,,0.000000e+000,4.816975e+001,2.047255e-004,0.000000e+000,1.263298e-002,0.000000e+000,3,9.802175e-001,1.825000e+000,,,,,,,,,,,,,,,,,,0,5.000000e+000,5.000000e-001,2,1,6.009483e-001,0,0,0,
1473348884.651,,0.000000e+000,4.726662e+001,2.110744e-004,0.000000e+000,1.243114e-002,0.000000e+000,3,9.803268e-001,1.825000e+000,,,,,,,,,,,,,,,,,,0,5.000000e+000,5.000000e-001,2,1,6.072693e-001,0,0,0,
1473348898.901,,0.000000e+000,4.636753e+001,2.172693e-004,0.000000e+000,1.210694e-002,0.000000e+000,3,9.804499e-001,1.825000e+000,,,,,,,,,,,,,,,,,,0,5.000000e+000,5.000000e-001,2,1,6.165390e-001,0,0,0,
1473348911.365,,0.000000e+000,4.553020e+001,2.225953e-004,0.000000e+000,1.192801e-002,0.000000e+000,3,9.804597e-001,1.825000e+000,,,,,,,,,,,,,,,,,,0,5.000000e+000,5.000000e-001,2,1,7.636909e-001,0,0,0,
1473348926.845,,0.000000e+000,4.462618e+001,2.292066e-004,0.000000e+000,1.160926e-002,0.000000e+000,3,9.806036e-001,1.825000e+000,,,,,,,,,,,,,,,,,,0,5.000000e+000,5.000000e-001,2,1,7.629509e-001,0,0,0,
1473348940.060,,0.000000e+000,4.369646e+001,2.347571e-004,0.000000e+000,1.134207e-002,0.000000e+000,3,9.807370e-001,1.825000e+000,,,,,,,,,,,,,,,,,,0,5.000000e+000,5.000000e-001,2,1,7.827797e-001,0,0,0,
1473348954.833,,0.000000e+000,4.277229e+001,2.410100e-004,0.000000e+000,1.105412e-002,0.000000e+000,3,9.807738e-001,1.825000e+000,,,,,,,,,,,,,,,,,,0,5.000000e+000,5.000000e-001,2,1,7.793999e-001,0,0,0,
1473348967.832,,0.000000e+000,4.183196e+001,2.464007e-004,0.000000e+000,1.086696e-002,0.000000e+000,3,9.808912e-001,1.825000e+000,,,,,,,,,,,,,,,,,,0,5.000000e+000,5.000000e-001,2,1,7.888985e-001,0,0,0,
1473348981.046,,0.000000e+000,4.104528e+001,2.518372e-004,0.000000e+000,1.065175e-002,0.000000e+000,3,9.809322e-001,1.825000e+000,,,,,,,,,,,,,,,,,,0,5.000000e+000,5.000000e-001,2,1,7.844620e-001,0,0,0,
1473348994.510,,0.000000e+000,4.009901e+001,2.572421e-004,0.000000e+000,1.037079e-002,0.000000e+000,3,9.809657e-001,1.825000e+000,,,,,,,,,,,,,,,,,,0,5.000000e+000,5.000000e-001,2,1,7.948494e-001,0,0,0,
1473349021.989,,0.000000e+000,3.832746e+001,2.681263e-004,0.000000e+000,9.930096e-003,0.000000e+000,3,9.813327e-001,1.825000e+000,,,,,,,,,,,,,,,,,,0,5.000000e+000,5.000000e-001,2,1,5.003204e-001,0,1,0,
1473349033.634,,0.000000e+000,3.758183e+001,2.726084e-004,0.000000e+000,9.780549e-003,0.000000e+000,3,9.812949e-001,1.825000e+000,,,,,,,,,,,,,,,,,,0,5.000000e+000,5.000000e-001,2,1,6.517105e-001,0,1,0,
1473349045.456,,0.000000e+000,3.676496e+001,2.769368e-004,0.000000e+000,9.571763e-003,0.000000e+000,3,9.813814e-001,1.825000e+000,,,,,,,,,,,,,,,,,,0,5.000000e+000,5.000000e-001,2,1,6.522179e-001,0,1,0,
1473349058.678,,0.000000e+000,3.604266e+001,2.816258e-004,0.000000e+000,9.330601e-003,0.000000e+000,3,9.814972e-001,1.825000e+000,,,,,,,,,,,,,,,,,,0,5.000000e+000,5.000000e-001,2,1,4.787292e-001,0,1,0,
1473349071.142,,0.000000e+000,3.525416e+001,2.857504e-004,0.000000e+000,9.180511e-003,0.000000e+000,3,9.815923e-001,1.825000e+000,,,,,,,,,,,,,,,,,,0,5.000000e+000,5.000000e-001,2,1,7.908821e-001,0,1,0,
1473349083.356,,0.000000e+000,3.447121e+001,2.897543e-004,0.000000e+000,8.974211e-003,0.000000e+000,3,9.815449e-001,1.825000e+000,,,,,,,,,,,,,,,,,,0,5.000000e+000,5.000000e-001,2,1,4.702606e-001,0,1,0,
1473349095.820,,0.000000e+000,3.376260e+001,2.936430e-004,0.000000e+000,8.823475e-003,0.000000e+000,3,9.815673e-001,1.825000e+000,,,,,,,,,,,,,,,,,,0,5.000000e+000,5.000000e-001,2,1,6.487312e-001,0,1,0,
1473349109.718,,0.000000e+000,3.287244e+001,2.978440e-004,0.000000e+000,8.682895e-003,0.000000e+000,3,9.816321e-001,1.825000e+000,,,,,,,,,,,,,,,,,,0,5.000000e+000,5.000000e-001,2,1,5.616608e-001,0,1,0,
1473349122.290,,0.000000e+000,3.218639e+001,3.014934e-004,0.000000e+000,8.557399e-003,0.000000e+000,3,9.816881e-001,1.825000e+000,,,,,,,,,,,,,,,,,,0,5.000000e+000,5.000000e-001,2,1,5.448112e-001,0,1,0,
1473349136.254,,0.000000e+000,3.136819e+001,3.053287e-004,0.000000e+000,8.288531e-003,0.000000e+000,3,9.817023e-001,1.825000e+000,,,,,,,,,,,,,,,,,,0,5.000000e+000,5.000000e-001,2,1,5.416203e-001,0,1,0,
1473349151.648,,0.000000e+000,3.063356e+001,3.094756e-004,0.000000e+000,8.172069e-003,0.000000e+000,3,9.816371e-001,1.825000e+000,,,,,,,,,,,,,,,,,,0,5.000000e+000,5.000000e-001,2,1,4.016705e-001,0,1,0,
1473349163.720,,0.000000e+000,2.996512e+001,3.126445e-004,0.000000e+000,8.002376e-003,0.000000e+000,3,9.816114e-001,1.825000e+000,,,,,,,,,,,,,,,,,,0,5.000000e+000,5.000000e-001,2,1,6.710701e-001,0,1,0,
1473349174.730,,0.000000e+000,2.922445e+001,3.154462e-004,0.000000e+000,7.824352e-003,0.000000e+000,3,9.817162e-001,1.825000e+000,,,,,,,,,,,,,,,,,,0,5.000000e+000,5.000000e-001,2,1,5.411110e-001,0,1,0,
1473349188.376,,0.000000e+000,2.855449e+001,3.187999e-004,0.000000e+000,7.733119e-003,0.000000e+000,3,9.817567e-001,1.825000e+000,,,,,,,,,,,,,,,,,,0,5.000000e+000,5.000000e-001,2,1,5.347004e-001,0,1,0,
1473349201.627,,0.000000e+000,2.782204e+001,3.220285e-004,0.000000e+000,7.575342e-003,0.000000e+000,3,9.817941e-001,1.825000e+000,,,,,,,,,,,,,,,,,,0,5.000000e+000,5.000000e-001,2,1,6.651211e-001,0,1,0,
1473349214.199,,0.000000e+000,2.716021e+001,3.249009e-004,0.000000e+000,7.497628e-003,0.000000e+000,3,9.818487e-001,1.825000e+000,,,,,,,,,,,,,,,,,,0,5.000000e+000,5.000000e-001,2,1,3.957195e-001,0,1,0,
1473349227.101,,0.000000e+000,2.657049e+001,3.277801e-004,0.000000e+000,7.349506e-003,0.000000e+000,3,9.818435e-001,1.825000e+000,,,,,,,,,,,,,,,,,,0,5.000000e+000,5.000000e-001,2,1,5.266399e-001,0,1,0,
1473349238.729,,0.000000e+000,2.584096e+001,3.304045e-004,0.000000e+000,7.243065e-003,0.000000e+000,3,9.818785e-001,1.825000e+000,,,,,,,,,,,,,,,,,,0,5.000000e+000,5.000000e-001,2,1,6.635208e-001,0,1,0,
1473349252.943,,0.000000e+000,2.510229e+001,3.334429e-004,0.000000e+000,7.095577e-003,0.000000e+000,3,9.819157e-001,1.825000e+000,,,,,,,,,,,,,,,,,,0,5.000000e+000,5.000000e-001,2,1,5.413284e-001,0,1,0,
1473349266.657,,0.000000e+000,2.431884e+001,3.365524e-004,0.000000e+000,7.046236e-003,0.000000e+000,3,9.819033e-001,1.825000e+000,,,,,,,,,,,,,,,,,,0,5.000000e+000,5.000000e-001,2,1,4.603710e-001,0,1,0,
1473349279.054,,0.000000e+000,2.356103e+001,3.393482e-004,0.000000e+000,6.902825e-003,0.000000e+000,3,9.819791e-001,1.825000e+000,,,,,,,,,,,,,,,,,,0,5.000000e+000,5.000000e-001,2,1,4.351196e-001,0,1,0,
1473349290.876,,0.000000e+000,2.315566e+001,3.409214e-004,0.000000e+000,6.769766e-003,0.000000e+000,3,9.820324e-001,1.825000e+000,,,,,,,,,,,,,,,,,,0,5.000000e+000,5.000000e-001,2,1,3.756199e-001,0,1,0,
1473349305.144,,0.000000e+000,2.258751e+001,3.428842e-004,0.000000e+000,6.809161e-003,0.000000e+000,3,9.820337e-001,1.825000e+000,,,,,,,,,,,,,,,,,,0,5.000000e+000,5.000000e-001,2,1,4.563713e-001,0,1,0,
1473349318.359,,0.000000e+000,2.181141e+001,3.457694e-004,0.000000e+000,6.660068e-003,0.000000e+000,3,9.820444e-001,1.825000e+000,,,,,,,,,,,,,,,,,,0,5.000000e+000,5.000000e-001,2,1,8.095303e-001,0,1,0,
1473349329.122,,0.000000e+000,2.115675e+001,3.482385e-004,0.000000e+000,6.569052e-003,0.000000e+000,3,9.821039e-001,1.825000e+000,,,,,,,,,,,,,,,,,,0,5.000000e+000,5.000000e-001,2,1,4.997692e-001,0,1,0,
1473349342.336,,0.000000e+000,2.059979e+001,3.496722e-004,0.000000e+000,6.486615e-003,0.000000e+000,3,9.822790e-001,1.825000e+000,,,,,,,,,,,,,,,,,,0,5.000000e+000,5.000000e-001,2,1,1.669502e-001,0,1,0,
1473349360.051,,0.000000e+000,2.014326e+001,3.512821e-004,0.000000e+000,6.461760e-003,0.000000e+000,3,9.820845e-001,1.825000e+000,,,,,,,,,,,,,,,,,,0,5.000000e+000,5.000000e-001,2,1,6.713905e-001,0,1,0,
1473349403.751,,0.000000e+000,1.716510e+001,3.603563e-004,0.000000e+000,6.105585e-003,0.000000e+000,3,9.820295e-001,1.825000e+000,,,,,,,,,,,,,,,,,,0,5.000000e+000,5.000000e-001,2,1,5.228100e-001,0,1,0,
1473349417.215,,0.000000e+000,1.650199e+001,3.621380e-004,0.000000e+000,6.022999e-003,0.000000e+000,3,9.820740e-001,1.825000e+000,,,,,,,,,,,,,,,,,,0,5.000000e+000,5.000000e-001,2,1,5.654011e-001,0,0,0,
1473349429.180,,0.000000e+000,1.619987e+001,3.625214e-004,0.000000e+000,5.975472e-003,0.000000e+000,3,9.821938e-001,1.825000e+000,,,,,,,,,,,,,,,,,,0,5.000000e+000,5.000000e-001,2,1,3.882980e-002,0,0,0,
1473349445.144,,0.000000e+000,1.609536e+001,3.627366e-004,0.000000e+000,6.034056e-003,0.000000e+000,3,9.820944e-001,1.825000e+000,,,,,,,,,,,,,,,,,,0,5.000000e+000,5.000000e-001,2,1,2.000799e-001,0,0,0,
1473349458.609,,0.000000e+000,1.542461e+001,3.653032e-004,0.000000e+000,5.980888e-003,0.000000e+000,3,9.820391e-001,1.825000e+000,,,,,,,,,,,,,,,,,,0,5.000000e+000,5.000000e-001,2,1,8.339500e-001,0,0,0,
1473349474.101,,0.000000e+000,1.397918e+001,3.681708e-004,0.000000e+000,5.898937e-003,0.000000e+000,3,9.820094e-001,1.825000e+000,,,,,,,,,,,,,,,,,,0,5.000000e+000,5.000000e-001,2,1,9.471998e-001,0,0,0,
1473349487.583,,0.000000e+000,1.274141e+001,3.703577e-004,0.000000e+000,5.807179e-003,0.000000e+000,3,9.820894e-001,1.825000e+000,,,,,,,,,,,,,,,,,,0,5.000000e+000,5.000000e-001,2,1,7.669096e-001,0,0,0,
1473349715.571,,0.000000e+000,1.499664e+001,3.655984e-004,0.000000e+000,5.999181e-003,0.000000e+000,3,9.821728e-001,1.825000e+000,,,,,,,,,,,,,,,,,,0,5.000000e+000,5.000000e-001,2,1,1.219749e-003,0,0,0,
1473349747.002,,0.000000e+000,1.499999e+001,3.656037e-004,0.000000e+000,6.067249e-003,0.000000e+000,3,9.822960e-001,1.825000e+000,,,,,,,,,,,,,,,,,,0,5.000000e+000,5.000000e-001,2,1,1.830101e-003,0,1,0,
1473349759.218,,0.000000e+000,1.500213e+001,3.656447e-004,0.000000e+000,6.050557e-003,0.000000e+000,3,9.821745e-001,1.825000e+000,,,,,,,,,,,,,,,,,,0,5.000000e+000,5.000000e-001,2,1,2.440453e-003,0,1,0,
1473349771.431,,0.000000e+000,1.500396e+001,3.656386e-004,0.000000e+000,6.022818e-003,0.000000e+000,3,9.822623e-001,1.825000e+000,,,,,,,,,,,,,,,,,,0,5.000000e+000,5.000000e-001,2,1,1.219749e-003,0,1,0,
1473349862.082,,0.000000e+000,1.500305e+001,3.656377e-004,0.000000e+000,6.064924e-003,0.000000e+000,3,9.822988e-001,1.825000e+000,,,,,,,,,,,,,,,,,,0,5.000000e+000,5.000000e-001,2,1,6.103516e-004,0,1,0,
1473349874.681,,0.000000e+000,1.500274e+001,3.656197e-004,0.000000e+000,6.017839e-003,0.000000e+000,3,9.822596e-001,1.825000e+000,,,,,,,,,,,,,,,,,,0,5.000000e+000,5.000000e-001,2,1,0.000000e+000,0,1,0,
1473349886.645,,0.000000e+000,1.500518e+001,3.656412e-004,0.000000e+000,6.008442e-003,0.000000e+000,3,9.822503e-001,1.825000e+000,,,,,,,,,,,,,,,,,,0,5.000000e+000,5.000000e-001,2,1,1.219749e-003,0,1,0,
1473349899.613,,0.000000e+000,1.500488e+001,3.656085e-004,0.000000e+000,6.013410e-003,0.000000e+000,3,9.822347e-001,1.825000e+000,,,,,,,,,,,,,,,,,,0,5.000000e+000,5.000000e-001,2,1,1.830101e-003,0,1,0,
1473349980.560,,0.000000e+000,1.345656e+001,3.691957e-004,0.000000e+000,5.949792e-003,0.000000e+000,3,9.822155e-001,1.825000e+000,,,,,,,,,,,,,,,,,,0,5.000000e+000,5.000000e-001,2,1,1.908598e-001,0,1,0,
1473350005.488,,0.000000e+000,1.296337e+001,3.701458e-004,0.000000e+000,5.874862e-003,0.000000e+000,3,9.821760e-001,1.825000e+000,,,,,,,,,,,,,,,,,,0,5.000000e+000,5.000000e-001,2,1,2.331495e-001,0,0,0,
1473350018.703,,0.000000e+000,1.270741e+001,3.706582e-004,0.000000e+000,5.892533e-003,0.000000e+000,3,9.821787e-001,1.825000e+000,,,,,,,,,,,,,,,,,,0,5.000000e+000,5.000000e-001,2,1,1.874905e-001,0,0,0,
1473350031.961,,0.000000e+000,1.245163e+001,3.711720e-004,0.000000e+000,5.812584e-003,0.000000e+000,3,9.821817e-001,1.825000e+000,,,,,,,,,,,,,,,,,,0,5.000000e+000,5.000000e-001,2,1,2.338600e-001,0,0,0,
1473350048.926,,0.000000e+000,1.212803e+001,3.717805e-004,0.000000e+000,5.839949e-003,0.000000e+000,3,9.822057e-001,1.825000e+000,,,,,,,,,,,,,,,,,,0,5.000000e+000,5.000000e-001,2,1,2.278996e-001,0,0,0,
1473350063.076,,0.000000e+000,1.187778e+001,3.722804e-004,0.000000e+000,5.852214e-003,0.000000e+000,3,9.822180e-001,1.825000e+000,,,,,,,,,,,,,,,,,,0,5.000000e+000,5.000000e-001,2,1,1.820898e-001,0,0,0,
1473350075.148,,0.000000e+000,1.165456e+001,3.726657e-004,0.000000e+000,5.853303e-003,0.000000e+000,3,9.822479e-001,1.825000e+000,,,,,,,,,,,,,,,,,,0,5.000000e+000,5.000000e-001,2,1,1.769199e-001,0,0,0,
1473350088.621,,0.000000e+000,1.139156e+001,3.731155e-004,0.000000e+000,5.806976e-003,0.000000e+000,3,9.821898e-001,1.825000e+000,,,,,,,,,,,,,,,,,,0,5.000000e+000,5.000000e-001,2,1,1.760798e-001,0,0,0,
1473350102.100,,0.000000e+000,1.114970e+001,3.735151e-004,0.000000e+000,5.814658e-003,0.000000e+000,3,9.821936e-001,1.825000e+000,,,,,,,,,,,,,,,,,,0,5.000000e+000,5.000000e-001,2,1,1.319103e-001,0,0,0,
1473350114.814,,0.000000e+000,1.091152e+001,3.738920e-004,0.000000e+000,5.812696e-003,0.000000e+000,3,9.822534e-001,1.825000e+000,,,,,,,,,,,,,,,,,,0,5.000000e+000,5.000000e-001,2,1,1.736794e-001,0,0,0,
1473350127.028,,0.000000e+000,1.069554e+001,3.742633e-004,0.000000e+000,5.818107e-003,0.000000e+000,3,9.822049e-001,1.825000e+000,,,,,,,,,,,,,,,,,,0,5.000000e+000,5.000000e-001,2,1,1.717596e-001,0,0,0,
1473350140.493,,0.000000e+000,1.047969e+001,3.746125e-004,0.000000e+000,5.802786e-003,0.000000e+000,3,9.822561e-001,1.825000e+000,,,,,,,,,,,,,,,,,,0,5.000000e+000,5.000000e-001,2,1,1.735697e-001,0,0,0,
1473350153.707,,0.000000e+000,1.022400e+001,3.749511e-004,0.000000e+000,5.774581e-003,0.000000e+000,3,9.822026e-001,1.825000e+000,,,,,,,,,,,,,,,,,,0,5.000000e+000,5.000000e-001,2,1,1.705103e-001,0,0,0,
1473350167.171,,0.000000e+000,1.001168e+001,3.753276e-004,0.000000e+000,5.800864e-003,0.000000e+000,3,9.822018e-001,1.825000e+000,,,,,,,,,,,,,,,,,,0,5.000000e+000,5.000000e-001,2,1,1.697521e-001,0,0,0,
1473350180.148,,0.000000e+000,9.784807e+000,3.756334e-004,0.000000e+000,5.798886e-003,0.000000e+000,3,9.822338e-001,1.825000e+000,,,,,,,,,,,,,,,,,,0,5.000000e+000,5.000000e-001,2,1,2.037516e-001,0,0,0,
1473350195.362,,0.000000e+000,9.518269e+000,3.759978e-004,0.000000e+000,5.765339e-003,0.000000e+000,3,9.821821e-001,1.825000e+000,,,,,,,,,,,,,,,,,,0,5.000000e+000,5.000000e-001,2,1,1.637526e-001,0,0,0,
1473350209.831,,0.000000e+000,9.296227e+000,3.763020e-004,0.000000e+000,5.775994e-003,0.000000e+000,3,9.822357e-001,1.825000e+000,,,,,,,,,,,,,,,,,,0,5.000000e+000,5.000000e-001,2,1,2.008743e-001,0,0,0,
1473350224.795,,0.000000e+000,9.056994e+000,3.766622e-004,0.000000e+000,5.779234e-003,0.000000e+000,3,9.822227e-001,1.825000e+000,,,,,,,,,,,,,,,,,,0,5.000000e+000,5.000000e-001,2,1,1.994495e-001,0,0,0,
1473350236.449,,0.000000e+000,8.843432e+000,3.768662e-004,0.000000e+000,5.798757e-003,0.000000e+000,3,9.822364e-001,1.825000e+000,,,,,,,,,,,,,,,,,,0,5.000000e+000,5.000000e-001,2,1,1.523380e-001,0,0,0,
1473350250.522,,0.000000e+000,8.617922e+000,3.771648e-004,0.000000e+000,5.777190e-003,0.000000e+000,3,9.822261e-001,1.825000e+000,,,,,,,,,,,,,,,,,,0,5.000000e+000,5.000000e-001,2,1,1.480598e-001,0,0,0,
1473350265.034,,0.000000e+000,8.416792e+000,3.773916e-004,0.000000e+000,5.757642e-003,0.000000e+000,3,9.822280e-001,1.825000e+000,,,,,,,,,,,,,,,,,,0,5.000000e+000,5.000000e-001,2,1,1.812286e-001,0,0,0,
1473350277.558,,0.000000e+000,8.220398e+000,3.776092e-004,0.000000e+000,5.772660e-003,0.000000e+000,3,9.822314e-001,1.825000e+000,,,,,,,,,,,,,,,,,,0,5.000000e+000,5.000000e-001,2,1,1.396170e-001,0,0,0,
1473350290.715,,0.000000e+000,8.047873e+000,3.778179e-004,0.000000e+000,5.736172e-003,0.000000e+000,3,9.821848e-001,1.825000e+000,,,,,,,,,,,,,,,,,,0,5.000000e+000,5.000000e-001,2,1,1.373234e-001,0,0,0,
1473350303.037,,0.000000e+000,7.880832e+000,3.780155e-004,0.000000e+000,5.772237e-003,0.000000e+000,3,9.821775e-001,1.825000e+000,,,,,,,,,,,,,,,,,,0,5.000000e+000,5.000000e-001,2,1,1.319470e-001,0,0,0,
1473350317.001,,0.000000e+000,7.689094e+000,3.782003e-004,0.000000e+000,5.740807e-003,0.000000e+000,3,9.822416e-001,1.825000e+000,,,,,,,,,,,,,,,,,,0,5.000000e+000,5.000000e-001,2,1,1.262817e-001,0,0,0,
1473350329.665,,0.000000e+000,7.534245e+000,3.783666e-004,0.000000e+000,5.752373e-003,0.000000e+000,3,9.822567e-001,1.825000e+000,,,,,,,,,,,,,,,,,,0,5.000000e+000,5.000000e-001,2,1,1.247883e-001,0,0,0,
1473350343.237,,0.000000e+000,7.372148e+000,3.785327e-004,0.000000e+000,5.722205e-003,0.000000e+000,3,9.822159e-001,1.825000e+000,,,,,,,,,,,,,,,,,,0,5.000000e+000,5.000000e-001,2,1,1.445017e-001,0,0,0,
1473350356.451,,0.000000e+000,7.215657e+000,3.786662e-004,0.000000e+000,5.778355e-003,0.000000e+000,3,9.822463e-001,1.825000e+000,,,,,,,,,,,,,,,,,,0,5.000000e+000,5.000000e-001,2,1,1.125283e-001,0,1,0,
1473350383.687,,0.000000e+000,6.925509e+000,3.789041e-004,0.000000e+000,5.743804e-003,0.000000e+000,3,9.823318e-001,1.825000e+000,,,,,,,,,,,,,,,,,,0,5.000000e+000,5.000000e-001,2,1,7.740307e-002,0,1,0,
1473350397.652,,0.000000e+000,6.804005e+000,3.790094e-004,0.000000e+000,5.713990e-003,0.000000e+000,3,9.823265e-001,1.825000e+000,,,,,,,,,,,,,,,,,,0,5.000000e+000,5.000000e-001,2,1,7.117605e-002,0,1,0,
1473350410.116,,0.000000e+000,6.689847e+000,3.791490e-004,0.000000e+000,5.727352e-003,0.000000e+000,3,9.822955e-001,1.825000e+000,,,,,,,,,,,,,,,,,,0,5.000000e+000,5.000000e-001,2,1,6.643867e-002,0,1,0,
1473350423.330,,0.000000e+000,6.580460e+000,3.792158e-004,0.000000e+000,5.729731e-003,0.000000e+000,3,9.822550e-001,1.825000e+000,,,,,,,,,,,,,,,,,,0,5.000000e+000,5.000000e-001,2,1,6.789589e-002,0,1,0,
1473350491.979,,0.000000e+000,5.852478e+000,3.797637e-004,0.000000e+000,5.697696e-003,0.000000e+000,3,9.823130e-001,1.825000e+000,,,,,,,,,,,,,,,,,,0,5.000000e+000,5.000000e-001,2,1,1.171722e-001,0,1,0,
1473350505.067,,0.000000e+000,5.700153e+000,3.798994e-004,0.000000e+000,5.674126e-003,0.000000e+000,3,9.822505e-001,1.825000e+000,,,,,,,,,,,,,,,,,,0,5.000000e+000,5.000000e-001,2,1,1.262021e-001,0,1,0,
1473350518.532,,0.000000e+000,5.513143e+000,3.799696e-004,0.000000e+000,5.740606e-003,0.000000e+000,3,9.823226e-001,1.825000e+000,,,,,,,,,,,,,,,,,,0,5.000000e+000,5.000000e-001,2,1,1.251869e-001,0,1,0,
1473350531.021,,0.000000e+000,5.358058e+000,3.801258e-004,0.000000e+000,5.663710e-003,0.000000e+000,3,9.822401e-001,1.825000e+000,,,,,,,,,,,,,,,,,,0,5.000000e+000,5.000000e-001,2,1,1.211987e-001,0,1,0,
1473350655.496,,0.000000e+000,5.041624e+000,3.802497e-004,0.000000e+000,5.696455e-003,0.000000e+000,3,9.822813e-001,1.825000e+000,,,,,,,,,,,,,,,,,,0,5.000000e+000,5.000000e-001,2,1,5.797863e-003,0,0,0,
1473350668.211,,0.000000e+000,5.048693e+000,3.802439e-004,0.000000e+000,5.699144e-003,0.000000e+000,3,9.823241e-001,1.825000e+000,,,,,,,,,,,,,,,,,,0,5.000000e+000,5.000000e-001,2,1,2.528667e-003,0,0,0,
1473350680.980,,0.000000e+000,5.053887e+000,3.802545e-004,0.000000e+000,5.624665e-003,0.000000e+000,3,9.822955e-001,1.825000e+000,,,,,,,,,,,,,,,,,,0,5.000000e+000,5.000000e-001,2,1,7.860184e-003,0,0,0,
1473350693.693,,0.000000e+000,5.058642e+000,3.802623e-004,0.000000e+000,5.641948e-003,0.000000e+000,3,9.823276e-001,1.825000e+000,,,,,,,,,,,,,,,,,,0,5.000000e+000,5.000000e-001,2,1,1.277924e-004,0,0,0,