File: data/A344/dat/A344_GdN_ZFC_500_Oe_160908.rso.dat
[Header]
TITLE,MPMS RSO Measurement
BYAPP,MPMS Measurement,1.1,Summary
FILEOPENTIME, 1473351021.298000 9/9/2016, 4:10:21 AM

INFO, APPNAME, MPMS MultiVu Application, Revision 1.61,  Build 082

INFO, NAME, A344
INFO, WEIGHT, 10.500
INFO, AREA, 1.000
INFO, LENGTH, 1.000
INFO, SHAPE, 0
INFO, COMMENT, m = 0.0105g
INFO, SEQUENCE FILE: ZFC_5K-120K.seq


INFO, BACKGROUND DATA FILE:, None


STARTUPAXIS,X,4,LINEAR,AUTO,0.000000,0.000000
STARTUPAXIS,Y1,5,LINEAR,AUTO,0.000000,0.000000


STARTUPGROUP,Longitudinal
FIELDGROUP,Longitudinal,1,2,3,4,5,6,7,8,9,10,11,19,20,21,22,23,35
FIELDGROUP,Transverse,1,2,3,4,12,13,14,15,16,17,18,24,25,26,27,28,35

PLOT_APPEARANCE,ALL,HORZ_GRID_ON,VERT_GRID_ON,MARKERS_AND_LINES

[Data]
Time,Comment,Field (Oe),Temperature (K),Long Moment (emu),Long Scan Std Dev,Long Offset (cm),Long Offset Std Dev,Long Algorithm,Long Reg Fit,Long Reg Factor,Trans Moment (emu),Trans Scan Std Dev,Trans Offset (cm),Trans Offset Std Dev,Trans Algorithm,Trans Reg Fit,Trans Reg Factor,Long Moment [w/o ABS] (emu),Long Scan Std Dev [w/o ABS],Long Offset [w/o ABS] (cm),Long Offset Std Dev [w/o ABS],Long Reg Fit [w/o ABS],Trans Moment [w/o ABS] (emu),Trans Scan Std Dev [w/o ABS],Trans Offset [w/o ABS] (cm),Trans Offset Std Dev [w/o ABS],Trans Reg Fit [w/o ABS],RSO Position (deg),Amplitude (cm),Frequency,Cycles to Average,Scans per Measurement,Delta Temp (K),Error,EC Comp. Running,Using ABS,
1473351021.297,,5.000000e+002,4.970631e+000,1.098326e-003,0.000000e+000,4.178550e-003,0.000000e+000,3,9.688616e-001,1.825000e+000,,,,,,,,,,,,,,,,,,0,5.000000e+000,5.000000e-001,2,1,2.316952e-003,0,0,0,
1473351034.011,,5.000000e+002,4.971606e+000,1.098500e-003,0.000000e+000,4.250739e-003,0.000000e+000,3,9.688304e-001,1.825000e+000,,,,,,,,,,,,,,,,,,0,5.000000e+000,5.000000e-001,2,1,8.549690e-004,0,0,0,
1473351047.475,,5.000000e+002,4.969351e+000,1.098561e-003,0.000000e+000,4.199551e-003,0.000000e+000,3,9.688636e-001,1.825000e+000,,,,,,,,,,,,,,,,,,0,5.000000e+000,5.000000e-001,2,1,2.683163e-003,0,1,0,
1473351059.120,,5.000000e+002,4.968191e+000,1.098732e-003,0.000000e+000,4.239358e-003,0.000000e+000,3,9.687921e-001,1.825000e+000,,,,,,,,,,,,,,,,,,0,5.000000e+000,5.000000e-001,2,1,3.647804e-004,0,1,0,
1473351161.705,,5.000000e+002,6.222412e+000,1.103560e-003,0.000000e+000,4.222406e-003,0.000000e+000,3,9.688609e-001,1.825000e+000,,,,,,,,,,,,,,,,,,0,5.000000e+000,5.000000e-001,2,1,1.234469e-001,0,1,0,
1473351174.436,,5.000000e+002,6.443357e+000,1.104791e-003,0.000000e+000,4.198098e-003,0.000000e+000,3,9.689192e-001,1.825000e+000,,,,,,,,,,,,,,,,,,0,5.000000e+000,5.000000e-001,2,1,1.571903e-001,0,1,0,
1473351186.650,,5.000000e+002,6.651884e+000,1.106000e-003,0.000000e+000,4.203786e-003,0.000000e+000,3,9.689106e-001,1.825000e+000,,,,,,,,,,,,,,,,,,0,5.000000e+000,5.000000e-001,2,1,1.061668e-001,0,1,0,
1473351201.615,,5.000000e+002,6.856950e+000,1.107379e-003,0.000000e+000,4.202589e-003,0.000000e+000,3,9.689876e-001,1.825000e+000,,,,,,,,,,,,,,,,,,0,5.000000e+000,5.000000e-001,2,1,1.544271e-001,0,1,0,
1473351217.770,,5.000000e+002,7.120724e+000,1.108686e-003,0.000000e+000,4.228281e-003,0.000000e+000,3,9.689826e-001,1.825000e+000,,,,,,,,,,,,,,,,,,0,5.000000e+000,5.000000e-001,2,1,1.443086e-001,0,1,0,
1473351229.092,,5.000000e+002,7.309929e+000,1.109565e-003,0.000000e+000,4.196050e-003,0.000000e+000,3,9.690173e-001,1.825000e+000,,,,,,,,,,,,,,,,,,0,5.000000e+000,5.000000e-001,2,1,1.556683e-001,0,1,0,
1473351242.806,,5.000000e+002,7.543983e+000,1.110703e-003,0.000000e+000,4.216685e-003,0.000000e+000,3,9.689690e-001,1.825000e+000,,,,,,,,,,,,,,,,,,0,5.000000e+000,5.000000e-001,2,1,1.591692e-001,0,1,0,
1473351255.020,,5.000000e+002,7.740659e+000,1.111579e-003,0.000000e+000,4.237469e-003,0.000000e+000,3,9.689744e-001,1.825000e+000,,,,,,,,,,,,,,,,,,0,5.000000e+000,5.000000e-001,2,1,1.574492e-001,0,1,0,
1473351281.179,,5.000000e+002,8.151031e+000,1.113500e-003,0.000000e+000,4.225757e-003,0.000000e+000,3,9.690619e-001,1.825000e+000,,,,,,,,,,,,,,,,,,0,5.000000e+000,5.000000e-001,2,1,1.591215e-001,0,1,0,
1473351294.751,,5.000000e+002,8.375373e+000,1.114328e-003,0.000000e+000,4.222051e-003,0.000000e+000,3,9.691001e-001,1.825000e+000,,,,,,,,,,,,,,,,,,0,5.000000e+000,5.000000e-001,2,1,1.312084e-001,0,1,0,
1473351308.716,,5.000000e+002,8.585477e+000,1.043218e-003,0.000000e+000,-5.412962e-002,0.000000e+000,3,8.173895e-001,1.825000e+000,,,,,,,,,,,,,,,,,,0,5.000000e+000,5.000000e-001,2,1,1.525402e-001,0,1,0,
1473351320.680,,5.000000e+002,8.777772e+000,1.115773e-003,0.000000e+000,4.212544e-003,0.000000e+000,3,9.689942e-001,1.825000e+000,,,,,,,,,,,,,,,,,,0,5.000000e+000,5.000000e-001,2,1,1.544781e-001,0,0,0,
1473351342.905,,5.000000e+002,9.108234e+000,1.116967e-003,0.000000e+000,4.247838e-003,0.000000e+000,3,9.691269e-001,1.825000e+000,,,,,,,,,,,,,,,,,,0,5.000000e+000,5.000000e-001,2,1,1.478968e-001,0,0,0,
1473351354.869,,5.000000e+002,9.355224e+000,1.117403e-003,0.000000e+000,4.280548e-003,0.000000e+000,3,9.691944e-001,1.825000e+000,,,,,,,,,,,,,,,,,,0,5.000000e+000,5.000000e-001,2,1,1.173458e-001,0,0,0,
1473351367.834,,5.000000e+002,9.540812e+000,1.118042e-003,0.000000e+000,4.311043e-003,0.000000e+000,3,9.691265e-001,1.825000e+000,,,,,,,,,,,,,,,,,,0,5.000000e+000,5.000000e-001,2,1,1.835270e-001,0,0,0,
1473351379.589,,5.000000e+002,9.706770e+000,1.118468e-003,0.000000e+000,4.288124e-003,0.000000e+000,3,9.691494e-001,1.825000e+000,,,,,,,,,,,,,,,,,,0,5.000000e+000,5.000000e-001,2,1,1.483879e-001,0,0,0,
1473351406.808,,5.000000e+002,1.015751e+001,1.119395e-003,0.000000e+000,4.300164e-003,0.000000e+000,3,9.690799e-001,1.825000e+000,,,,,,,,,,,,,,,,,,0,5.000000e+000,5.000000e-001,2,1,1.562099e-001,0,0,0,
1473351421.308,,5.000000e+002,1.037716e+001,1.119709e-003,0.000000e+000,4.331846e-003,0.000000e+000,3,9.691510e-001,1.825000e+000,,,,,,,,,,,,,,,,,,0,5.000000e+000,5.000000e-001,2,1,1.436901e-001,0,0,0,
1473351432.272,,5.000000e+002,1.054346e+001,1.119964e-003,0.000000e+000,4.351645e-003,0.000000e+000,3,9.691473e-001,1.825000e+000,,,,,,,,,,,,,,,,,,0,5.000000e+000,5.000000e-001,2,1,1.889296e-001,0,0,0,
1473351442.986,,5.000000e+002,1.073903e+001,1.120121e-003,0.000000e+000,4.355774e-003,0.000000e+000,3,9.691479e-001,1.825000e+000,,,,,,,,,,,,,,,,,,0,5.000000e+000,5.000000e-001,2,1,1.254101e-001,0,0,0,
1473351471.141,,5.000000e+002,1.113271e+001,1.120698e-003,0.000000e+000,4.368878e-003,0.000000e+000,3,9.691526e-001,1.825000e+000,,,,,,,,,,,,,,,,,,0,5.000000e+000,5.000000e-001,2,1,1.403799e-001,0,0,0,
1473351483.463,,5.000000e+002,1.131929e+001,1.120740e-003,0.000000e+000,4.351556e-003,0.000000e+000,3,9.691564e-001,1.825000e+000,,,,,,,,,,,,,,,,,,0,5.000000e+000,5.000000e-001,2,1,1.550798e-001,0,0,0,
1473351496.427,,5.000000e+002,1.154181e+001,1.120846e-003,0.000000e+000,4.357325e-003,0.000000e+000,3,9.691694e-001,1.825000e+000,,,,,,,,,,,,,,,,,,0,5.000000e+000,5.000000e-001,2,1,1.461897e-001,0,0,0,
1473351508.392,,5.000000e+002,1.172970e+001,1.120958e-003,0.000000e+000,4.372933e-003,0.000000e+000,3,9.691712e-001,1.825000e+000,,,,,,,,,,,,,,,,,,0,5.000000e+000,5.000000e-001,2,1,1.537800e-001,0,0,0,
1473351543.608,,5.000000e+002,1.226406e+001,1.120772e-003,0.000000e+000,4.400375e-003,0.000000e+000,3,9.691549e-001,1.825000e+000,,,,,,,,,,,,,,,,,,0,5.000000e+000,5.000000e-001,2,1,1.590300e-001,0,0,0,
1473351556.322,,5.000000e+002,1.243123e+001,1.120625e-003,0.000000e+000,4.428479e-003,0.000000e+000,3,9.691929e-001,1.825000e+000,,,,,,,,,,,,,,,,,,0,5.000000e+000,5.000000e-001,2,1,1.752996e-001,0,0,0,
1473351570.537,,5.000000e+002,1.269229e+001,1.120424e-003,0.000000e+000,4.368617e-003,0.000000e+000,3,9.692023e-001,1.825000e+000,,,,,,,,,,,,,,,,,,0,5.000000e+000,5.000000e-001,2,1,1.178694e-001,0,0,0,
1473351582.251,,5.000000e+002,1.290867e+001,1.120305e-003,0.000000e+000,4.414131e-003,0.000000e+000,3,9.692479e-001,1.825000e+000,,,,,,,,,,,,,,,,,,0,5.000000e+000,5.000000e-001,2,1,1.572199e-001,0,0,0,
1473351600.216,,5.000000e+002,1.320677e+001,1.119824e-003,0.000000e+000,4.459188e-003,0.000000e+000,3,9.692389e-001,1.825000e+000,,,,,,,,,,,,,,,,,,0,5.000000e+000,5.000000e-001,2,1,1.869602e-001,0,0,0,
1473351614.180,,5.000000e+002,1.343887e+001,1.119520e-003,0.000000e+000,4.480280e-003,0.000000e+000,3,9.691938e-001,1.825000e+000,,,,,,,,,,,,,,,,,,0,5.000000e+000,5.000000e-001,2,1,1.871805e-001,0,0,0,
1473351628.645,,5.000000e+002,1.370670e+001,1.119107e-003,0.000000e+000,4.447148e-003,0.000000e+000,3,9.691849e-001,1.825000e+000,,,,,,,,,,,,,,,,,,0,5.000000e+000,5.000000e-001,2,1,1.181898e-001,0,0,0,
1473351643.609,,5.000000e+002,1.391839e+001,1.118619e-003,0.000000e+000,4.491291e-003,0.000000e+000,3,9.692220e-001,1.825000e+000,,,,,,,,,,,,,,,,,,0,5.000000e+000,5.000000e-001,2,1,2.328100e-001,0,0,0,
1473351656.073,,5.000000e+002,1.416490e+001,1.118171e-003,0.000000e+000,4.481367e-003,0.000000e+000,3,9.692298e-001,1.825000e+000,,,,,,,,,,,,,,,,,,0,5.000000e+000,5.000000e-001,2,1,1.145306e-001,0,0,0,
1473351669.538,,5.000000e+002,1.439025e+001,1.117744e-003,0.000000e+000,4.545933e-003,0.000000e+000,3,9.691819e-001,1.825000e+000,,,,,,,,,,,,,,,,,,0,5.000000e+000,5.000000e-001,2,1,1.110306e-001,0,0,0,
1473351683.767,,5.000000e+002,1.463144e+001,1.117067e-003,0.000000e+000,4.550398e-003,0.000000e+000,3,9.691722e-001,1.825000e+000,,,,,,,,,,,,,,,,,,0,5.000000e+000,5.000000e-001,2,1,1.491299e-001,0,0,0,
1473351696.675,,5.000000e+002,1.479641e+001,1.116559e-003,0.000000e+000,4.478314e-003,0.000000e+000,3,9.692008e-001,1.825000e+000,,,,,,,,,,,,,,,,,,0,5.000000e+000,5.000000e-001,2,1,1.561804e-001,0,0,0,
1473351779.260,,5.000000e+002,1.500091e+001,1.117830e-003,0.000000e+000,4.555754e-003,0.000000e+000,3,9.691291e-001,1.825000e+000,,,,,,,,,,,,,,,,,,0,5.000000e+000,5.000000e-001,2,1,1.219749e-003,0,1,0,
1473351792.224,,5.000000e+002,1.500152e+001,1.117991e-003,0.000000e+000,4.572903e-003,0.000000e+000,3,9.691798e-001,1.825000e+000,,,,,,,,,,,,,,,,,,0,5.000000e+000,5.000000e-001,2,1,0.000000e+000,0,1,0,
1473351804.439,,5.000000e+002,1.500274e+001,1.118112e-003,0.000000e+000,4.524168e-003,0.000000e+000,3,9.691813e-001,1.825000e+000,,,,,,,,,,,,,,,,,,0,5.000000e+000,5.000000e-001,2,1,1.220703e-003,0,1,0,
1473351817.402,,5.000000e+002,1.500152e+001,1.118273e-003,0.000000e+000,4.550129e-003,0.000000e+000,3,9.691173e-001,1.825000e+000,,,,,,,,,,,,,,,,,,0,5.000000e+000,5.000000e-001,2,1,1.219749e-003,0,1,0,
1473351909.375,,5.000000e+002,1.500152e+001,1.118916e-003,0.000000e+000,4.589206e-003,0.000000e+000,3,9.691884e-001,1.825000e+000,,,,,,,,,,,,,,,,,,0,5.000000e+000,5.000000e-001,2,1,2.439499e-003,0,1,0,
1473351920.839,,5.000000e+002,1.500213e+001,1.118859e-003,0.000000e+000,4.532426e-003,0.000000e+000,3,9.691438e-001,1.825000e+000,,,,,,,,,,,,,,,,,,0,5.000000e+000,5.000000e-001,2,1,1.219749e-003,0,1,0,
1473351933.053,,5.000000e+002,1.500213e+001,1.119019e-003,0.000000e+000,4.598982e-003,0.000000e+000,3,9.691229e-001,1.825000e+000,,,,,,,,,,,,,,,,,,0,5.000000e+000,5.000000e-001,2,1,0.000000e+000,0,1,0,
1473351945.517,,5.000000e+002,1.500213e+001,1.118924e-003,0.000000e+000,4.556546e-003,0.000000e+000,3,9.692048e-001,1.825000e+000,,,,,,,,,,,,,,,,,,0,5.000000e+000,5.000000e-001,2,1,0.000000e+000,0,1,0,
1473352028.742,,5.000000e+002,1.840763e+001,1.100568e-003,0.000000e+000,4.776357e-003,0.000000e+000,3,9.689400e-001,1.825000e+000,,,,,,,,,,,,,,,,,,0,5.000000e+000,5.000000e-001,2,1,4.580898e-001,0,0,0,
1473352042.706,,5.000000e+002,1.905889e+001,1.096868e-003,0.000000e+000,4.840688e-003,0.000000e+000,3,9.689231e-001,1.825000e+000,,,,,,,,,,,,,,,,,,0,5.000000e+000,5.000000e-001,2,1,6.153107e-001,0,0,0,
1473352054.920,,5.000000e+002,1.974247e+001,1.093786e-003,0.000000e+000,4.869243e-003,0.000000e+000,3,9.688278e-001,1.825000e+000,,,,,,,,,,,,,,,,,,0,5.000000e+000,5.000000e-001,2,1,5.357113e-001,0,0,0,
1473352066.634,,5.000000e+002,2.030307e+001,1.090331e-003,0.000000e+000,4.951341e-003,0.000000e+000,3,9.687764e-001,1.825000e+000,,,,,,,,,,,,,,,,,,0,5.000000e+000,5.000000e-001,2,1,3.529110e-001,0,0,0,
1473352085.849,,5.000000e+002,2.118201e+001,1.084316e-003,0.000000e+000,4.977396e-003,0.000000e+000,3,9.686456e-001,1.825000e+000,,,,,,,,,,,,,,,,,,0,5.000000e+000,5.000000e-001,2,1,4.677505e-001,0,0,0,
1473352097.317,,5.000000e+002,2.182512e+001,1.080465e-003,0.000000e+000,5.026840e-003,0.000000e+000,3,9.685841e-001,1.825000e+000,,,,,,,,,,,,,,,,,,0,5.000000e+000,5.000000e-001,2,1,5.804901e-001,0,0,0,
1473352109.782,,5.000000e+002,2.246256e+001,1.076084e-003,0.000000e+000,5.101415e-003,0.000000e+000,3,9.685019e-001,1.825000e+000,,,,,,,,,,,,,,,,,,0,5.000000e+000,5.000000e-001,2,1,4.623203e-001,0,0,0,
1473352121.746,,5.000000e+002,2.302063e+001,1.071854e-003,0.000000e+000,5.159144e-003,0.000000e+000,3,9.684334e-001,1.825000e+000,,,,,,,,,,,,,,,,,,0,5.000000e+000,5.000000e-001,2,1,4.210014e-001,0,0,0,
1473352155.008,,5.000000e+002,2.458115e+001,1.060009e-003,0.000000e+000,5.412419e-003,0.000000e+000,3,9.682724e-001,1.825000e+000,,,,,,,,,,,,,,,,,,0,5.000000e+000,5.000000e-001,2,1,5.468311e-001,0,0,0,
1473352168.223,,5.000000e+002,2.515578e+001,1.055185e-003,0.000000e+000,5.490956e-003,0.000000e+000,3,9.682057e-001,1.825000e+000,,,,,,,,,,,,,,,,,,0,5.000000e+000,5.000000e-001,2,1,4.428711e-001,0,0,0,
1473352182.491,,5.000000e+002,2.582791e+001,1.049219e-003,0.000000e+000,5.643541e-003,0.000000e+000,3,9.681422e-001,1.825000e+000,,,,,,,,,,,,,,,,,,0,5.000000e+000,5.000000e-001,2,1,6.769905e-001,0,0,0,
1473352194.705,,5.000000e+002,2.648402e+001,1.043925e-003,0.000000e+000,5.671162e-003,0.000000e+000,3,9.680305e-001,1.825000e+000,,,,,,,,,,,,,,,,,,0,5.000000e+000,5.000000e-001,2,1,6.352291e-001,0,0,0,
1473352210.447,,5.000000e+002,2.727963e+001,1.036991e-003,0.000000e+000,5.746545e-003,0.000000e+000,3,9.679017e-001,1.825000e+000,,,,,,,,,,,,,,,,,,0,5.000000e+000,5.000000e-001,2,1,4.753208e-001,0,0,0,
1473352222.192,,5.000000e+002,2.787204e+001,1.031629e-003,0.000000e+000,5.837254e-003,0.000000e+000,3,9.678056e-001,1.825000e+000,,,,,,,,,,,,,,,,,,0,5.000000e+000,5.000000e-001,2,1,4.738388e-001,0,0,0,
1473352235.906,,5.000000e+002,2.858492e+001,1.025289e-003,0.000000e+000,5.923592e-003,0.000000e+000,3,9.676756e-001,1.825000e+000,,,,,,,,,,,,,,,,,,0,5.000000e+000,5.000000e-001,2,1,4.694805e-001,0,0,0,
1473352248.121,,5.000000e+002,2.917374e+001,1.019571e-003,0.000000e+000,6.040662e-003,0.000000e+000,3,9.675363e-001,1.825000e+000,,,,,,,,,,,,,,,,,,0,5.000000e+000,5.000000e-001,2,1,4.703789e-001,0,0,0,
1473352270.836,,5.000000e+002,3.014029e+001,1.008807e-003,0.000000e+000,6.197721e-003,0.000000e+000,3,9.673437e-001,1.825000e+000,,,,,,,,,,,,,,,,,,0,5.000000e+000,5.000000e-001,2,1,5.294704e-001,0,0,0,
1473352286.068,,5.000000e+002,3.092770e+001,1.001228e-003,0.000000e+000,6.337367e-003,0.000000e+000,3,9.672175e-001,1.825000e+000,,,,,,,,,,,,,,,,,,0,5.000000e+000,5.000000e-001,2,1,3.469009e-001,0,0,0,
1473352299.033,,5.000000e+002,3.162239e+001,9.944763e-004,0.000000e+000,6.437107e-003,0.000000e+000,3,9.670514e-001,1.825000e+000,,,,,,,,,,,,,,,,,,0,5.000000e+000,5.000000e-001,2,1,3.463898e-001,0,0,0,
1473352313.451,,5.000000e+002,3.237263e+001,9.868301e-004,0.000000e+000,6.590771e-003,0.000000e+000,3,9.669914e-001,1.825000e+000,,,,,,,,,,,,,,,,,,0,5.000000e+000,5.000000e-001,2,1,4.599609e-001,0,0,0,
1473352332.051,,5.000000e+002,3.323606e+001,9.767369e-004,0.000000e+000,6.696747e-003,0.000000e+000,3,9.667404e-001,1.825000e+000,,,,,,,,,,,,,,,,,,0,5.000000e+000,5.000000e-001,2,1,5.721893e-001,0,0,0,
1473352344.265,,5.000000e+002,3.386995e+001,9.698713e-004,0.000000e+000,6.790405e-003,0.000000e+000,3,9.666316e-001,1.825000e+000,,,,,,,,,,,,,,,,,,0,5.000000e+000,5.000000e-001,2,1,4.597702e-001,0,0,0,
1473352355.729,,5.000000e+002,3.439220e+001,9.640850e-004,0.000000e+000,6.955249e-003,0.000000e+000,3,9.664195e-001,1.825000e+000,,,,,,,,,,,,,,,,,,0,5.000000e+000,5.000000e-001,2,1,3.653412e-001,0,0,0,
1473352369.694,,5.000000e+002,3.499744e+001,9.567669e-004,0.000000e+000,7.063318e-003,0.000000e+000,3,9.663076e-001,1.825000e+000,,,,,,,,,,,,,,,,,,0,5.000000e+000,5.000000e-001,2,1,4.121094e-001,0,0,0,
1473352406.861,,5.000000e+002,3.673901e+001,9.351284e-004,0.000000e+000,7.428342e-003,0.000000e+000,3,9.658650e-001,1.825000e+000,,,,,,,,,,,,,,,,,,0,5.000000e+000,5.000000e-001,2,1,6.410103e-001,0,0,0,
1473352420.685,,5.000000e+002,3.738628e+001,9.270150e-004,0.000000e+000,7.592059e-003,0.000000e+000,3,9.656897e-001,1.825000e+000,,,,,,,,,,,,,,,,,,0,5.000000e+000,5.000000e-001,2,1,6.535301e-001,0,0,0,
1473352432.648,,5.000000e+002,3.810104e+001,9.196081e-004,0.000000e+000,7.662136e-003,0.000000e+000,3,9.654711e-001,1.825000e+000,,,,,,,,,,,,,,,,,,0,5.000000e+000,5.000000e-001,2,1,3.281784e-001,0,0,0,
1473352449.363,,5.000000e+002,3.876357e+001,9.088157e-004,0.000000e+000,7.784105e-003,0.000000e+000,3,9.652345e-001,1.825000e+000,,,,,,,,,,,,,,,,,,0,5.000000e+000,5.000000e-001,2,1,5.589905e-001,0,0,0,
1473352465.263,,5.000000e+002,3.959319e+001,8.982756e-004,0.000000e+000,7.935300e-003,0.000000e+000,3,9.650350e-001,1.825000e+000,,,,,,,,,,,,,,,,,,0,5.000000e+000,5.000000e-001,2,1,4.411316e-001,0,0,0,
1473352480.836,,5.000000e+002,4.031043e+001,8.878760e-004,0.000000e+000,8.107728e-003,0.000000e+000,3,9.647110e-001,1.825000e+000,,,,,,,,,,,,,,,,,,0,5.000000e+000,5.000000e-001,2,1,5.491600e-001,0,0,0,
1473352495.800,,5.000000e+002,4.110172e+001,8.774950e-004,0.000000e+000,8.202949e-003,0.000000e+000,3,9.644310e-001,1.825000e+000,,,,,,,,,,,,,,,,,,0,5.000000e+000,5.000000e-001,2,1,5.935478e-001,0,0,0,
1473352509.451,,5.000000e+002,4.187209e+001,8.679188e-004,0.000000e+000,8.330117e-003,0.000000e+000,3,9.642227e-001,1.825000e+000,,,,,,,,,,,,,,,,,,0,5.000000e+000,5.000000e-001,2,1,4.700012e-001,0,0,0,
1473352521.773,,5.000000e+002,4.251460e+001,8.590568e-004,0.000000e+000,8.453916e-003,0.000000e+000,3,9.639586e-001,1.825000e+000,,,,,,,,,,,,,,,,,,0,5.000000e+000,5.000000e-001,2,1,3.490906e-001,0,0,0,
1473352535.532,,5.000000e+002,4.315429e+001,8.491573e-004,0.000000e+000,8.655603e-003,0.000000e+000,3,9.636399e-001,1.825000e+000,,,,,,,,,,,,,,,,,,0,5.000000e+000,5.000000e-001,2,1,4.642487e-001,0,0,0,
1473352549.446,,5.000000e+002,4.390958e+001,8.389432e-004,0.000000e+000,8.750813e-003,0.000000e+000,3,9.634321e-001,1.825000e+000,,,,,,,,,,,,,,,,,,0,5.000000e+000,5.000000e-001,2,1,5.700493e-001,0,0,0,
1473352564.268,,5.000000e+002,4.459238e+001,8.277220e-004,0.000000e+000,8.918610e-003,0.000000e+000,3,9.631138e-001,1.825000e+000,,,,,,,,,,,,,,,,,,0,5.000000e+000,5.000000e-001,2,1,5.771408e-001,0,0,0,
1473352578.776,,5.000000e+002,4.528237e+001,8.165105e-004,0.000000e+000,9.071305e-003,0.000000e+000,3,9.627813e-001,1.825000e+000,,,,,,,,,,,,,,,,,,0,5.000000e+000,5.000000e-001,2,1,5.758400e-001,0,0,0,
1473352591.785,,5.000000e+002,4.602531e+001,8.063165e-004,0.000000e+000,9.154130e-003,0.000000e+000,3,9.625199e-001,1.825000e+000,,,,,,,,,,,,,,,,,,0,5.000000e+000,5.000000e-001,2,1,4.561691e-001,0,0,0,
1473352604.502,,5.000000e+002,4.657885e+001,7.963579e-004,0.000000e+000,9.340652e-003,0.000000e+000,3,9.621542e-001,1.825000e+000,,,,,,,,,,,,,,,,,,0,5.000000e+000,5.000000e-001,2,1,4.254684e-001,0,0,0,
1473352617.513,,5.000000e+002,4.723062e+001,7.860902e-004,0.000000e+000,9.433211e-003,0.000000e+000,3,9.618968e-001,1.825000e+000,,,,,,,,,,,,,,,,,,0,5.000000e+000,5.000000e-001,2,1,4.447594e-001,0,0,0,
1473352631.747,,5.000000e+002,4.788738e+001,7.742904e-004,0.000000e+000,9.639236e-003,0.000000e+000,3,9.615359e-001,1.825000e+000,,,,,,,,,,,,,,,,,,0,5.000000e+000,5.000000e-001,2,1,6.455421e-001,0,0,0,
1473352644.961,,5.000000e+002,4.853495e+001,7.636168e-004,0.000000e+000,9.768231e-003,0.000000e+000,3,9.611392e-001,1.825000e+000,,,,,,,,,,,,,,,,,,0,5.000000e+000,5.000000e-001,2,1,4.334793e-001,0,0,0,
1473352659.676,,5.000000e+002,4.930315e+001,7.513002e-004,0.000000e+000,9.846638e-003,0.000000e+000,3,9.607465e-001,1.825000e+000,,,,,,,,,,,,,,,,,,0,5.000000e+000,5.000000e-001,2,1,4.402885e-001,0,0,0,
1473352673.640,,5.000000e+002,4.996771e+001,7.389770e-004,0.000000e+000,1.000079e-002,0.000000e+000,3,9.602431e-001,1.825000e+000,,,,,,,,,,,,,,,,,,0,5.000000e+000,5.000000e-001,2,1,4.428978e-001,0,0,0,
1473352690.400,,5.000000e+002,5.079414e+001,7.237198e-004,0.000000e+000,1.011412e-002,0.000000e+000,3,9.597123e-001,1.825000e+000,,,,,,,,,,,,,,,,,,0,5.000000e+000,5.000000e-001,2,1,5.528488e-001,0,0,0,
1473352703.614,,5.000000e+002,5.146338e+001,7.113632e-004,0.000000e+000,1.031779e-002,0.000000e+000,3,9.592361e-001,1.825000e+000,,,,,,,,,,,,,,,,,,0,5.000000e+000,5.000000e-001,2,1,5.601730e-001,0,1,0,
1473352716.328,,5.000000e+002,5.214389e+001,6.989970e-004,0.000000e+000,1.042100e-002,0.000000e+000,3,9.586842e-001,1.825000e+000,,,,,,,,,,,,,,,,,,0,5.000000e+000,5.000000e-001,2,1,3.483505e-001,0,1,0,
1473352728.293,,5.000000e+002,5.266911e+001,6.869836e-004,0.000000e+000,1.052878e-002,0.000000e+000,3,9.581447e-001,1.825000e+000,,,,,,,,,,,,,,,,,,0,5.000000e+000,5.000000e-001,2,1,4.660683e-001,0,1,0,
1473352749.258,,5.000000e+002,5.373291e+001,6.654634e-004,0.000000e+000,1.065419e-002,0.000000e+000,3,9.572434e-001,1.825000e+000,,,,,,,,,,,,,,,,,,0,5.000000e+000,5.000000e-001,2,1,4.627380e-001,0,1,0,
1473352761.222,,5.000000e+002,5.430503e+001,6.534314e-004,0.000000e+000,1.077835e-002,0.000000e+000,3,9.567312e-001,1.825000e+000,,,,,,,,,,,,,,,,,,0,5.000000e+000,5.000000e-001,2,1,4.571304e-001,0,1,0,
1473352771.686,,5.000000e+002,5.488231e+001,6.422808e-004,0.000000e+000,1.088487e-002,0.000000e+000,3,9.561035e-001,1.825000e+000,,,,,,,,,,,,,,,,,,0,5.000000e+000,5.000000e-001,2,1,4.714394e-001,0,1,0,
1473352786.651,,5.000000e+002,5.551917e+001,6.258092e-004,0.000000e+000,1.098217e-002,0.000000e+000,3,9.554710e-001,1.825000e+000,,,,,,,,,,,,,,,,,,0,5.000000e+000,5.000000e-001,2,1,5.865898e-001,0,1,0,
1473352820.678,,5.000000e+002,5.723182e+001,5.872344e-004,0.000000e+000,1.120230e-002,0.000000e+000,3,9.532723e-001,1.825000e+000,,,,,,,,,,,,,,,,,,0,5.000000e+000,5.000000e-001,2,1,3.487091e-001,0,1,0,
1473352844.375,,5.000000e+002,5.833206e+001,5.579721e-004,0.000000e+000,1.124366e-002,0.000000e+000,3,9.515235e-001,1.825000e+000,,,,,,,,,,,,,,,,,,0,5.000000e+000,5.000000e-001,2,1,4.750786e-001,0,1,0,
1473352856.625,,5.000000e+002,5.892113e+001,5.416023e-004,0.000000e+000,1.133705e-002,0.000000e+000,3,9.504513e-001,1.825000e+000,,,,,,,,,,,,,,,,,,0,5.000000e+000,5.000000e-001,2,1,4.707527e-001,0,1,0,
1473352871.590,,5.000000e+002,5.962592e+001,5.207966e-004,0.000000e+000,1.137325e-002,0.000000e+000,3,9.489287e-001,1.825000e+000,,,,,,,,,,,,,,,,,,0,5.000000e+000,5.000000e-001,2,1,4.747124e-001,0,1,0,
1473352884.105,,5.000000e+002,6.028455e+001,5.020350e-004,0.000000e+000,1.132617e-002,0.000000e+000,3,9.475352e-001,1.825000e+000,,,,,,,,,,,,,,,,,,0,5.000000e+000,5.000000e-001,2,1,5.967407e-001,0,1,0,
1473352896.069,,5.000000e+002,6.094176e+001,4.834855e-004,0.000000e+000,1.131037e-002,0.000000e+000,3,9.459990e-001,1.825000e+000,,,,,,,,,,,,,,,,,,0,5.000000e+000,5.000000e-001,2,1,4.733315e-001,0,1,0,
1473352911.968,,5.000000e+002,6.171584e+001,4.573528e-004,0.000000e+000,1.119978e-002,0.000000e+000,3,9.435806e-001,1.825000e+000,,,,,,,,,,,,,,,,,,0,5.000000e+000,5.000000e-001,2,1,6.016884e-001,0,1,0,
1473352924.337,,5.000000e+002,6.231087e+001,4.354668e-004,0.000000e+000,1.104572e-002,0.000000e+000,3,9.413862e-001,1.825000e+000,,,,,,,,,,,,,,,,,,0,5.000000e+000,5.000000e-001,2,1,5.883713e-001,0,1,0,
1473352937.551,,5.000000e+002,6.296483e+001,4.107605e-004,0.000000e+000,1.086444e-002,0.000000e+000,3,9.385394e-001,1.825000e+000,,,,,,,,,,,,,,,,,,0,5.000000e+000,5.000000e-001,2,1,4.785805e-001,0,1,0,
1473352951.766,,5.000000e+002,6.368068e+001,3.820785e-004,0.000000e+000,1.051837e-002,0.000000e+000,3,9.348459e-001,1.825000e+000,,,,,,,,,,,,,,,,,,0,5.000000e+000,5.000000e-001,2,1,4.810715e-001,0,1,0,
1473352964.980,,5.000000e+002,6.433208e+001,3.532884e-004,0.000000e+000,9.988220e-003,0.000000e+000,3,9.305693e-001,1.825000e+000,,,,,,,,,,,,,,,,,,0,5.000000e+000,5.000000e-001,2,1,5.909729e-001,0,1,0,
1473352978.445,,5.000000e+002,6.510518e+001,3.216805e-004,0.000000e+000,9.370736e-003,0.000000e+000,3,9.249275e-001,1.825000e+000,,,,,,,,,,,,,,,,,,0,5.000000e+000,5.000000e-001,2,1,4.749985e-001,0,1,0,
1473352992.909,,5.000000e+002,6.582095e+001,2.846322e-004,0.000000e+000,8.309858e-003,0.000000e+000,3,9.167048e-001,1.825000e+000,,,,,,,,,,,,,,,,,,0,5.000000e+000,5.000000e-001,2,1,4.702759e-001,0,1,0,
1473353004.623,,5.000000e+002,6.641592e+001,2.522106e-004,0.000000e+000,7.004596e-003,0.000000e+000,3,9.072880e-001,1.825000e+000,,,,,,,,,,,,,,,,,,0,5.000000e+000,5.000000e-001,2,1,4.613342e-001,0,1,0,
1473353017.838,,5.000000e+002,6.700829e+001,2.147148e-004,0.000000e+000,5.093275e-003,0.000000e+000,3,8.929992e-001,1.825000e+000,,,,,,,,,,,,,,,,,,0,5.000000e+000,5.000000e-001,2,1,4.735184e-001,0,1,0,
1473353030.052,,5.000000e+002,6.760077e+001,1.790580e-004,0.000000e+000,2.273335e-003,0.000000e+000,3,8.734646e-001,1.825000e+000,,,,,,,,,,,,,,,,,,0,5.000000e+000,5.000000e-001,2,1,4.704971e-001,0,1,0,
1473353048.017,,5.000000e+002,6.852598e+001,1.314708e-004,0.000000e+000,-3.686849e-003,0.000000e+000,3,8.301980e-001,1.825000e+000,,,,,,,,,,,,,,,,,,0,5.000000e+000,5.000000e-001,2,1,4.533691e-001,0,1,0,
1473353062.171,,5.000000e+002,6.922038e+001,9.983386e-005,0.000000e+000,-1.163591e-002,0.000000e+000,3,7.781386e-001,1.825000e+000,,,,,,,,,,,,,,,,,,0,5.000000e+000,5.000000e-001,2,1,4.640121e-001,0,1,0,
1473353074.994,,5.000000e+002,6.980023e+001,7.630927e-005,0.000000e+000,-2.271577e-002,0.000000e+000,3,7.114209e-001,1.825000e+000,,,,,,,,,,,,,,,,,,0,5.000000e+000,5.000000e-001,2,1,4.767303e-001,0,1,0,
1473353099.129,,5.000000e+002,7.104034e+001,4.501312e-005,0.000000e+000,-6.663717e-002,0.000000e+000,3,5.133634e-001,1.825000e+000,,,,,,,,,,,,,,,,,,0,5.000000e+000,5.000000e-001,2,1,5.903931e-001,0,1,0,
1473353113.951,,5.000000e+002,7.179585e+001,3.223321e-005,0.000000e+000,-1.346968e-001,0.000000e+000,3,3.221707e-001,1.825000e+000,,,,,,,,,,,,,,,,,,0,5.000000e+000,5.000000e-001,2,1,4.587479e-001,0,1,0,
1473353127.347,,5.000000e+002,7.249915e+001,2.390153e-005,0.000000e+000,-3.005174e-001,0.000000e+000,3,8.897356e-002,1.825000e+000,,,,,,,,,,,,,,,,,,0,5.000000e+000,5.000000e-001,2,1,4.270477e-001,0,1,0,
1473353140.420,,5.000000e+002,7.306577e+001,1.874020e-005,0.000000e+000,-1.208417e+000,0.000000e+000,3,0.000000e+000,1.825000e+000,,,,,,,,,,,,,,,,,,0,5.000000e+000,5.000000e-001,2,1,4.719772e-001,0,1,0,
1473353152.884,,5.000000e+002,7.364732e+001,2.081747e-005,0.000000e+000,-1.261501e+000,0.000000e+000,3,6.145282e-002,1.825000e+000,,,,,,,,,,,,,,,,,,0,5.000000e+000,5.000000e-001,2,1,4.636612e-001,0,1,0,
1473353182.808,,5.000000e+002,7.518050e+001,1.484898e-006,0.000000e+000,0.000000e+000,0.000000e+000,3,0.000000e+000,1.825000e+000,,,,,,,,,,,,,,,,,,0,5.000000e+000,5.000000e-001,2,1,4.716339e-001,0,1,0,
1473353196.880,,5.000000e+002,7.588754e+001,-1.857500e-006,0.000000e+000,0.000000e+000,0.000000e+000,3,0.000000e+000,1.825000e+000,,,,,,,,,,,,,,,,,,0,5.000000e+000,5.000000e-001,2,1,4.664764e-001,0,1,0,
1473353211.598,,5.000000e+002,7.659071e+001,-5.268816e-006,0.000000e+000,1.582115e-001,0.000000e+000,3,0.000000e+000,1.825000e+000,,,,,,,,,,,,,,,,,,0,5.000000e+000,5.000000e-001,2,1,4.720459e-001,0,0,0,
1473353226.010,,5.000000e+002,7.733563e+001,-7.075876e-006,0.000000e+000,-5.842526e-003,0.000000e+000,3,0.000000e+000,1.825000e+000,,,,,,,,,,,,,,,,,,0,5.000000e+000,5.000000e-001,2,1,5.983505e-001,0,0,0,
1473353241.583,,5.000000e+002,7.810365e+001,-9.620991e-006,0.000000e+000,4.593280e-002,0.000000e+000,3,0.000000e+000,1.825000e+000,,,,,,,,,,,,,,,,,,0,5.000000e+000,5.000000e-001,2,1,4.864883e-001,0,0,0,
1473353258.298,,5.000000e+002,7.892085e+001,-1.169864e-005,0.000000e+000,7.998863e-002,0.000000e+000,3,0.000000e+000,1.825000e+000,,,,,,,,,,,,,,,,,,0,5.000000e+000,5.000000e-001,2,1,4.641800e-001,0,0,0,
1473353271.793,,5.000000e+002,7.960486e+001,-1.318737e-005,0.000000e+000,6.684393e-002,0.000000e+000,3,0.000000e+000,1.825000e+000,,,,,,,,,,,,,,,,,,0,5.000000e+000,5.000000e-001,2,1,4.838638e-001,0,0,0,
1473353294.515,,5.000000e+002,8.044722e+001,-1.491795e-005,0.000000e+000,7.051983e-002,0.000000e+000,3,0.000000e+000,1.825000e+000,,,,,,,,,,,,,,,,,,0,5.000000e+000,5.000000e-001,2,1,1.295700e-001,0,0,0,
1473353447.287,,5.000000e+002,8.004191e+001,-1.433390e-005,0.000000e+000,7.140826e-002,0.000000e+000,3,0.000000e+000,1.825000e+000,,,,,,,,,,,,,,,,,,0,5.000000e+000,5.000000e-001,2,1,1.222229e-002,0,0,0,
1473353462.002,,5.000000e+002,8.003732e+001,-1.431404e-005,0.000000e+000,7.112840e-002,0.000000e+000,3,0.000000e+000,1.825000e+000,,,,,,,,,,,,,,,,,,0,5.000000e+000,5.000000e-001,2,1,3.051758e-003,0,0,0,
1473353475.216,,5.000000e+002,8.002205e+001,-1.429294e-005,0.000000e+000,7.116879e-002,0.000000e+000,3,0.000000e+000,1.825000e+000,,,,,,,,,,,,,,,,,,0,5.000000e+000,5.000000e-001,2,1,3.036499e-003,0,0,0,
1473353489.129,,5.000000e+002,8.002357e+001,-1.428645e-005,0.000000e+000,7.093091e-002,0.000000e+000,3,0.000000e+000,1.825000e+000,,,,,,,,,,,,,,,,,,0,5.000000e+000,5.000000e-001,2,1,0.000000e+000,0,0,0,
1473353679.500,,5.000000e+002,8.000372e+001,-1.424832e-005,0.000000e+000,7.108889e-002,0.000000e+000,3,0.000000e+000,1.825000e+000,,,,,,,,,,,,,,,,,,0,5.000000e+000,5.000000e-001,2,1,3.059387e-003,0,0,0,
1473353692.964,,5.000000e+002,8.000220e+001,-1.424957e-005,0.000000e+000,7.129554e-002,0.000000e+000,3,0.000000e+000,1.825000e+000,,,,,,,,,,,,,,,,,,0,5.000000e+000,5.000000e-001,2,1,0.000000e+000,0,0,0,
1473353705.678,,5.000000e+002,7.999304e+001,-1.424514e-005,0.000000e+000,7.113711e-002,0.000000e+000,3,0.000000e+000,1.825000e+000,,,,,,,,,,,,,,,,,,0,5.000000e+000,5.000000e-001,2,1,6.111145e-003,0,0,0,
1473353719.159,,5.000000e+002,7.999609e+001,-1.423049e-005,0.000000e+000,7.119014e-002,0.000000e+000,3,0.000000e+000,1.825000e+000,,,,,,,,,,,,,,,,,,0,5.000000e+000,5.000000e-001,2,1,0.000000e+000,0,0,0,
1473353821.415,,5.000000e+002,8.566176e+001,-2.094768e-005,0.000000e+000,7.250671e-002,0.000000e+000,3,0.000000e+000,1.825000e+000,,,,,,,,,,,,,,,,,,0,5.000000e+000,5.000000e-001,2,1,9.410706e-001,0,0,0,
1473353834.879,,5.000000e+002,8.681890e+001,-2.186403e-005,0.000000e+000,7.184553e-002,0.000000e+000,3,3.399922e-003,1.825000e+000,,,,,,,,,,,,,,,,,,0,5.000000e+000,5.000000e-001,2,1,9.652557e-001,0,0,0,
1473353848.344,,5.000000e+002,8.794659e+001,-2.270086e-005,0.000000e+000,7.220019e-002,0.000000e+000,3,4.081788e-002,1.825000e+000,,,,,,,,,,,,,,,,,,0,5.000000e+000,5.000000e-001,2,1,1.290138e+000,0,0,0,
1473353860.562,,5.000000e+002,8.910239e+001,-2.336722e-005,0.000000e+000,7.163481e-002,0.000000e+000,3,6.775302e-002,1.825000e+000,,,,,,,,,,,,,,,,,,0,5.000000e+000,5.000000e-001,2,1,6.209488e-001,0,0,0,
1473353878.041,,5.000000e+002,9.053368e+001,-2.420563e-005,0.000000e+000,7.188659e-002,0.000000e+000,3,1.001239e-001,1.825000e+000,,,,,,,,,,,,,,,,,,0,5.000000e+000,5.000000e-001,2,1,1.021446e+000,0,0,0,
1473353890.755,,5.000000e+002,9.185940e+001,-2.470731e-005,0.000000e+000,7.188930e-002,0.000000e+000,3,1.187887e-001,1.825000e+000,,,,,,,,,,,,,,,,,,0,5.000000e+000,5.000000e-001,2,1,1.216171e+000,0,0,0,
1473353906.219,,5.000000e+002,9.316263e+001,-2.524239e-005,0.000000e+000,7.213575e-002,0.000000e+000,3,1.373509e-001,1.825000e+000,,,,,,,,,,,,,,,,,,0,5.000000e+000,5.000000e-001,2,1,9.641647e-001,0,0,0,
1473353921.684,,5.000000e+002,9.463995e+001,-2.570892e-005,0.000000e+000,7.271827e-002,0.000000e+000,3,1.528169e-001,1.825000e+000,,,,,,,,,,,,,,,,,,0,5.000000e+000,5.000000e-001,2,1,7.753067e-001,0,0,0,
1473353938.913,,5.000000e+002,9.617589e+001,-2.617615e-005,0.000000e+000,7.243047e-002,0.000000e+000,3,1.674113e-001,1.825000e+000,,,,,,,,,,,,,,,,,,0,5.000000e+000,5.000000e-001,2,1,7.473907e-001,0,0,0,
1473353952.417,,5.000000e+002,9.748665e+001,-2.648762e-005,0.000000e+000,7.288206e-002,0.000000e+000,3,1.772510e-001,1.825000e+000,,,,,,,,,,,,,,,,,,0,5.000000e+000,5.000000e-001,2,1,8.066635e-001,0,0,0,
1473353967.826,,5.000000e+002,9.864047e+001,-2.680277e-005,0.000000e+000,7.343692e-002,0.000000e+000,3,1.861379e-001,1.825000e+000,,,,,,,,,,,,,,,,,,0,5.000000e+000,5.000000e-001,2,1,7.478027e-001,0,1,0,
1473353980.149,,5.000000e+002,9.979220e+001,-2.705678e-005,0.000000e+000,7.333194e-002,0.000000e+000,3,1.945779e-001,1.825000e+000,,,,,,,,,,,,,,,,,,0,5.000000e+000,5.000000e-001,2,1,7.860107e-001,0,1,0,
1473353993.863,,5.000000e+002,1.009695e+002,-2.727104e-005,0.000000e+000,7.361284e-002,0.000000e+000,3,2.002479e-001,1.825000e+000,,,,,,,,,,,,,,,,,,0,5.000000e+000,5.000000e-001,2,1,8.003006e-001,0,1,0,
1473354008.139,,5.000000e+002,1.020753e+002,-2.749264e-005,0.000000e+000,7.410505e-002,0.000000e+000,3,2.070348e-001,1.825000e+000,,,,,,,,,,,,,,,,,,0,5.000000e+000,5.000000e-001,2,1,9.907990e-001,0,1,0,
1473354022.353,,5.000000e+002,1.033704e+002,-2.772395e-005,0.000000e+000,7.404856e-002,0.000000e+000,3,2.127699e-001,1.825000e+000,,,,,,,,,,,,,,,,,,0,5.000000e+000,5.000000e-001,2,1,7.770004e-001,0,1,0,
1473354035.567,,5.000000e+002,1.044482e+002,-2.788829e-005,0.000000e+000,7.459445e-002,0.000000e+000,3,2.178488e-001,1.825000e+000,,,,,,,,,,,,,,,,,,0,5.000000e+000,5.000000e-001,2,1,9.789963e-001,0,1,0,
1473354071.072,,5.000000e+002,1.072747e+002,-2.829243e-005,0.000000e+000,7.530503e-002,0.000000e+000,3,2.285551e-001,1.825000e+000,,,,,,,,,,,,,,,,,,0,5.000000e+000,5.000000e-001,2,1,1.209900e+000,0,1,0,
1473354085.786,,5.000000e+002,1.086559e+002,-2.842724e-005,0.000000e+000,7.598231e-002,0.000000e+000,3,2.318480e-001,1.825000e+000,,,,,,,,,,,,,,,,,,0,5.000000e+000,5.000000e-001,2,1,7.990952e-001,0,1,0,
1473354100.501,,5.000000e+002,1.098449e+002,-2.853753e-005,0.000000e+000,7.616577e-002,0.000000e+000,3,2.346262e-001,1.825000e+000,,,,,,,,,,,,,,,,,,0,5.000000e+000,5.000000e-001,2,1,7.769012e-001,0,1,0,
1473354113.218,,5.000000e+002,1.108298e+002,-2.868301e-005,0.000000e+000,7.661548e-002,0.000000e+000,3,2.384107e-001,1.825000e+000,,,,,,,,,,,,,,,,,,0,5.000000e+000,5.000000e-001,2,1,7.901001e-001,0,1,0,
1473354130.683,,5.000000e+002,1.123631e+002,-2.880982e-005,0.000000e+000,7.695553e-002,0.000000e+000,3,2.409998e-001,1.825000e+000,,,,,,,,,,,,,,,,,,0,5.000000e+000,5.000000e-001,2,1,8.267975e-001,0,1,0,
1473354143.670,,5.000000e+002,1.133952e+002,-2.890042e-005,0.000000e+000,7.741221e-002,0.000000e+000,3,2.431946e-001,1.825000e+000,,,,,,,,,,,,,,,,,,0,5.000000e+000,5.000000e-001,2,1,8.283997e-001,0,1,0,
1473354157.884,,5.000000e+002,1.146331e+002,-2.902347e-005,0.000000e+000,7.779153e-002,0.000000e+000,3,2.464718e-001,1.825000e+000,,,,,,,,,,,,,,,,,,0,5.000000e+000,5.000000e-001,2,1,8.251038e-001,0,1,0,
1473354170.849,,5.000000e+002,1.157649e+002,-2.913211e-005,0.000000e+000,7.825091e-002,0.000000e+000,3,2.492061e-001,1.825000e+000,,,,,,,,,,,,,,,,,,0,5.000000e+000,5.000000e-001,2,1,1.025200e+000,0,1,0,
1473354184.813,,5.000000e+002,1.168936e+002,-2.919594e-005,0.000000e+000,7.860708e-002,0.000000e+000,3,2.507276e-001,1.825000e+000,,,,,,,,,,,,,,,,,,0,5.000000e+000,5.000000e-001,2,1,8.165054e-001,0,1,0,
1473354198.778,,5.000000e+002,1.181246e+002,-2.924439e-005,0.000000e+000,7.890353e-002,0.000000e+000,3,2.513736e-001,1.825000e+000,,,,,,,,,,,,,,,,,,0,5.000000e+000,5.000000e-001,2,1,8.174057e-001,0,1,0,
1473354214.761,,5.000000e+002,1.193519e+002,-2.935513e-005,0.000000e+000,7.962494e-002,0.000000e+000,3,2.541919e-001,1.825000e+000,,,,,,,,,,,,,,,,,,0,5.000000e+000,5.000000e-001,2,1,8.178024e-001,0,1,0,
1473354233.226,,5.000000e+002,1.203720e+002,-2.945857e-005,0.000000e+000,8.002541e-002,0.000000e+000,3,2.574776e-001,1.825000e+000,,,,,,,,,,,,,,,,,,0,5.000000e+000,5.000000e-001,2,1,8.216019e-001,0,1,0,
1473354354.201,,5.000000e+002,1.202184e+002,-2.944813e-005,0.000000e+000,7.991600e-002,0.000000e+000,3,2.575173e-001,1.825000e+000,,,,,,,,,,,,,,,,,,0,5.000000e+000,5.000000e-001,2,1,4.630280e-002,0,1,0,
1473354367.195,,5.000000e+002,1.201623e+002,-2.942459e-005,0.000000e+000,8.041431e-002,0.000000e+000,3,2.560167e-001,1.825000e+000,,,,,,,,,,,,,,,,,,0,5.000000e+000,5.000000e-001,2,1,6.599426e-002,0,1,0,
1473354380.410,,5.000000e+002,1.201128e+002,-2.944181e-005,0.000000e+000,8.047938e-002,0.000000e+000,3,2.563203e-001,1.825000e+000,,,,,,,,,,,,,,,,,,0,5.000000e+000,5.000000e-001,2,1,3.300476e-002,0,1,0,
1473354393.374,,5.000000e+002,1.200798e+002,-2.944420e-005,0.000000e+000,8.047836e-002,0.000000e+000,3,2.567744e-001,1.825000e+000,,,,,,,,,,,,,,,,,,0,5.000000e+000,5.000000e-001,2,1,1.979828e-002,0,1,0,