File: data/A344/dat/A344_GdN_FC_500_Oe_160908.rso.dat
[Header]
TITLE,MPMS RSO Measurement
BYAPP,MPMS Measurement,1.1,Summary
FILEOPENTIME, 1473354629.147000 9/9/2016, 5:10:29 AM

INFO, APPNAME, MPMS MultiVu Application, Revision 1.61,  Build 082

INFO, NAME, A344
INFO, WEIGHT, 10.500
INFO, AREA, 1.000
INFO, LENGTH, 1.000
INFO, SHAPE, 0
INFO, COMMENT, m = 0.0105g
INFO, SEQUENCE FILE: FC_120K-5K.seq


INFO, BACKGROUND DATA FILE:, None


STARTUPAXIS,X,4,LINEAR,AUTO,0.000000,0.000000
STARTUPAXIS,Y1,5,LINEAR,AUTO,0.000000,0.000000


STARTUPGROUP,Longitudinal
FIELDGROUP,Longitudinal,1,2,3,4,5,6,7,8,9,10,11,19,20,21,22,23,35
FIELDGROUP,Transverse,1,2,3,4,12,13,14,15,16,17,18,24,25,26,27,28,35

PLOT_APPEARANCE,ALL,HORZ_GRID_ON,VERT_GRID_ON,MARKERS_AND_LINES

[Data]
Time,Comment,Field (Oe),Temperature (K),Long Moment (emu),Long Scan Std Dev,Long Offset (cm),Long Offset Std Dev,Long Algorithm,Long Reg Fit,Long Reg Factor,Trans Moment (emu),Trans Scan Std Dev,Trans Offset (cm),Trans Offset Std Dev,Trans Algorithm,Trans Reg Fit,Trans Reg Factor,Long Moment [w/o ABS] (emu),Long Scan Std Dev [w/o ABS],Long Offset [w/o ABS] (cm),Long Offset Std Dev [w/o ABS],Long Reg Fit [w/o ABS],Trans Moment [w/o ABS] (emu),Trans Scan Std Dev [w/o ABS],Trans Offset [w/o ABS] (cm),Trans Offset Std Dev [w/o ABS],Trans Reg Fit [w/o ABS],RSO Position (deg),Amplitude (cm),Frequency,Cycles to Average,Scans per Measurement,Delta Temp (K),Error,EC Comp. Running,Using ABS,
1473354629.146,,5.000000e+002,1.200123e+002,-2.938674e-005,0.000000e+000,8.005753e-002,0.000000e+000,3,2.540880e-001,1.825000e+000,,,,,,,,,,,,,,,,,,0,5.000000e+000,5.000000e-001,2,1,3.303528e-003,0,0,0,
1473354641.360,,5.000000e+002,1.200123e+002,-2.943081e-005,0.000000e+000,8.051827e-002,0.000000e+000,3,2.560927e-001,1.825000e+000,,,,,,,,,,,,,,,,,,0,5.000000e+000,5.000000e-001,2,1,3.303528e-003,0,0,0,
1473354653.378,,5.000000e+002,1.200073e+002,-2.943950e-005,0.000000e+000,8.031363e-002,0.000000e+000,3,2.563733e-001,1.825000e+000,,,,,,,,,,,,,,,,,,0,5.000000e+000,5.000000e-001,2,1,0.000000e+000,0,0,0,
1473354665.342,,5.000000e+002,1.200040e+002,-2.941473e-005,0.000000e+000,8.022909e-002,0.000000e+000,3,2.556329e-001,1.825000e+000,,,,,,,,,,,,,,,,,,0,5.000000e+000,5.000000e-001,2,1,0.000000e+000,0,0,0,
1473354899.083,,5.000000e+002,1.143640e+002,-2.903237e-005,0.000000e+000,7.872871e-002,0.000000e+000,3,2.458859e-001,1.825000e+000,,,,,,,,,,,,,,,,,,0,5.000000e+000,5.000000e-001,2,1,7.404022e-001,0,0,0,
1473354912.547,,5.000000e+002,1.133578e+002,-2.895935e-005,0.000000e+000,7.872210e-002,0.000000e+000,3,2.442630e-001,1.825000e+000,,,,,,,,,,,,,,,,,,0,5.000000e+000,5.000000e-001,2,1,6.482010e-001,0,0,0,
1473354925.511,,5.000000e+002,1.125120e+002,-2.885598e-005,0.000000e+000,7.857432e-002,0.000000e+000,3,2.410892e-001,1.825000e+000,,,,,,,,,,,,,,,,,,0,5.000000e+000,5.000000e-001,2,1,6.981964e-001,0,0,0,
1473354939.976,,5.000000e+002,1.113465e+002,-2.877671e-005,0.000000e+000,7.827577e-002,0.000000e+000,3,2.394256e-001,1.825000e+000,,,,,,,,,,,,,,,,,,0,5.000000e+000,5.000000e-001,2,1,9.420929e-001,0,0,0,
1473354992.064,,5.000000e+002,1.069277e+002,-2.825519e-005,0.000000e+000,7.775623e-002,0.000000e+000,3,2.255093e-001,1.825000e+000,,,,,,,,,,,,,,,,,,0,5.000000e+000,5.000000e-001,2,1,9.096985e-001,0,1,0,
1473355006.140,,5.000000e+002,1.055191e+002,-2.806931e-005,0.000000e+000,7.725817e-002,0.000000e+000,3,2.207423e-001,1.825000e+000,,,,,,,,,,,,,,,,,,0,5.000000e+000,5.000000e-001,2,1,9.593048e-001,0,1,0,
1473355019.355,,5.000000e+002,1.043134e+002,-2.787501e-005,0.000000e+000,7.706454e-002,0.000000e+000,3,2.150843e-001,1.825000e+000,,,,,,,,,,,,,,,,,,0,5.000000e+000,5.000000e-001,2,1,1.452194e+000,0,1,0,
1473355033.569,,5.000000e+002,1.028347e+002,-2.765546e-005,0.000000e+000,7.678482e-002,0.000000e+000,3,2.086526e-001,1.825000e+000,,,,,,,,,,,,,,,,,,0,5.000000e+000,5.000000e-001,2,1,1.009399e+000,0,1,0,
1473355047.533,,5.000000e+002,1.015814e+002,-2.743468e-005,0.000000e+000,7.626422e-002,0.000000e+000,3,2.022783e-001,1.825000e+000,,,,,,,,,,,,,,,,,,0,5.000000e+000,5.000000e-001,2,1,1.027199e+000,0,1,0,
1473355061.748,,5.000000e+002,1.001999e+002,-2.715999e-005,0.000000e+000,7.619452e-002,0.000000e+000,3,1.947839e-001,1.825000e+000,,,,,,,,,,,,,,,,,,0,5.000000e+000,5.000000e-001,2,1,7.490845e-001,0,1,0,
1473355073.910,,5.000000e+002,9.904492e+001,-2.689291e-005,0.000000e+000,7.597362e-002,0.000000e+000,3,1.870579e-001,1.825000e+000,,,,,,,,,,,,,,,,,,0,5.000000e+000,5.000000e-001,2,1,1.032051e+000,0,1,0,
1473355087.771,,5.000000e+002,9.746860e+001,-2.657416e-005,0.000000e+000,7.560993e-002,0.000000e+000,3,1.770567e-001,1.825000e+000,,,,,,,,,,,,,,,,,,0,5.000000e+000,5.000000e-001,2,1,1.049904e+000,0,1,0,
1473355100.236,,5.000000e+002,9.618125e+001,-2.623722e-005,0.000000e+000,7.540394e-002,0.000000e+000,3,1.668318e-001,1.825000e+000,,,,,,,,,,,,,,,,,,0,5.000000e+000,5.000000e-001,2,1,1.017380e+000,0,1,0,
1473355115.450,,5.000000e+002,9.462747e+001,-2.575612e-005,0.000000e+000,7.524536e-002,0.000000e+000,3,1.507249e-001,1.825000e+000,,,,,,,,,,,,,,,,,,0,5.000000e+000,5.000000e-001,2,1,1.013802e+000,0,1,0,
1473355127.664,,5.000000e+002,9.345970e+001,-2.535597e-005,0.000000e+000,7.510167e-002,0.000000e+000,3,1.375200e-001,1.825000e+000,,,,,,,,,,,,,,,,,,0,5.000000e+000,5.000000e-001,2,1,1.321724e+000,0,1,0,
1473355141.129,,5.000000e+002,9.214662e+001,-2.483486e-005,0.000000e+000,7.459030e-002,0.000000e+000,3,1.193298e-001,1.825000e+000,,,,,,,,,,,,,,,,,,0,5.000000e+000,5.000000e-001,2,1,7.849503e-001,0,1,0,
1473355154.593,,5.000000e+002,9.073623e+001,-2.425659e-005,0.000000e+000,7.472136e-002,0.000000e+000,3,9.749618e-002,1.825000e+000,,,,,,,,,,,,,,,,,,0,5.000000e+000,5.000000e-001,2,1,1.052704e+000,0,1,0,
1473355167.057,,5.000000e+002,8.947829e+001,-2.366362e-005,0.000000e+000,7.471926e-002,0.000000e+000,3,7.517216e-002,1.825000e+000,,,,,,,,,,,,,,,,,,0,5.000000e+000,5.000000e-001,2,1,9.820328e-001,0,1,0,
1473355179.037,,5.000000e+002,8.836410e+001,-2.299133e-005,0.000000e+000,7.471448e-002,0.000000e+000,3,4.834304e-002,1.825000e+000,,,,,,,,,,,,,,,,,,0,5.000000e+000,5.000000e-001,2,1,7.180023e-001,0,1,0,
1473355192.001,,5.000000e+002,8.699039e+001,-2.220842e-005,0.000000e+000,7.455469e-002,0.000000e+000,3,1.472654e-002,1.825000e+000,,,,,,,,,,,,,,,,,,0,5.000000e+000,5.000000e-001,2,1,9.830322e-001,0,1,0,
1473355205.970,,5.000000e+002,8.581590e+001,-2.121009e-005,0.000000e+000,7.426088e-002,0.000000e+000,3,0.000000e+000,1.825000e+000,,,,,,,,,,,,,,,,,,0,5.000000e+000,5.000000e-001,2,1,9.319763e-001,0,1,0,
1473355219.364,,5.000000e+002,8.464999e+001,-2.016139e-005,0.000000e+000,7.439155e-002,0.000000e+000,3,0.000000e+000,1.825000e+000,,,,,,,,,,,,,,,,,,0,5.000000e+000,5.000000e-001,2,1,9.217682e-001,0,1,0,
1473355230.197,,5.000000e+002,8.374167e+001,-1.919943e-005,0.000000e+000,7.427424e-002,0.000000e+000,3,0.000000e+000,1.825000e+000,,,,,,,,,,,,,,,,,,0,5.000000e+000,5.000000e-001,2,1,8.948822e-001,0,1,0,
1473355244.411,,5.000000e+002,8.260576e+001,-1.783476e-005,0.000000e+000,7.415566e-002,0.000000e+000,3,0.000000e+000,1.825000e+000,,,,,,,,,,,,,,,,,,0,5.000000e+000,5.000000e-001,2,1,5.900650e-001,0,1,0,
1473355259.876,,5.000000e+002,8.140727e+001,-1.618599e-005,0.000000e+000,7.383082e-002,0.000000e+000,3,0.000000e+000,1.825000e+000,,,,,,,,,,,,,,,,,,0,5.000000e+000,5.000000e-001,2,1,5.472183e-001,0,1,0,
1473355272.370,,5.000000e+002,8.046979e+001,-1.463774e-005,0.000000e+000,7.260526e-002,0.000000e+000,3,0.000000e+000,1.825000e+000,,,,,,,,,,,,,,,,,,0,5.000000e+000,5.000000e-001,2,1,5.477676e-001,0,1,0,
1473355290.585,,5.000000e+002,7.960687e+001,-1.256420e-005,0.000000e+000,7.535498e-002,0.000000e+000,3,0.000000e+000,1.825000e+000,,,,,,,,,,,,,,,,,,0,5.000000e+000,5.000000e-001,2,1,2.509842e-001,0,1,0,
1473355303.553,,5.000000e+002,7.952513e+001,-1.225124e-005,0.000000e+000,7.652242e-002,0.000000e+000,3,0.000000e+000,1.825000e+000,,,,,,,,,,,,,,,,,,0,5.000000e+000,5.000000e-001,2,1,9.052277e-002,0,1,0,
1473355416.027,,5.000000e+002,8.012697e+001,-1.403074e-005,0.000000e+000,7.328683e-002,0.000000e+000,3,0.000000e+000,1.825000e+000,,,,,,,,,,,,,,,,,,0,5.000000e+000,5.000000e-001,2,1,1.529694e-002,0,1,0,
1473355427.741,,5.000000e+002,8.010172e+001,-1.400221e-005,0.000000e+000,7.430888e-002,0.000000e+000,3,0.000000e+000,1.825000e+000,,,,,,,,,,,,,,,,,,0,5.000000e+000,5.000000e-001,2,1,7.659912e-003,0,1,0,
1473355458.671,,5.000000e+002,8.008643e+001,-1.408876e-005,0.000000e+000,7.406411e-002,0.000000e+000,3,0.000000e+000,1.825000e+000,,,,,,,,,,,,,,,,,,0,5.000000e+000,5.000000e-001,2,1,2.905273e-002,0,1,0,
1473355470.635,,5.000000e+002,8.006197e+001,-1.410219e-005,0.000000e+000,7.348059e-002,0.000000e+000,3,0.000000e+000,1.825000e+000,,,,,,,,,,,,,,,,,,0,5.000000e+000,5.000000e-001,2,1,1.985931e-002,0,0,0,
1473355663.121,,5.000000e+002,8.000392e+001,-1.421729e-005,0.000000e+000,7.335271e-002,0.000000e+000,3,0.000000e+000,1.825000e+000,,,,,,,,,,,,,,,,,,0,5.000000e+000,5.000000e-001,2,1,4.570007e-003,0,0,0,
1473355676.334,,5.000000e+002,8.000394e+001,-1.424508e-005,0.000000e+000,7.314370e-002,0.000000e+000,3,0.000000e+000,1.825000e+000,,,,,,,,,,,,,,,,,,0,5.000000e+000,5.000000e-001,2,1,1.374054e-002,0,0,0,
1473355688.318,,5.000000e+002,8.000775e+001,-1.419184e-005,0.000000e+000,7.391309e-002,0.000000e+000,3,0.000000e+000,1.825000e+000,,,,,,,,,,,,,,,,,,0,5.000000e+000,5.000000e-001,2,1,9.162903e-003,0,0,0,
1473355700.727,,5.000000e+002,8.000317e+001,-1.420949e-005,0.000000e+000,7.261017e-002,0.000000e+000,3,0.000000e+000,1.825000e+000,,,,,,,,,,,,,,,,,,0,5.000000e+000,5.000000e-001,2,1,1.220703e-002,0,0,0,
1473355866.564,,5.000000e+002,7.648900e+001,-5.184108e-006,0.000000e+000,0.000000e+000,0.000000e+000,3,0.000000e+000,1.825000e+000,,,,,,,,,,,,,,,,,,0,5.000000e+000,5.000000e-001,2,1,5.001984e-001,0,0,0,
1473355879.529,,5.000000e+002,7.582645e+001,2.919514e-005,0.000000e+000,-1.382542e+000,0.000000e+000,3,5.335938e-001,1.825000e+000,,,,,,,,,,,,,,,,,,0,5.000000e+000,5.000000e-001,2,1,5.469513e-001,0,0,0,
1473355891.743,,5.000000e+002,7.519038e+001,6.709334e-007,0.000000e+000,0.000000e+000,0.000000e+000,3,0.000000e+000,1.825000e+000,,,,,,,,,,,,,,,,,,0,5.000000e+000,5.000000e-001,2,1,7.251740e-001,0,0,0,
1473355906.212,,5.000000e+002,7.429369e+001,5.446601e-006,0.000000e+000,0.000000e+000,0.000000e+000,3,0.000000e+000,1.825000e+000,,,,,,,,,,,,,,,,,,0,5.000000e+000,5.000000e-001,2,1,4.529266e-001,0,0,0,
1473355919.236,,5.000000e+002,7.349881e+001,2.087676e-005,0.000000e+000,-1.267265e+000,0.000000e+000,3,4.493556e-002,1.825000e+000,,,,,,,,,,,,,,,,,,0,5.000000e+000,5.000000e-001,2,1,7.821732e-001,0,0,0,
1473355931.700,,5.000000e+002,7.260483e+001,1.775020e-005,0.000000e+000,-1.224957e+000,0.000000e+000,3,0.000000e+000,1.825000e+000,,,,,,,,,,,,,,,,,,0,5.000000e+000,5.000000e-001,2,1,6.650696e-001,0,0,0,
1473355945.664,,5.000000e+002,7.178318e+001,3.011871e-005,0.000000e+000,-1.452668e-001,0.000000e+000,3,2.559246e-001,1.825000e+000,,,,,,,,,,,,,,,,,,0,5.000000e+000,5.000000e-001,2,1,6.499634e-001,0,0,0,
1473355958.879,,5.000000e+002,7.087544e+001,4.539859e-005,0.000000e+000,-5.421766e-002,0.000000e+000,3,4.994072e-001,1.825000e+000,,,,,,,,,,,,,,,,,,0,5.000000e+000,5.000000e-001,2,1,8.271866e-001,0,0,0,
1473355986.057,,5.000000e+002,6.916221e+001,1.029112e-004,0.000000e+000,-9.316694e-004,0.000000e+000,3,7.687896e-001,1.825000e+000,,,,,,,,,,,,,,,,,,0,5.000000e+000,5.000000e-001,2,1,6.455383e-001,0,1,0,
1473356000.022,,5.000000e+002,6.805226e+001,1.496688e-004,0.000000e+000,7.448290e-003,0.000000e+000,3,8.362134e-001,1.825000e+000,,,,,,,,,,,,,,,,,,0,5.000000e+000,5.000000e-001,2,1,5.391312e-001,0,1,0,
1473356025.200,,5.000000e+002,6.642442e+001,2.481524e-004,0.000000e+000,1.258623e-002,0.000000e+000,3,8.972555e-001,1.825000e+000,,,,,,,,,,,,,,,,,,0,5.000000e+000,5.000000e-001,2,1,7.028198e-001,0,1,0,
1473356038.931,,5.000000e+002,6.551592e+001,2.977521e-004,0.000000e+000,1.331402e-002,0.000000e+000,3,9.131289e-001,1.825000e+000,,,,,,,,,,,,,,,,,,0,5.000000e+000,5.000000e-001,2,1,5.119324e-001,0,1,0,
1473356051.645,,5.000000e+002,6.469800e+001,3.384894e-004,0.000000e+000,1.368576e-002,0.000000e+000,3,9.227749e-001,1.825000e+000,,,,,,,,,,,,,,,,,,0,5.000000e+000,5.000000e-001,2,1,8.147812e-001,0,1,0,
1473356064.359,,5.000000e+002,6.396748e+001,3.750394e-004,0.000000e+000,1.379651e-002,0.000000e+000,3,9.296249e-001,1.825000e+000,,,,,,,,,,,,,,,,,,0,5.000000e+000,5.000000e-001,2,1,6.462517e-001,0,1,0,
1473356088.037,,5.000000e+002,6.232648e+001,4.324462e-004,0.000000e+000,1.374971e-002,0.000000e+000,3,9.380271e-001,1.825000e+000,,,,,,,,,,,,,,,,,,0,5.000000e+000,5.000000e-001,2,1,4.694099e-001,0,1,0,
1473356099.937,,5.000000e+002,6.163528e+001,4.572166e-004,0.000000e+000,1.370787e-002,0.000000e+000,3,9.409195e-001,1.825000e+000,,,,,,,,,,,,,,,,,,0,5.000000e+000,5.000000e-001,2,1,6.317215e-001,0,1,0,
1473356114.759,,5.000000e+002,6.085362e+001,4.849191e-004,0.000000e+000,1.365531e-002,0.000000e+000,3,9.437867e-001,1.825000e+000,,,,,,,,,,,,,,,,,,0,5.000000e+000,5.000000e-001,2,1,3.870125e-001,0,1,0,
1473356127.973,,5.000000e+002,6.011167e+001,5.075887e-004,0.000000e+000,1.348895e-002,0.000000e+000,3,9.459057e-001,1.825000e+000,,,,,,,,,,,,,,,,,,0,5.000000e+000,5.000000e-001,2,1,5.528374e-001,0,1,0,
1473356139.989,,5.000000e+002,5.938660e+001,5.267698e-004,0.000000e+000,1.337341e-002,0.000000e+000,3,9.475803e-001,1.825000e+000,,,,,,,,,,,,,,,,,,0,5.000000e+000,5.000000e-001,2,1,3.882217e-001,0,1,0,
1473356152.953,,5.000000e+002,5.870201e+001,5.456118e-004,0.000000e+000,1.319914e-002,0.000000e+000,3,9.490204e-001,1.825000e+000,,,,,,,,,,,,,,,,,,0,5.000000e+000,5.000000e-001,2,1,5.163269e-001,0,1,0,
1473356165.417,,5.000000e+002,5.808064e+001,5.631766e-004,0.000000e+000,1.307210e-002,0.000000e+000,3,9.502757e-001,1.825000e+000,,,,,,,,,,,,,,,,,,0,5.000000e+000,5.000000e-001,2,1,4.893265e-001,0,1,0,
1473356176.678,,5.000000e+002,5.744688e+001,5.779729e-004,0.000000e+000,1.297660e-002,0.000000e+000,3,9.512616e-001,1.825000e+000,,,,,,,,,,,,,,,,,,0,5.000000e+000,5.000000e-001,2,1,5.066109e-001,0,1,0,
1473356189.325,,5.000000e+002,5.683878e+001,5.936284e-004,0.000000e+000,1.279715e-002,0.000000e+000,3,9.522621e-001,1.825000e+000,,,,,,,,,,,,,,,,,,0,5.000000e+000,5.000000e-001,2,1,4.789124e-001,0,1,0,
1473356204.187,,5.000000e+002,5.611819e+001,6.114467e-004,0.000000e+000,1.262014e-002,0.000000e+000,3,9.533691e-001,1.825000e+000,,,,,,,,,,,,,,,,,,0,5.000000e+000,5.000000e-001,2,1,4.703979e-001,0,1,0,
1473356216.151,,5.000000e+002,5.551865e+001,6.251107e-004,0.000000e+000,1.247508e-002,0.000000e+000,3,9.541546e-001,1.825000e+000,,,,,,,,,,,,,,,,,,0,5.000000e+000,5.000000e-001,2,1,4.744301e-001,0,1,0,
1473356228.866,,5.000000e+002,5.492091e+001,6.391832e-004,0.000000e+000,1.231555e-002,0.000000e+000,3,9.548686e-001,1.825000e+000,,,,,,,,,,,,,,,,,,0,5.000000e+000,5.000000e-001,2,1,4.750481e-001,0,1,0,
1473356240.830,,5.000000e+002,5.433121e+001,6.518464e-004,0.000000e+000,1.215936e-002,0.000000e+000,3,9.555486e-001,1.825000e+000,,,,,,,,,,,,,,,,,,0,5.000000e+000,5.000000e-001,2,1,4.604683e-001,0,1,0,
1473356252.855,,5.000000e+002,5.374432e+001,6.643821e-004,0.000000e+000,1.202313e-002,0.000000e+000,3,9.562157e-001,1.825000e+000,,,,,,,,,,,,,,,,,,0,5.000000e+000,5.000000e-001,2,1,4.657707e-001,0,1,0,
1473356265.819,,5.000000e+002,5.308366e+001,6.771192e-004,0.000000e+000,1.189512e-002,0.000000e+000,3,9.567707e-001,1.825000e+000,,,,,,,,,,,,,,,,,,0,5.000000e+000,5.000000e-001,2,1,3.464508e-001,0,1,0,
1473356276.783,,5.000000e+002,5.256105e+001,6.880393e-004,0.000000e+000,1.171656e-002,0.000000e+000,3,9.572952e-001,1.825000e+000,,,,,,,,,,,,,,,,,,0,5.000000e+000,5.000000e-001,2,1,4.724503e-001,0,1,0,
1473356288.748,,5.000000e+002,5.197676e+001,6.993098e-004,0.000000e+000,1.157022e-002,0.000000e+000,3,9.578020e-001,1.825000e+000,,,,,,,,,,,,,,,,,,0,5.000000e+000,5.000000e-001,2,1,4.745598e-001,0,1,0,
1473356301.774,,5.000000e+002,5.140458e+001,7.113106e-004,0.000000e+000,1.139795e-002,0.000000e+000,3,9.582944e-001,1.825000e+000,,,,,,,,,,,,,,,,,,0,5.000000e+000,5.000000e-001,2,1,4.555511e-001,0,1,0,
1473356313.988,,5.000000e+002,5.082442e+001,7.222783e-004,0.000000e+000,1.127604e-002,0.000000e+000,3,9.588102e-001,1.825000e+000,,,,,,,,,,,,,,,,,,0,5.000000e+000,5.000000e-001,2,1,4.586716e-001,0,1,0,
1473356326.952,,5.000000e+002,5.024589e+001,7.335953e-004,0.000000e+000,1.114310e-002,0.000000e+000,3,9.592529e-001,1.825000e+000,,,,,,,,,,,,,,,,,,0,5.000000e+000,5.000000e-001,2,1,4.601097e-001,0,1,0,
1473356338.917,,5.000000e+002,4.967107e+001,7.438262e-004,0.000000e+000,1.091902e-002,0.000000e+000,3,9.596162e-001,1.825000e+000,,,,,,,,,,,,,,,,,,0,5.000000e+000,5.000000e-001,2,1,4.538803e-001,0,1,0,
1473356354.185,,5.000000e+002,4.897095e+001,7.567621e-004,0.000000e+000,1.077589e-002,0.000000e+000,3,9.601107e-001,1.825000e+000,,,,,,,,,,,,,,,,,,0,5.000000e+000,5.000000e-001,2,1,4.645615e-001,0,1,0,
1473356369.150,,5.000000e+002,4.827691e+001,7.689275e-004,0.000000e+000,1.059955e-002,0.000000e+000,3,9.606249e-001,1.825000e+000,,,,,,,,,,,,,,,,,,0,5.000000e+000,5.000000e-001,2,1,4.663315e-001,0,1,0,
1473356381.864,,5.000000e+002,4.774106e+001,7.794818e-004,0.000000e+000,1.046597e-002,0.000000e+000,3,9.609171e-001,1.825000e+000,,,,,,,,,,,,,,,,,,0,5.000000e+000,5.000000e-001,2,1,6.053581e-001,0,1,0,
1473356394.861,,5.000000e+002,4.703705e+001,7.898741e-004,0.000000e+000,1.024966e-002,0.000000e+000,3,9.613211e-001,1.825000e+000,,,,,,,,,,,,,,,,,,0,5.000000e+000,5.000000e-001,2,1,3.483772e-001,0,1,0,
1473356408.075,,5.000000e+002,4.652683e+001,7.988894e-004,0.000000e+000,1.065118e-002,0.000000e+000,3,9.608158e-001,1.825000e+000,,,,,,,,,,,,,,,,,,0,5.000000e+000,5.000000e-001,2,1,4.332314e-001,0,1,0,
1473356420.540,,5.000000e+002,4.598125e+001,8.089856e-004,0.000000e+000,1.005961e-002,0.000000e+000,3,9.618585e-001,1.825000e+000,,,,,,,,,,,,,,,,,,0,5.000000e+000,5.000000e-001,2,1,4.373283e-001,0,1,0,
1473356432.801,,5.000000e+002,4.536979e+001,8.175966e-004,0.000000e+000,9.819208e-003,0.000000e+000,3,9.619905e-001,1.825000e+000,,,,,,,,,,,,,,,,,,0,5.000000e+000,5.000000e-001,2,1,5.511322e-001,0,1,0,
1473356446.015,,5.000000e+002,4.476701e+001,8.267598e-004,0.000000e+000,9.579609e-003,0.000000e+000,3,9.625329e-001,1.825000e+000,,,,,,,,,,,,,,,,,,0,5.000000e+000,5.000000e-001,2,1,4.386292e-001,0,1,0,
1473356459.411,,5.000000e+002,4.409480e+001,8.360547e-004,0.000000e+000,9.524697e-003,0.000000e+000,3,9.627364e-001,1.825000e+000,,,,,,,,,,,,,,,,,,0,5.000000e+000,5.000000e-001,2,1,4.476204e-001,0,1,0,
1473356472.233,,5.000000e+002,4.353539e+001,8.448782e-004,0.000000e+000,9.397052e-003,0.000000e+000,3,9.630027e-001,1.825000e+000,,,,,,,,,,,,,,,,,,0,5.000000e+000,5.000000e-001,2,1,4.568481e-001,0,0,0,
1473356484.197,,5.000000e+002,4.297245e+001,8.531851e-004,0.000000e+000,9.221720e-003,0.000000e+000,3,9.632596e-001,1.825000e+000,,,,,,,,,,,,,,,,,,0,5.000000e+000,5.000000e-001,2,1,4.636230e-001,0,0,0,
1473356497.161,,5.000000e+002,4.237801e+001,8.620757e-004,0.000000e+000,9.194418e-003,0.000000e+000,3,9.635741e-001,1.825000e+000,,,,,,,,,,,,,,,,,,0,5.000000e+000,5.000000e-001,2,1,4.791603e-001,0,0,0,
1473356510.380,,5.000000e+002,4.177900e+001,8.716484e-004,0.000000e+000,8.973268e-003,0.000000e+000,3,9.638539e-001,1.825000e+000,,,,,,,,,,,,,,,,,,0,5.000000e+000,5.000000e-001,2,1,4.847183e-001,0,0,0,
1473356524.594,,5.000000e+002,4.101136e+001,8.821920e-004,0.000000e+000,8.841028e-003,0.000000e+000,3,9.639535e-001,1.825000e+000,,,,,,,,,,,,,,,,,,0,5.000000e+000,5.000000e-001,2,1,5.221710e-001,0,0,0,
1473356545.474,,5.000000e+002,4.002673e+001,8.976781e-004,0.000000e+000,8.548946e-003,0.000000e+000,3,9.643661e-001,1.825000e+000,,,,,,,,,,,,,,,,,,0,5.000000e+000,5.000000e-001,2,1,4.114914e-001,0,0,0,
1473356558.568,,5.000000e+002,3.932940e+001,9.077266e-004,0.000000e+000,8.384426e-003,0.000000e+000,3,9.646052e-001,1.825000e+000,,,,,,,,,,,,,,,,,,0,5.000000e+000,5.000000e-001,2,1,7.140198e-001,0,0,0,
1473356570.845,,5.000000e+002,3.846410e+001,9.172419e-004,0.000000e+000,8.210042e-003,0.000000e+000,3,9.648734e-001,1.825000e+000,,,,,,,,,,,,,,,,,,0,5.000000e+000,5.000000e-001,2,1,7.322769e-001,0,0,0,
1473356583.059,,5.000000e+002,3.787675e+001,9.266246e-004,0.000000e+000,8.080822e-003,0.000000e+000,3,9.651096e-001,1.825000e+000,,,,,,,,,,,,,,,,,,0,5.000000e+000,5.000000e-001,2,1,4.424133e-001,0,0,0,
1473356595.523,,5.000000e+002,3.695676e+001,9.364944e-004,0.000000e+000,7.874878e-003,0.000000e+000,3,9.652842e-001,1.825000e+000,,,,,,,,,,,,,,,,,,0,5.000000e+000,5.000000e-001,2,1,4.641800e-001,0,0,0,
1473356608.238,,5.000000e+002,3.624767e+001,9.466224e-004,0.000000e+000,7.677762e-003,0.000000e+000,3,9.655323e-001,1.825000e+000,,,,,,,,,,,,,,,,,,0,5.000000e+000,5.000000e-001,2,1,6.384201e-001,0,0,0,
1473356620.202,,5.000000e+002,3.559879e+001,9.562413e-004,0.000000e+000,7.489099e-003,0.000000e+000,3,9.657810e-001,1.825000e+000,,,,,,,,,,,,,,,,,,0,5.000000e+000,5.000000e-001,2,1,6.593285e-001,0,0,0,
1473356634.866,,5.000000e+002,3.450793e+001,9.678397e-004,0.000000e+000,7.356370e-003,0.000000e+000,3,9.660220e-001,1.825000e+000,,,,,,,,,,,,,,,,,,0,5.000000e+000,5.000000e-001,2,1,5.147133e-001,0,0,0,
1473356646.138,,5.000000e+002,3.386826e+001,9.769468e-004,0.000000e+000,7.186164e-003,0.000000e+000,3,9.661767e-001,1.825000e+000,,,,,,,,,,,,,,,,,,0,5.000000e+000,5.000000e-001,2,1,7.646294e-001,0,0,0,
1473356658.961,,5.000000e+002,3.292737e+001,9.872089e-004,0.000000e+000,7.051044e-003,0.000000e+000,3,9.664359e-001,1.825000e+000,,,,,,,,,,,,,,,,,,0,5.000000e+000,5.000000e-001,2,1,8.086967e-001,0,0,0,
1473356672.720,,5.000000e+002,3.193759e+001,9.981244e-004,0.000000e+000,6.766347e-003,0.000000e+000,3,9.666777e-001,1.825000e+000,,,,,,,,,,,,,,,,,,0,5.000000e+000,5.000000e-001,2,1,4.905205e-001,0,0,0,
1473356688.185,,5.000000e+002,3.076833e+001,1.009876e-003,0.000000e+000,6.628667e-003,0.000000e+000,3,9.668985e-001,1.825000e+000,,,,,,,,,,,,,,,,,,0,5.000000e+000,5.000000e-001,2,1,8.395500e-001,0,0,0,
1473356703.399,,5.000000e+002,2.967054e+001,1.021538e-003,0.000000e+000,6.432534e-003,0.000000e+000,3,9.671606e-001,1.825000e+000,,,,,,,,,,,,,,,,,,0,5.000000e+000,5.000000e-001,2,1,6.741695e-001,0,0,0,
1473356715.863,,5.000000e+002,2.883213e+001,1.030535e-003,0.000000e+000,6.279525e-003,0.000000e+000,3,9.673445e-001,1.825000e+000,,,,,,,,,,,,,,,,,,0,5.000000e+000,5.000000e-001,2,1,6.740398e-001,0,0,0,
1473356728.328,,5.000000e+002,2.798502e+001,1.039597e-003,0.000000e+000,6.097746e-003,0.000000e+000,3,9.675147e-001,1.825000e+000,,,,,,,,,,,,,,,,,,0,5.000000e+000,5.000000e-001,2,1,6.777287e-001,0,0,0,
1473356741.083,,5.000000e+002,2.696066e+001,1.048613e-003,0.000000e+000,5.964141e-003,0.000000e+000,3,9.676848e-001,1.825000e+000,,,,,,,,,,,,,,,,,,0,5.000000e+000,5.000000e-001,2,1,6.848812e-001,0,0,0,
1473356753.797,,5.000000e+002,2.610669e+001,1.057179e-003,0.000000e+000,5.827280e-003,0.000000e+000,3,9.678357e-001,1.825000e+000,,,,,,,,,,,,,,,,,,0,5.000000e+000,5.000000e-001,2,1,6.890602e-001,0,0,0,
1473356766.762,,5.000000e+002,2.524969e+001,1.065916e-003,0.000000e+000,5.671391e-003,0.000000e+000,3,9.679907e-001,1.825000e+000,,,,,,,,,,,,,,,,,,0,5.000000e+000,5.000000e-001,2,1,6.883507e-001,0,0,0,
1473356780.727,,5.000000e+002,2.422191e+001,1.074745e-003,0.000000e+000,5.556377e-003,0.000000e+000,3,9.681149e-001,1.825000e+000,,,,,,,,,,,,,,,,,,0,5.000000e+000,5.000000e-001,2,1,6.638393e-001,0,0,0,
1473356794.704,,5.000000e+002,2.349516e+001,1.081850e-003,0.000000e+000,5.388964e-003,0.000000e+000,3,9.683570e-001,1.825000e+000,,,,,,,,,,,,,,,,,,0,5.000000e+000,5.000000e-001,2,1,4.644794e-001,0,0,0,
1473356808.227,,5.000000e+002,2.309698e+001,1.083324e-003,0.000000e+000,5.389376e-003,0.000000e+000,3,9.684156e-001,1.825000e+000,,,,,,,,,,,,,,,,,,0,5.000000e+000,5.000000e-001,2,1,1.833210e-001,0,0,0,
1473356821.732,,5.000000e+002,2.261312e+001,1.089349e-003,0.000000e+000,5.344096e-003,0.000000e+000,3,9.683604e-001,1.825000e+000,,,,,,,,,,,,,,,,,,0,5.000000e+000,5.000000e-001,2,1,5.183010e-001,0,0,0,
1473356834.695,,5.000000e+002,2.170107e+001,1.097394e-003,0.000000e+000,5.238580e-003,0.000000e+000,3,9.684623e-001,1.825000e+000,,,,,,,,,,,,,,,,,,0,5.000000e+000,5.000000e-001,2,1,5.456886e-001,0,0,0,
1473356848.660,,5.000000e+002,2.072222e+001,1.105134e-003,0.000000e+000,5.153788e-003,0.000000e+000,3,9.686776e-001,1.825000e+000,,,,,,,,,,,,,,,,,,0,5.000000e+000,5.000000e-001,2,1,9.394302e-001,0,0,0,
1473356862.124,,5.000000e+002,1.983978e+001,1.111541e-003,0.000000e+000,5.026654e-003,0.000000e+000,3,9.688117e-001,1.825000e+000,,,,,,,,,,,,,,,,,,0,5.000000e+000,5.000000e-001,2,1,8.254414e-001,0,0,0,
1473356876.838,,5.000000e+002,1.916251e+001,1.115356e-003,0.000000e+000,4.946490e-003,0.000000e+000,3,9.689729e-001,1.825000e+000,,,,,,,,,,,,,,,,,,0,5.000000e+000,5.000000e-001,2,1,1.271496e-001,0,0,0,
1473356889.604,,5.000000e+002,1.909424e+001,1.115404e-003,0.000000e+000,4.908903e-003,0.000000e+000,3,9.689505e-001,1.825000e+000,,,,,,,,,,,,,,,,,,0,5.000000e+000,5.000000e-001,2,1,3.459930e-003,0,0,0,
1473356904.318,,5.000000e+002,1.879358e+001,1.118294e-003,0.000000e+000,4.969089e-003,0.000000e+000,3,9.688869e-001,1.825000e+000,,,,,,,,,,,,,,,,,,0,5.000000e+000,5.000000e-001,2,1,5.112705e-001,0,0,0,
1473356918.037,,5.000000e+002,1.783825e+001,1.126651e-003,0.000000e+000,4.870040e-003,0.000000e+000,3,9.690437e-001,1.825000e+000,,,,,,,,,,,,,,,,,,0,5.000000e+000,5.000000e-001,2,1,9.932194e-001,0,0,0,
1473356931.752,,5.000000e+002,1.654394e+001,1.135483e-003,0.000000e+000,4.780554e-003,0.000000e+000,3,9.691329e-001,1.825000e+000,,,,,,,,,,,,,,,,,,0,5.000000e+000,5.000000e-001,2,1,1.181761e+000,0,0,0,
1473356945.216,,5.000000e+002,1.485659e+001,1.144674e-003,0.000000e+000,4.699543e-003,0.000000e+000,3,9.692843e-001,1.825000e+000,,,,,,,,,,,,,,,,,,0,5.000000e+000,5.000000e-001,2,1,1.168620e+000,0,0,0,
1473356961.720,,5.000000e+002,1.322304e+001,1.153271e-003,0.000000e+000,4.547387e-003,0.000000e+000,3,9.694493e-001,1.825000e+000,,,,,,,,,,,,,,,,,,0,5.000000e+000,5.000000e-001,2,1,9.926805e-001,0,0,0,
1473356972.684,,5.000000e+002,1.246954e+001,1.156435e-003,0.000000e+000,4.545458e-003,0.000000e+000,3,9.695705e-001,1.825000e+000,,,,,,,,,,,,,,,,,,0,5.000000e+000,5.000000e-001,2,1,5.143194e-001,0,0,0,
1473356991.149,,5.000000e+002,1.218238e+001,1.156126e-003,0.000000e+000,4.470493e-003,0.000000e+000,3,9.696167e-001,1.825000e+000,,,,,,,,,,,,,,,,,,0,5.000000e+000,5.000000e-001,2,1,5.085201e-001,0,1,0,
1473357006.057,,5.000000e+002,1.286654e+001,1.152715e-003,0.000000e+000,4.513532e-003,0.000000e+000,3,9.696375e-001,1.825000e+000,,,,,,,,,,,,,,,,,,0,5.000000e+000,5.000000e-001,2,1,5.989599e-001,0,1,0,
1473357161.648,,5.000000e+002,1.500640e+001,1.142649e-003,0.000000e+000,4.715290e-003,0.000000e+000,3,9.693673e-001,1.825000e+000,,,,,,,,,,,,,,,,,,0,5.000000e+000,5.000000e-001,2,1,1.230240e-003,0,1,0,
1473357174.311,,5.000000e+002,1.500640e+001,1.142694e-003,0.000000e+000,4.742121e-003,0.000000e+000,3,9.694101e-001,1.825000e+000,,,,,,,,,,,,,,,,,,0,5.000000e+000,5.000000e-001,2,1,1.230240e-003,0,1,0,
1473357186.883,,5.000000e+002,1.500457e+001,1.142666e-003,0.000000e+000,4.746049e-003,0.000000e+000,3,9.694000e-001,1.825000e+000,,,,,,,,,,,,,,,,,,0,5.000000e+000,5.000000e-001,2,1,2.439499e-003,0,1,0,
1473357200.348,,5.000000e+002,1.500426e+001,1.142676e-003,0.000000e+000,4.749776e-003,0.000000e+000,3,9.693848e-001,1.825000e+000,,,,,,,,,,,,,,,,,,0,5.000000e+000,5.000000e-001,2,1,1.830101e-003,0,1,0,
1473357293.570,,5.000000e+002,1.500152e+001,1.142708e-003,0.000000e+000,4.807236e-003,0.000000e+000,3,9.693872e-001,1.825000e+000,,,,,,,,,,,,,,,,,,0,5.000000e+000,5.000000e-001,2,1,1.219749e-003,0,1,0,
1473357305.034,,5.000000e+002,1.500213e+001,1.142688e-003,0.000000e+000,4.812198e-003,0.000000e+000,3,9.693779e-001,1.825000e+000,,,,,,,,,,,,,,,,,,0,5.000000e+000,5.000000e-001,2,1,0.000000e+000,0,1,0,
1473357317.248,,5.000000e+002,1.500121e+001,1.142642e-003,0.000000e+000,4.745558e-003,0.000000e+000,3,9.693664e-001,1.825000e+000,,,,,,,,,,,,,,,,,,0,5.000000e+000,5.000000e-001,2,1,6.103516e-004,0,1,0,
1473357329.713,,5.000000e+002,1.500091e+001,1.142638e-003,0.000000e+000,4.756053e-003,0.000000e+000,3,9.693729e-001,1.825000e+000,,,,,,,,,,,,,,,,,,0,5.000000e+000,5.000000e-001,2,1,1.219749e-003,0,1,0,
1473357398.182,,5.000000e+002,1.372441e+001,1.150277e-003,0.000000e+000,4.740648e-003,0.000000e+000,3,9.694632e-001,1.825000e+000,,,,,,,,,,,,,,,,,,0,5.000000e+000,5.000000e-001,2,1,2.235899e-001,0,0,0,
1473357410.401,,5.000000e+002,1.345224e+001,1.151744e-003,0.000000e+000,4.743818e-003,0.000000e+000,3,9.695191e-001,1.825000e+000,,,,,,,,,,,,,,,,,,0,5.000000e+000,5.000000e-001,2,1,2.142792e-001,0,0,0,
1473357423.314,,5.000000e+002,1.314345e+001,1.153153e-003,0.000000e+000,4.682025e-003,0.000000e+000,3,9.694676e-001,1.825000e+000,,,,,,,,,,,,,,,,,,0,5.000000e+000,5.000000e-001,2,1,1.985893e-001,0,0,0,
1473357435.071,,5.000000e+002,1.291851e+001,1.154299e-003,0.000000e+000,4.675611e-003,0.000000e+000,3,9.694678e-001,1.825000e+000,,,,,,,,,,,,,,,,,,0,5.000000e+000,5.000000e-001,2,1,1.563406e-001,0,0,0,
1473357448.951,,5.000000e+002,1.266729e+001,1.155680e-003,0.000000e+000,4.666129e-003,0.000000e+000,3,9.695125e-001,1.825000e+000,,,,,,,,,,,,,,,,,,0,5.000000e+000,5.000000e-001,2,1,2.532396e-001,0,0,0,
1473357461.665,,5.000000e+002,1.240747e+001,1.156727e-003,0.000000e+000,4.642320e-003,0.000000e+000,3,9.695572e-001,1.825000e+000,,,,,,,,,,,,,,,,,,0,5.000000e+000,5.000000e-001,2,1,1.751804e-001,0,0,0,
1473357473.629,,5.000000e+002,1.218780e+001,1.157832e-003,0.000000e+000,4.632509e-003,0.000000e+000,3,9.695474e-001,1.825000e+000,,,,,,,,,,,,,,,,,,0,5.000000e+000,5.000000e-001,2,1,1.737795e-001,0,0,0,
1473357486.523,,5.000000e+002,1.196959e+001,1.158861e-003,0.000000e+000,4.692567e-003,0.000000e+000,3,9.695545e-001,1.825000e+000,,,,,,,,,,,,,,,,,,0,5.000000e+000,5.000000e-001,2,1,1.759205e-001,0,0,0,
1473357498.596,,5.000000e+002,1.175101e+001,1.159748e-003,0.000000e+000,4.651875e-003,0.000000e+000,3,9.695694e-001,1.825000e+000,,,,,,,,,,,,,,,,,,0,5.000000e+000,5.000000e-001,2,1,1.747398e-001,0,0,0,
1473357512.310,,5.000000e+002,1.149071e+001,1.160888e-003,0.000000e+000,4.625672e-003,0.000000e+000,3,9.696150e-001,1.825000e+000,,,,,,,,,,,,,,,,,,0,5.000000e+000,5.000000e-001,2,1,1.736498e-001,0,0,0,
1473357524.292,,5.000000e+002,1.127579e+001,1.161862e-003,0.000000e+000,4.626413e-003,0.000000e+000,3,9.696092e-001,1.825000e+000,,,,,,,,,,,,,,,,,,0,5.000000e+000,5.000000e-001,2,1,1.707306e-001,0,0,0,
1473357535.256,,5.000000e+002,1.110518e+001,1.162704e-003,0.000000e+000,4.617001e-003,0.000000e+000,3,9.696352e-001,1.825000e+000,,,,,,,,,,,,,,,,,,0,5.000000e+000,5.000000e-001,2,1,1.704998e-001,0,0,0,
1473357548.017,,5.000000e+002,1.085308e+001,1.163632e-003,0.000000e+000,4.617213e-003,0.000000e+000,3,9.696038e-001,1.825000e+000,,,,,,,,,,,,,,,,,,0,5.000000e+000,5.000000e-001,2,1,1.685400e-001,0,0,0,
1473357559.482,,5.000000e+002,1.068468e+001,1.164508e-003,0.000000e+000,4.548267e-003,0.000000e+000,3,9.696468e-001,1.825000e+000,,,,,,,,,,,,,,,,,,0,5.000000e+000,5.000000e-001,2,1,1.682501e-001,0,0,0,
1473357571.446,,5.000000e+002,1.047590e+001,1.165300e-003,0.000000e+000,4.554454e-003,0.000000e+000,3,9.696752e-001,1.825000e+000,,,,,,,,,,,,,,,,,,0,5.000000e+000,5.000000e-001,2,1,1.676798e-001,0,0,0,
1473357584.940,,5.000000e+002,1.022737e+001,1.166206e-003,0.000000e+000,4.636273e-003,0.000000e+000,3,9.697248e-001,1.825000e+000,,,,,,,,,,,,,,,,,,0,5.000000e+000,5.000000e-001,2,1,1.662598e-001,0,0,0,
1473357607.467,,5.000000e+002,9.850266e+000,1.167645e-003,0.000000e+000,4.599785e-003,0.000000e+000,3,9.697139e-001,1.825000e+000,,,,,,,,,,,,,,,,,,0,5.000000e+000,5.000000e-001,2,1,1.662436e-001,0,0,0,
1473357620.182,,5.000000e+002,9.646827e+000,1.168500e-003,0.000000e+000,4.553311e-003,0.000000e+000,3,9.697438e-001,1.825000e+000,,,,,,,,,,,,,,,,,,0,5.000000e+000,5.000000e-001,2,1,1.623821e-001,0,0,0,
1473357633.396,,5.000000e+002,9.406085e+000,1.169181e-003,0.000000e+000,4.588150e-003,0.000000e+000,3,9.697819e-001,1.825000e+000,,,,,,,,,,,,,,,,,,0,5.000000e+000,5.000000e-001,2,1,1.587849e-001,0,0,0,
1473357645.360,,5.000000e+002,9.209063e+000,1.169878e-003,0.000000e+000,4.608748e-003,0.000000e+000,3,9.697542e-001,1.825000e+000,,,,,,,,,,,,,,,,,,0,5.000000e+000,5.000000e-001,2,1,1.562490e-001,0,0,0,
1473357669.826,,5.000000e+002,8.837982e+000,1.171124e-003,0.000000e+000,4.615592e-003,0.000000e+000,3,9.698350e-001,1.825000e+000,,,,,,,,,,,,,,,,,,0,5.000000e+000,5.000000e-001,2,1,1.915245e-001,0,0,0,
1473357681.790,,5.000000e+002,8.631381e+000,1.171684e-003,0.000000e+000,4.564930e-003,0.000000e+000,3,9.697894e-001,1.825000e+000,,,,,,,,,,,,,,,,,,0,5.000000e+000,5.000000e-001,2,1,1.466885e-001,0,0,0,
1473357694.004,,5.000000e+002,8.450660e+000,1.172233e-003,0.000000e+000,4.577825e-003,0.000000e+000,3,9.698235e-001,1.825000e+000,,,,,,,,,,,,,,,,,,0,5.000000e+000,5.000000e-001,2,1,1.427326e-001,0,0,0,
1473357705.972,,5.000000e+002,8.291119e+000,1.172751e-003,0.000000e+000,4.578041e-003,0.000000e+000,3,9.698163e-001,1.825000e+000,,,,,,,,,,,,,,,,,,0,5.000000e+000,5.000000e-001,2,1,1.049871e-001,0,0,0,
1473357731.712,,5.000000e+002,7.927502e+000,1.173773e-003,0.000000e+000,4.605334e-003,0.000000e+000,3,9.698918e-001,1.825000e+000,,,,,,,,,,,,,,,,,,0,5.000000e+000,5.000000e-001,2,1,1.342769e-001,0,0,0,
1473357744.426,,5.000000e+002,7.765171e+000,1.174320e-003,0.000000e+000,4.528202e-003,0.000000e+000,3,9.697800e-001,1.825000e+000,,,,,,,,,,,,,,,,,,0,5.000000e+000,5.000000e-001,2,1,1.289148e-001,0,0,0,
1473357755.907,,5.000000e+002,7.624346e+000,1.174656e-003,0.000000e+000,4.550177e-003,0.000000e+000,3,9.697947e-001,1.825000e+000,,,,,,,,,,,,,,,,,,0,5.000000e+000,5.000000e-001,2,1,9.255934e-002,0,0,0,
1473357767.870,,5.000000e+002,7.461175e+000,1.174992e-003,0.000000e+000,4.581776e-003,0.000000e+000,3,9.698026e-001,1.825000e+000,,,,,,,,,,,,,,,,,,0,5.000000e+000,5.000000e-001,2,1,1.173363e-001,0,0,0,
1473357817.588,,5.000000e+002,6.931169e+000,1.176392e-003,0.000000e+000,4.535167e-003,0.000000e+000,3,9.698889e-001,1.825000e+000,,,,,,,,,,,,,,,,,,0,5.000000e+000,5.000000e-001,2,1,7.812214e-002,0,1,0,
1473357829.587,,5.000000e+002,6.813600e+000,1.176668e-003,0.000000e+000,4.542714e-003,0.000000e+000,3,9.699172e-001,1.825000e+000,,,,,,,,,,,,,,,,,,0,5.000000e+000,5.000000e-001,2,1,1.151209e-001,0,1,0,
1473357841.551,,5.000000e+002,6.713395e+000,1.176852e-003,0.000000e+000,4.526278e-003,0.000000e+000,3,9.698858e-001,1.825000e+000,,,,,,,,,,,,,,,,,,0,5.000000e+000,5.000000e-001,2,1,8.528900e-002,0,1,0,
1473357855.713,,5.000000e+002,6.589453e+000,1.177176e-003,0.000000e+000,4.543311e-003,0.000000e+000,3,9.698713e-001,1.825000e+000,,,,,,,,,,,,,,,,,,0,5.000000e+000,5.000000e-001,2,1,7.307863e-002,0,1,0,
1473357916.988,,5.000000e+002,5.856871e+000,1.178687e-003,0.000000e+000,4.499289e-003,0.000000e+000,3,9.699551e-001,1.825000e+000,,,,,,,,,,,,,,,,,,0,5.000000e+000,5.000000e-001,2,1,1.596270e-001,0,1,0,
1473357929.331,,5.000000e+002,5.715677e+000,1.179113e-003,0.000000e+000,4.541703e-003,0.000000e+000,3,9.698560e-001,1.825000e+000,,,,,,,,,,,,,,,,,,0,5.000000e+000,5.000000e-001,2,1,1.227593e-001,0,1,0,
1473357941.073,,5.000000e+002,5.552672e+000,1.179324e-003,0.000000e+000,4.532692e-003,0.000000e+000,3,9.698713e-001,1.825000e+000,,,,,,,,,,,,,,,,,,0,5.000000e+000,5.000000e-001,2,1,1.481762e-001,0,1,0,
1473357952.537,,5.000000e+002,5.418247e+000,1.179616e-003,0.000000e+000,4.468554e-003,0.000000e+000,3,9.698628e-001,1.825000e+000,,,,,,,,,,,,,,,,,,0,5.000000e+000,5.000000e-001,2,1,1.206727e-001,0,1,0,
1473358076.809,,5.000000e+002,5.056865e+000,1.180253e-003,0.000000e+000,4.479956e-003,0.000000e+000,3,9.699093e-001,1.825000e+000,,,,,,,,,,,,,,,,,,0,5.000000e+000,5.000000e-001,2,1,2.157688e-003,0,0,0,
1473358089.801,,5.000000e+002,5.067492e+000,1.180278e-003,0.000000e+000,4.454226e-003,0.000000e+000,3,9.698768e-001,1.825000e+000,,,,,,,,,,,,,,,,,,0,5.000000e+000,5.000000e-001,2,1,5.356789e-003,0,0,0,
1473358101.265,,5.000000e+002,5.072561e+000,1.180198e-003,0.000000e+000,4.435148e-003,0.000000e+000,3,9.698901e-001,1.825000e+000,,,,,,,,,,,,,,,,,,0,5.000000e+000,5.000000e-001,2,1,4.783154e-003,0,0,0,
1473358113.421,,5.000000e+002,5.076298e+000,1.180226e-003,0.000000e+000,4.419023e-003,0.000000e+000,3,9.699144e-001,1.825000e+000,,,,,,,,,,,,,,,,,,0,5.000000e+000,5.000000e-001,2,1,2.689838e-003,0,0,0,